Workbook

Sheet Compiled
A1: Stress | B1: Exp | C1: Sim | D1: Ratio
A2: 173 | B2: =(Exp_773K_173MPa!C6-Exp_773K_173MPa!C2)/(Exp_773K_173MPa!B6-Exp_773K_173MPa!B2) -> 4.2938365e-11 | C2: =('773K_173MPa_64g'!B82-'773K_173MPa_64g'!B62)/('773K_173MPa_64g'!A82-'773K_173MPa_64g'!A62) -> 1.2817741e-10 | D2: =C2/B2 -> 2.9851487
A3: 121 | B3: =(Exp_773K_121MPa!C6-Exp_773K_121MPa!C2)/(Exp_773K_121MPa!B6-Exp_773K_121MPa!B2) -> 3.1469774e-11 | C3: =('773K_121MPa_64g'!B71-'773K_121MPa_64g'!B51)/('773K_121MPa_64g'!A71-'773K_121MPa_64g'!A51) -> 2.1260066e-11 | D3: =C3/B3 -> 0.67557099
A4: 87 | B4: =(Exp_773K_87MPa!C6-Exp_773K_87MPa!C2)/(Exp_773K_87MPa!B6-Exp_773K_87MPa!B2) -> 1.8581591e-11 | C4: =('773K_87MPa_64g'!B71-'773K_87MPa_64g'!B51)/('773K_87MPa_64g'!A71-'773K_87MPa_64g'!A51) -> 1.4469304e-11 | D4: =C4/B4 -> 0.77869024
A5: 52 | B5: =(Exp_773K_52MPa!C6-Exp_773K_52MPa!C2)/(Exp_773K_52MPa!B6-Exp_773K_52MPa!B2) -> 1.1756422e-11 | C5: =('773K_52MPa_64g'!B71-'773K_52MPa_64g'!B51)/('773K_52MPa_64g'!A71-'773K_52MPa_64g'!A51) -> 8.5299935e-12 | D5: =C5/B5 -> 0.72556032

Sheet 773K_173MPa_64g
A1: time | B1: Ep_eff | D1: cstrain_1 | E1: cstrain_10 | F1: cstrain_11 | G1: cstrain_12 | H1: cstrain_13 | I1: cstrain_14 | J1: cstrain_15 | K1: cstrain_16 | L1: cstrain_17 | M1: cstrain_18 | N1: cstrain_19 | O1: cstrain_2 | P1: cstrain_20 | Q1: cstrain_21 | R1: cstrain_22 | S1: cstrain_23 | T1: cstrain_24 | U1: cstrain_3 | V1: cstrain_4 | W1: cstrain_5 | X1: cstrain_6 | Y1: cstrain_7 | Z1: cstrain_8 | AA1: cstrain_9 | AB1: cstrainfrac1 | AC1: cstrainfrac2 | AD1: eeq | AE1: gstrain_1 | AF1: gstrain_10 | AG1: gstrain_11 | AH1: gstrain_12 | AI1: gstrain_13 | AJ1: gstrain_14 | AK1: gstrain_15 | AL1: gstrain_16 | AM1: gstrain_17 | AN1: gstrain_18 | AO1: gstrain_19 | AP1: gstrain_2 | AQ1: gstrain_20 | AR1: gstrain_21 | AS1: gstrain_22 | AT1: gstrain_23 | AU1: gstrain_24 | AV1: gstrain_3 | AW1: gstrain_4 | AX1: gstrain_5 | AY1: gstrain_6 | AZ1: gstrain_7 | BA1: gstrain_8 | BB1: gstrain_9 | BC1: rho_i | BD1: rho_m | BE1: strain_xx | BF1: strain_yy | BG1: strain_zz | BH1: stress_xx | BI1: stress_yy | BJ1: stress_zz | BK1: vonmises
A2: 0 | B2: 0 | D2: 0 | E2: 0 | F2: 0 | G2: 0 | H2: 0 | I2: 0 | J2: 0 | K2: 0 | L2: 0 | M2: 0 | N2: 0 | O2: 0 | P2: 0 | Q2: 0 | R2: 0 | S2: 0 | T2: 0 | U2: 0 | V2: 0 | W2: 0 | X2: 0 | Y2: 0 | Z2: 0 | AA2: 0 | AB2: 0 | AC2: 0 | AD2: 0 | AE2: 0 | AF2: 0 | AG2: 0 | AH2: 0 | AI2: 0 | AJ2: 0 | AK2: 0 | AL2: 0 | AM2: 0 | AN2: 0 | AO2: 0 | AP2: 0 | AQ2: 0 | AR2: 0 | AS2: 0 | AT2: 0 | AU2: 0 | AV2: 0 | AW2: 0 | AX2: 0 | AY2: 0 | AZ2: 0 | BA2: 0 | BB2: 0 | BC2: 0 | BD2: 0 | BE2: 0 | BF2: 0 | BG2: 0 | BH2: 0 | BI2: 0 | BJ2: 0 | BK2: 0
A3: 0.39716412 | B3: 1.303504e-14 | D3: 4.276218e-15 | E3: 5.171694e-15 | F3: 5.171694e-15 | G3: 5.171694e-15 | H3: 4.276218e-15 | I3: 4.276218e-15 | J3: 4.276218e-15 | K3: 4.5333744e-15 | L3: 4.5333744e-15 | M3: 4.5333744e-15 | N3: 4.7240689e-15 | O3: 4.276218e-15 | P3: 4.7240689e-15 | Q3: 4.7240689e-15 | R3: 5.171694e-15 | S3: 5.171694e-15 | T3: 5.171694e-15 | U3: 4.276218e-15 | V3: 4.5333744e-15 | W3: 4.5333744e-15 | X3: 4.5333744e-15 | Y3: 4.7240689e-15 | Z3: 4.7240689e-15 | AA3: 4.7240689e-15 | AB3: 1 | AC3: 1 | AD3: 2.1719977e-06 | AE3: 3.5534297e-28 | AF3: -3.0489455e-28 | AG3: 4.53743e-28 | AH3: -4.4524357e-28 | AI3: -6.7852105e-29 | AJ3: -3.1005518e-28 | AK3: 2.2466826e-28 | AL3: 2.6509988e-28 | AM3: 1.7203459e-28 | AN3: -3.9923604e-28 | AO3: 2.0875491e-28 | AP3: -2.0885686e-28 | AQ3: 6.6761722e-28 | AR3: -8.3446218e-28 | AS3: 4.1056385e-28 | AT3: 6.9172389e-29 | AU3: -4.7640056e-28 | AV3: -2.0219835e-28 | AW3: 2.522356e-28 | AX3: 6.2596494e-29 | AY3: -2.7172138e-28 | AZ3: 2.8967264e-28 | BA3: 6.0179856e-28 | BB3: -8.7247492e-28 | BC3: 16000000 | BD3: 4000000 | BE3: -1.0595459e-06 | BF3: 2.2239772e-06 | BG3: 6.3087334e-07 | BH3: -1.4189681e-08 | BI3: 0.52894053 | BJ3: 0.26447038 | BK3: 0.48684516
A4: 3.9716412 | B4: 1.3264095e-12 | D4: 4.2847775e-14 | E4: 5.1831621e-14 | F4: 5.1831621e-14 | G4: 5.1831621e-14 | H4: 4.2847775e-14 | I4: 4.2847775e-14 | J4: 4.2847775e-14 | K4: 4.541833e-14 | L4: 4.541833e-14 | M4: 4.541833e-14 | N4: 4.7339212e-14 | O4: 4.2847775e-14 | P4: 4.7339212e-14 | Q4: 4.7339212e-14 | R4: 5.1831621e-14 | S4: 5.1831621e-14 | T4: 5.1831621e-14 | U4: 4.2847775e-14 | V4: 4.541833e-14 | W4: 4.541833e-14 | X4: 4.541833e-14 | Y4: 4.7339212e-14 | Z4: 4.7339212e-14 | AA4: 4.7339212e-14 | AB4: 1 | AC4: 1 | AD4: 2.1718031e-05 | AE4: 7.1492667e-27 | AF4: 3.2796171e-26 | AG4: 5.211159e-26 | AH4: 2.4709375e-27 | AI4: 3.1723756e-27 | AJ4: 2.4144649e-27 | AK4: 1.9020786e-26 | AL4: 1.8348709e-26 | AM4: -8.5223944e-27 | AN4: -6.2868989e-27 | AO4: 2.4445294e-26 | AP4: -3.7251564e-27 | AQ4: 2.6900474e-26 | AR4: -6.2560676e-26 | AS4: 7.1828656e-27 | AT4: 1.2474409e-26 | AU4: -3.1879189e-26 | AV4: -1.2333497e-26 | AW4: 5.5001682e-27 | AX4: 2.579602e-26 | AY4: -5.0475573e-27 | AZ4: -2.0288203e-26 | BA4: 2.8997001e-26 | BB4: -7.5300348e-26 | BC4: 16000000 | BD4: 4000000 | BE4: -1.0595225e-05 | BF4: 2.2236969e-05 | BG4: 6.3089258e-06 | BH4: -1.4192439e-06 | BI4: 5.289393 | BJ4: 2.6447085 | BK4: 4.8684002
A5: 39.716412 | B5: 1.3490679e-10 | D5: 4.3728323e-13 | E5: 5.3009476e-13 | F5: 5.3009476e-13 | G5: 5.3009476e-13 | H5: 4.3728323e-13 | I5: 4.3728323e-13 | J5: 4.3728323e-13 | K5: 4.6285308e-13 | L5: 4.6285308e-13 | M5: 4.6285308e-13 | N5: 4.8351526e-13 | O5: 4.3728323e-13 | P5: 4.8351526e-13 | Q5: 4.8351526e-13 | R5: 5.3009476e-13 | S5: 5.3009476e-13 | T5: 5.3009476e-13 | U5: 4.3728323e-13 | V5: 4.6285308e-13 | W5: 4.6285308e-13 | X5: 4.6285308e-13 | Y5: 4.8351526e-13 | Z5: 4.8351526e-13 | AA5: 4.8351526e-13 | AB5: 0.99999995 | AC5: 0.99999982 | AD5: 0.00021698605 | AE5: -1.1553236e-20 | AF5: 6.8937177e-20 | AG5: 5.8369313e-20 | AH5: 8.4958859e-21 | AI5: -1.7831054e-21 | AJ5: 1.645473e-20 | AK5: 4.6317207e-21 | AL5: 1.8905846e-20 | AM5: -2.54188e-21 | AN5: -4.8112731e-22 | AO5: 2.2401116e-20 | AP5: -6.5952669e-22 | AQ5: 1.2237034e-20 | AR5: -8.1879583e-20 | AS5: -8.6284449e-21 | AT5: 8.663903e-21 | AU5: -2.1862063e-20 | AV5: -1.5035811e-20 | AW5: -5.2801793e-21 | AX5: 5.4433429e-20 | AY5: 1.0027286e-20 | AZ5: -3.9296692e-20 | BA5: 4.1156316e-20 | BB5: -1.3725097e-19 | BC5: 16000000 | BD5: 4000000 | BE5: -0.00010592893 | BF5: 0.00022208992 | BG5: 6.31084e-05 | BH5: -0.0001420993 | BI5: 52.892701 | BJ5: 26.447545 | BK5: 48.67888
A6: 397.16412 | B6: 4.5268777e-07 | D6: 2.267314e-12 | E6: 2.7732976e-12 | F6: 2.7732908e-12 | G6: 2.7732768e-12 | H6: 2.2672961e-12 | I6: 2.2673008e-12 | J6: 2.2672975e-12 | K6: 2.3839266e-12 | L6: 2.3839405e-12 | M6: 2.383924e-12 | N6: 2.515509e-12 | O6: 2.2672963e-12 | P6: 2.5155026e-12 | Q6: 2.5155644e-12 | R6: 2.7732772e-12 | S6: 2.7732728e-12 | T6: 2.7732766e-12 | U6: 2.2672978e-12 | V6: 2.3839347e-12 | W6: 2.3839482e-12 | X6: 2.3839319e-12 | Y6: 2.5155085e-12 | Z6: 2.5155694e-12 | AA6: 2.515585e-12 | AB6: 0.39504736 | AC6: 0.20893614 | AD6: 0.00081720485 | AE6: -3.5057464e-11 | AF6: 1.9399995e-10 | AG6: 1.1904631e-10 | AH6: 1.6380066e-12 | AI6: -3.353551e-12 | AJ6: 3.1109848e-11 | AK6: -3.4641475e-13 | AL6: 2.1276012e-11 | AM6: 1.4589117e-11 | AN6: -9.3339925e-12 | AO6: 3.409205e-11 | AP6: 5.9973175e-13 | AQ6: 1.028134e-11 | AR6: -2.7912374e-10 | AS6: -2.1113031e-11 | AT6: 6.6767038e-12 | AU6: -2.9374825e-11 | AV6: -2.1086004e-11 | AW6: -1.8881395e-11 | AX6: 1.3483863e-10 | AY6: 2.6686017e-11 | AZ6: -7.3384548e-11 | BA6: 2.1865333e-10 | BB6: -5.8196135e-10 | BC6: 16000200 | BD6: 4000043.4 | BE6: -0.00040012104 | BF6: 0.0008352942 | BG6: 0.0002385652 | BH6: -0.002005185 | BI6: 199.74983 | BJ6: 99.891739 | BK6: 183.7848
A7: 3971.6412 | B7: 5.7176149e-06 | D7: 2.2683608e-12 | E7: 2.7727723e-12 | F7: 2.7726892e-12 | G7: 2.77244e-12 | H7: 2.268039e-12 | I7: 2.2681217e-12 | J7: 2.2680643e-12 | K7: 2.3832255e-12 | L7: 2.3834636e-12 | M7: 2.3831784e-12 | N7: 2.5161782e-12 | O7: 2.2680425e-12 | P7: 2.5160805e-12 | Q7: 2.5168717e-12 | R7: 2.7724399e-12 | S7: 2.7723655e-12 | T7: 2.7724346e-12 | U7: 2.26807e-12 | V7: 2.3833629e-12 | W7: 2.3835867e-12 | X7: 2.3833239e-12 | Y7: 2.5161872e-12 | Z7: 2.5170797e-12 | AA7: 2.5172061e-12 | AB7: 0.3888344 | AC7: 0.20428004 | AD7: 0.00082238384 | AE7: -2.6606405e-11 | AF7: 1.4926978e-10 | AG7: 1.0697734e-10 | AH7: 3.8451949e-12 | AI7: -3.3242177e-12 | AJ7: 2.6859086e-11 | AK7: -5.5617227e-13 | AL7: 1.8533193e-11 | AM7: 1.2726067e-11 | AN7: -7.6193679e-12 | AO7: 2.2086433e-11 | AP7: 3.5234405e-13 | AQ7: 6.0235917e-12 | AR7: -1.1851536e-10 | AS7: -1.4521003e-11 | AT7: 5.085493e-12 | AU7: -2.6160207e-11 | AV7: -2.1103861e-11 | AW7: -1.4312222e-11 | AX7: 1.054475e-10 | AY7: 2.3749058e-11 | AZ7: -6.3195551e-11 | BA7: 1.2018472e-10 | BB7: -3.0445422e-10 | BC7: 16002481 | BD7: 4000553.7 | BE7: -0.000404374 | BF7: 0.00083964842 | BG7: 0.0002386724 | BH7: -0.0021745864 | BI7: 199.7496 | BJ7: 99.891679 | BK7: 183.8081
A8: 39716.412 | B8: 3.5374998e-05 | D8: 2.2728119e-12 | E8: 2.7724154e-12 | F8: 2.7721204e-12 | G8: 2.770476e-12 | H8: 2.2703096e-12 | I8: 2.2709512e-12 | J8: 2.2705233e-12 | K8: 2.3819535e-12 | L8: 2.3835095e-12 | M8: 2.3815302e-12 | N8: 2.5178142e-12 | O8: 2.2703342e-12 | P8: 2.5172398e-12 | Q8: 2.5211958e-12 | R8: 2.7702594e-12 | S8: 2.7697296e-12 | T8: 2.7702712e-12 | U8: 2.2706229e-12 | V8: 2.3828358e-12 | W8: 2.3843518e-12 | X8: 2.3827404e-12 | Y8: 2.5180515e-12 | Z8: 2.5224824e-12 | AA8: 2.5236763e-12 | AB8: 0.36528927 | AC8: 0.18237294 | AD8: 0.00085062359 | AE8: -4.5179108e-12 | AF8: 7.2319499e-11 | AG8: 5.88625e-11 | AH8: 1.0031434e-11 | AI8: -2.491887e-12 | AJ8: 1.3747072e-11 | AK8: -4.5348994e-13 | AL8: 1.2610561e-11 | AM8: 6.8074366e-12 | AN8: -2.343141e-12 | AO8: 7.052851e-12 | AP8: -9.1935645e-13 | AQ8: 3.2777603e-12 | AR8: -4.7043166e-11 | AS8: -4.2250787e-12 | AT8: 2.0355324e-12 | AU8: -1.3125975e-11 | AV8: -1.8888785e-11 | AW8: -4.2725293e-12 | AX8: 6.1413384e-11 | AY8: 1.5157582e-11 | AZ8: -3.5483808e-11 | BA8: 3.1471096e-11 | BB8: -1.2014818e-10 | BC8: 16014355 | BD8: 4003392 | BE8: -0.00042750124 | BF8: 0.00086401627 | BG8: 0.00023953617 | BH8: -0.0028107798 | BI8: 199.74796 | BJ8: 99.891496 | BK8: 183.96751
A9: 397164.12 | B9: 0.00016867573 | D9: 2.290485e-12 | E9: 2.7787189e-12 | F9: 2.7779044e-12 | G9: 2.774028e-12 | H9: 2.2788988e-12 | I9: 2.2817813e-12 | J9: 2.2796394e-12 | K9: 2.3864021e-12 | L9: 2.3936441e-12 | M9: 2.383615e-12 | N9: 2.5225133e-12 | O9: 2.2788828e-12 | P9: 2.5189612e-12 | Q9: 2.5332717e-12 | R9: 2.770306e-12 | S9: 2.7678546e-12 | T9: 2.7707901e-12 | U9: 2.2811919e-12 | V9: 2.3900732e-12 | W9: 2.3982691e-12 | X9: 2.3907917e-12 | Y9: 2.5235206e-12 | Z9: 2.5386161e-12 | AA9: 2.5449809e-12 | AB9: 0.36279437 | AC9: 0.1406277 | AD9: 0.00097400494 | AE9: 2.3382705e-13 | AF9: 2.0730374e-11 | AG9: 1.9060745e-11 | AH9: 1.1171522e-11 | AI9: -2.1222123e-13 | AJ9: 3.8208453e-12 | AK9: 9.7849094e-13 | AL9: 4.3803012e-12 | AM9: 1.1306759e-12 | AN9: -9.3113499e-13 | AO9: 1.6202086e-12 | AP9: -3.8346339e-12 | AQ9: 2.2786207e-12 | AR9: -1.4587134e-11 | AS9: 1.490844e-12 | AT9: 3.2468623e-13 | AU9: -1.5986627e-12 | AV9: -1.1488279e-11 | AW9: -4.0724342e-12 | AX9: 2.4422068e-11 | AY9: 9.0779599e-12 | AZ9: -1.6949604e-11 | BA9: 4.0211293e-12 | BB9: -3.6418415e-11 | BC9: 16059219 | BD9: 4015313.1 | BE9: -0.00052537467 | BF9: 0.00097454757 | BG9: 0.00024815943 | BH9: -0.004988434 | BI9: 199.74529 | BJ9: 99.891966 | BK9: 184.63053
A10: 44562.547 | B10: 3.8289099e-05 | D10: 2.2741853e-12 | E10: 2.7725258e-12 | F10: 2.772165e-12 | G10: 2.7701752e-12 | H10: 2.2709732e-12 | I10: 2.271798e-12 | J10: 2.2712515e-12 | K10: 2.3819661e-12 | L10: 2.3839205e-12 | M10: 2.3813986e-12 | N10: 2.5181611e-12 | O10: 2.2710027e-12 | P10: 2.5174303e-12 | Q10: 2.5222584e-12 | R10: 2.7698181e-12 | S10: 2.7691427e-12 | T10: 2.7698391e-12 | U10: 2.2714025e-12 | V10: 2.3830645e-12 | W10: 2.3850135e-12 | X10: 2.3829839e-12 | Y10: 2.5184756e-12 | Z10: 2.5238356e-12 | AA10: 2.5254417e-12 | AB10: 0.36109247 | AC10: 0.17693983 | AD10: 0.00085334435 | AE10: -3.0298902e-12 | AF10: 6.2065669e-11 | AG10: 5.1199942e-11 | AH10: 1.0965148e-11 | AI10: -2.2495304e-12 | AJ10: 1.2004285e-11 | AK10: -4.0367966e-13 | AL10: 1.154702e-11 | AM10: 5.5354282e-12 | AN10: -1.842363e-12 | AO10: 5.8143576e-12 | AP10: -1.2698285e-12 | AQ10: 3.1413325e-12 | AR10: -4.0954327e-11 | AS10: -2.9385472e-12 | AT10: 1.6199207e-12 | AU10: -1.0919243e-11 | AV10: -1.8143104e-11 | AW10: -3.4899158e-12 | AX10: 5.5860599e-11 | AY10: 1.3785456e-11 | AZ10: -3.1886974e-11 | BA10: 2.5075571e-11 | BB10: -1.0277766e-10 | BC10: 16015452 | BD10: 4003665.7 | BE10: -0.00042971393 | BF10: 0.00086640677 | BG10: 0.00023964551 | BH10: -0.0023114046 | BI10: 199.74779 | BJ10: 99.89181 | BK10: 183.98262
A11: 50000 | B11: 4.1436182e-05 | D11: 2.274699e-12 | E11: 2.772605e-12 | F11: 2.7722196e-12 | G11: 2.770112e-12 | H11: 2.2712145e-12 | I11: 2.2721095e-12 | J11: 2.2715174e-12 | K11: 2.3820041e-12 | L11: 2.3841123e-12 | M11: 2.3813782e-12 | N11: 2.5182994e-12 | O11: 2.2712454e-12 | P11: 2.5175051e-12 | Q11: 2.5226597e-12 | R11: 2.7696903e-12 | S11: 2.768959e-12 | T11: 2.7697159e-12 | U11: 2.2716919e-12 | V11: 2.383184e-12 | W11: 2.3853058e-12 | X11: 2.3831129e-12 | Y11: 2.5186423e-12 | Z11: 2.5243466e-12 | AA11: 2.5261137e-12 | AB11: 0.3598247 | AC11: 0.17500933 | AD11: 0.00085628135 | AE11: -2.6986346e-12 | AF11: 5.8817903e-11 | AG11: 4.8789341e-11 | AH11: 1.121864e-11 | AI11: -2.1621514e-12 | AJ11: 1.1455493e-11 | AK11: -3.7422444e-13 | AL11: 1.1176782e-11 | AM11: 5.1311015e-12 | AN11: -1.7116578e-12 | AO11: 5.4656172e-12 | AP11: -1.3955341e-12 | AQ11: 3.1041616e-12 | AR11: -3.9037729e-11 | AS11: -2.533168e-12 | AT11: 1.495844e-12 | AU11: -1.021436e-11 | AV11: -1.7857734e-11 | AW11: -3.3160342e-12 | AX11: 5.4031988e-11 | AY11: 1.3366062e-11 | AZ11: -3.0786156e-11 | BA11: 2.3210259e-11 | BB11: -9.7555107e-11 | BC11: 16016626 | BD11: 4003960.3 | BE11: -0.00043210127 | BF11: 0.00086898963 | BG11: 0.00023977185 | BH11: -0.0023323937 | BI11: 199.74764 | BJ11: 99.891816 | BK11: 183.9994
A12: 56100.923 | B12: 4.4833228e-05 | D12: 2.2752506e-12 | E12: 2.772697e-12 | F12: 2.7722859e-12 | G12: 2.7700579e-12 | H12: 2.2714739e-12 | I12: 2.2724439e-12 | J12: 2.2718029e-12 | K12: 2.3821326e-12 | L12: 2.3844064e-12 | M12: 2.3814426e-12 | N12: 2.5184461e-12 | O12: 2.2715061e-12 | P12: 2.5175818e-12 | Q12: 2.5230838e-12 | R12: 2.7695626e-12 | S12: 2.7687714e-12 | T12: 2.7695937e-12 | U12: 2.2720044e-12 | V12: 2.3833992e-12 | W12: 2.3857093e-12 | X12: 2.3833401e-12 | Y12: 2.5188189e-12 | Z12: 2.5248882e-12 | AA12: 2.5268287e-12 | AB12: 0.35861834 | AC12: 0.17301422 | AD12: 0.00085944665 | AE12: -2.4164233e-12 | AF12: 5.5632901e-11 | AG12: 4.6434723e-11 | AH12: 1.1445345e-11 | AI12: -2.0714693e-12 | AJ12: 1.0916145e-11 | AK12: -3.3797207e-13 | AL12: 1.0798426e-11 | AM12: 4.7400977e-12 | AN12: -1.5941725e-12 | AO12: 5.1392943e-12 | AP12: -1.5260611e-12 | AQ12: 3.0696161e-12 | AR12: -3.7153853e-11 | AS12: -2.1365732e-12 | AT12: 1.3772273e-12 | AU12: -9.5218617e-12 | AV12: -1.7559418e-11 | AW12: -3.1756945e-12 | AX12: 5.2199394e-11 | AY12: 1.2962664e-11 | AZ12: -2.9716166e-11 | BA12: 2.1438824e-11 | BB12: -9.2511251e-11 | BC12: 16017883 | BD12: 4004277.3 | BE12: -0.0004346707 | BF12: 0.00087177796 | BG12: 0.00023991429 | BH12: -0.0023546351 | BI12: 199.74748 | BJ12: 99.891822 | BK12: 184.01742
A13: 62946.271 | B13: 4.8498453e-05 | D13: 2.2758445e-12 | E13: 2.7728038e-12 | F13: 2.7723662e-12 | G13: 2.7700159e-12 | H13: 2.271755e-12 | I13: 2.2728049e-12 | J13: 2.2721116e-12 | K13: 2.3822869e-12 | L13: 2.3847393e-12 | M13: 2.3815268e-12 | N13: 2.5186001e-12 | O13: 2.2717881e-12 | P13: 2.5176587e-12 | Q13: 2.5235299e-12 | R13: 2.7694368e-12 | S13: 2.7685814e-12 | T13: 2.7694745e-12 | U13: 2.2723438e-12 | V13: 2.3836459e-12 | W13: 2.3861613e-12 | X13: 2.3836015e-12 | Y13: 2.5190044e-12 | Z13: 2.5254603e-12 | AA13: 2.527587e-12 | AB13: 0.35749203 | AC13: 0.17095988 | AD13: 0.00086285668 | AE13: -2.1775716e-12 | AF13: 5.2523894e-11 | AG13: 4.4142211e-11 | AH13: 1.164203e-11 | AI13: -1.977372e-12 | AJ13: 1.0386515e-11 | AK13: -2.9434195e-13 | AL13: 1.0411813e-11 | AM13: 4.3643104e-12 | AN13: -1.4897976e-12 | AO13: 4.8348194e-12 | AP13: -1.6609721e-12 | AQ13: 3.0369291e-12 | AR13: -3.5305687e-11 | AS13: -1.751177e-12 | AT13: 1.2646939e-12 | AU13: -8.8443202e-12 | AV13: -1.7248274e-11 | AW13: -3.0689379e-12 | AX13: 5.0364537e-11 | AY13: 1.2578507e-11 | AZ13: -2.8677943e-11 | BA13: 1.9761228e-11 | BB13: -8.7650054e-11 | BC13: 16019228 | BD13: 4004618.1 | BE13: -0.00043743475 | BF13: 0.00087478697 | BG13: 0.00024007495 | BH13: -0.0023781739 | BI13: 199.74732 | BJ13: 99.891829 | BK13: 184.03675
... A76: 49077747 | B76: 0.0054577419 | D76: 2.5306151e-12 | E76: 2.8929075e-12 | F76: 2.9322316e-12 | G76: 2.8406466e-12 | H76: 2.2936796e-12 | I76: 2.3894673e-12 | J76: 2.2028909e-12 | K76: 2.4401077e-12 | L76: 2.6472589e-12 | M76: 2.4051941e-12 | N76: 2.6167205e-12 | O76: 2.2789636e-12 | P76: 2.4420101e-12 | Q76: 2.7395865e-12 | R76: 2.7489745e-12 | S76: 2.6773307e-12 | T76: 2.8567688e-12 | U76: 2.2701347e-12 | V76: 2.5534354e-12 | W76: 2.7700947e-12 | X76: 2.4757279e-12 | Y76: 2.6021414e-12 | Z76: 2.798416e-12 | AA76: 2.9211948e-12 | AB76: 0.54229721 | AC76: 0.24156932 | AD76: 0.0062913361 | AE76: 1.4869096e-12 | AF76: 6.0355234e-12 | AG76: 5.5765667e-12 | AH76: 3.0298752e-12 | AI76: -3.9258675e-13 | AJ76: 9.1854989e-14 | AK76: 9.1007313e-13 | AL76: 3.5681961e-13 | AM76: 1.5193905e-12 | AN76: -1.1473169e-12 | AO76: -1.4944429e-12 | AP76: -5.2739252e-13 | AQ76: -1.4417691e-13 | AR76: -5.9802354e-12 | AS76: -2.2423383e-13 | AT76: 6.2737198e-14 | AU76: -1.7182321e-12 | AV76: -1.2601629e-12 | AW76: -1.0234724e-12 | AX76: 3.4099248e-12 | AY76: 9.6114247e-13 | AZ76: -4.3762131e-12 | BA76: 5.8297401e-13 | BB76: -6.7662332e-12 | BC76: 16632171 | BD76: 4307379.3 | BE76: -0.0037822105 | BF76: 0.0062511712 | BG76: 0.0012221966 | BH76: -0.017701937 | BI76: 199.70137 | BJ76: 99.89148 | BK76: 187.53034

Sheet 773K_52MPa_64g
A1: time | B1: Ep_eff | C1: StrainRate | D1: cstrain_1 | E1: cstrain_10 | F1: cstrain_11 | G1: cstrain_12 | H1: cstrain_13 | I1: cstrain_14 | J1: cstrain_15 | K1: cstrain_16 | L1: cstrain_17 | M1: cstrain_18 | N1: cstrain_19 | O1: cstrain_2 | P1: cstrain_20 | Q1: cstrain_21 | R1: cstrain_22 | S1: cstrain_23 | T1: cstrain_24 | U1: cstrain_3 | V1: cstrain_4 | W1: cstrain_5 | X1: cstrain_6 | Y1: cstrain_7 | Z1: cstrain_8 | AA1: cstrain_9 | AB1: cstrainfrac1 | AC1: cstrainfrac2 | AD1: eeq | AE1: gstrain_1 | AF1: gstrain_10 | AG1: gstrain_11 | AH1: gstrain_12 | AI1: gstrain_13 | AJ1: gstrain_14 | AK1: gstrain_15 | AL1: gstrain_16 | AM1: gstrain_17 | AN1: gstrain_18 | AO1: gstrain_19 | AP1: gstrain_2 | AQ1: gstrain_20 | AR1: gstrain_21 | AS1: gstrain_22 | AT1: gstrain_23 | AU1: gstrain_24 | AV1: gstrain_3 | AW1: gstrain_4 | AX1: gstrain_5 | AY1: gstrain_6 | AZ1: gstrain_7 | BA1: gstrain_8 | BB1: gstrain_9 | BC1: rho_i | BD1: rho_m | BE1: strain_xx | BF1: strain_yy | BG1: strain_zz | BH1: stress_xx | BI1: stress_yy | BJ1: stress_zz | BK1: vonmises
A2: 0 | B2: 0 | D2: 0 | E2: 0 | F2: 0 | G2: 0 | H2: 0 | I2: 0 | J2: 0 | K2: 0 | L2: 0 | M2: 0 | N2: 0 | O2: 0 | P2: 0 | Q2: 0 | R2: 0 | S2: 0 | T2: 0 | U2: 0 | V2: 0 | W2: 0 | X2: 0 | Y2: 0 | Z2: 0 | AA2: 0 | AB2: 0 | AC2: 0 | AD2: 0 | AE2: 0 | AF2: 0 | AG2: 0 | AH2: 0 | AI2: 0 | AJ2: 0 | AK2: 0 | AL2: 0 | AM2: 0 | AN2: 0 | AO2: 0 | AP2: 0 | AQ2: 0 | AR2: 0 | AS2: 0 | AT2: 0 | AU2: 0 | AV2: 0 | AW2: 0 | AX2: 0 | AY2: 0 | AZ2: 0 | BA2: 0 | BB2: 0 | BC2: 0 | BD2: 0 | BE2: 0 | BF2: 0 | BG2: 0 | BH2: 0 | BI2: 0 | BJ2: 0 | BK2: 0
A3: 0.39716412 | B3: 3.7804376e-15 | C3: =(BF3-BF2)/(A3-A2) -> 1.6831461e-06 | D3: 1.2852078e-15 | E3: 1.5543018e-15 | F3: 1.5543018e-15 | G3: 1.5543018e-15 | H3: 1.2852078e-15 | I3: 1.2852078e-15 | J3: 1.2852078e-15 | K3: 1.3624938e-15 | L3: 1.3624938e-15 | M3: 1.3624938e-15 | N3: 1.4197905e-15 | O3: 1.2852078e-15 | P3: 1.4197905e-15 | Q3: 1.4197905e-15 | R3: 1.5543018e-15 | S3: 1.5543018e-15 | T3: 1.5543018e-15 | U3: 1.2852078e-15 | V3: 1.3624938e-15 | W3: 1.3624938e-15 | X3: 1.3624938e-15 | Y3: 1.4197905e-15 | Z3: 1.4197905e-15 | AA3: 1.4197905e-15 | AB3: 1 | AC3: 1 | AD3: 6.5285935e-07 | AE3: 1.9651072e-28 | AF3: -2.6062795e-28 | AG3: 1.3940386e-28 | AH3: -2.7469899e-28 | AI3: -6.9391133e-29 | AJ3: -1.8627427e-28 | AK3: 7.60127e-29 | AL3: 1.3439296e-28 | AM3: 1.2701404e-28 | AN3: -2.2764603e-28 | AO3: 6.4381532e-29 | AP3: -1.2824681e-28 | AQ3: 3.4410003e-28 | AR3: -3.5769246e-28 | AS3: 2.1163419e-28 | AT3: 3.0525141e-30 | AU3: -1.9346673e-28 | AV3: -1.1212728e-28 | AW3: 1.219317e-28 | AX3: 3.5671408e-30 | AY3: -1.1703634e-28 | AZ3: 2.1289675e-28 | BA3: 2.7310468e-28 | BB3: -3.8153988e-28 | BC3: 16000000 | BD3: 4000000 | BE3: -3.1847677e-07 | BF3: 6.6848524e-07 | BG3: 1.8962622e-07 | BH3: -1.28265e-09 | BI3: 0.15898793 | BJ3: 0.079493977 | BK3: 0.14633508
A4: 3.9716412 | B4: 3.9801798e-13 | C4: =(BF4-BF3)/(A4-A3) -> 1.6830753e-06 | D4: 1.2858954e-14 | E4: 1.55525e-14 | F4: 1.55525e-14 | G4: 1.55525e-14 | H4: 1.2858954e-14 | I4: 1.2858954e-14 | J4: 1.2858954e-14 | K4: 1.3631867e-14 | L4: 1.3631867e-14 | M4: 1.3631867e-14 | N4: 1.4205963e-14 | O4: 1.2858954e-14 | P4: 1.4205963e-14 | Q4: 1.4205963e-14 | R4: 1.55525e-14 | S4: 1.55525e-14 | T4: 1.55525e-14 | U4: 1.2858954e-14 | V4: 1.3631867e-14 | W4: 1.3631867e-14 | X4: 1.3631867e-14 | Y4: 1.4205963e-14 | Z4: 1.4205963e-14 | AA4: 1.4205963e-14 | AB4: 1 | AC4: 1 | AD4: 6.5284179e-06 | AE4: 9.922861e-28 | AF4: 2.3578653e-28 | AG4: 2.4632676e-27 | AH4: -8.7425822e-28 | AI4: 5.5739707e-29 | AJ4: -6.3464972e-28 | AK4: 1.1037085e-27 | AL4: 9.7764555e-28 | AM4: 9.5952311e-29 | AN4: -1.0179428e-27 | AO4: 1.1435399e-27 | AP4: -4.9409783e-28 | AQ4: 2.1570813e-27 | AR4: -3.4771632e-27 | AS4: 1.161737e-27 | AT4: 5.4185861e-28 | AU4: -1.9887147e-27 | AV4: -6.8042212e-28 | AW4: 7.7380287e-28 | AX4: 6.8036413e-28 | AY4: -8.8511287e-28 | AZ4: 1.1598711e-28 | BA4: 2.1833239e-27 | BB4: -3.7398244e-27 | BC4: 16000000 | BD4: 4000000 | BE4: -3.1847466e-06 | BF4: 6.6845994e-06 | BG4: 1.8962798e-06 | BH4: -1.2820923e-07 | BI4: 1.5898782 | BJ4: 0.79494019 | BK4: 1.4633462
A5: 39.716412 | B5: 4.0023657e-11 | C5: =(BF5-BF4)/(A5-A4) -> 1.682375e-06 | D5: 1.2937341e-13 | E5: 1.5657305e-13 | F5: 1.5657305e-13 | G5: 1.5657305e-13 | H5: 1.2937341e-13 | I5: 1.2937341e-13 | J5: 1.2937341e-13 | K5: 1.3709178e-13 | L5: 1.3709178e-13 | M5: 1.3709178e-13 | N5: 1.4296068e-13 | O5: 1.2937341e-13 | P5: 1.4296068e-13 | Q5: 1.4296068e-13 | R5: 1.5657305e-13 | S5: 1.5657305e-13 | T5: 1.5657305e-13 | U5: 1.2937341e-13 | V5: 1.3709178e-13 | W5: 1.3709178e-13 | X5: 1.3709178e-13 | Y5: 1.4296068e-13 | Z5: 1.4296068e-13 | AA5: 1.4296068e-13 | AB5: 1 | AC5: 1 | AD5: 6.5266623e-05 | AE5: -3.1652424e-25 | AF5: 5.9030277e-24 | AG5: 6.3664267e-24 | AH5: 1.2113092e-24 | AI5: 9.0935393e-26 | AJ5: 1.3341566e-24 | AK5: 1.4929554e-24 | AL5: 2.371327e-24 | AM5: -1.1363751e-24 | AN5: -4.3775717e-26 | AO5: 2.8681256e-24 | AP5: -2.1828763e-25 | AQ5: 2.1835071e-24 | AR5: -7.6316339e-24 | AS5: -2.9033324e-25 | AT5: 1.3705374e-24 | AU5: -3.0725575e-24 | AV5: -1.6703224e-24 | AW5: -1.4150677e-25 | AX5: 4.6895365e-24 | AY5: 5.4149068e-25 | AZ5: -3.932845e-24 | BA5: 2.8757279e-24 | BB5: -1.0646058e-23 | BC5: 16000000 | BD5: 4000000 | BE5: -3.1845351e-05 | BF5: 6.6820707e-05 | BG5: 1.8964549e-05 | BH5: -1.2826129e-05 | BI5: 15.898671 | BJ5: 7.9494437 | BK5: 14.632998
A6: 397.16412 | B6: 2.7634145e-09 | C6: =(BF6-BF5)/(A6-A5) -> 5.1810782e-07 | D6: 6.3093011e-13 | E6: 7.6562698e-13 | F6: 7.6562698e-13 | G6: 7.6562698e-13 | H6: 6.3093011e-13 | I6: 6.3093011e-13 | J6: 6.3093011e-13 | K6: 6.6735618e-13 | L6: 6.6735618e-13 | M6: 6.6735618e-13 | N6: 6.9789262e-13 | O6: 6.3093011e-13 | P6: 6.9789262e-13 | Q6: 6.9789262e-13 | R6: 7.6562698e-13 | S6: 7.6562698e-13 | T6: 7.6562698e-13 | U6: 6.3093011e-13 | V6: 6.6735618e-13 | W6: 6.6735618e-13 | X6: 6.6735618e-13 | Y6: 6.9789262e-13 | Z6: 6.9789262e-13 | AA6: 6.9789262e-13 | AB6: 0.99999986 | AC6: 0.99999446 | AD6: 0.00024624852 | AE6: -6.0226066e-19 | AF6: 3.3620207e-18 | AG6: 2.6516035e-18 | AH6: 2.9516365e-19 | AI6: -9.1143536e-20 | AJ6: 7.5898925e-19 | AK6: 1.2494589e-19 | AL6: 7.7311417e-19 | AM6: 1.4937243e-20 | AN6: -6.1672395e-20 | AO6: 9.5448361e-19 | AP6: -1.3640688e-20 | AQ6: 4.660753e-19 | AR6: -4.097068e-18 | AS6: -4.3623233e-19 | AT6: 3.2957663e-19 | AU6: -9.1245624e-19 | AV6: -6.4334181e-19 | AW6: -2.7626207e-19 | AX6: 2.5806595e-18 | AY6: 4.8819229e-19 | AZ6: -1.7585288e-18 | BA6: 2.3335153e-18 | BB6: -7.2590219e-18 | BC6: 15999999 | BD6: 3999999.6 | BE6: -0.00012024338 | BF6: 0.00025201716 | BG6: 7.1646206e-05 | BH6: -0.00018197568 | BI6: 60.044439 | BJ6: 30.023754 | BK6: 55.259487
A7: 3971.6412 | B7: 3.4440047e-08 | C7: =(BF7-BF6)/(A7-A6) -> 9.6088059e-12 | D7: 6.3093011e-13 | E7: 7.6562335e-13 | F7: 7.6562335e-13 | G7: 7.6562335e-13 | H7: 6.3093011e-13 | I7: 6.3093011e-13 | J7: 6.3093011e-13 | K7: 6.6735511e-13 | L7: 6.6735511e-13 | M7: 6.6735511e-13 | N7: 6.9788976e-13 | O7: 6.3093011e-13 | P7: 6.9788976e-13 | Q7: 6.9788976e-13 | R7: 7.6562335e-13 | S7: 7.6562335e-13 | T7: 7.6562335e-13 | U7: 6.3093011e-13 | V7: 6.6735511e-13 | W7: 6.6735511e-13 | X7: 6.6735511e-13 | Y7: 6.9788976e-13 | Z7: 6.9788976e-13 | AA7: 6.9788976e-13 | AB7: 0.99999998 | AC7: 0.99999446 | AD7: 0.0002462747 | AE7: -6.0232877e-19 | AF7: 3.3616236e-18 | AG7: 2.6514105e-18 | AH7: 2.9523572e-19 | AI7: -9.11597e-20 | AJ7: 7.5898797e-19 | AK7: 1.2494539e-19 | AL7: 7.730858e-19 | AM7: 1.5300079e-20 | AN7: -6.1673409e-20 | AO7: 9.5443304e-19 | AP7: -1.3618425e-20 | AQ7: 4.6610825e-19 | AR7: -4.0970532e-18 | AS7: -4.3613161e-19 | AT7: 3.2952093e-19 | AU7: -9.1234513e-19 | AV7: -6.4335564e-19 | AW7: -2.7622039e-19 | AX7: 2.5803729e-18 | AY7: 4.8814982e-19 | AZ7: -1.7583133e-18 | BA7: 2.3335146e-18 | BB7: -7.2590565e-18 | BC7: 15999982 | BD7: 3999994.6 | BE7: -0.00012023781 | BF7: 0.00025205151 | BG7: 7.1665506e-05 | BH7: -0.00018202008 | BI7: 60.044438 | BJ7: 30.023754 | BK7: 55.259093
A8: 39716.412 | B8: 3.5119659e-07 | C8: =(BF8-BF7)/(A8-A7) -> 9.6086213e-12 | D8: 6.3092794e-13 | E8: 7.6558401e-13 | F8: 7.6558401e-13 | G8: 7.6558401e-13 | H8: 6.3092794e-13 | I8: 6.3092794e-13 | J8: 6.3092794e-13 | K8: 6.6734204e-13 | L8: 6.6734204e-13 | M8: 6.6734204e-13 | N8: 6.9785792e-13 | O8: 6.3092794e-13 | P8: 6.9785792e-13 | Q8: 6.9785792e-13 | R8: 7.6558401e-13 | S8: 7.6558401e-13 | T8: 7.6558401e-13 | U8: 6.3092794e-13 | V8: 6.6734204e-13 | W8: 6.6734204e-13 | X8: 6.6734204e-13 | Y8: 6.9785792e-13 | Z8: 6.9785792e-13 | AA8: 6.9785792e-13 | AB8: 1 | AC8: 0.99999446 | AD8: 0.00024653658 | AE8: -6.0298311e-19 | AF8: 3.3574563e-18 | AG8: 2.6493197e-18 | AH8: 2.9595614e-19 | AI8: -9.1307994e-20 | AJ8: 7.589563e-19 | AK8: 1.2495515e-19 | AL8: 7.7279542e-19 | AM8: 1.8953648e-20 | AN8: -6.1652084e-20 | AO8: 9.5387617e-19 | AP8: -1.3398615e-20 | AQ8: 4.6642626e-19 | AR8: -4.0964022e-18 | AS8: -4.3507654e-19 | AT8: 3.2895729e-19 | AU8: -9.1115371e-19 | AV8: -6.434662e-19 | AW8: -2.7578333e-19 | AX8: 2.5773915e-18 | AY8: 4.8771569e-19 | AZ8: -1.7560712e-18 | BA8: 2.3332291e-18 | BB8: -7.2588714e-18 | BC8: 15999822 | BD8: 3999945.3 | BE8: -0.00012018207 | BF8: 0.00025239496 | BG8: 7.1858499e-05 | BH8: -0.00018191545 | BI8: 60.044438 | BJ8: 30.023755 | BK8: 55.255163
A9: 397164.12 | B9: 3.5177856e-06 | C9: =(BF9-BF8)/(A9-A8) -> 9.6028751e-12 | D9: 6.3090578e-13 | E9: 7.6519139e-13 | F9: 7.6519139e-13 | G9: 7.6519139e-13 | H9: 6.3090578e-13 | I9: 6.3090578e-13 | J9: 6.3090578e-13 | K9: 6.6721126e-13 | L9: 6.6721126e-13 | M9: 6.6721126e-13 | N9: 6.9754043e-13 | O9: 6.3090578e-13 | P9: 6.9754043e-13 | Q9: 6.9754043e-13 | R9: 7.6519139e-13 | S9: 7.6519139e-13 | T9: 7.6519139e-13 | U9: 6.3090578e-13 | V9: 6.6721126e-13 | W9: 6.6721126e-13 | X9: 6.6721126e-13 | Y9: 6.9754043e-13 | Z9: 6.9754043e-13 | AA9: 6.9754044e-13 | AB9: 1 | AC9: 0.99999444 | AD9: 0.00024916117 | AE9: -6.0954223e-19 | AF9: 3.3160052e-18 | AG9: 2.6285435e-18 | AH9: 3.0318164e-19 | AI9: -9.2789677e-20 | AJ9: 7.5860057e-19 | AK9: 1.2503411e-19 | AL9: 7.6992816e-19 | AM9: 5.5672233e-20 | AN9: -6.1456856e-20 | AO9: 9.4834359e-19 | AP9: -1.1212929e-20 | AQ9: 4.6954645e-19 | AR9: -4.0896583e-18 | AS9: -4.2456601e-19 | AT9: 3.2334106e-19 | AU9: -8.9927055e-19 | AV9: -6.4458958e-19 | AW9: -2.7136541e-19 | AX9: 2.5475465e-18 | AY9: 4.832884e-19 | AZ9: -1.7337848e-18 | BA9: 2.3302674e-18 | BB9: -7.2566257e-18 | BC9: 15998215 | BD9: 3999451.8 | BE9: -0.00011962347 | BF9: 0.00025582749 | BG9: 7.3788157e-05 | BH9: -0.00018096556 | BI9: 60.044436 | BJ9: 30.02376 | BK9: 55.216075
A10: 44562.547 | B10: 3.9413947e-07 | C10: =(BF10-BF9)/(A10-A9) -> 9.602832e-12 | D10: 6.3092695e-13 | E10: 7.6556665e-13 | F10: 7.6556665e-13 | G10: 7.6556665e-13 | H10: 6.3092695e-13 | I10: 6.3092695e-13 | J10: 6.3092695e-13 | K10: 6.6733626e-13 | L10: 6.6733626e-13 | M10: 6.6733626e-13 | N10: 6.9784387e-13 | O10: 6.3092695e-13 | P10: 6.9784387e-13 | Q10: 6.9784387e-13 | R10: 7.6556665e-13 | S10: 7.6556665e-13 | T10: 7.6556665e-13 | U10: 6.3092695e-13 | V10: 6.6733626e-13 | W10: 6.6733626e-13 | X10: 6.6733626e-13 | Y10: 6.9784387e-13 | Z10: 6.9784387e-13 | AA10: 6.9784387e-13 | AB10: 0.99999997 | AC10: 0.99999446 | AD10: 0.00024657209 | AE10: -6.0327126e-19 | AF10: 3.3556208e-18 | AG10: 2.648399e-18 | AH10: 2.9627349e-19 | AI10: -9.1373226e-20 | AJ10: 7.5894208e-19 | AK10: 1.2495954e-19 | AL10: 7.7266773e-19 | AM10: 2.0563707e-20 | AN10: -6.1642559e-20 | AO10: 9.5363089e-19 | AP10: -1.3301943e-20 | AQ10: 4.6656597e-19 | AR10: -4.0961111e-18 | AS10: -4.3461169e-19 | AT10: 3.2870915e-19 | AU10: -9.1062888e-19 | AV10: -6.4351486e-19 | AW10: -2.7559044e-19 | AX10: 2.5760778e-18 | AY10: 4.8752402e-19 | AZ10: -1.755084e-18 | BA10: 2.3331017e-18 | BB10: -7.2587846e-18 | BC10: 15999800 | BD10: 3999938.6 | BE10: -0.00012017451 | BF10: 0.00025244152 | BG10: 7.1884664e-05 | BH10: -0.0001819008 | BI10: 60.044438 | BJ10: 30.023755 | BK10: 55.25463
A11: 50000 | B11: 4.4232174e-07 | C11: =(BF11-BF10)/(A11-A10) -> 9.6075032e-12 | D11: 6.3092653e-13 | E11: 7.655592e-13 | F11: 7.655592e-13 | G11: 7.655592e-13 | H11: 6.3092653e-13 | I11: 6.3092653e-13 | J11: 6.3092653e-13 | K11: 6.6733378e-13 | L11: 6.6733378e-13 | M11: 6.6733378e-13 | N11: 6.9783785e-13 | O11: 6.3092653e-13 | P11: 6.9783785e-13 | Q11: 6.9783785e-13 | R11: 7.655592e-13 | S11: 7.655592e-13 | T11: 7.655592e-13 | U11: 6.3092653e-13 | V11: 6.6733378e-13 | W11: 6.6733378e-13 | X11: 6.6733378e-13 | Y11: 6.9783785e-13 | Z11: 6.9783785e-13 | AA11: 6.9783785e-13 | AB11: 0.99999998 | AC11: 0.99999446 | AD11: 0.00024661194 | AE11: -6.0339515e-19 | AF11: 3.3548325e-18 | AG11: 2.6480035e-18 | AH11: 2.9640993e-19 | AI11: -9.1401289e-20 | AJ11: 7.5893591e-19 | AK11: 1.2496134e-19 | AL11: 7.7261288e-19 | AM11: 2.1255953e-20 | AN11: -6.1638557e-20 | AO11: 9.5352556e-19 | AP11: -1.3260393e-20 | AQ11: 4.6662595e-19 | AR11: -4.0959866e-18 | AS11: -4.3441202e-19 | AT11: 3.2860251e-19 | AU11: -9.104034e-19 | AV11: -6.4353584e-19 | AW11: -2.7550749e-19 | AX11: 2.5755133e-18 | AY11: 4.8744153e-19 | AZ11: -1.7546599e-18 | BA11: 2.333047e-18 | BB11: -7.2587476e-18 | BC11: 15999776 | BD11: 3999931.1 | BE11: -0.00012016603 | BF11: 0.00025249376 | BG11: 7.1914021e-05 | BH11: -0.0001818848 | BI11: 60.044438 | BJ11: 30.023755 | BK11: 55.254032
A12: 56100.923 | B12: 4.9638258e-07 | C12: =(BF12-BF11)/(A12-A11) -> 9.6073134e-12 | D12: 6.3092606e-13 | E12: 7.6555084e-13 | F12: 7.6555084e-13 | G12: 7.6555084e-13 | H12: 6.3092606e-13 | I12: 6.3092606e-13 | J12: 6.3092606e-13 | K12: 6.67331e-13 | L12: 6.67331e-13 | M12: 6.67331e-13 | N12: 6.9783108e-13 | O12: 6.3092606e-13 | P12: 6.9783108e-13 | Q12: 6.9783108e-13 | R12: 7.6555084e-13 | S12: 7.6555084e-13 | T12: 7.6555084e-13 | U12: 6.3092606e-13 | V12: 6.67331e-13 | W12: 6.67331e-13 | X12: 6.67331e-13 | Y12: 6.9783108e-13 | Z12: 6.9783108e-13 | AA12: 6.9783108e-13 | AB12: 0.99999998 | AC12: 0.99999446 | AD12: 0.00024665665 | AE12: -6.0353417e-19 | AF12: 3.3539481e-18 | AG12: 2.6475599e-18 | AH12: 2.9656304e-19 | AI12: -9.1432777e-20 | AJ12: 7.5892896e-19 | AK12: 1.2496336e-19 | AL12: 7.7255137e-19 | AM12: 2.2032797e-20 | AN12: -6.1634081e-20 | AO12: 9.5340739e-19 | AP12: -1.3213785e-20 | AQ12: 4.666932e-19 | AR12: -4.0958466e-18 | AS12: -4.3418802e-19 | AT12: 3.2848287e-19 | AU12: -9.1015044e-19 | AV12: -6.435594e-19 | AW12: -2.7541439e-19 | AX12: 2.5748799e-18 | AY12: 4.8734891e-19 | AZ12: -1.7541842e-18 | BA12: 2.3329856e-18 | BB12: -7.2587058e-18 | BC12: 15999748 | BD12: 3999922.7 | BE12: -0.00012015651 | BF12: 0.00025255237 | BG12: 7.194696e-05 | BH12: -0.00018186685 | BI12: 60.044438 | BJ12: 30.023755 | BK12: 55.253362
A13: 62946.271 | B13: 5.5703915e-07 | C13: =(BF13-BF12)/(A13-A12) -> 9.6071006e-12 | D13: 6.3092554e-13 | E13: 7.6554147e-13 | F13: 7.6554147e-13 | G13: 7.6554147e-13 | H13: 6.3092554e-13 | I13: 6.3092554e-13 | J13: 6.3092554e-13 | K13: 6.6732789e-13 | L13: 6.6732789e-13 | M13: 6.6732789e-13 | N13: 6.978235e-13 | O13: 6.3092554e-13 | P13: 6.978235e-13 | Q13: 6.978235e-13 | R13: 7.6554147e-13 | S13: 7.6554147e-13 | T13: 7.6554147e-13 | U13: 6.3092554e-13 | V13: 6.6732789e-13 | W13: 6.6732789e-13 | X13: 6.6732789e-13 | Y13: 6.978235e-13 | Z13: 6.978235e-13 | AA13: 6.978235e-13 | AB13: 0.99999998 | AC13: 0.99999445 | AD13: 0.00024670682 | AE13: -6.0369015e-19 | AF13: 3.352956e-18 | AG13: 2.6470624e-18 | AH13: 2.9673484e-19 | AI13: -9.1468105e-20 | AJ13: 7.5892111e-19 | AK13: 1.249656e-19 | AL13: 7.7248238e-19 | AM13: 2.2904596e-20 | AN13: -6.1629076e-20 | AO13: 9.5327484e-19 | AP13: -1.3161504e-20 | AQ13: 4.667686e-19 | AR13: -4.0956894e-18 | AS13: -4.3393672e-19 | AT13: 3.2834866e-19 | AU13: -9.0986665e-19 | AV13: -6.4358586e-19 | AW13: -2.7530987e-19 | AX13: 2.5741691e-18 | AY13: 4.872449e-19 | AZ13: -1.7536506e-18 | BA13: 2.3329167e-18 | BB13: -7.2586584e-18 | BC13: 15999717 | BD13: 3999913.2 | BE13: -0.00012014583 | BF13: 0.00025261813 | BG13: 7.1983919e-05 | BH13: -0.0001818467 | BI13: 60.044438 | BJ13: 30.023755 | BK13: 55.25261
A14: 70626.877 | B14: 6.2509607e-07 | C14: =(BF14-BF13)/(A14-A13) -> 9.6068619e-12 | D14: 6.3092495e-13 | E14: 7.6553095e-13 | F14: 7.6553095e-13 | G14: 7.6553095e-13 | H14: 6.3092495e-13 | I14: 6.3092495e-13 | J14: 6.3092495e-13 | K14: 6.6732439e-13 | L14: 6.6732439e-13 | M14: 6.6732439e-13 | N14: 6.9781499e-13 | O14: 6.3092495e-13 | P14: 6.9781499e-13 | Q14: 6.9781499e-13 | R14: 7.6553095e-13 | S14: 7.6553095e-13 | T14: 7.6553095e-13 | U14: 6.3092495e-13 | V14: 6.6732439e-13 | W14: 6.6732439e-13 | X14: 6.6732439e-13 | Y14: 6.9781499e-13 | Z14: 6.9781499e-13 | AA14: 6.9781499e-13 | AB14: 0.99999998 | AC14: 0.99999445 | AD14: 0.00024676311 | AE14: -6.0386519e-19 | AF14: 3.3518431e-18 | AG14: 2.6465042e-18 | AH14: 2.9692763e-19 | AI14: -9.1507743e-20 | AJ14: 7.5891225e-19 | AK14: 1.249681e-19 | AL14: 7.7240502e-19 | AM14: 2.3882977e-20 | AN14: -6.1623482e-20 | AO14: 9.5312616e-19 | AP14: -1.3102862e-20 | AQ14: 4.6685312e-19 | AR14: -4.0955126e-18 | AS14: -4.3365481e-19 | AT14: 3.281981e-19 | AU14: -9.0954826e-19 | AV14: -6.4361557e-19 | AW14: -2.7519254e-19 | AX14: 2.5733716e-18 | AY14: 4.8712809e-19 | AZ14: -1.753052e-18 | BA14: 2.3328391e-18 | BB14: -7.2586048e-18 | BC14: 15999683 | BD14: 3999902.6 | BE14: -0.00012013385 | BF14: 0.00025269192 | BG14: 7.2025386e-05 | BH14: -0.00018182408 | BI14: 60.044438 | BJ14: 30.023755 | BK14: 55.251766
... A71: 50000000 | B71: 0.00042796986 | C71: =(BF71-BF70)/(A71-A70) -> 8.5881169e-12 | D71: 6.2623882e-13 | E71: 7.169718e-13 | F71: 7.1697181e-13 | G71: 7.1697187e-13 | H71: 6.2623869e-13 | I71: 6.2623871e-13 | J71: 6.2623872e-13 | K71: 6.4590862e-13 | L71: 6.4590892e-13 | M71: 6.4590851e-13 | N71: 6.6350293e-13 | O71: 6.2623868e-13 | P71: 6.6350276e-13 | Q71: 6.6350338e-13 | R71: 7.1697176e-13 | S71: 7.1697174e-13 | T71: 7.169718e-13 | U71: 6.2623873e-13 | V71: 6.4590854e-13 | W71: 6.4590892e-13 | X71: 6.4590872e-13 | Y71: 6.6350272e-13 | Z71: 6.6350318e-13 | AA71: 6.6350374e-13 | AB71: 1 | AC71: 0.99998907 | AD71: 0.0006411456 | AE71: -4.8566632e-19 | AF71: 4.753056e-19 | AG71: 1.242504e-18 | AH71: 1.9805158e-18 | AI71: -6.6118855e-19 | AJ71: -3.7713792e-19 | AK71: -3.4668641e-19 | AL71: 1.5856779e-19 | AM71: 9.0174707e-18 | AN71: -2.9435619e-19 | AO71: -1.1116508e-18 | AP71: 1.0174426e-19 | AQ71: -4.2996759e-20 | AR71: -2.9070935e-18 | AS71: 4.6720924e-19 | AT71: -4.358563e-19 | AU71: 6.6629655e-19 | AV71: -1.3286139e-18 | AW71: 2.1951717e-19 | AX71: -4.1157667e-18 | AY71: -1.6208411e-18 | AZ71: 7.1168513e-20 | BA71: -1.8655747e-19 | BB71: -4.3937839e-18 | BC71: 15780130 | BD71: 3933197 | BE71: -2.56998e-05 | BF71: 0.00070239773 | BG71: 0.00033752292 | BH71: -5.9415458e-05 | BI71: 60.045083 | BJ71: 30.02393 | BK71: 52.414517

Sheet 773K_87MPa_64g
A1: time | B1: Ep_eff | C1: StrainRate | D1: cstrain_1 | E1: cstrain_10 | F1: cstrain_11 | G1: cstrain_12 | H1: cstrain_13 | I1: cstrain_14 | J1: cstrain_15 | K1: cstrain_16 | L1: cstrain_17 | M1: cstrain_18 | N1: cstrain_19 | O1: cstrain_2 | P1: cstrain_20 | Q1: cstrain_21 | R1: cstrain_22 | S1: cstrain_23 | T1: cstrain_24 | U1: cstrain_3 | V1: cstrain_4 | W1: cstrain_5 | X1: cstrain_6 | Y1: cstrain_7 | Z1: cstrain_8 | AA1: cstrain_9 | AB1: cstrainfrac1 | AC1: cstrainfrac2 | AD1: eeq | AE1: gstrain_1 | AF1: gstrain_10 | AG1: gstrain_11 | AH1: gstrain_12 | AI1: gstrain_13 | AJ1: gstrain_14 | AK1: gstrain_15 | AL1: gstrain_16 | AM1: gstrain_17 | AN1: gstrain_18 | AO1: gstrain_19 | AP1: gstrain_2 | AQ1: gstrain_20 | AR1: gstrain_21 | AS1: gstrain_22 | AT1: gstrain_23 | AU1: gstrain_24 | AV1: gstrain_3 | AW1: gstrain_4 | AX1: gstrain_5 | AY1: gstrain_6 | AZ1: gstrain_7 | BA1: gstrain_8 | BB1: gstrain_9 | BC1: rho_i | BD1: rho_m | BE1: strain_xx | BF1: strain_yy | BG1: strain_zz | BH1: stress_xx | BI1: stress_yy | BJ1: stress_zz | BK1: vonmises
A2: 0 | B2: 0 | D2: 0 | E2: 0 | F2: 0 | G2: 0 | H2: 0 | I2: 0 | J2: 0 | K2: 0 | L2: 0 | M2: 0 | N2: 0 | O2: 0 | P2: 0 | Q2: 0 | R2: 0 | S2: 0 | T2: 0 | U2: 0 | V2: 0 | W2: 0 | X2: 0 | Y2: 0 | Z2: 0 | AA2: 0 | AB2: 0 | AC2: 0 | AD2: 0 | AE2: 0 | AF2: 0 | AG2: 0 | AH2: 0 | AI2: 0 | AJ2: 0 | AK2: 0 | AL2: 0 | AM2: 0 | AN2: 0 | AO2: 0 | AP2: 0 | AQ2: 0 | AR2: 0 | AS2: 0 | AT2: 0 | AU2: 0 | AV2: 0 | AW2: 0 | AX2: 0 | AY2: 0 | AZ2: 0 | BA2: 0 | BB2: 0 | BC2: 0 | BD2: 0 | BE2: 0 | BF2: 0 | BG2: 0 | BH2: 0 | BI2: 0 | BJ2: 0 | BK2: 0
A3: 0.39716412 | B3: 6.4457756e-15 | C3: =(BF3-BF2)/(A3-A2) -> 2.8160249e-06 | D3: 2.1502795e-15 | E3: 2.6005259e-15 | F3: 2.6005259e-15 | G3: 2.6005259e-15 | H3: 2.1502795e-15 | I3: 2.1502795e-15 | J3: 2.1502795e-15 | K3: 2.2795954e-15 | L3: 2.2795954e-15 | M3: 2.2795954e-15 | N3: 2.3754626e-15 | O3: 2.1502795e-15 | P3: 2.3754626e-15 | Q3: 2.3754626e-15 | R3: 2.6005259e-15 | S3: 2.6005259e-15 | T3: 2.6005259e-15 | U3: 2.1502795e-15 | V3: 2.2795954e-15 | W3: 2.2795954e-15 | X3: 2.2795954e-15 | Y3: 2.3754626e-15 | Z3: 2.3754626e-15 | AA3: 2.3754626e-15 | AB3: 1 | AC3: 1 | AD3: 1.0922817e-06 | AE3: 2.4153968e-28 | AF3: -2.8436273e-28 | AG3: 2.167849e-28 | AH3: -3.2724028e-28 | AI3: -7.1438277e-29 | AJ3: -2.2396415e-28 | AK3: 1.133495e-28 | AL3: 1.6922382e-28 | AM3: 1.4399047e-28 | AN3: -2.7760802e-28 | AO3: 9.9792766e-29 | AP3: -1.521168e-28 | AQ3: 4.3321172e-28 | AR3: -4.8208126e-28 | AS3: 2.6851001e-28 | AT3: 1.8334963e-29 | AU3: -2.6761155e-28 | AV3: -1.3640708e-28 | AW3: 1.5856888e-28 | AX3: 1.5299186e-29 | AY3: -1.6026476e-28 | AZ3: 2.4195578e-28 | BA3: 3.6182549e-28 | BB3: -5.0818739e-28 | BC3: 16000000 | BD3: 4000000 | BE3: -5.3283588e-07 | BF3: 1.1184241e-06 | BG3: 3.1725947e-07 | BH3: -3.5895553e-09 | BI3: 0.26599903 | BJ3: 0.13299954 | BK3: 0.24482979
A4: 3.9716412 | B4: 6.6631332e-13 | C4: =(BF4-BF3)/(A4-A3) -> 2.8158267e-06 | D4: 2.1523725e-14 | E4: 2.6033523e-14 | F4: 2.6033523e-14 | G4: 2.6033523e-14 | H4: 2.1523725e-14 | I4: 2.1523725e-14 | J4: 2.1523725e-14 | K4: 2.2816749e-14 | L4: 2.2816749e-14 | M4: 2.2816749e-14 | N4: 2.3778835e-14 | O4: 2.1523725e-14 | P4: 2.3778835e-14 | Q4: 2.3778835e-14 | R4: 2.6033523e-14 | S4: 2.6033523e-14 | T4: 2.6033523e-14 | U4: 2.1523725e-14 | V4: 2.2816749e-14 | W4: 2.2816749e-14 | X4: 2.2816749e-14 | Y4: 2.3778835e-14 | Z4: 2.3778835e-14 | AA4: 2.3778835e-14 | AB4: 1 | AC4: 1 | AD4: 1.0922325e-05 | AE4: 2.0555037e-27 | AF4: 2.6639915e-27 | AG4: 7.4477307e-27 | AH4: -1.1119326e-27 | AI4: 4.1546776e-28 | AJ4: -8.1544174e-28 | AK4: 3.1198313e-27 | AL4: 2.686504e-27 | AM4: -5.2172553e-28 | AN4: -1.9612869e-27 | AO4: 3.480054e-27 | AP4: -9.5858005e-28 | AQ4: 5.1464514e-27 | AR4: -9.611804e-27 | AS4: 2.3172843e-27 | AT4: 1.7477473e-27 | AU4: -5.3287408e-27 | AV4: -1.8197883e-27 | AW4: 1.6188951e-27 | AX4: 2.6830438e-27 | AY4: -1.8192464e-27 | AZ4: -1.219643e-27 | BA4: 5.3969298e-27 | BB4: -1.0742795e-26 | BC4: 16000000 | BD4: 4000000 | BE4: -5.3282996e-06 | BF4: 1.1183532e-05 | BG4: 3.1726436e-06 | BH4: -3.5889975e-07 | BI4: 2.6599872 | BJ4: 1.3299966 | BK4: 2.4482849
A5: 39.716412 | B5: 6.7215436e-11 | C5: =(BF5-BF4)/(A5-A4) -> 2.8138659e-06 | D5: 2.1744184e-13 | E5: 2.6328286e-13 | F5: 2.6328286e-13 | G5: 2.6328286e-13 | H5: 2.1744184e-13 | I5: 2.1744184e-13 | J5: 2.1744184e-13 | K5: 2.3034059e-13 | L5: 2.3034059e-13 | M5: 2.3034059e-13 | N5: 2.4032243e-13 | O5: 2.1744184e-13 | P5: 2.4032243e-13 | Q5: 2.4032243e-13 | R5: 2.6328286e-13 | S5: 2.6328286e-13 | T5: 2.6328286e-13 | U5: 2.1744184e-13 | V5: 2.3034059e-13 | W5: 2.3034059e-13 | X5: 2.3034059e-13 | Y5: 2.4032243e-13 | Z5: 2.4032243e-13 | AA5: 2.4032243e-13 | AB5: 1 | AC5: 1 | AD5: 0.0001091741 | AE5: -2.0980911e-23 | AF5: 1.7673312e-22 | AG5: 1.7076265e-22 | AH5: 3.2612698e-23 | AI5: -1.7449402e-24 | AJ5: 4.3175324e-23 | AK5: 2.7879878e-23 | AL5: 6.2412813e-23 | AM5: -2.2674479e-23 | AN5: 9.1049349e-25 | AO5: 7.2909602e-23 | AP5: -4.1668168e-24 | AQ5: 4.8237834e-23 | AR5: -2.1368045e-22 | AS5: -1.6861242e-23 | AT5: 3.2632696e-23 | AU5: -7.4084548e-23 | AV5: -4.592491e-23 | AW5: -9.9732828e-24 | AX5: 1.4252225e-22 | AY5: 2.3013938e-23 | AZ5: -1.1336282e-22 | BA5: 8.6040724e-23 | BB5: -3.2165866e-22 | BC5: 16000000 | BD5: 4000000 | BE5: -5.3277085e-05 | BF5: 0.00011176452 | BG5: 3.1731309e-05 | BH5: -3.5912649e-05 | BI5: 26.599561 | BJ5: 13.300083 | BK5: 24.481552
A6: 397.16412 | B6: 4.730386e-09 | C6: =(BF6-BF5)/(A6-A5) -> 8.6548466e-07 | D6: 1.0790255e-12 | E6: 1.312402e-12 | F6: 1.312402e-12 | G6: 1.312402e-12 | H6: 1.0790255e-12 | I6: 1.0790255e-12 | J6: 1.0790255e-12 | K6: 1.1394707e-12 | L6: 1.1394707e-12 | M6: 1.1394707e-12 | N6: 1.1945815e-12 | O6: 1.0790255e-12 | P6: 1.1945815e-12 | Q6: 1.1945815e-12 | R6: 1.312402e-12 | S6: 1.312402e-12 | T6: 1.312402e-12 | U6: 1.0790255e-12 | V6: 1.1394707e-12 | W6: 1.1394707e-12 | X6: 1.1394707e-12 | Y6: 1.1945815e-12 | Z6: 1.1945815e-12 | AA6: 1.1945815e-12 | AB6: 0.99994679 | AC6: 0.99759604 | AD6: 0.00041162874 | AE6: -5.1117263e-16 | AF6: 2.7718928e-15 | AG6: 1.9574394e-15 | AH6: 1.2079235e-16 | AI6: -6.6358673e-17 | AJ6: 5.5109971e-16 | AK6: 3.1207643e-17 | AL6: 4.7023572e-16 | AM6: 1.3301533e-16 | AN6: -9.4578895e-17 | AO6: 6.41989e-16 | AP6: 2.79215e-18 | AQ6: 2.606595e-16 | AR6: -3.7084552e-15 | AS6: -3.4976367e-16 | AT6: 1.7841119e-16 | AU6: -5.8811841e-16 | AV6: -4.1937239e-16 | AW6: -2.4653909e-16 | AX6: 2.0252634e-15 | AY6: 3.9176707e-16 | AZ6: -1.2578682e-15 | BA6: 2.4256267e-15 | BB6: -7.0155363e-15 | BC6: 15999998 | BD6: 3999999.3 | BE6: -0.00020113411 | BF6: 0.00042113003 | BG6: 0.00011989967 | BH6: -0.00050792347 | BI6: 100.45701 | BJ6: 50.232787 | BK6: 92.444433
A7: 3971.6412 | B7: 5.9075529e-08 | C7: =(BF7-BF6)/(A7-A6) -> 1.655453e-11 | D7: 1.0790239e-12 | E7: 1.3123931e-12 | F7: 1.3123931e-12 | G7: 1.3123931e-12 | H7: 1.0790239e-12 | I7: 1.0790239e-12 | J7: 1.0790239e-12 | K7: 1.1394674e-12 | L7: 1.1394674e-12 | M7: 1.1394674e-12 | N7: 1.1945744e-12 | O7: 1.0790239e-12 | P7: 1.1945744e-12 | Q7: 1.1945744e-12 | R7: 1.3123931e-12 | S7: 1.3123931e-12 | T7: 1.3123931e-12 | U7: 1.0790239e-12 | V7: 1.1394674e-12 | W7: 1.1394674e-12 | X7: 1.1394674e-12 | Y7: 1.1945744e-12 | Z7: 1.1945744e-12 | AA7: 1.1945745e-12 | AB7: 0.99999292 | AC7: 0.99759598 | AD7: 0.0004116739 | AE7: -5.1124959e-16 | AF7: 2.7714536e-15 | AG7: 1.9572356e-15 | AH7: 1.2084673e-16 | AI7: -6.6364438e-17 | AJ7: 5.5109151e-16 | AK7: 3.1208628e-17 | AL7: 4.7023179e-16 | AM7: 1.3336527e-16 | AN7: -9.4576644e-17 | AO7: 6.4195521e-16 | AP7: 2.8067978e-18 | AQ7: 2.6067599e-16 | AR7: -3.7082457e-15 | AS7: -3.4967036e-16 | AT7: 1.7837429e-16 | AU7: -5.8803428e-16 | AV7: -4.1937778e-16 | AW7: -2.4650136e-16 | AX7: 2.0250168e-15 | AY7: 3.9172967e-16 | AZ7: -1.2576604e-15 | BA7: 2.4255839e-15 | BB7: -7.0152936e-15 | BC7: 15999973 | BD7: 3999990.9 | BE7: -0.00020112482 | BF7: 0.0004211892 | BG7: 0.00011993251 | BH7: -0.00050793085 | BI7: 100.45701 | BJ7: 50.232787 | BK7: 92.443754
A8: 39716.412 | B8: 6.0250533e-07 | C8: =(BF8-BF7)/(A8-A7) -> 1.6553538e-11 | D8: 1.0790074e-12 | E8: 1.312305e-12 | F8: 1.312305e-12 | G8: 1.3123049e-12 | H8: 1.0790072e-12 | I8: 1.0790073e-12 | J8: 1.0790073e-12 | K8: 1.1394339e-12 | L8: 1.139434e-12 | M8: 1.1394339e-12 | N8: 1.1945039e-12 | O8: 1.0790072e-12 | P8: 1.1945039e-12 | Q8: 1.1945043e-12 | R8: 1.3123049e-12 | S8: 1.3123049e-12 | T8: 1.3123049e-12 | U8: 1.0790073e-12 | V8: 1.139434e-12 | W8: 1.1394341e-12 | X8: 1.1394339e-12 | Y8: 1.1945039e-12 | Z8: 1.1945043e-12 | AA8: 1.1945044e-12 | AB8: 0.99999926 | AC8: 0.99759534 | AD8: 0.00041212564 | AE8: -5.1201915e-16 | AF8: 2.7670648e-15 | AG8: 1.9551994e-15 | AH8: 1.2139081e-16 | AI8: -6.6422048e-17 | AJ8: 5.5100917e-16 | AK8: 3.1218342e-17 | AL8: 4.7019285e-16 | AM8: 1.3686709e-16 | AN8: -9.4554119e-17 | AO8: 6.4161769e-16 | AP8: 2.9532048e-18 | AQ8: 2.6084047e-16 | AR8: -3.7061475e-15 | AS8: -3.4873784e-16 | AT8: 1.7800548e-16 | AU8: -5.8719313e-16 | AV8: -4.1943182e-16 | AW8: -2.4612344e-16 | AX8: 2.0225501e-15 | AY8: 3.9135468e-16 | AZ8: -1.2555838e-15 | BA8: 2.4251537e-15 | BB8: -7.0128619e-15 | BC8: 15999726 | BD8: 3999907 | BE8: -0.00020103181 | BF8: 0.00042178091 | BG8: 0.00012026091 | BH8: -0.00050763368 | BI8: 100.45701 | BJ8: 50.232789 | BK8: 92.436978
A9: 397164.12 | B9: 6.0346392e-06 | C9: =(BF9-BF8)/(A9-A8) -> 1.6541685e-11 | D9: 1.0788422e-12 | E9: 1.3114263e-12 | F9: 1.311426e-12 | G9: 1.311425e-12 | H9: 1.0788405e-12 | I9: 1.0788411e-12 | J9: 1.0788407e-12 | K9: 1.139099e-12 | L9: 1.1391002e-12 | M9: 1.1390987e-12 | N9: 1.1938013e-12 | O9: 1.0788406e-12 | P9: 1.1938007e-12 | Q9: 1.1938051e-12 | R9: 1.311425e-12 | S9: 1.3114245e-12 | T9: 1.3114249e-12 | U9: 1.0788407e-12 | V9: 1.1390996e-12 | W9: 1.1391007e-12 | X9: 1.1390993e-12 | Y9: 1.1938011e-12 | Z9: 1.1938051e-12 | AA9: 1.1938063e-12 | AB9: 0.99999993 | AC9: 0.99758892 | AD9: 0.00041665247 | AE9: -5.1971357e-16 | AF9: 2.7234986e-15 | AG9: 1.9349921e-15 | AH9: 1.2685323e-16 | AI9: -6.6996604e-17 | AJ9: 5.5016079e-16 | AK9: 3.1298555e-17 | AL9: 4.6983713e-16 | AM9: 1.7211679e-16 | AN9: -9.433398e-17 | AO9: 6.3828172e-16 | AP9: 4.4106417e-18 | AQ9: 2.6244297e-16 | AR9: -3.6849132e-15 | AS9: -3.3947434e-16 | AT9: 1.7433514e-16 | AU9: -5.78806e-16 | AV9: -4.1998572e-16 | AW9: -2.4229097e-16 | AX9: 1.997829e-15 | AY9: 3.8750682e-16 | AZ9: -1.2349899e-15 | BA9: 2.4207253e-15 | BB9: -6.9881967e-15 | BC9: 15997254 | BD9: 3999068.9 | BE9: -0.00020009966 | BF9: 0.00042769369 | BG9: 0.00012354422 | BH9: -0.00050490481 | BI9: 100.457 | BJ9: 50.232803 | BK9: 92.369601
A10: 44562.547 | B10: 6.7617757e-07 | C10: =(BF10-BF9)/(A10-A9) -> 1.6541616e-11 | D10: 1.0790001e-12 | E10: 1.3122662e-12 | F10: 1.3122661e-12 | G10: 1.312266e-12 | H10: 1.0789998e-12 | I10: 1.0789999e-12 | J10: 1.0789999e-12 | K10: 1.1394191e-12 | L10: 1.1394192e-12 | M10: 1.139419e-12 | N10: 1.1944728e-12 | O10: 1.0789998e-12 | P10: 1.1944727e-12 | Q10: 1.1944733e-12 | R10: 1.312266e-12 | S10: 1.3122659e-12 | T10: 1.312266e-12 | U10: 1.0789998e-12 | V10: 1.1394191e-12 | W10: 1.1394193e-12 | X10: 1.1394191e-12 | Y10: 1.1944728e-12 | Z10: 1.1944733e-12 | AA10: 1.1944735e-12 | AB10: 0.99998892 | AC10: 0.99759506 | AD10: 0.00041218688 | AE10: -5.1235794e-16 | AF10: 2.7651314e-15 | AG10: 1.9543025e-15 | AH10: 1.2163053e-16 | AI10: -6.644733e-17 | AJ10: 5.5097269e-16 | AK10: 3.1222753e-17 | AL10: 4.7017586e-16 | AM10: 1.3841033e-16 | AN10: -9.4543857e-17 | AO10: 6.4146891e-16 | AP10: 3.0175796e-18 | AQ10: 2.6091265e-16 | AR10: -3.705216e-15 | AS10: -3.483269e-16 | AT10: 1.7784311e-16 | AU10: -5.8682243e-16 | AV10: -4.194555e-16 | AW10: -2.4595649e-16 | AX10: 2.0214628e-15 | AY10: 3.91189e-16 | AZ10: -1.2546693e-15 | BA10: 2.4249614e-15 | BB10: -7.0117827e-15 | BC10: 15999692 | BD10: 3999895.7 | BE10: -0.0002010192 | BF10: 0.00042186109 | BG10: 0.00012030543 | BH10: -0.00050759194 | BI10: 100.45701 | BJ10: 50.232789 | BK10: 92.436057
A11: 50000 | B11: 7.5883822e-07 | C11: =(BF11-BF10)/(A11-A10) -> 1.6551069e-11 | D11: 1.0789969e-12 | E11: 1.3122495e-12 | F11: 1.3122494e-12 | G11: 1.3122493e-12 | H11: 1.0789967e-12 | I11: 1.0789967e-12 | J11: 1.0789967e-12 | K11: 1.1394127e-12 | L11: 1.1394129e-12 | M11: 1.1394127e-12 | N11: 1.1944595e-12 | O11: 1.0789967e-12 | P11: 1.1944594e-12 | Q11: 1.1944601e-12 | R11: 1.3122493e-12 | S11: 1.3122492e-12 | T11: 1.3122493e-12 | U11: 1.0789967e-12 | V11: 1.1394128e-12 | W11: 1.139413e-12 | X11: 1.1394128e-12 | Y11: 1.1944594e-12 | Z11: 1.1944601e-12 | AA11: 1.1944602e-12 | AB11: 0.99999006 | AC11: 0.99759494 | AD11: 0.00041225561 | AE11: -5.1250357e-16 | AF11: 2.7643014e-15 | AG11: 1.9539174e-15 | AH11: 1.2173359e-16 | AI11: -6.6458223e-17 | AJ11: 5.5095698e-16 | AK11: 3.1224564e-17 | AL11: 4.701686e-16 | AM11: 1.3907398e-16 | AN11: -9.4539564e-17 | AO11: 6.414051e-16 | AP11: 3.045257e-18 | AQ11: 2.6094363e-16 | AR11: -3.704817e-15 | AS11: -3.481505e-16 | AT11: 1.7777334e-16 | AU11: -5.8666323e-16 | AV11: -4.1946576e-16 | AW11: -2.458847e-16 | AX11: 2.0209956e-15 | AY11: 3.9111766e-16 | AZ11: -1.2542767e-15 | BA11: 2.4248791e-15 | BB11: -7.0113202e-15 | BC11: 15999655 | BD11: 3999882.9 | BE11: -0.00020100505 | BF11: 0.00042195109 | BG11: 0.00012035538 | BH11: -0.00050754649 | BI11: 100.457 | BJ11: 50.232789 | BK11: 92.435027
A12: 56100.923 | B12: 8.5158377e-07 | C12: =(BF12-BF11)/(A12-A11) -> 1.6550678e-11 | D12: 1.0789934e-12 | E12: 1.3122308e-12 | F12: 1.3122307e-12 | G12: 1.3122305e-12 | H12: 1.0789931e-12 | I12: 1.0789932e-12 | J12: 1.0789931e-12 | K12: 1.1394056e-12 | L12: 1.1394058e-12 | M12: 1.1394055e-12 | N12: 1.1944445e-12 | O12: 1.0789931e-12 | P12: 1.1944444e-12 | Q12: 1.1944452e-12 | R12: 1.3122305e-12 | S12: 1.3122304e-12 | T12: 1.3122305e-12 | U12: 1.0789931e-12 | V12: 1.1394057e-12 | W12: 1.1394059e-12 | X12: 1.1394056e-12 | Y12: 1.1944445e-12 | Z12: 1.1944452e-12 | AA12: 1.1944454e-12 | AB12: 0.99999109 | AC12: 0.99759481 | AD12: 0.00041233274 | AE12: -5.1266696e-16 | AF12: 2.7633703e-15 | AG12: 1.9534855e-15 | AH12: 1.2184925e-16 | AI12: -6.6470444e-17 | AJ12: 5.5093933e-16 | AK12: 3.1226584e-17 | AL12: 4.7016047e-16 | AM12: 1.3981878e-16 | AN12: -9.4534751e-17 | AO12: 6.4133352e-16 | AP12: 3.0763052e-18 | AQ12: 2.6097835e-16 | AR12: -3.7043692e-15 | AS12: -3.4795261e-16 | AT12: 1.7769508e-16 | AU12: -5.8648462e-16 | AV12: -4.1947729e-16 | AW12: -2.4580411e-16 | AX12: 2.0204713e-15 | AY12: 3.9103753e-16 | AZ12: -1.2538363e-15 | BA12: 2.4247867e-15 | BB12: -7.010801e-15 | BC12: 15999613 | BD12: 3999868.6 | BE12: -0.00020098917 | BF12: 0.00042205206 | BG12: 0.00012041143 | BH12: -0.00050749547 | BI12: 100.457 | BJ12: 50.232789 | BK12: 92.433871
A13: 62946.271 | B13: 9.5564445e-07 | C13: =(BF13-BF12)/(A13-A12) -> 1.6550239e-11 | D13: 1.0789895e-12 | E13: 1.3122098e-12 | F13: 1.3122097e-12 | G13: 1.3122095e-12 | H13: 1.0789891e-12 | I13: 1.0789892e-12 | J13: 1.0789892e-12 | K13: 1.1393976e-12 | L13: 1.1393978e-12 | M13: 1.1393975e-12 | N13: 1.1944277e-12 | O13: 1.0789891e-12 | P13: 1.1944276e-12 | Q13: 1.1944284e-12 | R13: 1.3122095e-12 | S13: 1.3122094e-12 | T13: 1.3122095e-12 | U13: 1.0789892e-12 | V13: 1.1393977e-12 | W13: 1.1393979e-12 | X13: 1.1393977e-12 | Y13: 1.1944277e-12 | Z13: 1.1944284e-12 | AA13: 1.1944287e-12 | AB13: 0.99999201 | AC13: 0.99759466 | AD13: 0.00041241927 | AE13: -5.1285028e-16 | AF13: 2.7623259e-15 | AG13: 1.953001e-15 | AH13: 1.2197904e-16 | AI13: -6.6484155e-17 | AJ13: 5.509195e-16 | AK13: 3.1228834e-17 | AL13: 4.7015138e-16 | AM13: 1.4065467e-16 | AN13: -9.4529356e-17 | AO13: 6.4125325e-16 | AP13: 3.1111339e-18 | AQ13: 2.6101726e-16 | AR13: -3.7038664e-15 | AS13: -3.4773064e-16 | AT13: 1.7760729e-16 | AU13: -5.8628424e-16 | AV13: -4.1949023e-16 | AW13: -2.4571363e-16 | AX13: 2.019883e-15 | AY13: 3.9094753e-16 | AZ13: -1.2533423e-15 | BA13: 2.4246829e-15 | BB13: -7.010218e-15 | BC13: 15999565 | BD13: 3999852.6 | BE13: -0.00020097135 | BF13: 0.00042216536 | BG13: 0.00012047432 | BH13: -0.00050743821 | BI13: 100.457 | BJ13: 50.232789 | BK13: 92.432574
A14: 70626.877 | B14: 1.0724005e-06 | C14: =(BF14-BF13)/(A14-A13) -> 1.6549746e-11 | D14: 1.078985e-12 | E14: 1.3121862e-12 | F14: 1.3121861e-12 | G14: 1.3121859e-12 | H14: 1.0789847e-12 | I14: 1.0789848e-12 | J14: 1.0789847e-12 | K14: 1.1393886e-12 | L14: 1.1393889e-12 | M14: 1.1393885e-12 | N14: 1.1944088e-12 | O14: 1.0789847e-12 | P14: 1.1944087e-12 | Q14: 1.1944097e-12 | R14: 1.3121859e-12 | S14: 1.3121858e-12 | T14: 1.3121859e-12 | U14: 1.0789847e-12 | V14: 1.1393888e-12 | W14: 1.139389e-12 | X14: 1.1393887e-12 | Y14: 1.1944088e-12 | Z14: 1.1944097e-12 | AA14: 1.19441e-12 | AB14: 0.99999285 | AC14: 0.99759449 | AD14: 0.00041251638 | AE14: -5.1305595e-16 | AF14: 2.7611545e-15 | AG14: 1.9524576e-15 | AH14: 1.2212468e-16 | AI14: -6.6499538e-17 | AJ14: 5.5089721e-16 | AK14: 3.1231339e-17 | AL14: 4.7014122e-16 | AM14: 1.4159281e-16 | AN14: -9.4523308e-17 | AO14: 6.4116323e-16 | AP14: 3.1502024e-18 | AQ14: 2.6106088e-16 | AR14: -3.703302e-15 | AS14: -3.4748166e-16 | AT14: 1.775088e-16 | AU14: -5.8605945e-16 | AV14: -4.1950477e-16 | AW14: -2.4561204e-16 | AX14: 2.0192229e-15 | AY14: 3.9084643e-16 | AZ14: -1.2527882e-15 | BA14: 2.4245663e-15 | BB14: -7.0095635e-15 | BC14: 15999512 | BD14: 3999834.5 | BE14: -0.00020095136 | BF14: 0.00042229247 | BG14: 0.00012054488 | BH14: -0.00050737394 | BI14: 100.457 | BJ14: 50.23279 | BK14: 92.431119
... A71: 50000000 | B71: 0.00072671777 | C71: =(BF71-BF70)/(A71-A70) -> 1.4475558e-11 | D71: 1.0530596e-12 | E71: 1.2043699e-12 | F71: 1.2043858e-12 | G71: 1.2044501e-12 | H71: 1.0528974e-12 | I71: 1.0529246e-12 | J71: 1.0529292e-12 | K71: 1.0855366e-12 | L71: 1.0860342e-12 | M71: 1.0854042e-12 | N71: 1.1157315e-12 | O71: 1.052894e-12 | P71: 1.1154814e-12 | Q71: 1.1163168e-12 | R71: 1.2043118e-12 | S71: 1.2042929e-12 | T71: 1.2043569e-12 | U71: 1.0529514e-12 | V71: 1.0854365e-12 | W71: 1.0859947e-12 | X71: 1.0857254e-12 | Y71: 1.115452e-12 | Z71: 1.1160895e-12 | AA71: 1.1169392e-12 | AB71: 0.99999998 | AC71: 0.99500955 | AD71: 0.0010837439 | AE71: -3.5672797e-16 | AF71: 2.3289155e-16 | AG71: 7.7637412e-16 | AH71: 1.5269603e-15 | AI71: -4.0259103e-16 | AJ71: -3.7200005e-16 | AK71: -2.5659326e-16 | AL71: 2.0613225e-16 | AM71: 9.028297e-15 | AN71: -2.4411548e-16 | AO71: -1.2543261e-15 | AP71: 3.6135365e-17 | AQ71: -1.6372421e-16 | AR71: -2.1853463e-15 | AS71: 3.3371254e-16 | AT71: -3.1391189e-16 | AU71: 5.499842e-16 | AV71: -9.9733643e-16 | AW71: 1.0323534e-16 | AX71: -4.0870547e-15 | AY71: -1.7689021e-15 | AZ71: 1.248186e-16 | BA71: -3.2577866e-16 | BB71: -3.5505836e-15 | BC71: 15665769 | BD71: 3888708.4 | BE71: -4.2715343e-05 | BF71: 0.0011874504 | BG71: 0.00056933628 | BH71: -0.000157849 | BI71: 100.45886 | BJ71: 50.233265 | BK71: 87.659919

Sheet 773K_121MPa_64g
A1: time | B1: Ep_eff | C1: StrainRate | D1: cstrain_1 | E1: cstrain_10 | F1: cstrain_11 | G1: cstrain_12 | H1: cstrain_13 | I1: cstrain_14 | J1: cstrain_15 | K1: cstrain_16 | L1: cstrain_17 | M1: cstrain_18 | N1: cstrain_19 | O1: cstrain_2 | P1: cstrain_20 | Q1: cstrain_21 | R1: cstrain_22 | S1: cstrain_23 | T1: cstrain_24 | U1: cstrain_3 | V1: cstrain_4 | W1: cstrain_5 | X1: cstrain_6 | Y1: cstrain_7 | Z1: cstrain_8 | AA1: cstrain_9 | AB1: cstrainfrac1 | AC1: cstrainfrac2 | AD1: eeq | AE1: gstrain_1 | AF1: gstrain_10 | AG1: gstrain_11 | AH1: gstrain_12 | AI1: gstrain_13 | AJ1: gstrain_14 | AK1: gstrain_15 | AL1: gstrain_16 | AM1: gstrain_17 | AN1: gstrain_18 | AO1: gstrain_19 | AP1: gstrain_2 | AQ1: gstrain_20 | AR1: gstrain_21 | AS1: gstrain_22 | AT1: gstrain_23 | AU1: gstrain_24 | AV1: gstrain_3 | AW1: gstrain_4 | AX1: gstrain_5 | AY1: gstrain_6 | AZ1: gstrain_7 | BA1: gstrain_8 | BB1: gstrain_9 | BC1: rho_i | BD1: rho_m | BE1: strain_xx | BF1: strain_yy | BG1: strain_zz | BH1: stress_xx | BI1: stress_yy | BJ1: stress_zz | BK1: vonmises
A2: 0 | B2: 0 | D2: 0 | E2: 0 | F2: 0 | G2: 0 | H2: 0 | I2: 0 | J2: 0 | K2: 0 | L2: 0 | M2: 0 | N2: 0 | O2: 0 | P2: 0 | Q2: 0 | R2: 0 | S2: 0 | T2: 0 | U2: 0 | V2: 0 | W2: 0 | X2: 0 | Y2: 0 | Z2: 0 | AA2: 0 | AB2: 0 | AC2: 0 | AD2: 0 | AE2: 0 | AF2: 0 | AG2: 0 | AH2: 0 | AI2: 0 | AJ2: 0 | AK2: 0 | AL2: 0 | AM2: 0 | AN2: 0 | AO2: 0 | AP2: 0 | AQ2: 0 | AR2: 0 | AS2: 0 | AT2: 0 | AU2: 0 | AV2: 0 | AW2: 0 | AX2: 0 | AY2: 0 | AZ2: 0 | BA2: 0 | BB2: 0 | BC2: 0 | BD2: 0 | BE2: 0 | BF2: 0 | BG2: 0 | BH2: 0 | BI2: 0 | BJ2: 0 | BK2: 0
A3: 0.39716412 | B3: 9.0532381e-15 | C3: =(BF3-BF2)/(A3-A2) -> 3.9165296e-06 | D3: 2.9907101e-15 | E3: 3.6169585e-15 | F3: 3.6169585e-15 | G3: 3.6169585e-15 | H3: 2.9907101e-15 | I3: 2.9907101e-15 | J3: 2.9907101e-15 | K3: 3.1705683e-15 | L3: 3.1705683e-15 | M3: 3.1705683e-15 | N3: 3.3039162e-15 | O3: 2.9907101e-15 | P3: 3.3039162e-15 | Q3: 3.3039162e-15 | R3: 3.6169585e-15 | S3: 3.6169585e-15 | T3: 3.6169585e-15 | U3: 2.9907101e-15 | V3: 3.1705683e-15 | W3: 3.1705683e-15 | X3: 3.1705683e-15 | Y3: 3.3039162e-15 | Z3: 3.3039162e-15 | AA3: 3.3039162e-15 | AB3: 1 | AC3: 1 | AD3: 1.5191475e-06 | AE3: 2.8539487e-28 | AF3: -2.9840518e-28 | AG3: 3.0170622e-28 | AH3: -3.7499551e-28 | AI3: -7.1323901e-29 | AJ3: -2.5858332e-28 | AK3: 1.5367471e-28 | AL3: 2.0485987e-28 | AM3: 1.5708675e-28 | AN3: -3.2517881e-28 | AO3: 1.3876507e-28 | AP3: -1.7448294e-28 | AQ3: 5.2208146e-28 | AR3: -6.1192935e-28 | AS3: 3.2357097e-28 | AT3: 3.6067023e-29 | AU3: -3.4479542e-28 | AV3: -1.6099661e-28 | AW3: 1.9455656e-28 | AX3: 3.06654e-29 | AY3: -2.0299625e-28 | AZ3: 2.6437345e-28 | BA3: 4.5194223e-28 | BB3: -6.4154253e-28 | BC3: 16000000 | BD3: 4000000 | BE3: -7.4107023e-07 | BF3: 1.555505e-06 | BG3: 4.4124622e-07 | BH3: -6.941307e-09 | BI3: 0.36995265 | BJ3: 0.18497638 | BK3: 0.34051032
A4: 3.9716412 | B4: 9.2713751e-13 | C4: =(BF4-BF3)/(A4-A3) -> 3.9161461e-06 | D4: 2.9948473e-14 | E4: 3.6225166e-14 | F4: 3.6225166e-14 | G4: 3.6225166e-14 | H4: 2.9948473e-14 | I4: 2.9948473e-14 | J4: 2.9948473e-14 | K4: 3.1746645e-14 | L4: 3.1746645e-14 | M4: 3.1746645e-14 | N4: 3.3086863e-14 | O4: 2.9948473e-14 | P4: 3.3086863e-14 | Q4: 3.3086863e-14 | R4: 3.6225166e-14 | S4: 3.6225166e-14 | T4: 3.6225166e-14 | U4: 2.9948473e-14 | V4: 3.1746645e-14 | W4: 3.1746645e-14 | X4: 3.1746645e-14 | Y4: 3.3086863e-14 | Z4: 3.3086863e-14 | AA4: 3.3086863e-14 | AB4: 1 | AC4: 1 | AD4: 1.5190523e-05 | AE4: 3.6149235e-27 | AF4: 8.7372271e-27 | AG4: 1.7537375e-26 | AH4: -7.746071e-28 | AI4: 1.1077495e-27 | AJ4: -5.1053298e-28 | AK4: 6.9370377e-27 | AL4: 6.1717523e-27 | AM4: -2.1502061e-27 | AN4: -3.2832987e-27 | AO4: 8.2206589e-27 | AP4: -1.6916758e-27 | AQ4: 1.0491366e-26 | AR4: -2.1705485e-26 | AS4: 3.895406e-27 | AT4: 4.1904077e-27 | AU4: -1.163016e-26 | AV4: -4.1481663e-27 | AW4: 2.8242758e-27 | AX4: 7.39834e-27 | AY4: -3.0142161e-27 | AZ4: -4.9054796e-27 | BA4: 1.1161153e-26 | BB4: -2.5069505e-26 | BC4: 16000000 | BD4: 4000000 | BE4: -7.4105879e-06 | BF4: 1.5553679e-05 | BG4: 4.4125565e-06 | BH4: -6.9425036e-07 | BI4: 3.6995205 | BJ4: 1.8497661 | BK4: 3.405078
