Workbook

Sheet Compiled
A1: Stress | B1: Exp | C1: Sim | D1: Ratio
A2: 173 | B2: =(Exp_773K_173MPa!C6-Exp_773K_173MPa!C2)/(Exp_773K_173MPa!B6-Exp_773K_173MPa!B2) -> 4.2938365e-11 | C2: =('773K_173MPa_512g'!B71-'773K_173MPa_512g'!B62)/('773K_173MPa_512g'!A71-'773K_173MPa_512g'!A62) -> 1.1882734e-10 | D2: =C2/B2 -> 2.7673932
A3: 121 | B3: =(Exp_773K_121MPa!C6-Exp_773K_121MPa!C2)/(Exp_773K_121MPa!B6-Exp_773K_121MPa!B2) -> 3.1469774e-11 | C3: =('773K_121MPa_512g'!B35-'773K_121MPa_512g'!B25)/('773K_121MPa_512g'!A35-'773K_121MPa_512g'!A25) -> 2.0986992e-11 | D3: =C3/B3 -> 0.66689365
A4: 87 | B4: =(Exp_773K_87MPa!C6-Exp_773K_87MPa!C2)/(Exp_773K_87MPa!B6-Exp_773K_87MPa!B2) -> 1.8581591e-11 | C4: =('773K_87MPa_512g'!B35-'773K_87MPa_512g'!B25)/('773K_87MPa_512g'!A35-'773K_87MPa_512g'!A25) -> 1.431915e-11 | D4: =C4/B4 -> 0.77060947
A5: 52 | B5: =(Exp_773K_52MPa!C6-Exp_773K_52MPa!C2)/(Exp_773K_52MPa!B6-Exp_773K_52MPa!B2) -> 1.1756422e-11 | C5: =('773K_52MPa_512g'!B35-'773K_52MPa_512g'!B25)/('773K_52MPa_512g'!A35-'773K_52MPa_512g'!A25) -> 8.4597495e-12 | D5: =C5/B5 -> 0.71958537

Sheet 773K_173MPa_512g
A1: time | B1: Ep_eff | C1: StrainRate | D1: cstrain_1 | E1: cstrain_10 | F1: cstrain_11 | G1: cstrain_12 | H1: cstrain_13 | I1: cstrain_14 | J1: cstrain_15 | K1: cstrain_16 | L1: cstrain_17 | M1: cstrain_18 | N1: cstrain_19 | O1: cstrain_2 | P1: cstrain_20 | Q1: cstrain_21 | R1: cstrain_22 | S1: cstrain_23 | T1: cstrain_24 | U1: cstrain_3 | V1: cstrain_4 | W1: cstrain_5 | X1: cstrain_6 | Y1: cstrain_7 | Z1: cstrain_8 | AA1: cstrain_9 | AB1: cstrainfrac1 | AC1: cstrainfrac2 | AD1: eeq | AE1: gstrain_1 | AF1: gstrain_10 | AG1: gstrain_11 | AH1: gstrain_12 | AI1: gstrain_13 | AJ1: gstrain_14 | AK1: gstrain_15 | AL1: gstrain_16 | AM1: gstrain_17 | AN1: gstrain_18 | AO1: gstrain_19 | AP1: gstrain_2 | AQ1: gstrain_20 | AR1: gstrain_21 | AS1: gstrain_22 | AT1: gstrain_23 | AU1: gstrain_24 | AV1: gstrain_3 | AW1: gstrain_4 | AX1: gstrain_5 | AY1: gstrain_6 | AZ1: gstrain_7 | BA1: gstrain_8 | BB1: gstrain_9 | BC1: rho_i | BD1: rho_m | BE1: strain_xx | BF1: strain_yy | BG1: strain_zz | BH1: stress_xx | BI1: stress_yy | BJ1: stress_zz | BK1: vonmises
A2: 0 | B2: 0 | D2: 0 | E2: 0 | F2: 0 | G2: 0 | H2: 0 | I2: 0 | J2: 0 | K2: 0 | L2: 0 | M2: 0 | N2: 0 | O2: 0 | P2: 0 | Q2: 0 | R2: 0 | S2: 0 | T2: 0 | U2: 0 | V2: 0 | W2: 0 | X2: 0 | Y2: 0 | Z2: 0 | AA2: 0 | AB2: 0 | AC2: 0 | AD2: 0 | AE2: 0 | AF2: 0 | AG2: 0 | AH2: 0 | AI2: 0 | AJ2: 0 | AK2: 0 | AL2: 0 | AM2: 0 | AN2: 0 | AO2: 0 | AP2: 0 | AQ2: 0 | AR2: 0 | AS2: 0 | AT2: 0 | AU2: 0 | AV2: 0 | AW2: 0 | AX2: 0 | AY2: 0 | AZ2: 0 | BA2: 0 | BB2: 0 | BC2: 0 | BD2: 0 | BE2: 0 | BF2: 0 | BG2: 0 | BH2: 0 | BI2: 0 | BJ2: 0 | BK2: 0
A3: 0.39716412 | B3: 1.2994713e-14 | C3: =(BF3-BF2)/(A3-A2) -> 5.5982928e-06 | D3: 4.6266833e-15 | E3: 4.7017771e-15 | F3: 4.7017771e-15 | G3: 4.7017771e-15 | H3: 4.6266833e-15 | I3: 4.6266833e-15 | J3: 4.6266833e-15 | K3: 4.640447e-15 | L3: 4.640447e-15 | M3: 4.640447e-15 | N3: 4.7369816e-15 | O3: 4.6266833e-15 | P3: 4.7369816e-15 | Q3: 4.7369816e-15 | R3: 4.7017771e-15 | S3: 4.7017771e-15 | T3: 4.7017771e-15 | U3: 4.6266833e-15 | V3: 4.640447e-15 | W3: 4.640447e-15 | X3: 4.640447e-15 | Y3: 4.7369816e-15 | Z3: 4.7369816e-15 | AA3: 4.7369816e-15 | AB3: 1 | AC3: 1 | AD3: 2.17458e-06 | AE3: 1.830598e-29 | AF3: -3.5581301e-29 | AG3: 9.5901822e-29 | AH3: -1.230877e-28 | AI3: 3.2853145e-30 | AJ3: -9.8795667e-30 | AK3: 2.0770796e-30 | AL3: 4.4762151e-29 | AM3: -3.9444533e-29 | AN3: -4.0164097e-29 | AO3: 3.3254347e-29 | AP3: -1.5501883e-29 | AQ3: 8.8164175e-29 | AR3: -1.4593661e-28 | AS3: 5.8006559e-29 | AT3: 3.5607541e-29 | AU3: -1.1793007e-28 | AV3: 1.6666737e-29 | AW3: -2.4374185e-29 | AX3: 5.1195042e-29 | AY3: -3.3134763e-29 | AZ3: 2.9499688e-29 | BA3: 1.1119589e-28 | BB3: -1.0612163e-28 | BC3: 16000000 | BD3: 4000000 | BE3: -1.0428588e-06 | BF3: 2.223441e-06 | BG3: 6.1472234e-07 | BH3: -1.7927403e-08 | BI3: 0.52894059 | BJ3: 0.26447035 | BK3: 0.48285069
A4: 3.9716412 | B4: 1.3232886e-12 | C4: =(BF4-BF3)/(A4-A3) -> 5.5975121e-06 | D4: 4.6361124e-14 | E4: 4.7112421e-14 | F4: 4.7112421e-14 | G4: 4.7112421e-14 | H4: 4.6361124e-14 | I4: 4.6361124e-14 | J4: 4.6361124e-14 | K4: 4.6498197e-14 | L4: 4.6498197e-14 | M4: 4.6498197e-14 | N4: 4.7469077e-14 | O4: 4.6361124e-14 | P4: 4.7469077e-14 | Q4: 4.7469077e-14 | R4: 4.7112421e-14 | S4: 4.7112421e-14 | T4: 4.7112421e-14 | U4: 4.6361124e-14 | V4: 4.6498197e-14 | W4: 4.6498197e-14 | X4: 4.6498197e-14 | Y4: 4.7469077e-14 | Z4: 4.7469077e-14 | AA4: 4.7469077e-14 | AB4: 1 | AC4: 1 | AD4: 2.1743846e-05 | AE4: 2.0265003e-28 | AF4: 5.370405e-27 | AG4: 8.472692e-27 | AH4: -4.1718357e-27 | AI4: 8.5801025e-28 | AJ4: -1.2130508e-27 | AK4: -8.6612951e-28 | AL4: 3.9585701e-27 | AM4: -1.3939359e-27 | AN4: 1.1759617e-27 | AO4: 1.4697511e-27 | AP4: -1.6063481e-27 | AQ4: 3.6533215e-27 | AR4: -7.5165176e-27 | AS4: 2.9725916e-27 | AT4: 6.9255258e-27 | AU4: -5.2919693e-27 | AV4: 1.3042638e-27 | AW4: 3.9079068e-27 | AX4: 8.9103918e-27 | AY4: 3.8813571e-27 | AZ4: -1.3640726e-27 | BA4: 2.2136341e-27 | BB4: -9.2795799e-27 | BC4: 16000000 | BD4: 4000000 | BE4: -1.0428367e-05 | BF4: 2.223162e-05 | BG4: 6.1474076e-06 | BH4: -1.7928124e-06 | BI4: 5.2893996 | BJ4: 2.6447046 | BK4: 4.8284658
A5: 39.716412 | B5: 1.3458364e-10 | C5: =(BF5-BF4)/(A5-A4) -> 5.5897983e-06 | D5: 4.7329589e-13 | E5: 4.8083022e-13 | F5: 4.8083022e-13 | G5: 4.8083022e-13 | H5: 4.7329589e-13 | I5: 4.7329589e-13 | J5: 4.7329589e-13 | K5: 4.7460895e-13 | L5: 4.7460895e-13 | M5: 4.7460895e-13 | N5: 4.8488987e-13 | O5: 4.7329589e-13 | P5: 4.8488987e-13 | Q5: 4.8488987e-13 | R5: 4.8083022e-13 | S5: 4.8083022e-13 | T5: 4.8083022e-13 | U5: 4.7329589e-13 | V5: 4.7460895e-13 | W5: 4.7460895e-13 | X5: 4.7460895e-13 | Y5: 4.8488987e-13 | Z5: 4.8488987e-13 | AA5: 4.8488987e-13 | AB5: 1 | AC5: 0.99999982 | AD5: 0.00021724338 | AE5: 1.69046e-21 | AF5: -7.085805e-21 | AG5: 6.3453774e-20 | AH5: -2.8137832e-21 | AI5: -3.8845323e-22 | AJ5: -3.161191e-22 | AK5: -6.7707246e-22 | AL5: 8.8557028e-21 | AM5: -2.7291303e-21 | AN5: 1.2235939e-21 | AO5: -2.8297231e-21 | AP5: -2.5646518e-21 | AQ5: -1.0981398e-21 | AR5: -1.1398941e-20 | AS5: 2.5423359e-20 | AT5: 7.2791638e-22 | AU5: -9.1705942e-21 | AV5: 6.8700192e-21 | AW5: 1.0183788e-20 | AX5: 2.2286389e-20 | AY5: 1.5216645e-21 | AZ5: 6.8218168e-22 | BA5: 5.0490449e-21 | BB5: -1.2929112e-20 | BC5: 16000000 | BD5: 4000000 | BE5: -0.00010426155 | BF5: 0.00022203768 | BG5: 6.1492414e-05 | BH5: -0.00017933875 | BI5: 52.893354 | BJ5: 26.447163 | BK5: 48.280552
A6: 188.81866 | B6: 1.302124e-07 | C6: =(BF6-BF5)/(A6-A5) -> 4.1100306e-06 | D6: 2.4571658e-12 | E6: 2.493055e-12 | F6: 2.4933018e-12 | G6: 2.4931326e-12 | H6: 2.4571642e-12 | I6: 2.4571615e-12 | J6: 2.4571632e-12 | K6: 2.4619295e-12 | L6: 2.4619306e-12 | M6: 2.4619342e-12 | N6: 2.5237115e-12 | O6: 2.4571638e-12 | P6: 2.5237118e-12 | Q6: 2.5237103e-12 | R6: 2.4931147e-12 | S6: 2.4930519e-12 | T6: 2.4930595e-12 | U6: 2.4571893e-12 | V6: 2.4619431e-12 | W6: 2.4619357e-12 | X6: 2.461941e-12 | Y6: 2.5237285e-12 | Z6: 2.5237188e-12 | AA6: 2.5237186e-12 | AB6: 0.93717524 | AC6: 0.24393665 | AD6: 0.00081786207 | AE6: 1.8228648e-11 | AF6: -8.4637738e-11 | AG6: 1.5164516e-09 | AH6: 2.4121842e-10 | AI6: -7.1655659e-12 | AJ6: 1.0187019e-12 | AK6: -4.9660034e-12 | AL6: 2.3331598e-11 | AM6: -1.7794463e-11 | AN6: 2.1892686e-11 | AO6: -1.553785e-11 | AP6: -5.7871617e-12 | AQ6: -4.2064391e-11 | AR6: -3.8556372e-11 | AS6: 4.2355011e-10 | AT6: -3.7935226e-11 | AU6: -4.914163e-11 | AV6: 1.4885015e-11 | AW6: 6.4694022e-11 | AX6: 8.9285248e-11 | AY6: -1.7792784e-11 | AZ6: -2.7942311e-11 | BA6: 6.3922321e-11 | BB6: -4.4184575e-11 | BC6: 16000001 | BD6: 4000072.5 | BE6: -0.00039359157 | BF6: 0.00083485248 | BG6: 0.00023244948 | BH6: -0.002581979 | BI6: 199.75904 | BJ6: 99.88634 | BK6: 182.29088
A7: 1759.9964 | B7: 3.0213759e-06 | C7: =(BF7-BF6)/(A7-A6) -> 1.6050489e-09 | D7: 2.4577947e-12 | E7: 2.4941298e-12 | F7: 2.4968132e-12 | G7: 2.4955768e-12 | H7: 2.4576822e-12 | I7: 2.4575466e-12 | J7: 2.4575995e-12 | K7: 2.4617751e-12 | L7: 2.4618731e-12 | M7: 2.4619626e-12 | N7: 2.5236157e-12 | O7: 2.4577137e-12 | P7: 2.5234942e-12 | Q7: 2.5234817e-12 | R7: 2.4945687e-12 | S7: 2.4936285e-12 | T7: 2.4937786e-12 | U7: 2.4590507e-12 | V7: 2.4625239e-12 | W7: 2.4622471e-12 | X7: 2.4624721e-12 | Y7: 2.524267e-12 | Z7: 2.5240925e-12 | AA7: 2.5240355e-12 | AB7: 1.0041305 | AC7: 0.24124536 | AD7: 0.00082095537 | AE7: 5.7861345e-12 | AF7: -3.4565456e-11 | AG7: 7.3423783e-11 | AH7: -5.852431e-11 | AI7: 2.3305151e-13 | AJ7: -7.2933779e-13 | AK7: -3.1291905e-12 | AL7: 1.577881e-11 | AM7: -9.3308977e-12 | AN7: 3.5274938e-12 | AO7: -1.3033662e-11 | AP7: -5.2592636e-12 | AQ7: -7.5001485e-12 | AR7: -1.8580992e-11 | AS7: 1.9093693e-11 | AT7: 7.9694588e-13 | AU7: -9.4679632e-12 | AV7: 3.930155e-11 | AW7: 3.5383224e-11 | AX7: 6.0148786e-11 | AY7: -7.9732709e-12 | AZ7: 1.1124079e-11 | BA7: 2.9626141e-11 | BB7: -2.0938402e-11 | BC7: 15999920 | BD7: 4001737.2 | BE7: -0.00039604646 | BF7: 0.0008373743 | BG7: 0.00023247006 | BH7: -0.0026224651 | BI7: 199.75837 | BJ7: 99.886332 | BK7: 182.29953
A8: 17599.964 | B8: 1.8117639e-05 | C8: =(BF8-BF7)/(A8-A7) -> 7.9234828e-10 | D8: 2.4617138e-12 | E8: 2.4993426e-12 | F8: 2.5070462e-12 | G8: 2.505212e-12 | H8: 2.4608803e-12 | I8: 2.4603402e-12 | J8: 2.4601757e-12 | K8: 2.4623165e-12 | L8: 2.4634567e-12 | M8: 2.4629992e-12 | N8: 2.5253784e-12 | O8: 2.4616834e-12 | P8: 2.5240341e-12 | Q8: 2.524123e-12 | R8: 2.4995616e-12 | S8: 2.4962083e-12 | T8: 2.4967743e-12 | U8: 2.4699979e-12 | V8: 2.4668852e-12 | W8: 2.4663421e-12 | X8: 2.4667642e-12 | Y8: 2.5280133e-12 | Z8: 2.5283574e-12 | AA8: 2.5283602e-12 | AB8: 0.99927813 | AC8: 0.22871199 | AD8: 0.00083591823 | AE8: 7.5125154e-13 | AF8: -8.0822473e-12 | AG8: 8.7383266e-12 | AH8: -1.7443e-11 | AI8: -1.4020283e-12 | AJ8: -1.3973409e-12 | AK8: -8.7045083e-13 | AL8: 6.7269321e-12 | AM8: -1.5644623e-12 | AN8: 5.2705768e-14 | AO8: -7.2155897e-12 | AP8: -2.7470091e-12 | AQ8: -1.1949642e-12 | AR8: -1.0251531e-11 | AS8: 3.7411801e-12 | AT8: 3.6987337e-12 | AU8: -1.7132264e-12 | AV8: 1.1091613e-11 | AW8: 1.7092094e-11 | AX8: 2.6375863e-11 | AY8: -1.3412876e-13 | AZ8: 3.6484579e-12 | BA8: 2.9299583e-12 | BB8: -1.4943784e-11 | BC8: 15998845 | BD8: 4010502.8 | BE8: -0.00040800322 | BF8: 0.00084992507 | BG8: 0.00023280239 | BH8: -0.0027696526 | BI8: 199.75727 | BJ8: 99.886375 | BK8: 182.35444
A9: 141611.39 | B9: 7.6707478e-05 | C9: =(BF9-BF8)/(A9-A8) -> 3.9014692e-10 | D9: 2.4815538e-12 | E9: 2.5227357e-12 | F9: 2.5450372e-12 | G9: 2.5401833e-12 | H9: 2.4749427e-12 | I9: 2.4761984e-12 | J9: 2.4714704e-12 | K9: 2.46893e-12 | L9: 2.4773694e-12 | M9: 2.4704822e-12 | N9: 2.5422686e-12 | O9: 2.4823246e-12 | P9: 2.533907e-12 | Q9: 2.5342291e-12 | R9: 2.5216502e-12 | S9: 2.5071696e-12 | T9: 2.5101882e-12 | U9: 2.5175857e-12 | V9: 2.4907462e-12 | W9: 2.4915117e-12 | X9: 2.489428e-12 | Y9: 2.5516928e-12 | Z9: 2.5532519e-12 | AA9: 2.5591969e-12 | AB9: 0.98873337 | AC9: 0.19361441 | AD9: 0.0008916165 | AE9: -8.1621334e-13 | AF9: 3.2032078e-13 | AG9: 1.8188242e-12 | AH9: -4.4639288e-12 | AI9: -1.4634321e-12 | AJ9: -3.6284789e-13 | AK9: 1.7283598e-14 | AL9: 1.5318809e-12 | AM9: 1.2490242e-12 | AN9: 3.1258732e-13 | AO9: -8.3513715e-13 | AP9: -9.5533191e-13 | AQ9: 5.3306787e-13 | AR9: -4.5366065e-12 | AS9: 3.8200166e-13 | AT9: 2.437899e-12 | AU9: 2.8197512e-13 | AV9: -9.0266642e-13 | AW9: 5.7592245e-12 | AX9: 7.6015002e-12 | AY9: 2.7362465e-12 | AZ9: -5.1359866e-13 | BA9: -3.1939728e-12 | BB9: -7.4168617e-12 | BC9: 15991550 | BD9: 4044689.9 | BE9: -0.00045161255 | BF9: 0.00089830775 | BG9: 0.00023541178 | BH9: -0.0028984829 | BI9: 199.75434 | BJ9: 99.886401 | BK9: 182.55044
A10: 278087.68 | B10: 0.00011977353 | C10: =(BF10-BF9)/(A10-A9) -> 2.6538651e-10 | D10: 2.4958839e-12 | E10: 2.5396108e-12 | F10: 2.5698314e-12 | G10: 2.5620827e-12 | H10: 2.4838064e-12 | I10: 2.4882492e-12 | J10: 2.4786238e-12 | K10: 2.4750888e-12 | L10: 2.4897557e-12 | M10: 2.4770462e-12 | N10: 2.5563992e-12 | O10: 2.4965422e-12 | P10: 2.5427558e-12 | Q10: 2.5433386e-12 | R10: 2.5382456e-12 | S10: 2.5145582e-12 | T10: 2.520012e-12 | U10: 2.5469913e-12 | V10: 2.5089359e-12 | W10: 2.5109012e-12 | X10: 2.5056478e-12 | Y10: 2.5704185e-12 | Z10: 2.5711083e-12 | AA10: 2.5831744e-12 | AB10: 1.004981 | AC10: 0.18231114 | AD10: 0.000932304 | AE10: -9.9144857e-13 | AF10: 8.269134e-13 | AG10: 1.5346654e-12 | AH10: -2.988165e-12 | AI10: -1.2136883e-12 | AJ10: -2.7775703e-13 | AK10: -1.0281904e-13 | AL10: 8.8443382e-13 | AM10: 1.2219618e-12 | AN10: 3.1614846e-13 | AO10: 1.1490244e-13 | AP10: -7.7056079e-13 | AQ10: 4.8994209e-13 | AR10: -3.3645389e-12 | AS10: 2.9143564e-13 | AT10: 1.8672046e-12 | AU10: 4.3578596e-13 | AV10: -1.0986479e-12 | AW10: 4.363617e-12 | AX10: 5.2771463e-12 | AY10: 2.9872278e-12 | AZ10: -8.0623407e-13 | BA10: -3.1400322e-12 | BB10: -5.386549e-12 | BC10: 15984583 | BD10: 4069881.8 | BE10: -0.00048249079 | BF10: 0.00093452671 | BG10: 0.00023828057 | BH10: -0.002983621 | BI10: 199.75273 | BJ10: 99.886528 | BK10: 182.67169
A11: 658130.16 | B11: 0.00021224891 | C11: =(BF11-BF10)/(A11-A10) -> 2.1024766e-10 | D11: 2.5280696e-12 | E11: 2.5772615e-12 | F11: 2.6223053e-12 | G11: 2.6074831e-12 | H11: 2.5025719e-12 | I11: 2.5156318e-12 | J11: 2.4936877e-12 | K11: 2.4900915e-12 | L11: 2.5197626e-12 | M11: 2.4928979e-12 | N11: 2.5882858e-12 | O11: 2.5269905e-12 | P11: 2.5627449e-12 | Q11: 2.5645309e-12 | R11: 2.5760843e-12 | S11: 2.5303717e-12 | T11: 2.5423541e-12 | U11: 2.6056942e-12 | V11: 2.5499594e-12 | W11: 2.5542712e-12 | X11: 2.5403672e-12 | Y11: 2.6122226e-12 | Z11: 2.6088578e-12 | AA11: 2.6345503e-12 | AB11: 1.0138212 | AC11: 0.17430756 | AD11: 0.0010205312 | AE11: -7.610955e-13 | AF11: 1.0943432e-12 | AG11: 1.3757447e-12 | AH11: -1.7551132e-12 | AI11: -9.2167203e-13 | AJ11: -3.8271633e-13 | AK11: -2.7441123e-13 | AL11: 4.0541347e-13 | AM11: 8.9265073e-13 | AN11: 1.7332793e-13 | AO11: 5.8894565e-13 | AP11: -5.4560535e-13 | AQ11: 2.8958428e-13 | AR11: -2.2068871e-12 | AS11: 3.0025617e-13 | AT11: 1.2540936e-12 | AU11: 4.9844376e-13 | AV11: -7.9409138e-13 | AW11: 2.9881074e-12 | AX11: 3.4942054e-12 | AY11: 2.6206336e-12 | AZ11: -9.4414223e-13 | BA11: -2.5081279e-12 | BB11: -3.2426857e-12 | BC11: 15967208 | BD11: 4124038.2 | BE11: -0.00054721051 | BF11: 0.0010144298 | BG11: 0.0002461939 | BH11: -0.003476695 | BI11: 199.74843 | BJ11: 99.886239 | BK11: 182.8887
A12: 930613.72 | B12: 0.00026728788 | C12: =(BF12-BF11)/(A12-A11) -> 1.7941617e-10 | D12: 2.5476663e-12 | E12: 2.5998285e-12 | F12: 2.6527179e-12 | G12: 2.6334455e-12 | H12: 2.5137951e-12 | I12: 2.5322394e-12 | J12: 2.5025201e-12 | K12: 2.4995847e-12 | L12: 2.538726e-12 | M12: 2.502801e-12 | N12: 2.6074022e-12 | O12: 2.5449443e-12 | P12: 2.5746152e-12 | Q12: 2.5774853e-12 | R12: 2.5989586e-12 | S12: 2.539509e-12 | T12: 2.5559985e-12 | U12: 2.638429e-12 | V12: 2.5746974e-12 | W12: 2.5801385e-12 | X12: 2.5604785e-12 | Y12: 2.6370443e-12 | Z12: 2.6306016e-12 | AA12: 2.6639129e-12 | AB12: 1.0017293 | AC12: 0.17506489 | AD12: 0.0010737227 | AE12: -5.6490673e-13 | AF12: 1.1819744e-12 | AG12: 1.3434404e-12 | AH12: -1.4118981e-12 | AI12: -8.3743271e-13 | AJ12: -4.3618853e-13 | AK12: -3.097138e-13 | AL12: 2.98483e-13 | AM12: 7.7830693e-13 | AN12: 8.4163019e-14 | AO12: 6.4053068e-13 | AP12: -4.4833951e-13 | AQ12: 2.2302903e-13 | AR12: -1.8726869e-12 | AS12: 2.8428524e-13 | AT12: 1.0708643e-12 | AU12: 4.8320442e-13 | AV12: -6.7755724e-13 | AW12: 2.5273685e-12 | AX12: 3.0215305e-12 | AY12: 2.3224349e-12 | AZ12: -9.6926181e-13 | BA12: -2.1792928e-12 | BB12: -2.6049611e-12 | BC12: 15955738 | BD12: 4156270.7 | BE12: -0.00058498997 | BF12: 0.0010633177 | BG12: 0.00025182591 | BH12: -0.0036278868 | BI12: 199.74618 | BJ12: 99.8864 | BK12: 182.99185
A13: 1216670.9 | B13: 0.00031994952 | C13: =(BF13-BF12)/(A13-A12) -> 1.6622339e-10 | D13: 2.566408e-12 | E13: 2.6211553e-12 | F13: 2.6810566e-12 | G13: 2.657508e-12 | H13: 2.5245532e-12 | I13: 2.5480289e-12 | J13: 2.5108276e-12 | K13: 2.508801e-12 | L13: 2.5570858e-12 | M13: 2.5122802e-12 | N13: 2.625523e-12 | O13: 2.5618989e-12 | P13: 2.5857991e-12 | Q13: 2.5898837e-12 | R13: 2.620634e-12 | S13: 2.5479562e-12 | T13: 2.5690392e-12 | U13: 2.6684832e-12 | V13: 2.5981124e-12 | W13: 2.6045298e-12 | X13: 2.5792261e-12 | Y13: 2.6603876e-12 | Z13: 2.6508649e-12 | AA13: 2.6910024e-12 | AB13: 1.0009412 | AC13: 0.17753111 | AD13: 0.0011250402 | AE13: -4.0234118e-13 | AF13: 1.2416491e-12 | AG13: 1.3299281e-12 | AH13: -1.1926533e-12 | AI13: -7.841615e-13 | AJ13: -4.684123e-13 | AK13: -3.2653636e-13 | AL13: 2.3877629e-13 | AM13: 7.162488e-13 | AN13: 1.4157578e-14 | AO13: 6.5069888e-13 | AP13: -3.716663e-13 | AQ13: 1.8775783e-13 | AR13: -1.6649641e-12 | AS13: 2.740015e-13 | AT13: 9.4954401e-13 | AU13: 4.5538823e-13 | AV13: -6.0321862e-13 | AW13: 2.2066949e-12 | AX13: 2.7065993e-12 | AY13: 2.0730982e-12 | AZ13: -9.8351794e-13 | BA13: -1.9295061e-12 | BB13: -2.1964343e-12 | BC13: 15944211 | BD13: 4187068.5 | BE13: -0.0006207349 | BF13: 0.0011108671 | BG13: 0.00025772686 | BH13: -0.0038603743 | BI13: 199.74355 | BJ13: 99.886083 | BK13: 183.07653
A14: 1538786.6 | B14: 0.00037504869 | C14: =(BF14-BF13)/(A14-A13) -> 1.5666028e-10 | D14: 2.5855269e-12 | E14: 2.6426842e-12 | F14: 2.7093853e-12 | G14: 2.6814638e-12 | H14: 2.5355918e-12 | I14: 2.5640418e-12 | J14: 2.5191938e-12 | K14: 2.5183145e-12 | L14: 2.5759547e-12 | M14: 2.5219124e-12 | N14: 2.6438557e-12 | O14: 2.5790341e-12 | P14: 2.5970569e-12 | Q14: 2.6025184e-12 | R14: 2.6425675e-12 | S14: 2.5563306e-12 | T14: 2.5823458e-12 | U14: 2.6982112e-12 | V14: 2.6217447e-12 | W14: 2.629132e-12 | X14: 2.5979797e-12 | Y14: 2.6838185e-12 | Z14: 2.6711284e-12 | AA14: 2.7178228e-12 | AB14: 0.99928227 | AC14: 0.18102346 | AD14: 0.0011791246 | AE14: -2.6939698e-13 | AF14: 1.2821618e-12 | AG14: 1.3270089e-12 | AH14: -1.0389806e-12 | AI14: -7.4784941e-13 | AJ14: -4.8968306e-13 | AK14: -3.3830334e-13 | AL14: 1.9808292e-13 | AM14: 6.7392148e-13 | AN14: -3.7305276e-14 | AO14: 6.4450525e-13 | AP14: -3.0847043e-13 | AQ14: 1.6921578e-13 | AR14: -1.5170457e-12 | AS14: 2.7696204e-13 | AT14: 8.5764335e-13 | AU14: 4.2135882e-13 | AV14: -5.5074439e-13 | AW14: 1.9511914e-12 | AX14: 2.4574894e-12 | AY14: 1.8615193e-12 | AZ14: -9.9573957e-13 | BA14: -1.7309977e-12 | BB14: -1.9023914e-12 | BC14: 15931687 | BD14: 4219219.6 | BE14: -0.00065776006 | BF14: 0.0011613298 | BG14: 0.00026437723 | BH14: -0.0041515344 | BI14: 199.74113 | BJ14: 99.886101 | BK14: 183.15322
... A71: 49341110 | B71: 0.0060242831 | C71: =(BF71-BF70)/(A71-A70) -> 1.2292493e-10 | D71: 3.9947666e-12 | E71: 4.130483e-12 | F71: 4.5404065e-12 | G71: 4.1173196e-12 | H71: 3.5308733e-12 | I71: 3.7460427e-12 | J71: 3.1886117e-12 | K71: 3.3692607e-12 | L71: 4.0562858e-12 | M71: 3.2467623e-12 | N71: 3.9479262e-12 | O71: 3.7111692e-12 | P71: 3.4538072e-12 | Q71: 3.5779776e-12 | R71: 4.2435138e-12 | S71: 3.1756948e-12 | T71: 3.7097386e-12 | U71: 4.4369046e-12 | V71: 4.1699468e-12 | W71: 4.2581305e-12 | X71: 3.7882295e-12 | Y71: 4.1602835e-12 | Z71: 4.0107889e-12 | AA71: 4.2267056e-12 | AB71: 0.99950382 | AC71: 0.30497112 | AD71: 0.0068681024 | AE71: 5.938598e-13 | AF71: 1.1559811e-12 | AG71: 6.2261801e-13 | AH71: -6.7560183e-13 | AI71: -1.340175e-12 | AJ71: -1.1763515e-12 | AK71: -1.1383996e-12 | AL71: -9.9869581e-13 | AM71: -3.805363e-13 | AN71: -8.7388123e-13 | AO71: -5.2158483e-13 | AP71: 3.0777519e-14 | AQ71: -4.9848643e-13 | AR71: -1.6093397e-12 | AS71: -4.5390534e-13 | AT71: -1.8457082e-13 | AU71: -5.8834932e-13 | AV71: -1.3500163e-13 | AW71: 7.5563353e-13 | AX71: 1.3669727e-12 | AY71: 9.1130396e-13 | AZ71: -9.5233103e-13 | BA71: -1.2556531e-12 | BB71: -7.482564e-14 | BC71: 14711770 | BD71: 6759985.8 | BE71: -0.00371675 | BF71: 0.0068801373 | BG71: 0.0014336317 | BH71: -0.019348252 | BI71: 199.5342 | BJ71: 99.884231 | BK71: 184.86267

Sheet 773K_52MPa_512g
A1: time | B1: Ep_eff | C1: StrainRate | D1: cstrain_1 | E1: cstrain_10 | F1: cstrain_11 | G1: cstrain_12 | H1: cstrain_13 | I1: cstrain_14 | J1: cstrain_15 | K1: cstrain_16 | L1: cstrain_17 | M1: cstrain_18 | N1: cstrain_19 | O1: cstrain_2 | P1: cstrain_20 | Q1: cstrain_21 | R1: cstrain_22 | S1: cstrain_23 | T1: cstrain_24 | U1: cstrain_3 | V1: cstrain_4 | W1: cstrain_5 | X1: cstrain_6 | Y1: cstrain_7 | Z1: cstrain_8 | AA1: cstrain_9 | AB1: cstrainfrac1 | AC1: cstrainfrac2 | AD1: eeq | AE1: gstrain_1 | AF1: gstrain_10 | AG1: gstrain_11 | AH1: gstrain_12 | AI1: gstrain_13 | AJ1: gstrain_14 | AK1: gstrain_15 | AL1: gstrain_16 | AM1: gstrain_17 | AN1: gstrain_18 | AO1: gstrain_19 | AP1: gstrain_2 | AQ1: gstrain_20 | AR1: gstrain_21 | AS1: gstrain_22 | AT1: gstrain_23 | AU1: gstrain_24 | AV1: gstrain_3 | AW1: gstrain_4 | AX1: gstrain_5 | AY1: gstrain_6 | AZ1: gstrain_7 | BA1: gstrain_8 | BB1: gstrain_9 | BC1: rho_i | BD1: rho_m | BE1: strain_xx | BF1: strain_yy | BG1: strain_zz | BH1: stress_xx | BI1: stress_yy | BJ1: stress_zz | BK1: vonmises
A2: 0 | B2: 0 | D2: 0 | E2: 0 | F2: 0 | G2: 0 | H2: 0 | I2: 0 | J2: 0 | K2: 0 | L2: 0 | M2: 0 | N2: 0 | O2: 0 | P2: 0 | Q2: 0 | R2: 0 | S2: 0 | T2: 0 | U2: 0 | V2: 0 | W2: 0 | X2: 0 | Y2: 0 | Z2: 0 | AA2: 0 | AB2: 0 | AC2: 0 | AD2: 0 | AE2: 0 | AF2: 0 | AG2: 0 | AH2: 0 | AI2: 0 | AJ2: 0 | AK2: 0 | AL2: 0 | AM2: 0 | AN2: 0 | AO2: 0 | AP2: 0 | AQ2: 0 | AR2: 0 | AS2: 0 | AT2: 0 | AU2: 0 | AV2: 0 | AW2: 0 | AX2: 0 | AY2: 0 | AZ2: 0 | BA2: 0 | BB2: 0 | BC2: 0 | BD2: 0 | BE2: 0 | BF2: 0 | BG2: 0 | BH2: 0 | BI2: 0 | BJ2: 0 | BK2: 0
A3: 0.39716412 | B3: 3.7696642e-15 | C3: =(BF3-BF2)/(A3-A2) -> 1.6827403e-06 | D3: 1.3905256e-15 | E3: 1.4130878e-15 | F3: 1.4130878e-15 | G3: 1.4130878e-15 | H3: 1.3905256e-15 | I3: 1.3905256e-15 | J3: 1.3905256e-15 | K3: 1.3946654e-15 | L3: 1.3946654e-15 | M3: 1.3946654e-15 | N3: 1.4236706e-15 | O3: 1.3905256e-15 | P3: 1.4236706e-15 | Q3: 1.4236706e-15 | R3: 1.4130878e-15 | S3: 1.4130878e-15 | T3: 1.4130878e-15 | U3: 1.3905256e-15 | V3: 1.3946654e-15 | W3: 1.3946654e-15 | X3: 1.3946654e-15 | Y3: 1.4236706e-15 | Z3: 1.4236706e-15 | AA3: 1.4236706e-15 | AB3: 1 | AC3: 1 | AD3: 6.5363556e-07 | AE3: 1.7507514e-29 | AF3: -4.2644407e-29 | AG3: 3.6468554e-29 | AH3: -6.86082e-29 | AI3: -9.4183439e-30 | AJ3: -2.1247738e-30 | AK3: 9.680079e-30 | AL3: 2.3744049e-29 | AM3: -2.384714e-29 | AN3: -3.603003e-29 | AO3: 9.4630754e-30 | AP3: -3.2681692e-30 | AQ3: 5.1105051e-29 | AR3: -8.1184686e-29 | AS3: 2.6634334e-29 | AT3: -9.3671145e-31 | AU3: -5.4721236e-29 | AV3: 4.1137729e-30 | AW3: -2.3361797e-29 | AX3: 2.2427832e-29 | AY3: -2.7603168e-29 | AZ3: 2.6263525e-29 | BA3: 6.3002802e-29 | BB3: -4.5642469e-29 | BC3: 16000000 | BD3: 4000000 | BE3: -3.1346097e-07 | BF3: 6.6832405e-07 | BG3: 1.847716e-07 | BH3: -1.6195354e-09 | BI3: 0.15898794 | BJ3: 0.079493974 | BK3: 0.14513441
A4: 3.9716412 | B4: 3.9710067e-13 | C4: =(BF4-BF3)/(A4-A3) -> 1.6826698e-06 | D4: 1.3912966e-14 | E4: 1.4138723e-14 | F4: 1.4138723e-14 | G4: 1.4138723e-14 | H4: 1.3912966e-14 | I4: 1.3912966e-14 | J4: 1.3912966e-14 | K4: 1.3954296e-14 | L4: 1.3954296e-14 | M4: 1.3954296e-14 | N4: 1.4244824e-14 | O4: 1.3912966e-14 | P4: 1.4244824e-14 | Q4: 1.4244824e-14 | R4: 1.4138723e-14 | S4: 1.4138723e-14 | T4: 1.4138723e-14 | U4: 1.3912966e-14 | V4: 1.3954296e-14 | W4: 1.3954296e-14 | X4: 1.3954296e-14 | Y4: 1.4244824e-14 | Z4: 1.4244824e-14 | AA4: 1.4244824e-14 | AB4: 1 | AC4: 1 | AD4: 6.5361792e-06 | AE4: 1.155674e-29 | AF4: 1.3228273e-28 | AG4: 4.3969722e-28 | AH4: -3.4611913e-28 | AI4: 7.4422403e-29 | AJ4: -6.2788823e-29 | AK4: -5.132616e-29 | AL4: 1.6490238e-28 | AM4: -1.0822386e-28 | AN4: -9.680924e-30 | AO4: 1.4673446e-28 | AP4: -8.1713987e-29 | AQ4: 2.5989081e-28 | AR4: -4.6127185e-28 | AS4: 2.034723e-28 | AT4: 3.004877e-28 | AU4: -4.1417599e-28 | AV4: 7.8258681e-29 | AW4: 5.2745386e-29 | AX4: 2.844932e-28 | AY4: 3.7339476e-29 | AZ4: -4.5835338e-30 | BA4: 2.9462275e-28 | BB4: -4.6267258e-28 | BC4: 16000000 | BD4: 4000000 | BE4: -3.1345897e-06 | BF4: 6.6829886e-06 | BG4: 1.8477328e-06 | BH4: -1.6197113e-07 | BI4: 1.5898788 | BJ4: 0.79493985 | BK4: 1.4513404
A5: 39.716412 | B5: 3.9929422e-11 | C5: =(BF5-BF4)/(A5-A4) -> 1.6819726e-06 | D5: 1.3999195e-13 | E5: 1.4225179e-13 | F5: 1.4225179e-13 | G5: 1.4225179e-13 | H5: 1.3999195e-13 | I5: 1.3999195e-13 | J5: 1.3999195e-13 | K5: 1.4040024e-13 | L5: 1.4040024e-13 | M5: 1.4040024e-13 | N5: 1.4335604e-13 | O5: 1.3999195e-13 | P5: 1.4335604e-13 | Q5: 1.4335604e-13 | R5: 1.4225179e-13 | S5: 1.4225179e-13 | T5: 1.4225179e-13 | U5: 1.3999195e-13 | V5: 1.4040024e-13 | W5: 1.4040024e-13 | X5: 1.4040024e-13 | Y5: 1.4335604e-13 | Z5: 1.4335604e-13 | AA5: 1.4335604e-13 | AB5: 1 | AC5: 1 | AD5: 6.5344162e-05 | AE5: 9.5654303e-26 | AF5: 3.1812403e-25 | AG5: 1.4162382e-24 | AH5: -6.0130983e-25 | AI5: -1.230281e-26 | AJ5: -9.3326378e-26 | AK5: -3.2082491e-26 | AL5: 7.2753069e-25 | AM5: -1.678222e-25 | AN5: 1.0609387e-25 | AO5: -4.3736613e-26 | AP5: -2.3366104e-25 | AQ5: 3.2946844e-25 | AR5: -1.0339326e-24 | AS5: 5.8051776e-25 | AT5: 6.8158983e-25 | AU5: -5.3842597e-25 | AV5: 2.7489494e-25 | AW5: 7.033872e-25 | AX5: 1.6307841e-24 | AY5: 5.0289809e-25 | AZ5: -7.5654561e-26 | BA5: 1.1785777e-25 | BB5: -1.2358957e-24 | BC5: 16000000 | BD5: 4000000 | BE5: -3.1343891e-05 | BF5: 6.6804712e-05 | BG5: 1.8479007e-05 | BH5: -1.6198863e-05 | BI5: 15.89873 | BJ5: 7.9494091 | BK5: 14.513032
A6: 397.16412 | B6: 2.7567984e-09 | C6: =(BF6-BF5)/(A6-A5) -> 5.179857e-07 | D6: 6.8299372e-13 | E6: 6.9377082e-13 | F6: 6.9377082e-13 | G6: 6.9377082e-13 | H6: 6.8299372e-13 | I6: 6.8299372e-13 | J6: 6.8299372e-13 | K6: 6.8482955e-13 | L6: 6.8482955e-13 | M6: 6.8482955e-13 | N6: 6.9992008e-13 | O6: 6.8299372e-13 | P6: 6.9992008e-13 | Q6: 6.9992008e-13 | R6: 6.9377082e-13 | S6: 6.9377082e-13 | T6: 6.9377082e-13 | U6: 6.8299372e-13 | V6: 6.8482955e-13 | W6: 6.8482955e-13 | X6: 6.8482955e-13 | Y6: 6.9992008e-13 | Z6: 6.9992008e-13 | AA6: 6.9992008e-13 | AB6: 0.99999998 | AC6: 0.99999392 | AD6: 0.00024653955 | AE6: 1.0669534e-19 | AF6: -5.4019331e-19 | AG6: 5.750378e-18 | AH6: 3.2851601e-19 | AI6: -2.6240764e-20 | AJ6: -6.8782566e-21 | AK6: -4.4450551e-20 | AL6: 4.26102e-19 | AM6: -1.6068686e-19 | AN6: 9.197082e-20 | AO6: -1.6448553e-19 | AP6: -1.1888989e-19 | AQ6: -1.6042223e-19 | AR6: -5.5318708e-19 | AS6: 2.0706213e-18 | AT6: -1.2802284e-19 | AU6: -5.6831841e-19 | AV6: 3.8329558e-19 | AW6: 5.6445613e-19 | AX6: 1.1560515e-18 | AY6: 1.1339153e-21 | AZ6: 1.2382071e-20 | BA6: 3.7850258e-19 | BB6: -6.2435775e-19 | BC6: 15999999 | BD6: 3999999.6 | BE6: -0.00011835077 | BF6: 0.00025195751 | BG6: 6.9811818e-05 | BH6: -0.00022994068 | BI6: 60.04528 | BJ6: 30.023262 | BK6: 54.807533
A7: 3971.6412 | B7: 3.4355812e-08 | C7: =(BF7-BF6)/(A7-A6) -> 9.5694888e-12 | D7: 6.8299136e-13 | E7: 6.9376889e-13 | F7: 6.9376889e-13 | G7: 6.9376889e-13 | H7: 6.8299136e-13 | I7: 6.8299136e-13 | J7: 6.8299136e-13 | K7: 6.8482713e-13 | L7: 6.8482713e-13 | M7: 6.8482713e-13 | N7: 6.9991771e-13 | O7: 6.8299136e-13 | P7: 6.9991771e-13 | Q7: 6.9991771e-13 | R7: 6.9376889e-13 | S7: 6.9376889e-13 | T7: 6.9376889e-13 | U7: 6.8299136e-13 | V7: 6.8482713e-13 | W7: 6.8482713e-13 | X7: 6.8482713e-13 | Y7: 6.9991771e-13 | Z7: 6.9991771e-13 | AA7: 6.9991771e-13 | AB7: 0.99999999 | AC7: 0.99999392 | AD7: 0.00024656549 | AE7: 1.066233e-19 | AF7: -5.4011596e-19 | AG7: 5.7494885e-18 | AH7: 3.285866e-19 | AI7: -2.6244002e-20 | AJ7: -6.8805867e-21 | AK7: -4.437497e-20 | AL7: 4.2611049e-19 | AM7: -1.6060657e-19 | AN7: 9.2018595e-20 | AO7: -1.6441032e-19 | AP7: -1.1889518e-19 | AQ7: -1.6034219e-19 | AR7: -5.5316756e-19 | AS7: 2.0704309e-18 | AT7: -1.2796845e-19 | AU7: -5.6813284e-19 | AV7: 3.8304038e-19 | AW7: 5.643696e-19 | AX7: 1.1559111e-18 | AY7: 1.1405751e-21 | AZ7: 1.2330825e-20 | BA7: 3.785588e-19 | BB7: -6.2439893e-19 | BC7: 15999982 | BD7: 3999994.6 | BE7: -0.00011834496 | BF7: 0.00025199172 | BG7: 6.983102e-05 | BH7: -0.0002299396 | BI7: 60.04528 | BJ7: 30.023262 | BK7: 54.807157
A8: 39716.412 | B8: 3.503362e-07 | C8: =(BF8-BF7)/(A8-A7) -> 9.5689384e-12 | D8: 6.8296778e-13 | E8: 6.9374958e-13 | F8: 6.9374958e-13 | G8: 6.9374958e-13 | H8: 6.8296778e-13 | I8: 6.8296778e-13 | J8: 6.8296778e-13 | K8: 6.8480294e-13 | L8: 6.8480294e-13 | M8: 6.8480294e-13 | N8: 6.9989411e-13 | O8: 6.8296778e-13 | P8: 6.9989411e-13 | Q8: 6.9989411e-13 | R8: 6.9374958e-13 | S8: 6.9374958e-13 | T8: 6.9374958e-13 | U8: 6.8296778e-13 | V8: 6.8480294e-13 | W8: 6.8480294e-13 | X8: 6.8480294e-13 | Y8: 6.9989411e-13 | Z8: 6.9989411e-13 | AA8: 6.9989411e-13 | AB8: 1 | AC8: 0.99999392 | AD8: 0.00024682492 | AE8: 1.0590386e-19 | AF8: -5.3934391e-19 | AG8: 5.7406009e-18 | AH8: 3.2929011e-19 | AI8: -2.6276767e-20 | AJ8: -6.9044822e-21 | AK8: -4.3620222e-20 | AL8: 4.2619496e-19 | AM8: -1.5980379e-19 | AN8: 9.2494976e-20 | AO8: -1.6365993e-19 | AP8: -1.18948e-19 | AQ8: -1.5954278e-19 | AR8: -5.5297266e-19 | AS8: 2.0685277e-18 | AT8: -1.2742481e-19 | AU8: -5.6627931e-19 | AV8: 3.8048996e-19 | AW8: 5.6350682e-19 | AX8: 1.1545078e-18 | AY8: 1.207421e-21 | AZ8: 1.1819414e-20 | BA8: 3.7911988e-19 | BB8: -6.2481068e-19 | BC8: 15999822 | BD8: 3999945.3 | BE8: -0.00011828689 | BF8: 0.00025233376 | BG8: 7.0023038e-05 | BH8: -0.00022987638 | BI8: 60.04528 | BJ8: 30.023262 | BK8: 54.803397
A9: 397164.12 | B9: 3.5091678e-06 | C9: =(BF9-BF8)/(A9-A8) -> 9.5631779e-12 | D9: 6.8273335e-13 | E9: 6.9355747e-13 | F9: 6.9355747e-13 | G9: 6.9355747e-13 | H9: 6.8273335e-13 | I9: 6.8273335e-13 | J9: 6.8273335e-13 | K9: 6.8456242e-13 | L9: 6.8456242e-13 | M9: 6.8456242e-13 | N9: 6.9965953e-13 | O9: 6.8273335e-13 | P9: 6.9965953e-13 | Q9: 6.9965953e-13 | R9: 6.9355747e-13 | S9: 6.9355747e-13 | T9: 6.9355747e-13 | U9: 6.8273335e-13 | V9: 6.8456242e-13 | W9: 6.8456242e-13 | X9: 6.8456242e-13 | Y9: 6.9965953e-13 | Z9: 6.9965953e-13 | AA9: 6.9965953e-13 | AB9: 1 | AC9: 0.99999392 | AD9: 0.00024942515 | AE9: 9.8804401e-20 | AF9: -5.3177226e-19 | AG9: 5.6524727e-18 | AH9: 3.3608673e-19 | AI9: -2.6643696e-20 | AJ9: -7.2039682e-21 | AK9: -3.6179307e-20 | AL9: 4.2699792e-19 | AM9: -1.5178936e-19 | AN9: 9.7122455e-20 | AO9: -1.5632975e-19 | AP9: -1.1947386e-19 | AQ9: -1.5164504e-19 | AR9: -5.5106003e-19 | AS9: 2.049541e-18 | AT9: -1.2201497e-19 | AU9: -5.4796423e-19 | AV9: 3.5514145e-19 | AW9: 5.5512929e-19 | AX9: 1.1405184e-18 | AY9: 1.9009454e-21 | AZ9: 6.8087712e-21 | BA9: 3.8461765e-19 | BB9: -6.2892856e-19 | BC9: 15998215 | BD9: 3999451.9 | BE9: -0.00011770507 | BF9: 0.00025575209 | BG9: 7.1942998e-05 | BH9: -0.00022933438 | BI9: 60.045285 | BJ9: 30.023263 | BK9: 54.766047
A10: 125594.32 | B10: 1.10941e-06 | C10: =(BF10-BF9)/(A10-A9) -> 9.5620171e-12 | D10: 6.829011e-13 | E10: 6.9369502e-13 | F10: 6.9369502e-13 | G10: 6.9369502e-13 | H10: 6.829011e-13 | I10: 6.829011e-13 | J10: 6.829011e-13 | K10: 6.8473455e-13 | L10: 6.8473455e-13 | M10: 6.8473455e-13 | N10: 6.9982739e-13 | O10: 6.829011e-13 | P10: 6.9982739e-13 | Q10: 6.9982739e-13 | R10: 6.9369502e-13 | S10: 6.9369502e-13 | T10: 6.9369502e-13 | U10: 6.829011e-13 | V10: 6.8473455e-13 | W10: 6.8473455e-13 | X10: 6.8473455e-13 | Y10: 6.9982739e-13 | Z10: 6.9982739e-13 | AA10: 6.9982739e-13 | AB10: 1 | AC10: 0.99999392 | AD10: 0.00024744862 | AE10: 1.0387642e-19 | AF10: -5.3717266e-19 | AG10: 5.7155083e-18 | AH10: 3.3125661e-19 | AI10: -2.637324e-20 | AJ10: -6.9780547e-21 | AK10: -4.149405e-20 | AL10: 4.2642987e-19 | AM10: -1.575322e-19 | AN10: 9.3829919e-20 | AO10: -1.6155254e-19 | AP10: -1.1909717e-19 | AQ10: -1.5728885e-19 | AR10: -5.5242385e-19 | AS10: 2.0631428e-18 | AT10: -1.2588771e-19 | AU10: -5.6105303e-19 | AV10: 3.7328517e-19 | AW10: 5.6108894e-19 | AX10: 1.1505389e-18 | AY10: 1.3989582e-21 | AZ10: 1.0382052e-20 | BA10: 3.8069673e-19 | BB10: -6.2597569e-19 | BC10: 15999436 | BD10: 3999826.7 | BE10: -0.00011814728 | BF10: 0.00025315534 | BG10: 7.048435e-05 | BH10: -0.00022972265 | BI10: 60.045281 | BJ10: 30.023263 | BK10: 54.794382
A11: 397164.12 | B11: 3.5090974e-06 | C11: =(BF11-BF10)/(A11-A10) -> 9.5613295e-12 | D11: 6.8270167e-13 | E11: 6.9353138e-13 | F11: 6.9353138e-13 | G11: 6.9353138e-13 | H11: 6.8270167e-13 | I11: 6.8270167e-13 | J11: 6.8270167e-13 | K11: 6.8452987e-13 | L11: 6.8452987e-13 | M11: 6.8452987e-13 | N11: 6.9962777e-13 | O11: 6.8270167e-13 | P11: 6.9962777e-13 | Q11: 6.9962777e-13 | R11: 6.9353138e-13 | S11: 6.9353138e-13 | T11: 6.9353138e-13 | U11: 6.8270167e-13 | V11: 6.8452987e-13 | W11: 6.8452987e-13 | X11: 6.8452987e-13 | Y11: 6.9962778e-13 | Z11: 6.9962778e-13 | AA11: 6.9962778e-13 | AB11: 1 | AC11: 0.99999392 | AD11: 0.00024942492 | AE11: 9.7857055e-20 | AF11: -5.3076468e-19 | AG11: 5.6406121e-18 | AH11: 3.3695711e-19 | AI11: -2.669819e-20 | AJ11: -7.2537005e-21 | AK11: -3.5188437e-20 | AL11: 4.2709788e-19 | AM11: -1.5070595e-19 | AN11: 9.7727373e-20 | AO11: -1.5536245e-19 | AP11: -1.1954346e-19 | AQ11: -1.5058903e-19 | AR11: -5.508032e-19 | AS11: 2.0469636e-18 | AT11: -1.2128197e-19 | AU11: -5.4551432e-19 | AV11: 3.517367e-19 | AW11: 5.5403002e-19 | AX11: 1.138627e-18 | AY11: 1.9974826e-21 | AZ11: 6.1458912e-21 | BA11: 3.8534172e-19 | BB11: -6.2948124e-19 | BC11: 15998215 | BD11: 3999451.9 | BE11: -0.000117705 | BF11: 0.00025575191 | BG11: 7.1942984e-05 | BH11: -0.00022923881 | BI11: 60.045285 | BJ11: 30.023263 | BK11: 54.766048
A12: 1255943.2 | B12: 1.1090495e-05 | C12: =(BF12-BF11)/(A12-A11) -> 9.5438838e-12 | D12: 6.820812e-13 | E12: 6.9302173e-13 | F12: 6.9302174e-13 | G12: 6.9302173e-13 | H12: 6.820812e-13 | I12: 6.820812e-13 | J12: 6.820812e-13 | K12: 6.8389205e-13 | L12: 6.8389205e-13 | M12: 6.8389205e-13 | N12: 6.9900492e-13 | O12: 6.820812e-13 | P12: 6.9900492e-13 | Q12: 6.9900492e-13 | R12: 6.9302173e-13 | S12: 6.9302172e-13 | T12: 6.9302173e-13 | U12: 6.8208121e-13 | V12: 6.8389205e-13 | W12: 6.8389205e-13 | X12: 6.8389205e-13 | Y12: 6.9900492e-13 | Z12: 6.9900492e-13 | AA12: 6.9900492e-13 | AB12: 1 | AC12: 0.99999393 | AD12: 0.0002557123 | AE12: 7.9631293e-20 | AF12: -5.1171886e-19 | AG12: 5.410041e-18 | AH12: 3.5279207e-19 | AI12: -2.8051879e-20 | AJ12: -8.6482324e-21 | AK12: -1.6158525e-20 | AL12: 4.2883376e-19 | AM12: -1.2923297e-19 | AN12: 1.0890856e-19 | AO12: -1.3724267e-19 | AP12: -1.2093247e-19 | AQ12: -1.3022836e-19 | AR12: -5.4598165e-19 | AS12: 1.996154e-18 | AT12: -1.0690427e-19 | AU12: -4.9826424e-19 | AV12: 2.8497369e-19 | AW12: 5.3376483e-19 | AX12: 1.1013206e-18 | AY12: 4.0965501e-21 | AZ12: -6.397603e-21 | BA12: 3.9904724e-19 | BB12: -6.4054277e-19 | BC12: 15994356 | BD12: 3998267.7 | BE12: -0.00011629842 | BF12: 0.00026394799 | BG12: 7.6553971e-05 | BH12: -0.00022801021 | BI12: 60.045296 | BJ12: 30.023266 | BK12: 54.678157
A13: 3971641.2 | B13: 3.4996136e-05 | C13: =(BF13-BF12)/(A13-A12) -> 9.4902077e-12 | D13: 6.8019496e-13 | E13: 6.9148963e-13 | F13: 6.9148967e-13 | G13: 6.9148965e-13 | H13: 6.8019496e-13 | I13: 6.8019496e-13 | J13: 6.8019496e-13 | K13: 6.8197232e-13 | L13: 6.8197232e-13 | M13: 6.8197232e-13 | N13: 6.971248e-13 | O13: 6.8019496e-13 | P13: 6.971248e-13 | Q13: 6.971248e-13 | R13: 6.9148965e-13 | S13: 6.9148963e-13 | T13: 6.9148964e-13 | U13: 6.8019498e-13 | V13: 6.8197233e-13 | W13: 6.8197233e-13 | X13: 6.8197233e-13 | Y13: 6.971248e-13 | Z13: 6.971248e-13 | AA13: 6.971248e-13 | AB13: 1 | AC13: 0.99999391 | AD13: 0.00027592223 | AE13: 2.9279494e-20 | AF13: -4.6203242e-19 | AG13: 4.7388452e-18 | AH13: 3.8083565e-19 | AI13: -3.5250472e-20 | AJ13: -1.7948564e-20 | AK13: 3.5856696e-20 | AL13: 4.3076176e-19 | AM13: -6.207015e-20 | AN13: 1.3447971e-19 | AO13: -9.254338e-20 | AP13: -1.2526198e-19 | AQ13: -7.341234e-20 | AR13: -5.3359903e-19 | AS13: 1.8395664e-18 | AT13: -6.2623442e-20 | AU13: -3.661848e-19 | AV13: 8.657064e-20 | AW13: 4.8691229e-19 | AX13: 9.8666152e-19 | AY13: 1.271054e-20 | AZ13: -3.8962482e-20 | BA13: 4.3337801e-19 | BB13: -6.7528997e-19 | BC13: 15982173 | BD13: 3994532.9 | BE13: -0.00011177265 | BF13: 0.00028972053 | BG13: 9.1119721e-05 | BH13: -0.00023497854 | BI13: 60.045317 | BJ13: 30.023262 | BK13: 54.416505
A14: 4456254.7 | B14: 3.9249848e-05 | C14: =(BF14-BF13)/(A14-A13) -> 9.4362433e-12 | D14: 6.7954397e-13 | E14: 6.9096293e-13 | F14: 6.9096298e-13 | G14: 6.9096296e-13 | H14: 6.7954397e-13 | I14: 6.7954397e-13 | J14: 6.7954397e-13 | K14: 6.8131533e-13 | L14: 6.8131534e-13 | M14: 6.8131534e-13 | N14: 6.9648167e-13 | O14: 6.7954397e-13 | P14: 6.9648166e-13 | Q14: 6.9648166e-13 | R14: 6.9096295e-13 | S14: 6.9096293e-13 | T14: 6.9096294e-13 | U14: 6.7954399e-13 | V14: 6.8131534e-13 | W14: 6.8131534e-13 | X14: 6.8131534e-13 | Y14: 6.9648167e-13 | Z14: 6.9648167e-13 | AA14: 6.9648167e-13 | AB14: 1 | AC14: 0.9999939 | AD14: 0.00027956932 | AE14: 1.3693562e-20 | AF14: -4.4750551e-19 | AG14: 4.5181636e-18 | AH14: 3.8248148e-19 | AI14: -3.8757764e-20 | AJ14: -2.2962589e-20 | AK14: 5.1723119e-20 | AL14: 4.3015062e-19 | AM14: -3.8229726e-20 | AN14: 1.4055417e-19 | AO14: -8.059538e-20 | AP14: -1.2683017e-19 | AQ14: -5.5669102e-20 | AR14: -5.3013741e-19 | AS14: 1.7850869e-18 | AT14: -4.699786e-20 | AU14: -3.2488148e-19 | AV14: 2.0171501e-20 | AW14: 4.7532168e-19 | AX14: 9.467813e-19 | AY14: 1.6448843e-20 | AZ14: -4.8463565e-20 | BA14: 4.4249891e-19 | BB14: -6.8751527e-19 | BC14: 15980002 | BD14: 3993868.2 | BE14: -0.00011095128 | BF14: 0.00029429346 | BG14: 9.3716311e-05 | BH14: -0.00021908618 | BI14: 60.045343 | BJ14: 30.023278 | BK14: 54.372348
... A35: 50000000 | B35: 0.00042726318 | C35: =(BF35-BF34)/(A35-A34) -> 8.5455828e-12 | D35: 6.5439805e-13 | E35: 6.69181e-13 | F35: 6.6918135e-13 | G35: 6.6918147e-13 | H35: 6.5439811e-13 | I35: 6.5439812e-13 | J35: 6.5439806e-13 | K35: 6.5578135e-13 | L35: 6.5578147e-13 | M35: 6.5578135e-13 | N35: 6.7214186e-13 | O35: 6.5439809e-13 | P35: 6.7214172e-13 | Q35: 6.7214175e-13 | R35: 6.6918123e-13 | S35: 6.6918101e-13 | T35: 6.6918109e-13 | U35: 6.5439841e-13 | V35: 6.5578138e-13 | W35: 6.5578147e-13 | X35: 6.557815e-13 | Y35: 6.7214173e-13 | Z35: 6.7214186e-13 | AA35: 6.7214194e-13 | AB35: 1 | AC35: 0.99999007 | AD35: 0.00063911515 | AE35: -4.2011784e-20 | AF35: -1.8332701e-19 | AG35: -8.141895e-20 | AH35: -1.1398922e-18 | AI35: -5.2676645e-19 | AJ35: -1.2512251e-18 | AK35: 7.5854585e-20 | AL35: 9.7663631e-21 | AM35: 1.738733e-18 | AN35: -4.7692698e-20 | AO35: -5.09642e-19 | AP35: -5.7382714e-19 | AQ35: -9.1394206e-20 | AR35: -7.4239119e-19 | AS35: 6.7990732e-19 | AT35: 3.1000711e-19 | AU35: -5.8830612e-20 | AV35: -1.6498503e-18 | AW35: 6.9949161e-19 | AX35: -5.9637611e-19 | AY35: 3.9827344e-19 | AZ35: -2.7308445e-19 | BA35: -4.1700545e-19 | BB35: -9.5109395e-19 | BC35: 15780244 | BD35: 3933245.3 | BE35: -2.1801558e-05 | BF35: 0.0007002151 | BG35: 0.00033520149 | BH35: -6.8268223e-05 | BI35: 60.046022 | BJ35: 30.023344 | BK35: 52.303847

Sheet 773K_87MPa_512g
A1: time | B1: Ep_eff | C1: StrainRate | D1: cstrain_1 | E1: cstrain_10 | F1: cstrain_11 | G1: cstrain_12 | H1: cstrain_13 | I1: cstrain_14 | J1: cstrain_15 | K1: cstrain_16 | L1: cstrain_17 | M1: cstrain_18 | N1: cstrain_19 | O1: cstrain_2 | P1: cstrain_20 | Q1: cstrain_21 | R1: cstrain_22 | S1: cstrain_23 | T1: cstrain_24 | U1: cstrain_3 | V1: cstrain_4 | W1: cstrain_5 | X1: cstrain_6 | Y1: cstrain_7 | Z1: cstrain_8 | AA1: cstrain_9 | AB1: cstrainfrac1 | AC1: cstrainfrac2 | AD1: eeq | AE1: gstrain_1 | AF1: gstrain_10 | AG1: gstrain_11 | AH1: gstrain_12 | AI1: gstrain_13 | AJ1: gstrain_14 | AK1: gstrain_15 | AL1: gstrain_16 | AM1: gstrain_17 | AN1: gstrain_18 | AO1: gstrain_19 | AP1: gstrain_2 | AQ1: gstrain_20 | AR1: gstrain_21 | AS1: gstrain_22 | AT1: gstrain_23 | AU1: gstrain_24 | AV1: gstrain_3 | AW1: gstrain_4 | AX1: gstrain_5 | AY1: gstrain_6 | AZ1: gstrain_7 | BA1: gstrain_8 | BB1: gstrain_9 | BC1: rho_i | BD1: rho_m | BE1: strain_xx | BF1: strain_yy | BG1: strain_zz | BH1: stress_xx | BI1: stress_yy | BJ1: stress_zz | BK1: vonmises
A2: 0 | B2: 0 | D2: 0 | E2: 0 | F2: 0 | G2: 0 | H2: 0 | I2: 0 | J2: 0 | K2: 0 | L2: 0 | M2: 0 | N2: 0 | O2: 0 | P2: 0 | Q2: 0 | R2: 0 | S2: 0 | T2: 0 | U2: 0 | V2: 0 | W2: 0 | X2: 0 | Y2: 0 | Z2: 0 | AA2: 0 | AB2: 0 | AC2: 0 | AD2: 0 | AE2: 0 | AF2: 0 | AG2: 0 | AH2: 0 | AI2: 0 | AJ2: 0 | AK2: 0 | AL2: 0 | AM2: 0 | AN2: 0 | AO2: 0 | AP2: 0 | AQ2: 0 | AR2: 0 | AS2: 0 | AT2: 0 | AU2: 0 | AV2: 0 | AW2: 0 | AX2: 0 | AY2: 0 | AZ2: 0 | BA2: 0 | BB2: 0 | BC2: 0 | BD2: 0 | BE2: 0 | BF2: 0 | BG2: 0 | BH2: 0 | BI2: 0 | BJ2: 0 | BK2: 0
A3: 0.39716412 | B3: 6.4343438e-15 | C3: =(BF3-BF2)/(A3-A2) -> 2.8153459e-06 | D3: 2.3264981e-15 | E3: 2.3642551e-15 | F3: 2.3642551e-15 | G3: 2.3642551e-15 | H3: 2.3264981e-15 | I3: 2.3264981e-15 | J3: 2.3264981e-15 | K3: 2.3334223e-15 | L3: 2.3334223e-15 | M3: 2.3334223e-15 | N3: 2.3819545e-15 | O3: 2.3264981e-15 | P3: 2.3819545e-15 | Q3: 2.3819545e-15 | R3: 2.3642551e-15 | S3: 2.3642551e-15 | T3: 2.3642551e-15 | U3: 2.3264981e-15 | V3: 2.3334223e-15 | W3: 2.3334223e-15 | X3: 2.3334223e-15 | Y3: 2.3819545e-15 | Z3: 2.3819545e-15 | AA3: 2.3819545e-15 | AB3: 1 | AC3: 1 | AD3: 1.0935804e-06 | AE3: 1.8087345e-29 | AF3: -4.3119018e-29 | AG3: 5.1687619e-29 | AH3: -8.4196057e-29 | AI3: -6.3756164e-30 | AJ3: -3.9420568e-30 | AK3: 8.0674509e-30 | AL3: 2.9387418e-29 | AM3: -2.826641e-29 | AN3: -3.8191552e-29 | AO3: 1.5765955e-29 | AP3: -6.467113e-30 | AQ3: 6.147354e-29 | AR3: -9.9059232e-29 | AS3: 3.524388e-29 | AT3: 7.4471421e-30 | AU3: -7.1925533e-29 | AV3: 7.4531523e-30 | AW3: -2.4921746e-29 | AX3: 2.9147411e-29 | AY3: -3.0612742e-29 | AZ3: 2.8072774e-29 | BA3: 7.6891087e-29 | BB3: -6.11675e-29 | BC3: 16000000 | BD3: 4000000 | BE3: -5.2444407e-07 | BF3: 1.1181544e-06 | BG3: 3.0913731e-07 | BH3: -4.5337687e-09 | BI3: 0.26599904 | BJ3: 0.13299953 | BK3: 0.24282098
A4: 3.9716412 | B4: 6.6475686e-13 | C4: =(BF4-BF3)/(A4-A3) -> 2.8151486e-06 | D4: 2.3288149e-14 | E4: 2.3665894e-14 | F4: 2.3665894e-14 | G4: 2.3665894e-14 | H4: 2.3288149e-14 | I4: 2.3288149e-14 | J4: 2.3288149e-14 | K4: 2.3357234e-14 | L4: 2.3357234e-14 | M4: 2.3357234e-14 | N4: 2.3843936e-14 | O4: 2.3288149e-14 | P4: 2.3843936e-14 | Q4: 2.3843936e-14 | R4: 2.3665894e-14 | S4: 2.3665894e-14 | T4: 2.3665894e-14 | U4: 2.3288149e-14 | V4: 2.3357234e-14 | W4: 2.3357234e-14 | X4: 2.3357234e-14 | Y4: 2.3843936e-14 | Z4: 2.3843936e-14 | AA4: 2.3843936e-14 | AB4: 1 | AC4: 1 | AD4: 1.0935309e-05 | AE4: 5.0927345e-30 | AF4: 6.5339083e-28 | AG4: 1.2528391e-27 | AH4: -7.7482272e-28 | AI4: 2.067534e-28 | AJ4: -1.9054784e-28 | AK4: -1.6518135e-28 | AL4: 4.8536937e-28 | AM4: -2.503787e-28 | AN4: 1.0601772e-28 | AO4: 3.5531831e-28 | AP4: -2.3440932e-28 | AQ4: 6.2906889e-28 | AR4: -1.1719035e-27 | AS4: 5.0258253e-28 | AT4: 9.7736275e-28 | AU4: -1.0055893e-27 | AV4: 2.0685711e-28 | AW4: 3.5365455e-28 | AX4: 9.9073304e-28 | AY4: 3.4386536e-28 | AZ4: -1.3510453e-28 | BA4: 5.956013e-28 | BB4: -1.3331783e-27 | BC4: 16000000 | BD4: 4000000 | BE4: -5.2443846e-06 | BF4: 1.1180838e-05 | BG4: 3.0914199e-06 | BH4: -4.5339144e-07 | BI4: 2.6599888 | BJ4: 1.3299956 | BK4: 2.4281994
A5: 39.716412 | B5: 6.7056363e-11 | C5: =(BF5-BF4)/(A5-A4) -> 2.8131966e-06 | D5: 2.3530635e-13 | E5: 2.3908976e-13 | F5: 2.3908976e-13 | G5: 2.3908976e-13 | H5: 2.3530635e-13 | I5: 2.3530635e-13 | J5: 2.3530635e-13 | K5: 2.3598303e-13 | L5: 2.3598303e-13 | M5: 2.3598303e-13 | N5: 2.4099243e-13 | O5: 2.3530635e-13 | P5: 2.4099243e-13 | Q5: 2.4099243e-13 | R5: 2.3908976e-13 | S5: 2.3908976e-13 | T5: 2.3908976e-13 | U5: 2.3530635e-13 | V5: 2.3598303e-13 | W5: 2.3598303e-13 | X5: 2.3598303e-13 | Y5: 2.4099243e-13 | Z5: 2.4099243e-13 | AA5: 2.4099243e-13 | AB5: 1 | AC5: 1 | AD5: 0.00010930373 | AE5: 3.2881503e-24 | AF5: -1.3580547e-24 | AG5: 6.293592e-23 | AH5: -1.8350007e-23 | AI5: -8.4948803e-25 | AJ5: -1.7626822e-24 | AK5: -8.3763781e-25 | AL5: 2.2639304e-23 | AM5: -5.307306e-24 | AN5: 2.4196115e-24 | AO5: -4.099059e-24 | AP5: -6.9266748e-24 | AQ5: 5.3922808e-24 | AR5: -3.0057646e-23 | AS5: 2.7743076e-23 | AT5: 1.3484204e-23 | AU5: -1.7045647e-23 | AV5: 1.1618866e-23 | AW5: 2.2305236e-23 | AX5: 5.1837709e-23 | AY5: 1.0709988e-23 | AZ5: 1.8094104e-25 | BA5: 5.1502822e-24 | BB5: -3.4948294e-23 | BC5: 16000000 | BD5: 4000000 | BE5: -5.2438242e-05 | BF5: 0.00011173791 | BG5: 3.0918867e-05 | BH5: -4.5346864e-05 | BI5: 26.599727 | BJ5: 13.299986 | BK5: 24.280954
A6: 397.16412 | B6: 4.7202764e-09 | C6: =(BF6-BF5)/(A6-A5) -> 8.6528378e-07 | D6: 1.1684662e-12 | E6: 1.1865239e-12 | F6: 1.1865239e-12 | G6: 1.1865239e-12 | H6: 1.1684662e-12 | I6: 1.1684662e-12 | J6: 1.1684662e-12 | K6: 1.1713698e-12 | L6: 1.1713698e-12 | M6: 1.1713698e-12 | N6: 1.1981892e-12 | O6: 1.1684662e-12 | P6: 1.1981892e-12 | Q6: 1.1981892e-12 | R6: 1.1865239e-12 | S6: 1.1865239e-12 | T6: 1.1865239e-12 | U6: 1.1684662e-12 | V6: 1.1713698e-12 | W6: 1.1713698e-12 | X6: 1.1713698e-12 | Y6: 1.1981892e-12 | Z6: 1.1981892e-12 | AA6: 1.1981892e-12 | AB6: 0.99998907 | AC6: 0.9972322 | AD6: 0.00041211327 | AE6: 1.4136183e-16 | AF6: -7.2806055e-16 | AG6: 1.248757e-14 | AH6: 1.9342298e-15 | AI6: -4.7864449e-17 | AJ6: 3.549977e-18 | AK6: -5.156489e-17 | AL6: 3.4132737e-16 | AM6: -1.7772993e-16 | AN6: 1.4933751e-16 | AO6: -1.673929e-16 | AP6: -8.9904232e-17 | AQ6: -3.031512e-16 | AR6: -4.7427141e-16 | AS6: 3.7478083e-15 | AT6: -4.1570119e-16 | AU6: -7.1847557e-16 | AV6: 3.1431667e-16 | AW6: 6.0081419e-16 | AX6: 1.0617134e-15 | AY6: -9.4295303e-17 | AZ6: -9.1982214e-17 | BA6: 5.2943913e-16 | BB6: -5.3648235e-16 | BC6: 15999998 | BD6: 3999999.3 | BE6: -0.00019796961 | BF6: 0.00042103161 | BG6: 0.00011682962 | BH6: -0.00064158599 | BI6: 100.45935 | BJ6: 50.231412 | BK6: 91.689975
A7: 3971.6412 | B7: 5.8956479e-08 | C7: =(BF7-BF6)/(A7-A6) -> 1.6500494e-11 | D7: 1.1684607e-12 | E7: 1.1865191e-12 | F7: 1.1865193e-12 | G7: 1.1865192e-12 | H7: 1.1684607e-12 | I7: 1.1684607e-12 | J7: 1.1684607e-12 | K7: 1.1713641e-12 | L7: 1.1713641e-12 | M7: 1.1713641e-12 | N7: 1.1981836e-12 | O7: 1.1684607e-12 | P7: 1.1981836e-12 | Q7: 1.1981835e-12 | R7: 1.1865192e-12 | S7: 1.1865191e-12 | T7: 1.1865191e-12 | U7: 1.1684607e-12 | V7: 1.1713641e-12 | W7: 1.1713641e-12 | X7: 1.1713641e-12 | Y7: 1.1981836e-12 | Z7: 1.1981836e-12 | AA7: 1.1981836e-12 | AB7: 0.99999652 | AC7: 0.99723237 | AD7: 0.00041215808 | AE7: 1.4125341e-16 | AF7: -7.2785482e-16 | AG7: 1.2469089e-14 | AH7: 1.9303179e-15 | AI7: -4.7841798e-17 | AJ7: 3.5445679e-18 | AK7: -5.1475951e-17 | AL7: 3.4133493e-16 | AM7: -1.7764496e-16 | AN7: 1.4937861e-16 | AO7: -1.6729523e-16 | AP7: -8.9904296e-17 | AQ7: -3.0298047e-16 | AR7: -4.7419741e-16 | AS7: 3.7437485e-15 | AT7: -4.1494833e-16 | AU7: -7.1725361e-16 | AV7: 3.1405413e-16 | AW7: 6.0062967e-16 | AX7: 1.0615345e-15 | AY7: -9.4299377e-17 | AZ7: -9.1972723e-17 | BA7: 5.2948844e-16 | BB7: -5.3646114e-16 | BC7: 15999973 | BD7: 3999990.9 | BE7: -0.00019795997 | BF7: 0.00042109059 | BG7: 0.00011686229 | BH7: -0.00064160887 | BI7: 100.45935 | BJ7: 50.231412 | BK7: 91.689325
A8: 39716.412 | B8: 6.0129392e-07 | C8: =(BF8-BF7)/(A8-A7) -> 1.6499389e-11 | D8: 1.1684053e-12 | E8: 1.1864717e-12 | F8: 1.1864731e-12 | G8: 1.1864722e-12 | H8: 1.1684053e-12 | I8: 1.1684053e-12 | J8: 1.1684053e-12 | K8: 1.1713072e-12 | L8: 1.1713072e-12 | M8: 1.1713072e-12 | N8: 1.1981269e-12 | O8: 1.1684053e-12 | P8: 1.1981269e-12 | Q8: 1.1981269e-12 | R8: 1.1864721e-12 | S8: 1.1864717e-12 | T8: 1.1864718e-12 | U8: 1.1684056e-12 | V8: 1.1713073e-12 | W8: 1.1713073e-12 | X8: 1.1713073e-12 | Y8: 1.1981271e-12 | Z8: 1.198127e-12 | AA8: 1.198127e-12 | AB8: 0.99999918 | AC8: 0.99723402 | AD8: 0.0004126063 | AE8: 1.4017177e-16 | AF8: -7.2580558e-16 | AG8: 1.228811e-14 | AH8: 1.8918774e-15 | AI8: -4.7616609e-17 | AJ8: 3.4898923e-18 | AK8: -5.0589222e-17 | AL8: 3.4141014e-16 | AM8: -1.7679601e-16 | AN8: 1.4978747e-16 | AO8: -1.6632163e-16 | AP8: -8.9904942e-17 | AQ8: -3.0127861e-16 | AR8: -4.7346039e-16 | AS8: 3.7037548e-15 | AT8: -4.0754251e-16 | AU8: -7.0532763e-16 | AV8: 3.1142599e-16 | AW8: 5.9879125e-16 | AX8: 1.0597458e-15 | AY8: -9.4339062e-17 | AZ8: -9.1878681e-17 | BA8: 5.2997994e-16 | BB8: -5.3625321e-16 | BC8: 15999726 | BD8: 3999907.3 | BE8: -0.00019786355 | BF8: 0.00042168035 | BG8: 0.00011718901 | BH8: -0.0006414316 | BI8: 100.45936 | BJ8: 50.231412 | BK8: 91.682833
A9: 397164.12 | B9: 6.0222319e-06 | C9: =(BF9-BF8)/(A9-A8) -> 1.6486435e-11 | D9: 1.167855e-12 | E9: 1.1859992e-12 | F9: 1.1860118e-12 | G9: 1.1860037e-12 | H9: 1.1678549e-12 | I9: 1.1678546e-12 | J9: 1.1678548e-12 | K9: 1.170741e-12 | L9: 1.1707412e-12 | M9: 1.1707414e-12 | N9: 1.1975638e-12 | O9: 1.1678548e-12 | P9: 1.1975636e-12 | Q9: 1.1975636e-12 | R9: 1.1860026e-12 | S9: 1.1859988e-12 | T9: 1.1859995e-12 | U9: 1.1678573e-12 | V9: 1.1707423e-12 | W9: 1.1707418e-12 | X9: 1.1707421e-12 | Y9: 1.197565e-12 | Z9: 1.1975645e-12 | AA9: 1.1975645e-12 | AB9: 0.9999999 | AC9: 0.99725005 | AD9: 0.00041709764 | AE9: 1.2960889e-16 | AF9: -7.0608846e-16 | AG9: 1.0784228e-14 | AH9: 1.5642368e-15 | AI9: -4.5492442e-17 | AJ9: 2.881758e-18 | AK9: -4.1988482e-17 | AL9: 3.4211513e-16 | AM9: -1.6838569e-16 | AN9: 1.5365792e-16 | AO9: -1.5690642e-16 | AP9: -8.9914907e-17 | AQ9: -2.8479878e-16 | AR9: -4.6637589e-16 | AS9: 3.3547659e-15 | AT9: -3.438059e-16 | AU9: -6.0886649e-16 | AV9: 2.8498879e-16 | AW9: 5.8108423e-16 | AX9: 1.041994e-15 | AY9: -9.4635014e-17 | AZ9: -9.1022204e-17 | BA9: 5.3474819e-16 | BB9: -5.3455163e-16 | BC9: 15997253 | BD9: 3999071.7 | BE9: -0.00019689708 | BF9: 0.00042757339 | BG9: 0.00012045569 | BH9: -0.00063988445 | BI9: 100.45937 | BJ9: 50.231415 | BK9: 91.618363
A10: 125594.32 | B10: 1.9040766e-06 | C10: =(BF10-BF9)/(A10-A9) -> 1.6483863e-11 | D10: 1.1682488e-12 | E10: 1.1863376e-12 | F10: 1.1863422e-12 | G10: 1.1863392e-12 | H10: 1.1682488e-12 | I10: 1.1682487e-12 | J10: 1.1682487e-12 | K10: 1.1711462e-12 | L10: 1.1711463e-12 | M10: 1.1711463e-12 | N10: 1.1979668e-12 | O10: 1.1682488e-12 | P10: 1.1979667e-12 | Q10: 1.1979667e-12 | R10: 1.1863388e-12 | S10: 1.1863374e-12 | T10: 1.1863377e-12 | U10: 1.1682496e-12 | V10: 1.1711467e-12 | W10: 1.1711465e-12 | X10: 1.1711466e-12 | Y10: 1.1979672e-12 | Z10: 1.197967e-12 | AA10: 1.197967e-12 | AB10: 0.99999947 | AC10: 0.99723865 | AD10: 0.00041368376 | AE10: 1.3713523e-16 | AF10: -7.2008316e-16 | AG10: 1.1811464e-14 | AH10: 1.7895276e-15 | AI10: -4.6992609e-17 | AJ10: 3.3289965e-18 | AK10: -4.8105245e-17 | AL10: 3.4161823e-16 | AM10: -1.7440065e-16 | AN10: 1.5092282e-16 | AO10: -1.6359666e-16 | AP10: -8.9906951e-17 | AQ10: -2.9651514e-16 | AR10: -4.7140373e-16 | AS10: 3.5962932e-15 | AT10: -3.8774946e-16 | AU10: -6.7426956e-16 | AV10: 3.0395905e-16 | AW10: 5.9365367e-16 | AX10: 1.0546949e-15 | AY10: -9.4441118e-17 | AZ10: -9.1621308e-17 | BA10: 5.3135654e-16 | BB10: -5.3570501e-16 | BC10: 15999132 | BD10: 3999706.5 | BE10: -0.00019763173 | BF10: 0.00042309687 | BG10: 0.00011797393 | BH10: -0.00064099978 | BI10: 100.45936 | BJ10: 50.231413 | BK10: 91.667267
A11: 397164.12 | B11: 6.0220584e-06 | C11: =(BF11-BF10)/(A11-A10) -> 1.6482241e-11 | D11: 1.1677805e-12 | E11: 1.185935e-12 | F11: 1.185949e-12 | G11: 1.18594e-12 | H11: 1.1677804e-12 | I11: 1.16778e-12 | J11: 1.1677802e-12 | K11: 1.1706644e-12 | L11: 1.1706646e-12 | M11: 1.1706647e-12 | N11: 1.1974875e-12 | O11: 1.1677803e-12 | P11: 1.1974873e-12 | Q11: 1.1974872e-12 | R11: 1.1859388e-12 | S11: 1.1859345e-12 | T11: 1.1859354e-12 | U11: 1.1677831e-12 | V11: 1.1706658e-12 | W11: 1.1706652e-12 | X11: 1.1706656e-12 | Y11: 1.1974888e-12 | Z11: 1.1974882e-12 | AA11: 1.1974883e-12 | AB11: 0.99999982 | AC11: 0.99725211 | AD11: 0.00041709714 | AE11: 1.2821723e-16 | AF11: -7.0353016e-16 | AG11: 1.0622032e-14 | AH11: 1.5281675e-15 | AI11: -4.5225051e-17 | AJ11: 2.7899948e-18 | AK11: -4.0863755e-17 | AL11: 3.422007e-16 | AM11: -1.6725851e-16 | AN11: 1.5414892e-16 | AO11: -1.5567608e-16 | AP11: -8.9915421e-17 | AQ11: -2.8264943e-16 | AR11: -4.6545655e-16 | AS11: 3.3148882e-15 | AT11: -3.3667479e-16 | AU11: -5.9875623e-16 | AV11: 2.8137838e-16 | AW11: 5.7878214e-16 | AX11: 1.0396061e-15 | AY11: -9.4659556e-17 | AZ11: -9.0923437e-17 | BA11: 5.3536844e-16 | BB11: -5.3437371e-16 | BC11: 15997253 | BD11: 3999071.7 | BE11: -0.00019689693 | BF11: 0.00042757295 | BG11: 0.00012045566 | BH11: -0.00063963547 | BI11: 100.45937 | BJ11: 50.231415 | BK11: 91.618361
A12: 1255943.2 | B12: 1.9027205e-05 | C12: =(BF12-BF11)/(A12-A11) -> 1.6444021e-11 | D12: 1.1663206e-12 | E12: 1.1846784e-12 | F12: 1.1847171e-12 | G12: 1.1846934e-12 | H12: 1.1663203e-12 | I12: 1.1663192e-12 | J12: 1.1663197e-12 | K12: 1.1691626e-12 | L12: 1.1691634e-12 | M12: 1.1691638e-12 | N12: 1.1959924e-12 | O12: 1.16632e-12 | P12: 1.1959919e-12 | Q12: 1.1959916e-12 | R12: 1.1846891e-12 | S12: 1.1846768e-12 | T12: 1.1846792e-12 | U12: 1.1663287e-12 | V12: 1.169167e-12 | W12: 1.1691654e-12 | X12: 1.1691665e-12 | Y12: 1.1959964e-12 | Z12: 1.1959948e-12 | AA12: 1.195995e-12 | AB12: 0.99999994 | AC12: 0.9972901 | AD12: 0.00042794997 | AE12: 1.0202494e-16 | AF12: -6.5697816e-16 | AG12: 8.1951624e-15 | AH12: 9.7691615e-16 | AI12: -4.0525561e-17 | AJ12: 5.8965255e-19 | AK12: -2.0120274e-17 | AL12: 3.4363527e-16 | AM12: -1.4520683e-16 | AN12: 1.6260415e-16 | AO12: -1.3325975e-16 | AP12: -8.9971068e-17 | AQ12: -2.4299647e-16 | AR12: -4.4850071e-16 | AS12: 2.6852192e-15 | AT12: -2.2585917e-16 | AU12: -4.5070066e-16 | AV12: 2.1077207e-16 | AW12: 5.3721251e-16 | AX12: 9.9299985e-16 | AY12: -9.4597722e-17 | AZ12: -8.9366174e-17 | BA12: 5.4672174e-16 | BB12: -5.3236486e-16 | BC12: 15991319 | BD12: 3997065.8 | BE12: -0.0001945571 | BF12: 0.00044169473 | BG12: 0.0001282996 | BH12: -0.00063599352 | BI12: 100.45939 | BJ12: 50.231422 | BK12: 91.466822
A13: 3971641.2 | B13: 5.9993964e-05 | C13: =(BF13-BF12)/(A13-A12) -> 1.6329755e-11 | D13: 1.1618718e-12 | E13: 1.1808705e-12 | F13: 1.1809637e-12 | G13: 1.1809141e-12 | H13: 1.1618717e-12 | I13: 1.1618683e-12 | J13: 1.1618696e-12 | K13: 1.1646301e-12 | L13: 1.1646326e-12 | M13: 1.1646333e-12 | N13: 1.1914679e-12 | O13: 1.1618708e-12 | P13: 1.1914656e-12 | Q13: 1.1914651e-12 | R13: 1.1808973e-12 | S13: 1.1808654e-12 | T13: 1.1808719e-12 | U13: 1.1618981e-12 | V13: 1.1646425e-12 | W13: 1.1646389e-12 | X13: 1.1646424e-12 | Y13: 1.1914782e-12 | Z13: 1.1914754e-12 | AA13: 1.191476e-12 | AB13: 0.99999998 | AC13: 0.99737093 | AD13: 0.00046278072 | AE13: 3.5093755e-17 | AF13: -5.500521e-16 | AG13: 4.8315e-15 | AH13: 1.7501942e-16 | AI13: -3.1886885e-17 | AJ13: -1.0618915e-17 | AK13: 2.9467106e-17 | AL13: 3.4459459e-16 | AM13: -7.8381909e-17 | AN13: 1.7619331e-16 | AO13: -8.3482948e-17 | AP13: -9.0549324e-17 | AQ13: -1.4814586e-16 | AR13: -4.0675434e-16 | AS13: 1.7152643e-15 | AT13: -5.4070462e-17 | AU13: -2.4441584e-16 | AV13: 6.9422636e-18 | AW13: 4.4748853e-16 | AX13: 8.5506997e-16 | AY13: -8.8891936e-17 | AZ13: -8.8821836e-17 | BA13: 5.7027577e-16 | BB13: -5.3707506e-16 | BC13: 15972603 | BD13: 3990742.7 | BE13: -0.00018700851 | BF13: 0.00048604142 | BG13: 0.00015306553 | BH13: -0.00065024576 | BI13: 100.45944 | BJ13: 50.231415 | BK13: 91.017096
A14: 4456254.7 | B14: 6.7276718e-05 | C14: =(BF14-BF13)/(A14-A13) -> 1.6215985e-11 | D14: 1.1603326e-12 | E14: 1.1795547e-12 | F14: 1.1796625e-12 | G14: 1.1796081e-12 | H14: 1.1603326e-12 | I14: 1.1603285e-12 | J14: 1.16033e-12 | K14: 1.1630739e-12 | L14: 1.1630771e-12 | M14: 1.1630776e-12 | N14: 1.1899146e-12 | O14: 1.1603316e-12 | P14: 1.1899115e-12 | Q14: 1.189911e-12 | R14: 1.179586e-12 | S14: 1.1795486e-12 | T14: 1.1795563e-12 | U14: 1.1603655e-12 | V14: 1.1630888e-12 | W14: 1.1630848e-12 | X14: 1.1630893e-12 | Y14: 1.1899264e-12 | Z14: 1.1899239e-12 | AA14: 1.1899247e-12 | AB14: 0.99999988 | AC14: 0.99738856 | AD14: 0.00046905703 | AE14: 1.5829355e-17 | AF14: -5.2196994e-16 | AG14: 4.1976676e-15 | AH14: 1.2771577e-17 | AI14: -3.0542155e-17 | AJ14: -1.6004845e-17 | AK14: 4.2941734e-17 | AL14: 3.4370171e-16 | AM14: -5.5041611e-17 | AN14: 1.7760734e-16 | AO14: -7.1740285e-17 | AP14: -9.0927572e-17 | AQ14: -1.2227998e-16 | AR14: -3.9502917e-16 | AS14: 1.5249758e-15 | AT14: -1.7367999e-17 | AU14: -2.0313635e-16 | AV14: -5.8818036e-17 | AW14: 4.2642641e-16 | AX14: 8.0873431e-16 | AY14: -8.533697e-17 | AZ14: -8.9688408e-17 | BA14: 5.7460987e-16 | BB14: -5.4103817e-16 | BC14: 15969272 | BD14: 3989618.3 | BE14: -0.00018563595 | BF14: 0.0004938999 | BG14: 0.00015747824 | BH14: -0.00061070395 | BI14: 100.45951 | BJ14: 50.231457 | BK14: 90.941384
... A35: 50000000 | B35: 0.00072549832 | C35: =(BF35-BF34)/(A35-A34) -> 1.4402001e-11 | D35: 1.0999014e-12 | E35: 1.1248038e-12 | F35: 1.1252603e-12 | G35: 1.125456e-12 | H35: 1.0999728e-12 | I35: 1.1000126e-12 | J35: 1.0999067e-12 | K35: 1.1020919e-12 | L35: 1.102265e-12 | M35: 1.1020874e-12 | N35: 1.1300996e-12 | O35: 1.0999652e-12 | P35: 1.1298842e-12 | Q35: 1.1299029e-12 | R35: 1.1251028e-12 | S35: 1.1247997e-12 | T35: 1.1248723e-12 | U35: 1.1004585e-12 | V35: 1.1021336e-12 | W35: 1.1022599e-12 | X35: 1.102329e-12 | Y35: 1.1298983e-12 | Z35: 1.1300816e-12 | AA35: 1.1302084e-12 | AB35: 0.99999998 | AC35: 0.99542563 | AD35: 0.0010802637 | AE35: -7.5199352e-17 | AF35: -2.051293e-16 | AG35: -4.5933544e-16 | AH35: -1.2537722e-15 | AI35: -3.9301969e-16 | AJ35: -1.1658451e-15 | AK35: 1.5545355e-17 | AL35: 1.0603672e-17 | AM35: 1.8064745e-15 | AN35: -3.3987724e-18 | AO35: -5.8307099e-16 | AP35: -5.4061148e-16 | AQ35: -1.6502996e-16 | AR35: -5.0695075e-16 | AS35: 6.4210245e-16 | AT35: 1.7905302e-16 | AU35: -7.3931845e-17 | AV35: -1.671263e-15 | AW35: 5.2277693e-16 | AX35: -6.6403685e-16 | AY35: 3.3502364e-16 | AZ35: -2.3625723e-16 | BA35: -4.0043262e-16 | BB35: -6.9125811e-16 | BC35: 15665993 | BD35: 3888733 | BE35: -3.6174992e-05 | BF35: 0.0011837256 | BG35: 0.00056542911 | BH35: -0.00018346283 | BI35: 100.4614 | BJ35: 50.231633 | BK35: 87.482265

Sheet 773K_121MPa_512g
A1: time | B1: Ep_eff | C1: StrainRate | D1: cstrain_1 | E1: cstrain_10 | F1: cstrain_11 | G1: cstrain_12 | H1: cstrain_13 | I1: cstrain_14 | J1: cstrain_15 | K1: cstrain_16 | L1: cstrain_17 | M1: cstrain_18 | N1: cstrain_19 | O1: cstrain_2 | P1: cstrain_20 | Q1: cstrain_21 | R1: cstrain_22 | S1: cstrain_23 | T1: cstrain_24 | U1: cstrain_3 | V1: cstrain_4 | W1: cstrain_5 | X1: cstrain_6 | Y1: cstrain_7 | Z1: cstrain_8 | AA1: cstrain_9 | AB1: cstrainfrac1 | AC1: cstrainfrac2 | AD1: eeq | AE1: gstrain_1 | AF1: gstrain_10 | AG1: gstrain_11 | AH1: gstrain_12 | AI1: gstrain_13 | AJ1: gstrain_14 | AK1: gstrain_15 | AL1: gstrain_16 | AM1: gstrain_17 | AN1: gstrain_18 | AO1: gstrain_19 | AP1: gstrain_2 | AQ1: gstrain_20 | AR1: gstrain_21 | AS1: gstrain_22 | AT1: gstrain_23 | AU1: gstrain_24 | AV1: gstrain_3 | AW1: gstrain_4 | AX1: gstrain_5 | AY1: gstrain_6 | AZ1: gstrain_7 | BA1: gstrain_8 | BB1: gstrain_9 | BC1: rho_i | BD1: rho_m | BE1: strain_xx | BF1: strain_yy | BG1: strain_zz | BH1: stress_xx | BI1: stress_yy | BJ1: stress_zz | BK1: vonmises
A2: 0 | B2: 0 | D2: 0 | E2: 0 | F2: 0 | G2: 0 | H2: 0 | I2: 0 | J2: 0 | K2: 0 | L2: 0 | M2: 0 | N2: 0 | O2: 0 | P2: 0 | Q2: 0 | R2: 0 | S2: 0 | T2: 0 | U2: 0 | V2: 0 | W2: 0 | X2: 0 | Y2: 0 | Z2: 0 | AA2: 0 | AB2: 0 | AC2: 0 | AD2: 0 | AE2: 0 | AF2: 0 | AG2: 0 | AH2: 0 | AI2: 0 | AJ2: 0 | AK2: 0 | AL2: 0 | AM2: 0 | AN2: 0 | AO2: 0 | AP2: 0 | AQ2: 0 | AR2: 0 | AS2: 0 | AT2: 0 | AU2: 0 | AV2: 0 | AW2: 0 | AX2: 0 | AY2: 0 | AZ2: 0 | BA2: 0 | BB2: 0 | BC2: 0 | BD2: 0 | BE2: 0 | BF2: 0 | BG2: 0 | BH2: 0 | BI2: 0 | BJ2: 0 | BK2: 0
