Workbook

Sheet Graphs
A1: Factor | B1: 0.375
A2: Factor | B2: 0.05

Sheet 400K_SR20
A1: Config1 | N1: Config2 | AA1: Config4 | AN1: Pstrain | AO1: Total | AP1: Totalmin | AQ1: Totalmax | AR1: Junction | AS1: Junctionmin | AT1: Junctionmax
A2: 0.000974606 | B2: 0.00150155 | C2: 127284000000000 | D2: 14477900000 | E2: 0 | F2: 0 | G2: 2 | H2: 29639100000000 | I2: 28593800000000 | J2: 29237100000000 | K2: 29314100000000 | L2: 10500100000000 | N2: 0.000990369 | O2: 0.00146597 | P2: 127455000000000 | Q2: 12050900000 | R2: 0 | S2: 0 | T2: 2 | U2: 30201100000000 | V2: 30221000000000 | W2: 30057900000000 | X2: 29634800000000 | Y2: 7340730000000 | AA2: 0.000989107 | AB2: 0.00149807 | AC2: 127202000000000 | AD2: 11494000000 | AE2: 0 | AF2: 0 | AG2: 2 | AH2: 28941700000000 | AI2: 29024000000000 | AJ2: 29174000000000 | AK2: 28900200000000 | AL2: 11161900000000 | AN2: =A2 -> 0.000974606 | AO2: =(C2) -> 127284000000000 | AP2: =MIN(C2,P2,AC2) -> 127202000000000 | AQ2: =MAX(C2,P2,AC2) -> 127455000000000 | AR2: =(L2) -> 10500100000000 | AS2: =MIN(L2,Y2,AL2) -> 7340730000000 | AT2: =MAX(L2,Y2,AL2) -> 11161900000000
A3: 0.00204321 | B3: 0.0025157 | C3: 126680000000000 | D3: 14707700000 | E3: 0 | F3: 0 | G3: 2 | H3: 28920900000000 | I3: 27950400000000 | J3: 28479100000000 | K3: 27912600000000 | L3: 13417100000000 | N3: 0.002124 | O3: 0.0025927 | P3: 127113000000000 | Q3: 29148300000 | R3: 0 | S3: 0 | T3: 2 | U3: 28811800000000 | V3: 29214300000000 | W3: 29156000000000 | X3: 28961900000000 | Y3: 10968700000000 | AA3: 0.00201989 | AB3: 0.00256861 | AC3: 127651000000000 | AD3: 2929670000 | AE3: 0 | AF3: 0 | AG3: 2 | AH3: 27792100000000 | AI3: 28187900000000 | AJ3: 28398300000000 | AK3: 27951000000000 | AL3: 15321700000000 | AN3: =A3 -> 0.00204321 | AO3: =(C3) -> 126680000000000 | AP3: =MIN(C3,P3,AC3) -> 126680000000000 | AQ3: =MAX(C3,P3,AC3) -> 127651000000000 | AR3: =(L3) -> 13417100000000 | AS3: =MIN(L3,Y3,AL3) -> 10968700000000 | AT3: =MAX(L3,Y3,AL3) -> 15321700000000
A4: 0.00297351 | B4: 0.00347727 | C4: 127092000000000 | D4: 16262200000 | E4: 0 | F4: 0 | G4: 2 | H4: 28458200000000 | I4: 27950600000000 | J4: 28270700000000 | K4: 27270000000000 | L4: 15141500000000 | N4: 0.00306679 | O4: 0.00347771 | P4: 126808000000000 | Q4: 19662500000 | R4: 0 | S4: 0 | T4: 2 | U4: 28172400000000 | V4: 29271600000000 | W4: 29072500000000 | X4: 29351600000000 | Y4: 10940300000000 | AA4: 0.00323733 | AB4: 0.00381179 | AC4: 127281000000000 | AD4: 10309000000 | AE4: 0 | AF4: 0 | AG4: 2 | AH4: 27188400000000 | AI4: 27115500000000 | AJ4: 27814300000000 | AK4: 28420900000000 | AL4: 16741700000000 | AN4: =A4 -> 0.00297351 | AO4: =(C4) -> 127092000000000 | AP4: =MIN(C4,P4,AC4) -> 126808000000000 | AQ4: =MAX(C4,P4,AC4) -> 127281000000000 | AR4: =(L4) -> 15141500000000 | AS4: =MIN(L4,Y4,AL4) -> 10940300000000 | AT4: =MAX(L4,Y4,AL4) -> 16741700000000
A5: 0.00403768 | B5: 0.00456 | C5: 126962000000000 | D5: 5676670000 | E5: 0 | F5: 0 | G5: 2 | H5: 28519900000000 | I5: 27585700000000 | J5: 27891000000000 | K5: 26837900000000 | L5: 16127400000000 | N5: 0.00400013 | O5: 0.00443865 | P5: 126542000000000 | Q5: 16871300000 | R5: 0 | S5: 0 | T5: 2 | U5: 27236400000000 | V5: 28773400000000 | W5: 27638900000000 | X5: 28423700000000 | Y5: 14469200000000 | AA5: 0.00398168 | AB5: 0.00455409 | AC5: 127170000000000 | AD5: 8632600000 | AE5: 0 | AF5: 0 | AG5: 2 | AH5: 27577500000000 | AI5: 28033400000000 | AJ5: 27536500000000 | AK5: 27789200000000 | AL5: 16233100000000 | AN5: =A5 -> 0.00403768 | AO5: =(C5) -> 126962000000000 | AP5: =MIN(C5,P5,AC5) -> 126542000000000 | AQ5: =MAX(C5,P5,AC5) -> 127170000000000 | AR5: =(L5) -> 16127400000000 | AS5: =MIN(L5,Y5,AL5) -> 14469200000000 | AT5: =MAX(L5,Y5,AL5) -> 16233100000000
A6: 0.00499008 | B6: 0.0055361 | C6: 127211000000000 | D6: 15526300000 | E6: 0 | F6: 0 | G6: 2 | H6: 28434800000000 | I6: 27310900000000 | J6: 27788700000000 | K6: 26949300000000 | L6: 16726800000000 | N6: 0.0050262 | O6: 0.00545315 | P6: 125886000000000 | Q6: 30786600000 | R6: 0 | S6: 0 | T6: 2 | U6: 26663400000000 | V6: 28167600000000 | W6: 26617200000000 | X6: 27957700000000 | Y6: 16479700000000 | AA6: 0.00498484 | AB6: 0.0055331 | AC6: 127370000000000 | AD6: 16666600000 | AE6: 0 | AF6: 0 | AG6: 2 | AH6: 27484800000000 | AI6: 28263000000000 | AJ6: 27943400000000 | AK6: 27551400000000 | AL6: 16127600000000 | AN6: =A6 -> 0.00499008 | AO6: =(C6) -> 127211000000000 | AP6: =MIN(C6,P6,AC6) -> 125886000000000 | AQ6: =MAX(C6,P6,AC6) -> 127370000000000 | AR6: =(L6) -> 16726800000000 | AS6: =MIN(L6,Y6,AL6) -> 16127600000000 | AT6: =MAX(L6,Y6,AL6) -> 16726800000000
A7: 0.00601634 | B7: 0.00653276 | C7: 127545000000000 | D7: 19131200000 | E7: 0 | F7: 0 | G7: 2 | H7: 28981100000000 | I7: 27552800000000 | J7: 27562500000000 | K7: 27778700000000 | L7: 15669800000000 | N7: 0.00609306 | O7: 0.00650958 | P7: 125931000000000 | Q7: 11745000000 | R7: 0 | S7: 0 | T7: 2 | U7: 26652600000000 | V7: 28343900000000 | W7: 27105800000000 | X7: 28229000000000 | Y7: 15599800000000 | AA7: 0.00600329 | AB7: 0.00656032 | AC7: 127498000000000 | AD7: 12154900000 | AE7: 0 | AF7: 0 | AG7: 2 | AH7: 27468900000000 | AI7: 28286400000000 | AJ7: 27587100000000 | AK7: 27444800000000 | AL7: 16710800000000 | AN7: =A7 -> 0.00601634 | AO7: =(C7) -> 127545000000000 | AP7: =MIN(C7,P7,AC7) -> 125931000000000 | AQ7: =MAX(C7,P7,AC7) -> 127545000000000 | AR7: =(L7) -> 15669800000000 | AS7: =MIN(L7,Y7,AL7) -> 15599800000000 | AT7: =MAX(L7,Y7,AL7) -> 16710800000000
A8: 0.00699688 | B8: 0.00755531 | C8: 128202000000000 | D8: 5368550000 | E8: 0 | F8: 0 | G8: 2 | H8: 27688200000000 | I8: 27815100000000 | J8: 27630400000000 | K8: 27648000000000 | L8: 17417300000000 | N8: 0.00699312 | O8: 0.0073905 | P8: 125813000000000 | Q8: 10788600000 | R8: 0 | S8: 0 | T8: 2 | U8: 27055400000000 | V8: 28463700000000 | W8: 27591200000000 | X8: 28462100000000 | Y8: 14240600000000 | AA8: 0.00695664 | AB8: 0.00745313 | AC8: 126872000000000 | AD8: 13096600000 | AE8: 0 | AF8: 0 | AG8: 2 | AH8: 27337100000000 | AI8: 28922800000000 | AJ8: 27489700000000 | AK8: 27514800000000 | AL8: 15607900000000 | AN8: =A8 -> 0.00699688 | AO8: =(C8) -> 128202000000000 | AP8: =MIN(C8,P8,AC8) -> 125813000000000 | AQ8: =MAX(C8,P8,AC8) -> 128202000000000 | AR8: =(L8) -> 17417300000000 | AS8: =MIN(L8,Y8,AL8) -> 14240600000000 | AT8: =MAX(L8,Y8,AL8) -> 17417300000000
A9: 0.00803321 | B9: 0.0086379 | C9: 128691000000000 | D9: 9487620000 | E9: 0 | F9: 0 | G9: 2 | H9: 27040000000000 | I9: 26634600000000 | J9: 27421100000000 | K9: 26684300000000 | L9: 20891300000000 | N9: 0.0080631 | O9: 0.00847194 | P9: 125469000000000 | Q9: 9402100000 | R9: 0 | S9: 0 | T9: 2 | U9: 26835500000000 | V9: 27714700000000 | W9: 27044200000000 | X9: 27929200000000 | Y9: 15945000000000 | AA9: 0.00812375 | AB9: 0.00861937 | AC9: 126697000000000 | AD9: 6717800000 | AE9: 0 | AF9: 0 | AG9: 2 | AH9: 27664900000000 | AI9: 28583300000000 | AJ9: 27820300000000 | AK9: 27585500000000 | AL9: 15040600000000 | AN9: =A9 -> 0.00803321 | AO9: =(C9) -> 128691000000000 | AP9: =MIN(C9,P9,AC9) -> 125469000000000 | AQ9: =MAX(C9,P9,AC9) -> 128691000000000 | AR9: =(L9) -> 20891300000000 | AS9: =MIN(L9,Y9,AL9) -> 15040600000000 | AT9: =MAX(L9,Y9,AL9) -> 20891300000000
A10: 0.00900416 | B10: 0.00960398 | C10: 129237000000000 | D10: 28134000000 | E10: 0 | F10: 0 | G10: 2 | H10: 26029900000000 | I10: 26062800000000 | J10: 27337600000000 | K10: 26065500000000 | L10: 23740700000000 | N10: 0.00900432 | O10: 0.0093911 | P10: 125539000000000 | Q10: 59222400000 | R10: 0 | S10: 0 | T10: 2 | U10: 27160000000000 | V10: 27980400000000 | W10: 27384600000000 | X10: 28259000000000 | Y10: 14755000000000 | AA10: 0.0090335 | AB10: 0.00953471 | AC10: 126930000000000 | AD10: 7955250000 | AE10: 0 | AF10: 0 | AG10: 2 | AH10: 27742300000000 | AI10: 28216400000000 | AJ10: 27764000000000 | AK10: 27665100000000 | AL10: 15542000000000 | AN10: =A10 -> 0.00900416 | AO10: =(C10) -> 129237000000000 | AP10: =MIN(C10,P10,AC10) -> 125539000000000 | AQ10: =MAX(C10,P10,AC10) -> 129237000000000 | AR10: =(L10) -> 23740700000000 | AS10: =MIN(L10,Y10,AL10) -> 14755000000000 | AT10: =MAX(L10,Y10,AL10) -> 23740700000000
A11: 0.0100131 | B11: 0.010564 | C11: 128056000000000 | D11: 14017500000 | E11: 0 | F11: 0 | G11: 2 | H11: 24064100000000 | I11: 24332800000000 | J11: 26391200000000 | K11: 24953100000000 | L11: 28314100000000 | N11: 0.0100997 | O11: 0.0105104 | P11: 125822000000000 | Q11: 20807200000 | R11: 0 | S11: 0 | T11: 2 | U11: 27419900000000 | V11: 28433800000000 | W11: 27329100000000 | X11: 28258700000000 | Y11: 14380900000000 | AA11: 0.0100048 | AB11: 0.0104919 | AC11: 126540000000000 | AD11: 20161000000 | AE11: 0 | AF11: 0 | AG11: 2 | AH11: 27881200000000 | AI11: 28150200000000 | AJ11: 27968400000000 | AK11: 27167200000000 | AL11: 15371900000000 | AN11: =A11 -> 0.0100131 | AO11: =(C11) -> 128056000000000 | AP11: =MIN(C11,P11,AC11) -> 125822000000000 | AQ11: =MAX(C11,P11,AC11) -> 128056000000000 | AR11: =(L11) -> 28314100000000 | AS11: =MIN(L11,Y11,AL11) -> 14380900000000 | AT11: =MAX(L11,Y11,AL11) -> 28314100000000
A12: 0.0110256 | B12: 0.0115959 | C12: 125926000000000 | D12: 4236480000 | E12: 0 | F12: 0 | G12: 2 | H12: 21301800000000 | I12: 21342400000000 | J12: 23043300000000 | K12: 23131700000000 | L12: 37106700000000 | N12: 0.0110179 | O12: 0.0114791 | P12: 125620000000000 | Q12: 83262400000 | R12: 0 | S12: 0 | T12: 2 | U12: 26405200000000 | V12: 27683500000000 | W12: 26885100000000 | X12: 27755500000000 | Y12: 16890300000000 | AA12: 0.0110689 | AB12: 0.0115566 | AC12: 126321000000000 | AD12: 6206200000 | AE12: 0 | AF12: 0 | AG12: 2 | AH12: 27960700000000 | AI12: 28684800000000 | AJ12: 28077200000000 | AK12: 27054400000000 | AL12: 14543500000000 | AN12: =A12 -> 0.0110256 | AO12: =(C12) -> 125926000000000 | AP12: =MIN(C12,P12,AC12) -> 125620000000000 | AQ12: =MAX(C12,P12,AC12) -> 126321000000000 | AR12: =(L12) -> 37106700000000 | AS12: =MIN(L12,Y12,AL12) -> 14543500000000 | AT12: =MAX(L12,Y12,AL12) -> 37106700000000
A13: 0.0120005 | B13: 0.0126315 | C13: 125953000000000 | D13: 26522100000 | E13: 0 | F13: 0 | G13: 2 | H13: 19266000000000 | I13: 19611800000000 | J13: 21347700000000 | K13: 21523900000000 | L13: 44200400000000 | N13: 0.0120621 | O13: 0.0126571 | P13: 126069000000000 | Q13: 14940500000 | R13: 0 | S13: 0 | T13: 2 | U13: 26420700000000 | V13: 26983700000000 | W13: 26345500000000 | X13: 27731800000000 | Y13: 18585700000000 | AA13: 0.0119677 | AB13: 0.0124856 | AC13: 126727000000000 | AD13: 21211400000 | AE13: 0 | AF13: 0 | AG13: 2 | AH13: 27798100000000 | AI13: 28201100000000 | AJ13: 28200100000000 | AK13: 26905200000000 | AL13: 15616500000000 | AN13: =A13 -> 0.0120005 | AO13: =(C13) -> 125953000000000 | AP13: =MIN(C13,P13,AC13) -> 125953000000000 | AQ13: =MAX(C13,P13,AC13) -> 126727000000000 | AR13: =(L13) -> 44200400000000 | AS13: =MIN(L13,Y13,AL13) -> 15616500000000 | AT13: =MAX(L13,Y13,AL13) -> 44200400000000
... A28: 0.0269637 | B28: 0.0278059 | C28: 121279000000000 | D28: 9068360000 | E28: 0 | F28: 0 | G28: 2 | H28: 13043900000000 | I28: 12027800000000 | J28: 10982700000000 | K28: 12850300000000 | L28: 72296900000000 | N28: 0.0269885 | O28: 0.027681 | P28: 123503000000000 | Q28: 8702430000 | R28: 0 | S28: 0 | T28: 2 | U28: 14944700000000 | V28: 13835600000000 | W28: 14091200000000 | X28: 14806700000000 | Y28: 65685200000000 | AA28: 0.0270004 | AB28: 0.0273913 | AC28: 126914000000000 | AD28: 4088190000 | AE28: 0 | AF28: 0 | AG28: 2 | AH28: 27684900000000 | AI28: 30619700000000 | AJ28: 31336800000000 | AK28: 27988000000000 | AL28: 9284870000000 | AN28: =A28 -> 0.0269637 | AO28: =(C28) -> 121279000000000 | AP28: =MIN(C28,P28,AC28) -> 121279000000000 | AQ28: =MAX(C28,P28,AC28) -> 126914000000000 | AR28: =(L28) -> 72296900000000 | AS28: =MIN(L28,Y28,AL28) -> 9284870000000 | AT28: =MAX(L28,Y28,AL28) -> 72296900000000
A29: 0.0281025 | B29: 0.0288026 | C29: 123207000000000 | D29: 14636000000 | E29: 0 | F29: 0 | G29: 2 | H29: 14827400000000 | I29: 12804400000000 | J29: 12448200000000 | K29: 15888900000000 | L29: 67157700000000 | N29: 0.0279744 | O29: 0.0288481 | P29: 122132000000000 | Q29: 22808200000 | R29: 0 | S29: 0 | T29: 2 | U29: 14123500000000 | V29: 12182400000000 | W29: 12663600000000 | X29: 12687900000000 | Y29: 70368800000000 | AN29: =A29 -> 0.0281025 | AO29: =(C29) -> 123207000000000 | AP29: =MIN(C29,P29,AC29) -> 122132000000000 | AQ29: =MAX(C29,P29,AC29) -> 123207000000000 | AR29: =(L29) -> 67157700000000 | AS29: =MIN(L29,Y29,AL29) -> 67157700000000 | AT29: =MAX(L29,Y29,AL29) -> 70368800000000
A30: 0.0289868 | B30: 0.0297027 | C30: 122664000000000 | D30: 12460700000 | E30: 0 | F30: 0 | G30: 2 | H30: 13944700000000 | I30: 13730800000000 | J30: 13215600000000 | K30: 13881000000000 | L30: 67795300000000 | AN30: =A30 -> 0.0289868 | AO30: =(C30) -> 122664000000000 | AP30: =MIN(C30,P30,AC30) -> 122664000000000 | AQ30: =MAX(C30,P30,AC30) -> 122664000000000 | AR30: =(L30) -> 67795300000000 | AS30: =MIN(L30,Y30,AL30) -> 67795300000000 | AT30: =MAX(L30,Y30,AL30) -> 67795300000000
AN31: =A31 -> 0 | AO31: =(C31) -> 0 | AP31: =MIN(C31,P31,AC31) -> 0 | AQ31: =MAX(C31,P31,AC31) -> 0 | AR31: =(L31) -> 0 | AS31: =MIN(L31,Y31,AL31) -> 0 | AT31: =MAX(L31,Y31,AL31) -> 0

Sheet 400K_SR20_Stress
A1: Config 1 | D1: Config 2 | G1: Config4 | K1: AverageValue of Last 0.5%
A2: 0.000974606 | B2: 110579000 | D2: 0.000990369 | E2: 99805500 | G2: 0.000989107 | H2: 106808000 | K2: TotalStress | L2: RhoI | M2: Rho | N2: TauF1 | O2: TauF2 | P2: TauF | Q2: Tau | R2: Tau/TauF | S2: RhoI/Rho
A3: 0.00204321 | B3: 99151100 | D3: 0.002124 | E3: 98356300 | G3: 0.00201989 | H3: 115151000 | J3: Config1 | K3: =AVERAGE(B25:B30)/1000000 -> 155.94133 | L3: =AVERAGE('400K_SR20'!L28:L32) -> 69083300000000 | M3: =AVERAGE('400K_SR20'!C28:C32) -> 122383333333333 | N3: =Graphs!$B$1*80.9*0.248*SQRT(L3)/1000000 -> 62.534259 | O3: =Graphs!$B$2*80.9*0.248*SQRT(M3)/1000000 -> 11.097658 | P3: =SQRT(N3^2+O3^2) -> 63.51135 | Q3: =K3*0.4707 -> 73.401586 | R3: =Q3/P3 -> 1.1557239 | S3: =L3/M3 -> 0.56448291
A4: 0.00297351 | B4: 105715000 | D4: 0.00306679 | E4: 86227800 | G4: 0.00323733 | H4: 120553000 | J4: Config2 | K4: =AVERAGE(E25:E30)/1000000 -> 167.2634 | L4: =AVERAGE('400K_SR20'!Y28:Y32) -> 68027000000000 | M4: =AVERAGE('400K_SR20'!P28:P32) -> 122817500000000 | N4: =Graphs!$B$1*80.9*0.248*SQRT(L4)/1000000 -> 62.054336 | O4: =Graphs!$B$2*80.9*0.248*SQRT(M4)/1000000 -> 11.117326 | P4: =SQRT(N4^2+O4^2) -> 63.042331 | Q4: =K4*0.4707 -> 78.730882 | R4: =Q4/P4 -> 1.2488574 | S4: =L4/M4 -> 0.55388686
A5: 0.00403768 | B5: 109610000 | D5: 0.00400013 | E5: 92019400 | G5: 0.00398168 | H5: 120121000 | J5: Config4 | K5: =AVERAGE(H24:H28)/1000000 -> 87.40314 | L5: =AVERAGE('400K_SR20'!AL28:AL32) -> 9284870000000 | M5: =AVERAGE('400K_SR20'!AC28:AC32) -> 126914000000000 | N5: =Graphs!$B$1*80.9*0.248*SQRT(L5)/1000000 -> 22.92553 | O5: =Graphs!$B$2*80.9*0.248*SQRT(M5)/1000000 -> 11.301211 | P5: =SQRT(N5^2+O5^2) -> 25.559681 | Q5: =K5*0.4707 -> 41.140658 | R5: =Q5/P5 -> 1.609592 | S5: =L5/M5 -> 0.073158753
A6: 0.00499008 | B6: 114582000 | D6: 0.0050262 | E6: 89592500 | G6: 0.00498484 | H6: 115054000
A7: 0.00601634 | B7: 108370000 | D7: 0.00609306 | E7: 87400300 | G7: 0.00600329 | H7: 116893000
A8: 0.00699688 | B8: 117188000 | D8: 0.00699312 | E8: 83381600 | G8: 0.00695664 | H8: 104188000
A9: 0.00803321 | B9: 126894000 | D9: 0.0080631 | E9: 85785500 | G9: 0.00812375 | H9: 104007000
A10: 0.00900416 | B10: 125873000 | D10: 0.00900432 | E10: 81150900 | G10: 0.0090335 | H10: 105178000
A11: 0.0100131 | B11: 115600000 | D11: 0.0100997 | E11: 86188000 | G11: 0.0100048 | H11: 102231000 | J11: 1-1.5%
A12: 0.0110256 | B12: 119675000 | D12: 0.0110179 | E12: 96758900 | G12: 0.0110689 | H12: 102355000 | K12: TotalStress | L12: RhoI | M12: Rho | N12: TauF1 | O12: TauF2 | P12: TauF | Q12: Tau | R12: Tau/TauF | S12: RhoI/Rho
A13: 0.0120005 | B13: 132414000 | D13: 0.0120621 | E13: 124863000 | G13: 0.0119677 | H13: 108677000 | J13: Config1 | K13: =AVERAGE(B12:B16)/1000000 -> 136.4098 | L13: =AVERAGE('400K_SR20'!L12:L16) -> 47569620000000 | M13: =AVERAGE('400K_SR20'!C12:C16) -> 125554400000000 | N13: =Graphs!$B$1*80.9*0.248*SQRT(L13)/1000000 -> 51.89151 | O13: =Graphs!$B$2*80.9*0.248*SQRT(M13)/1000000 -> 11.240514 | P13: =SQRT(N13^2+O13^2) -> 53.09499 | Q13: =K13*0.4707 -> 64.208093 | R13: =Q13/P13 -> 1.209306 | S13: =L13/M13 -> 0.37887657
A14: 0.0131082 | B14: 146766000 | D14: 0.0130452 | E14: 145691000 | G14: 0.0129759 | H14: 108822000 | J14: Config2 | K14: =AVERAGE(E12:E16)/1000000 -> 131.75038 | L14: =AVERAGE('400K_SR20'!Y12:Y16) -> 20649040000000 | M14: =AVERAGE('400K_SR20'!P12:P16) -> 127375000000000 | N14: =Graphs!$B$1*80.9*0.248*SQRT(L14)/1000000 -> 34.188607 | O14: =Graphs!$B$2*80.9*0.248*SQRT(M14)/1000000 -> 11.321717 | P14: =SQRT(N14^2+O14^2) -> 36.014471 | Q14: =K14*0.4707 -> 62.014904 | R14: =Q14/P14 -> 1.721944 | S14: =L14/M14 -> 0.16211219
A15: 0.0140191 | B15: 142697000 | D15: 0.0139858 | E15: 151131000 | G15: 0.0141253 | H15: 108317000 | J15: Config4 | K15: =AVERAGE(H12:H16)/1000000 -> 106.4906 | L15: =AVERAGE('400K_SR20'!AL12:AL16) -> 15820340000000 | M15: =AVERAGE('400K_SR20'!AC12:AC16) -> 126562200000000 | N15: =Graphs!$B$1*80.9*0.248*SQRT(L15)/1000000 -> 29.92536 | O15: =Graphs!$B$2*80.9*0.248*SQRT(M15)/1000000 -> 11.285537 | P15: =SQRT(N15^2+O15^2) -> 31.982659 | Q15: =K15*0.4707 -> 50.125125 | R15: =Q15/P15 -> 1.5672595 | S15: =L15/M15 -> 0.12500051
A16: 0.0150061 | B16: 140497000 | D16: 0.0150132 | E16: 140308000 | G16: 0.0148874 | H16: 104282000
A17: 0.0160272 | B17: 134553000 | D17: 0.0160216 | E17: 141558000 | G17: 0.0161202 | H17: 98637500
A18: 0.0169018 | B18: 196898000 | D18: 0.0171345 | E18: 135206000 | G18: 0.0170747 | H18: 96121700
A19: 0.0180332 | B19: 173200000 | D19: 0.0180138 | E19: 140272000 | G19: 0.0179877 | H19: 93269500
A20: 0.0189849 | B20: 197333000 | D20: 0.0189339 | E20: 139626000 | G20: 0.0189791 | H20: 91531900
A21: 0.0199998 | B21: 167221000 | D21: 0.0200167 | E21: 123552000 | G21: 0.0199769 | H21: 88576400
A22: 0.0207894 | B22: 192091000 | D22: 0.0209944 | E22: 134096000 | G22: 0.0210492 | H22: 83583500
A23: 0.0218755 | B23: 187385000 | D23: 0.0220424 | E23: 129314000 | G23: 0.0220476 | H23: 87511800
A24: 0.0228839 | B24: 165898000 | D24: 0.0229543 | E24: 132968000 | G24: 0.0229617 | H24: 93218600
A25: 0.0240288 | B25: 134088000 | D25: 0.0238307 | E25: 159191000 | G25: 0.0240296 | H25: 87847100
A26: 0.0249402 | B26: 170641000 | D26: 0.0249625 | E26: 193321000 | G26: 0.0250661 | H26: 89130200
A27: 0.0259639 | B27: 157028000 | D27: 0.0260463 | E27: 155163000 | G27: 0.0259647 | H27: 84810000
A28: 0.0269637 | B28: 176730000 | D28: 0.0269885 | E28: 145296000 | G28: 0.0270004 | H28: 82009800
A29: 0.0281025 | B29: 146932000 | D29: 0.0279744 | E29: 183346000
A30: 0.0289868 | B30: 150229000

Sheet 400K_SR40
A1: Config1 | N1: Config2 | AA1: Config3 | AN1: Pstrain | AO1: Total | AP1: Totalmin | AQ1: Totalmax | AR1: Junction | AS1: Junctionmin | AT1: Junctionmax
A2: 0.00100817 | B2: 0.00152811 | C2: 126734000000000 | D2: 69313100000 | E2: 0 | F2: 0 | G2: 2 | H2: 29819200000000 | I2: 29372200000000 | J2: 29316400000000 | K2: 28949500000000 | L2: 9276800000000 | N2: 0.000946734 | O2: 0.00150362 | P2: 127411000000000 | Q2: 5276330000 | R2: 0 | S2: 0 | T2: 2 | U2: 30399400000000 | V2: 29987900000000 | W2: 29623400000000 | X2: 29915400000000 | Y2: 7484320000000 | AA2: 0.000986807 | AB2: 0.00152015 | AC2: 127143000000000 | AD2: 4117280000 | AE2: 0 | AF2: 0 | AG2: 2 | AH2: 29600100000000 | AI2: 29478800000000 | AJ2: 29433300000000 | AK2: 28981400000000 | AL2: 9649260000000 | AN2: =A2 -> 0.00100817 | AO2: =(C2+P2+AC2)/3 -> 127096000000000 | AP2: =MIN(C2,P2,AC2) -> 126734000000000 | AQ2: =MAX(C2,P2,AC2) -> 127411000000000 | AR2: =(L2+Y2+AL2)/3 -> 8803460000000 | AS2: =MIN(L2,Y2,AL2) -> 7484320000000 | AT2: =MAX(L2,Y2,AL2) -> 9649260000000
A3: 0.00196264 | B3: 0.0025242 | C3: 126717000000000 | D3: 4892010000 | E3: 0 | F3: 0 | G3: 2 | H3: 28943000000000 | I3: 28336900000000 | J3: 28766500000000 | K3: 28165300000000 | L3: 12504900000000 | N3: 0.0020171 | O3: 0.00265706 | P3: 127647000000000 | Q3: 8085840000 | R3: 0 | S3: 0 | T3: 2 | U3: 28890100000000 | V3: 28534000000000 | W3: 27704800000000 | X3: 28746400000000 | Y3: 13771200000000 | AA3: 0.00202279 | AB3: 0.0026457 | AC3: 126880000000000 | AD3: 35600200000 | AE3: 0 | AF3: 0 | AG3: 2 | AH3: 28188000000000 | AI3: 28112100000000 | AJ3: 28022600000000 | AK3: 27596700000000 | AL3: 14960300000000 | AN3: =A3 -> 0.00196264 | AO3: =(C3+P3+AC3)/3 -> 127081333333333 | AP3: =MIN(C3,P3,AC3) -> 126717000000000 | AQ3: =MAX(C3,P3,AC3) -> 127647000000000 | AR3: =(L3+Y3+AL3)/3 -> 1.3745467e+13 | AS3: =MIN(L3,Y3,AL3) -> 12504900000000 | AT3: =MAX(L3,Y3,AL3) -> 14960300000000
A4: 0.00303062 | B4: 0.00362846 | C4: 126702000000000 | D4: 2656140000 | E4: 0 | F4: 0 | G4: 2 | H4: 27465900000000 | I4: 27424100000000 | J4: 27658700000000 | K4: 27068600000000 | L4: 17084800000000 | N4: 0.00295437 | O4: 0.00365188 | P4: 127992000000000 | Q4: 6747040000 | R4: 0 | S4: 0 | T4: 2 | U4: 27582400000000 | V4: 27389000000000 | W4: 27069800000000 | X4: 27498100000000 | Y4: 18452600000000 | AA4: 0.00301632 | AB4: 0.00370676 | AC4: 128103000000000 | AD4: 4585490000 | AE4: 0 | AF4: 0 | AG4: 2 | AH4: 27294700000000 | AI4: 27563900000000 | AJ4: 27468700000000 | AK4: 27688200000000 | AL4: 18086900000000 | AN4: =A4 -> 0.00303062 | AO4: =(C4+P4+AC4)/3 -> 127599000000000 | AP4: =MIN(C4,P4,AC4) -> 126702000000000 | AQ4: =MAX(C4,P4,AC4) -> 128103000000000 | AR4: =(L4+Y4+AL4)/3 -> 1.7874767e+13 | AS4: =MIN(L4,Y4,AL4) -> 17084800000000 | AT4: =MAX(L4,Y4,AL4) -> 18452600000000
A5: 0.00402491 | B5: 0.00464284 | C5: 127703000000000 | D5: 13288400000 | E5: 0 | F5: 0 | G5: 2 | H5: 27434600000000 | I5: 27399900000000 | J5: 28163600000000 | K5: 27161400000000 | L5: 17543400000000 | N5: 0.0040034 | O5: 0.00466247 | P5: 127340000000000 | Q5: 11682800000 | R5: 0 | S5: 0 | T5: 2 | U5: 27305400000000 | V5: 27008800000000 | W5: 26420900000000 | X5: 25944800000000 | Y5: 20660000000000 | AA5: 0.00400083 | AB5: 0.00465531 | AC5: 127739000000000 | AD5: 9730830000 | AE5: 0 | AF5: 0 | AG5: 2 | AH5: 26632500000000 | AI5: 26919900000000 | AJ5: 27380500000000 | AK5: 28002200000000 | AL5: 18803900000000 | AN5: =A5 -> 0.00402491 | AO5: =(C5+P5+AC5)/3 -> 127594000000000 | AP5: =MIN(C5,P5,AC5) -> 127340000000000 | AQ5: =MAX(C5,P5,AC5) -> 127739000000000 | AR5: =(L5+Y5+AL5)/3 -> 1.9002433e+13 | AS5: =MIN(L5,Y5,AL5) -> 17543400000000 | AT5: =MAX(L5,Y5,AL5) -> 20660000000000
A6: 0.00501723 | B6: 0.00562562 | C6: 127695000000000 | D6: 19670300000 | E6: 0 | F6: 0 | G6: 2 | H6: 27588500000000 | I6: 27475600000000 | J6: 27701200000000 | K6: 27641800000000 | L6: 17287700000000 | N6: 0.00501629 | O6: 0.00571476 | P6: 127502000000000 | Q6: 42832800000 | R6: 0 | S6: 0 | T6: 2 | U6: 26372800000000 | V6: 27290200000000 | W6: 25192300000000 | X6: 25401900000000 | Y6: 23240800000000 | AA6: 0.00501192 | AB6: 0.00557816 | AC6: 126751000000000 | AD6: 35700200000 | AE6: 0 | AF6: 0 | AG6: 2 | AH6: 26586600000000 | AI6: 26741200000000 | AJ6: 27512100000000 | AK6: 27657700000000 | AL6: 18252300000000 | AN6: =A6 -> 0.00501723 | AO6: =(C6+P6+AC6)/3 -> 127316000000000 | AP6: =MIN(C6,P6,AC6) -> 126751000000000 | AQ6: =MAX(C6,P6,AC6) -> 127695000000000 | AR6: =(L6+Y6+AL6)/3 -> 19593600000000 | AS6: =MIN(L6,Y6,AL6) -> 17287700000000 | AT6: =MAX(L6,Y6,AL6) -> 23240800000000
A7: 0.00599375 | B7: 0.00657748 | C7: 127158000000000 | D7: 6228020000 | E7: 0 | F7: 0 | G7: 2 | H7: 27804300000000 | I7: 27382700000000 | J7: 27717800000000 | K7: 28099800000000 | L7: 16152300000000 | N7: 0.00602332 | O7: 0.00671383 | P7: 128443000000000 | Q7: 32692700000 | R7: 0 | S7: 0 | T7: 2 | U7: 26464200000000 | V7: 26985300000000 | W7: 24446600000000 | X7: 25123400000000 | Y7: 25423000000000 | AA7: 0.00601177 | AB7: 0.00659708 | AC7: 127087000000000 | AD7: 85393700000 | AE7: 0 | AF7: 0 | AG7: 2 | AH7: 27196100000000 | AI7: 27244700000000 | AJ7: 28433100000000 | AK7: 28331200000000 | AL7: 15881500000000 | AN7: =A7 -> 0.00599375 | AO7: =(C7+P7+AC7)/3 -> 127562666666667 | AP7: =MIN(C7,P7,AC7) -> 127087000000000 | AQ7: =MAX(C7,P7,AC7) -> 128443000000000 | AR7: =(L7+Y7+AL7)/3 -> 1.9152267e+13 | AS7: =MIN(L7,Y7,AL7) -> 15881500000000 | AT7: =MAX(L7,Y7,AL7) -> 25423000000000
A8: 0.00698656 | B8: 0.00754123 | C8: 127488000000000 | D8: 20662700000 | E8: 0 | F8: 0 | G8: 2 | H8: 28432900000000 | I8: 27553000000000 | J8: 28101300000000 | K8: 28088400000000 | L8: 15307500000000 | N8: 0.00701347 | O8: 0.00772629 | P8: 128863000000000 | Q8: 21741100000 | R8: 0 | S8: 0 | T8: 2 | U8: 27319700000000 | V8: 27618600000000 | W8: 23339900000000 | X8: 25667200000000 | Y8: 24916300000000 | AA8: 0.00706293 | AB8: 0.00767411 | AC8: 127789000000000 | AD8: 7168850000 | AE8: 0 | AF8: 0 | AG8: 2 | AH8: 26638300000000 | AI8: 27317100000000 | AJ8: 28628700000000 | AK8: 28008100000000 | AL8: 17196500000000 | AN8: =A8 -> 0.00698656 | AO8: =(C8+P8+AC8)/3 -> 128046666666667 | AP8: =MIN(C8,P8,AC8) -> 127488000000000 | AQ8: =MAX(C8,P8,AC8) -> 128863000000000 | AR8: =(L8+Y8+AL8)/3 -> 19140100000000 | AS8: =MIN(L8,Y8,AL8) -> 15307500000000 | AT8: =MAX(L8,Y8,AL8) -> 24916300000000
A9: 0.00792094 | B9: 0.0085072 | C9: 127757000000000 | D9: 20026700000 | E9: 0 | F9: 0 | G9: 2 | H9: 28091400000000 | I9: 27954200000000 | J9: 28321500000000 | K9: 27424200000000 | L9: 15965200000000 | N9: 0.00799778 | O9: 0.0087257 | P9: 128531000000000 | Q9: 8646210000 | R9: 0 | S9: 0 | T9: 2 | U9: 26653800000000 | V9: 25884000000000 | W9: 22591800000000 | X9: 24670800000000 | Y9: 28728000000000 | AA9: 0.00802035 | AB9: 0.00865498 | AC9: 128018000000000 | AD9: 24702400000 | AE9: 0 | AF9: 0 | AG9: 2 | AH9: 26875000000000 | AI9: 27071600000000 | AJ9: 27793000000000 | AK9: 27567500000000 | AL9: 18710300000000 | AN9: =A9 -> 0.00792094 | AO9: =(C9+P9+AC9)/3 -> 128102000000000 | AP9: =MIN(C9,P9,AC9) -> 127757000000000 | AQ9: =MAX(C9,P9,AC9) -> 128531000000000 | AR9: =(L9+Y9+AL9)/3 -> 21134500000000 | AS9: =MIN(L9,Y9,AL9) -> 15965200000000 | AT9: =MAX(L9,Y9,AL9) -> 28728000000000
A10: 0.00898586 | B10: 0.00956327 | C10: 127695000000000 | D10: 175489000000 | E10: 0 | F10: 0 | G10: 2 | H10: 27944300000000 | I10: 27433400000000 | J10: 27682800000000 | K10: 27242400000000 | L10: 17388700000000 | N10: 0.0089879 | O10: 0.00975243 | P10: 130308000000000 | Q10: 25766200000 | R10: 0 | S10: 0 | T10: 2 | U10: 25783600000000 | V10: 24606700000000 | W10: 22372200000000 | X10: 24672300000000 | Y10: 32871800000000 | AA10: 0.00906845 | AB10: 0.00971131 | AC10: 127820000000000 | AD10: 4931100000 | AE10: 0 | AF10: 0 | AG10: 2 | AH10: 26326800000000 | AI10: 26228500000000 | AJ10: 27266300000000 | AK10: 26633500000000 | AL10: 21363700000000 | AN10: =A10 -> 0.00898586 | AO10: =(C10+P10+AC10)/3 -> 128607666666667 | AP10: =MIN(C10,P10,AC10) -> 127695000000000 | AQ10: =MAX(C10,P10,AC10) -> 130308000000000 | AR10: =(L10+Y10+AL10)/3 -> 2.3874733e+13 | AS10: =MIN(L10,Y10,AL10) -> 17388700000000 | AT10: =MAX(L10,Y10,AL10) -> 32871800000000
A11: 0.0100146 | B11: 0.0105786 | C11: 127265000000000 | D11: 52988200000 | E11: 0 | F11: 0 | G11: 2 | H11: 27954000000000 | I11: 27420100000000 | J11: 27915000000000 | K11: 27441300000000 | L11: 16534100000000 | N11: 0.00995588 | O11: 0.010734 | P11: 130520000000000 | Q11: 5108870000 | R11: 0 | S11: 0 | T11: 2 | U11: 25722600000000 | V11: 24964600000000 | W11: 22374700000000 | X11: 24371900000000 | Y11: 33085500000000 | AA11: 0.00996406 | AB11: 0.010629 | AC11: 127457000000000 | AD11: 4385630000 | AE11: 0 | AF11: 0 | AG11: 2 | AH11: 25539200000000 | AI11: 26313400000000 | AJ11: 26678200000000 | AK11: 25909200000000 | AL11: 23017300000000 | AN11: =A11 -> 0.0100146 | AO11: =(C11+P11+AC11)/3 -> 128414000000000 | AP11: =MIN(C11,P11,AC11) -> 127265000000000 | AQ11: =MAX(C11,P11,AC11) -> 130520000000000 | AR11: =(L11+Y11+AL11)/3 -> 24212300000000 | AS11: =MIN(L11,Y11,AL11) -> 16534100000000 | AT11: =MAX(L11,Y11,AL11) -> 33085500000000
A12: 0.0110441 | B12: 0.011575 | C12: 127272000000000 | D12: 10249300000 | E12: 0 | F12: 0 | G12: 2 | H12: 28546500000000 | I12: 27778400000000 | J12: 28354900000000 | K12: 28242000000000 | L12: 14350100000000 | N12: 0.0110491 | O12: 0.0118091 | P12: 134745000000000 | Q12: 5604470000 | R12: 0 | S12: 0 | T12: 2 | U12: 26713500000000 | V12: 24664500000000 | W12: 23731300000000 | X12: 24229800000000 | Y12: 35405800000000 | AA12: 0.0110879 | AB12: 0.0117777 | AC12: 128090000000000 | AD12: 9838750000 | AE12: 0 | AF12: 0 | AG12: 2 | AH12: 25894600000000 | AI12: 26603600000000 | AJ12: 26590500000000 | AK12: 26058600000000 | AL12: 22942300000000 | AN12: =A12 -> 0.0110441 | AO12: =(C12+P12+AC12)/3 -> 130035666666667 | AP12: =MIN(C12,P12,AC12) -> 127272000000000 | AQ12: =MAX(C12,P12,AC12) -> 134745000000000 | AR12: =(L12+Y12+AL12)/3 -> 2.4232733e+13 | AS12: =MIN(L12,Y12,AL12) -> 14350100000000 | AT12: =MAX(L12,Y12,AL12) -> 35405800000000
A13: 0.011965 | B13: 0.0125261 | C13: 127583000000000 | D13: 10573300000 | E13: 0 | F13: 0 | G13: 2 | H13: 28332700000000 | I13: 27681800000000 | J13: 28357600000000 | K13: 28378500000000 | L13: 14831900000000 | N13: 0.0119874 | O13: 0.0127627 | P13: 134472000000000 | Q13: 6467890000 | R13: 0 | S13: 0 | T13: 2 | U13: 27901700000000 | V13: 23823900000000 | W13: 22615300000000 | X13: 22469200000000 | Y13: 37660400000000 | AA13: 0.0119925 | AB13: 0.012699 | AC13: 129624000000000 | AD13: 4410190000 | AE13: 0 | AF13: 0 | AG13: 2 | AH13: 27131600000000 | AI13: 26704100000000 | AJ13: 27099900000000 | AK13: 25811000000000 | AL13: 22877000000000 | AN13: =A13 -> 0.011965 | AO13: =(C13+P13+AC13)/3 -> 130559666666667 | AP13: =MIN(C13,P13,AC13) -> 127583000000000 | AQ13: =MAX(C13,P13,AC13) -> 134472000000000 | AR13: =(L13+Y13+AL13)/3 -> 25123100000000 | AS13: =MIN(L13,Y13,AL13) -> 14831900000000 | AT13: =MAX(L13,Y13,AL13) -> 37660400000000
... A22: 0.0210149 | B22: 0.0215367 | C22: 126728000000000 | D22: 4405240000 | E22: 0 | F22: 0 | G22: 2 | H22: 26348000000000 | I22: 25683800000000 | J22: 27211100000000 | K22: 26132600000000 | L22: 21352700000000 | N22: 0.0210188 | O22: 0.0217945 | P22: 125504000000000 | Q22: 10036100000 | R22: 0 | S22: 0 | T22: 2 | U22: 17532400000000 | V22: 17291200000000 | W22: 15864600000000 | X22: 14912700000000 | Y22: 59893400000000 | AA22: 0.0209858 | AB22: 0.0217274 | AC22: 132418000000000 | AD22: 11139500000 | AE22: 0 | AF22: 0 | AG22: 2 | AH22: 18667300000000 | AI22: 22394800000000 | AJ22: 23876500000000 | AK22: 16801700000000 | AL22: 50674600000000 | AN22: =A22 -> 0.0210149 | AO22: =(C22+P22+AC22)/3 -> 128216666666667 | AP22: =MIN(C22,P22,AC22) -> 125504000000000 | AQ22: =MAX(C22,P22,AC22) -> 132418000000000 | AR22: =(L22+Y22+AL22)/3 -> 4.3973567e+13 | AS22: =MIN(L22,Y22,AL22) -> 21352700000000 | AT22: =MAX(L22,Y22,AL22) -> 59893400000000
A23: 0.0219729 | B23: 0.0225198 | C23: 128001000000000 | D23: 20752500000 | E23: 0 | F23: 0 | G23: 2 | H23: 27040100000000 | I23: 26660200000000 | J23: 28741300000000 | K23: 27047100000000 | L23: 18512000000000 | N23: 0.0219816 | O23: 0.0227829 | P23: 125970000000000 | Q23: 16393100000 | R23: 0 | S23: 0 | T23: 2 | U23: 16712100000000 | V23: 16682200000000 | W23: 15876300000000 | X23: 15130700000000 | Y23: 61561700000000 | AN23: =A23 -> 0.0219729 | AO23: =(C23+P23+AC23)/3 -> 84657000000000 | AP23: =MIN(C23,P23,AC23) -> 125970000000000 | AQ23: =MAX(C23,P23,AC23) -> 128001000000000 | AR23: =(L23+Y23+AL23)/3 -> 2.6691233e+13 | AS23: =MIN(L23,Y23,AL23) -> 18512000000000 | AT23: =MAX(L23,Y23,AL23) -> 61561700000000
A24: 0.0229663 | B24: 0.0235044 | C24: 126959000000000 | D24: 13443200000 | E24: 0 | F24: 0 | G24: 2 | H24: 26962700000000 | I24: 26777000000000 | J24: 28657600000000 | K24: 27123400000000 | L24: 17438100000000 | N24: 0.0229487 | O24: 0.0238397 | P24: 125007000000000 | Q24: 42046800000 | R24: 0 | S24: 0 | T24: 2 | U24: 16361900000000 | V24: 15702500000000 | W24: 15419200000000 | X24: 14522400000000 | Y24: 62988000000000 | AN24: =A24 -> 0.0229663 | AO24: =(C24+P24+AC24)/3 -> 8.3988667e+13 | AP24: =MIN(C24,P24,AC24) -> 125007000000000 | AQ24: =MAX(C24,P24,AC24) -> 126959000000000 | AR24: =(L24+Y24+AL24)/3 -> 26808700000000 | AS24: =MIN(L24,Y24,AL24) -> 17438100000000 | AT24: =MAX(L24,Y24,AL24) -> 62988000000000
A25: 0.0240019 | B25: 0.0245669 | C25: 126638000000000 | D25: 11365000000 | E25: 0 | F25: 0 | G25: 2 | H25: 26611800000000 | I25: 26268500000000 | J25: 28207400000000 | K25: 26068200000000 | L25: 19481900000000 | N25: 0.0240161 | O25: 0.0248109 | P25: 125035000000000 | Q25: 67702600000 | R25: 0 | S25: 0 | T25: 2 | U25: 15564700000000 | V25: 16145700000000 | W25: 15821700000000 | X25: 14244300000000 | Y25: 63249300000000 | AN25: =A25 -> 0.0240019 | AO25: =(C25+P25+AC25)/3 -> 83891000000000 | AP25: =MIN(C25,P25,AC25) -> 125035000000000 | AQ25: =MAX(C25,P25,AC25) -> 126638000000000 | AR25: =(L25+Y25+AL25)/3 -> 2.7577067e+13 | AS25: =MIN(L25,Y25,AL25) -> 19481900000000 | AT25: =MAX(L25,Y25,AL25) -> 63249300000000
A26: 0.0250139 | B26: 0.025635 | C26: 127077000000000 | D26: 7336290000 | E26: 0 | F26: 0 | G26: 2 | H26: 26989800000000 | I26: 26246500000000 | J26: 27567700000000 | K26: 25925500000000 | L26: 20347300000000 | N26: 0.0249183 | O26: 0.0257488 | P26: 124368000000000 | Q26: 29878000000 | R26: 0 | S26: 0 | T26: 2 | U26: 15168200000000 | V26: 14645600000000 | W26: 15444300000000 | X26: 14318100000000 | Y26: 64761500000000 | AN26: =A26 -> 0.0250139 | AO26: =(C26+P26+AC26)/3 -> 83815000000000 | AP26: =MIN(C26,P26,AC26) -> 124368000000000 | AQ26: =MAX(C26,P26,AC26) -> 127077000000000 | AR26: =(L26+Y26+AL26)/3 -> 28369600000000 | AS26: =MIN(L26,Y26,AL26) -> 20347300000000 | AT26: =MAX(L26,Y26,AL26) -> 64761500000000
A27: 0.0259837 | B27: 0.0265949 | C27: 127601000000000 | D27: 9972790000 | E27: 0 | F27: 0 | G27: 2 | H27: 27561100000000 | I27: 26752100000000 | J27: 26865400000000 | K27: 26118200000000 | L27: 20304700000000 | N27: 0.0260007 | O27: 0.0268065 | P27: 123914000000000 | Q27: 19019600000 | R27: 0 | S27: 0 | T27: 2 | U27: 15125000000000 | V27: 13555600000000 | W27: 14738800000000 | X27: 13862900000000 | Y27: 66563400000000 | AN27: =A27 -> 0.0259837 | AO27: =(C27+P27+AC27)/3 -> 8.3838333e+13 | AP27: =MIN(C27,P27,AC27) -> 123914000000000 | AQ27: =MAX(C27,P27,AC27) -> 127601000000000 | AR27: =(L27+Y27+AL27)/3 -> 2.8956033e+13 | AS27: =MIN(L27,Y27,AL27) -> 20304700000000 | AT27: =MAX(L27,Y27,AL27) -> 66563400000000
A28: 0.0269575 | B28: 0.0275834 | C28: 128123000000000 | D28: 20029300000 | E28: 0 | F28: 0 | G28: 2 | H28: 28005800000000 | I28: 27115300000000 | J28: 27606100000000 | K28: 26630100000000 | L28: 18752000000000 | N28: 0.0271111 | O28: 0.0279111 | P28: 123517000000000 | Q28: 18909600000 | R28: 0 | S28: 0 | T28: 2 | U28: 13752000000000 | V28: 14205700000000 | W28: 15083900000000 | X28: 12605900000000 | Y28: 67805500000000 | AN28: =A28 -> 0.0269575 | AO28: =(C28+P28+AC28)/3 -> 83880000000000 | AP28: =MIN(C28,P28,AC28) -> 123517000000000 | AQ28: =MAX(C28,P28,AC28) -> 128123000000000 | AR28: =(L28+Y28+AL28)/3 -> 28852500000000 | AS28: =MIN(L28,Y28,AL28) -> 18752000000000 | AT28: =MAX(L28,Y28,AL28) -> 67805500000000
A29: 0.0279955 | B29: 0.0286084 | C29: 127741000000000 | D29: 83915300000 | E29: 0 | F29: 0 | G29: 2 | H29: 28080500000000 | I29: 27118700000000 | J29: 28754700000000 | K29: 26867200000000 | L29: 16920000000000 | N29: 0.0281873 | O29: 0.0290286 | P29: 123393000000000 | Q29: 26384000000 | R29: 0 | S29: 0 | T29: 2 | U29: 13305900000000 | V29: 14137100000000 | W29: 15032500000000 | X29: 12492100000000 | Y29: 68343000000000 | AN29: =A29 -> 0.0279955 | AO29: =(C29+P29+AC29)/3 -> 8.3711333e+13 | AP29: =MIN(C29,P29,AC29) -> 123393000000000 | AQ29: =MAX(C29,P29,AC29) -> 127741000000000 | AR29: =(L29+Y29+AL29)/3 -> 28421000000000 | AS29: =MIN(L29,Y29,AL29) -> 16920000000000 | AT29: =MAX(L29,Y29,AL29) -> 68343000000000
A30: 0.0289777 | B30: 0.0296293 | C30: 127823000000000 | D30: 5791920000 | E30: 0 | F30: 0 | G30: 2 | H30: 28230100000000 | I30: 26864600000000 | J30: 28694000000000 | K30: 26620000000000 | L30: 17413900000000 | N30: 0.0290632 | O30: 0.0299062 | P30: 123346000000000 | Q30: 15983200000 | R30: 0 | S30: 0 | T30: 2 | U30: 13147200000000 | V30: 14907000000000 | W30: 14587300000000 | X30: 12760000000000 | Y30: 67892900000000 | AN30: =A30 -> 0.0289777 | AO30: =(C30+P30+AC30)/3 -> 83723000000000 | AP30: =MIN(C30,P30,AC30) -> 123346000000000 | AQ30: =MAX(C30,P30,AC30) -> 127823000000000 | AR30: =(L30+Y30+AL30)/3 -> 28435600000000 | AS30: =MIN(L30,Y30,AL30) -> 17413900000000 | AT30: =MAX(L30,Y30,AL30) -> 67892900000000
A31: 0.0299604 | B31: 0.0305727 | C31: 127339000000000 | D31: 9686550000 | E31: 0 | F31: 0 | G31: 2 | H31: 28223200000000 | I31: 26479200000000 | J31: 27934900000000 | K31: 26374300000000 | L31: 18327600000000 | N31: 0.0300038 | O31: 0.0308257 | P31: 123781000000000 | Q31: 23708700000 | R31: 0 | S31: 0 | T31: 2 | U31: 13820100000000 | V31: 14784600000000 | W31: 15131000000000 | X31: 12947000000000 | Y31: 67042700000000
A32: 0.0310262 | B32: 0.031678 | C32: 127674000000000 | D32: 18334600000 | E32: 0 | F32: 0 | G32: 2 | H32: 27080100000000 | I32: 27072500000000 | J32: 28138800000000 | K32: 26660400000000 | L32: 18719500000000 | N32: 0.0310638 | O32: 0.0318713 | P32: 124164000000000 | Q32: 128809000000 | R32: 0 | S32: 0 | T32: 2 | U32: 15469000000000 | V32: 14661300000000 | W32: 15025100000000 | X32: 14624400000000 | Y32: 64321800000000
A33: 0.0319183 | B33: 0.0326012 | C33: 128290000000000 | D33: 22866200000 | E33: 0 | F33: 0 | G33: 2 | H33: 26537700000000 | I33: 26310700000000 | J33: 27625000000000 | K33: 25699800000000 | L33: 22113600000000 | N33: 0.0319994 | O33: 0.0328331 | P33: 124714000000000 | Q33: 27975800000 | R33: 0 | S33: 0 | T33: 2 | U33: 16034900000000 | V33: 15298800000000 | W33: 15036000000000 | X33: 14881400000000 | Y33: 63424300000000
A34: 0.0329799 | B34: 0.0336575 | C34: 128042000000000 | D34: 23846900000 | E34: 0 | F34: 0 | G34: 2 | H34: 27070300000000 | I34: 26418400000000 | J34: 27187100000000 | K34: 26867500000000 | L34: 20498800000000 | N34: 0.0329693 | O34: 0.0337105 | P34: 124385000000000 | Q34: 26406600000 | R34: 0 | S34: 0 | T34: 2 | U34: 16193300000000 | V34: 15826300000000 | W34: 14200900000000 | X34: 14762500000000 | Y34: 63383300000000
A35: 0.0339601 | B35: 0.0345912 | C35: 127091000000000 | D35: 15545500000 | E35: 0 | F35: 0 | G35: 2 | H35: 26484900000000 | I35: 26266600000000 | J35: 27445600000000 | K35: 26154900000000 | L35: 20734100000000
A36: 0.0350297 | B36: 0.0357178 | C36: 127919000000000 | D36: 18150700000 | E36: 0 | F36: 0 | G36: 2 | H36: 26299900000000 | I36: 26430700000000 | J36: 26533400000000 | K36: 25011100000000 | L36: 23641600000000
A37: 0.0359889 | B37: 0.0367123 | C37: 128586000000000 | D37: 26882800000 | E37: 0 | F37: 0 | G37: 2 | H37: 26368900000000 | I37: 26112300000000 | J37: 25778600000000 | K37: 25548000000000 | L37: 24777100000000
A38: 0.0370473 | B38: 0.0378113 | C38: 129572000000000 | D38: 11049500000 | E38: 0 | F38: 0 | G38: 2 | H38: 26194800000000 | I38: 26061200000000 | J38: 24908500000000 | K38: 24929600000000 | L38: 27476300000000
A39: 0.0379742 | B39: 0.0387615 | C39: 131824000000000 | D39: 4860400000 | E39: 0 | F39: 0 | G39: 2 | H39: 26371500000000 | I39: 27176500000000 | J39: 24524300000000 | K39: 24727700000000 | L39: 29023500000000
A40: 0.0389928 | B40: 0.0397904 | C40: 135696000000000 | D40: 3822300000 | E40: 0 | F40: 0 | G40: 2 | H40: 26327100000000 | I40: 27359500000000 | J40: 24462800000000 | K40: 23504700000000 | L40: 34040100000000
A41: 0.0400154 | B41: 0.0407269 | C41: 141561000000000 | D41: 10731700000 | E41: 0 | F41: 0 | G41: 2 | H41: 27101100000000 | I41: 29122800000000 | J41: 26428700000000 | K41: 24425700000000 | L41: 34480700000000
A42: 0.0410017 | B42: 0.0416445 | C42: 146761000000000 | D42: 3361840000 | E42: 0 | F42: 0 | G42: 2 | H42: 27955200000000 | I42: 29786800000000 | J42: 28618600000000 | K42: 24615200000000 | L42: 35784800000000
A43: 0.0420089 | B43: 0.0426223 | C43: 149939000000000 | D43: 7064000000 | E43: 0 | F43: 0 | G43: 2 | H43: 28327000000000 | I43: 29261100000000 | J43: 28994000000000 | K43: 24896700000000 | L43: 38459200000000
A44: 0.0430132 | B44: 0.0436238 | C44: 148445000000000 | D44: 4096530000 | E44: 0 | F44: 0 | G44: 2 | H44: 29328700000000 | I44: 27740900000000 | J44: 27592800000000 | K44: 22768600000000 | L44: 41013300000000
A45: 0.0440045 | B45: 0.0446454 | C45: 145527000000000 | D45: 7109020000 | E45: 0 | F45: 0 | G45: 2 | H45: 27721100000000 | I45: 25640200000000 | J45: 26770100000000 | K45: 20646000000000 | L45: 44746500000000
A46: 0.0449796 | B46: 0.045639 | C46: 144380000000000 | D46: 4893220000 | E46: 0 | F46: 0 | G46: 2 | H46: 26942200000000 | I46: 26378300000000 | J46: 26893000000000 | K46: 21623700000000 | L46: 42533100000000
... A58: 0.0570082 | B58: 0.0577641 | C58: 123449000000000 | D58: 138322000000 | E58: 0 | F58: 0 | G58: 2 | H58: 15536400000000 | I58: 14396400000000 | J58: 15060800000000 | K58: 14413900000000 | L58: 63993300000000

Sheet 400K_SR40_Stress
A1: Config | B1: 1 | D1: Config 2 | G1: Config3 | J1: AverageValue of Last 0.5%
A2: 0.00100817 | B2: 109111000 | D2: 0.000946734 | E2: 116864000 | G2: 0.000986807 | H2: 111912000 | K2: TotalStress | L2: RhoI | M2: Rho | N2: TauF1 | O2: TauF2 | P2: TauF | Q2: Tau | R2: Tau/TauF | S2: RhoI/Rho
A3: 0.00196264 | B3: 117841000 | D3: 0.0020171 | E3: 134300000 | G3: 0.00202279 | H3: 130706000 | J3: C1 | K3: =AVERAGE(B26:B31)/1000000 -> 130.62367 | L3: =AVERAGE('400K_SR40'!L28:L32) -> 18026600000000 | M3: =AVERAGE('400K_SR40'!C28:C32) -> 127740000000000 | N3: =Graphs!$B$1*80.9*0.248*SQRT(L3)/1000000 -> 31.943933 | O3: =Graphs!$B$2*80.9*0.248*SQRT(M3)/1000000 -> 11.337927 | P3: =SQRT(N3^2+O3^2) -> 33.896363 | Q3: =K3*0.4707 -> 61.48456 | R3: =Q3/P3 -> 1.8138984 | S3: =L3/M3 -> 0.14111946
A4: 0.00303062 | B4: 125455000 | D4: 0.00295437 | E4: 146376000 | G4: 0.00301632 | H4: 144881000 | J4: C2 | K4: =AVERAGE(E26:E31)/1000000 -> 172.86867 | L4: =AVERAGE('400K_SR40'!Y28:Y32) -> 67081180000000 | M4: =AVERAGE('400K_SR40'!P28:P32) -> 123640200000000 | N4: =Graphs!$B$1*80.9*0.248*SQRT(L4)/1000000 -> 61.621436 | O4: =Graphs!$B$2*80.9*0.248*SQRT(M4)/1000000 -> 11.154499 | P4: =SQRT(N4^2+O4^2) -> 62.622873 | Q4: =K4*0.4707 -> 81.369281 | R4: =Q4/P4 -> 1.299354 | S4: =L4/M4 -> 0.54255153
A5: 0.00402491 | B5: 129670000 | D5: 0.0040034 | E5: 138309000 | G5: 0.00400083 | H5: 137333000 | J5: C3 | K5: =AVERAGE(H26:H29)/1000000 -> #DIV/0! | L5: =AVERAGE('400K_SR40'!AL28:AL32) -> #DIV/0! | M5: =AVERAGE('400K_SR40'!AC28:AC32) -> #DIV/0! | N5: =Graphs!$B$1*80.9*0.248*SQRT(L5)/1000000 -> #DIV/0! | O5: =Graphs!$B$2*80.9*0.248*SQRT(M5)/1000000 -> #DIV/0! | P5: =SQRT(N5^2+O5^2) -> #DIV/0! | Q5: =K5*0.4707 -> #DIV/0! | R5: =Q5/P5 -> #DIV/0! | S5: =L5/M5 -> #DIV/0!
A6: 0.00501723 | B6: 127665000 | D6: 0.00501629 | E6: 146577000 | G6: 0.00501192 | H6: 118814000
A7: 0.00599375 | B7: 122493000 | D7: 0.00602332 | E7: 144908000 | G7: 0.00601177 | H7: 122819000
A8: 0.00698656 | B8: 116393000 | D8: 0.00701347 | E8: 149588000 | G8: 0.00706293 | H8: 128246000
A9: 0.00792094 | B9: 123024000 | D9: 0.00799778 | E9: 152759000 | G9: 0.00802035 | H9: 133168000
A10: 0.00898586 | B10: 121166000 | D10: 0.0089879 | E10: 160442000 | G10: 0.00906845 | H10: 134897000
A11: 0.0100146 | B11: 118338000 | D11: 0.00995588 | E11: 163294000 | G11: 0.00996406 | H11: 139520000 | J11: 1-1.5%
A12: 0.0110441 | B12: 111389000 | D12: 0.0110491 | E12: 159479000 | G12: 0.0110879 | H12: 144749000 | J12: C1 | K12: =AVERAGE(B12:B16)/1000000 -> 113.2214 | L12: =AVERAGE('400K_SR40'!L12:L16) -> 15276820000000 | M12: =AVERAGE('400K_SR40'!C12:C16) -> 127231200000000 | N12: =Graphs!$B$1*80.9*0.248*SQRT(L12)/1000000 -> 29.406812 | O12: =Graphs!$B$2*80.9*0.248*SQRT(M12)/1000000 -> 11.315325 | P12: =SQRT(N12^2+O12^2) -> 31.508684 | Q12: =K12*0.4707 -> 53.293313 | R12: =Q12/P12 -> 1.6913849 | S12: =L12/M12 -> 0.12007133
A13: 0.011965 | B13: 117733000 | D13: 0.0119874 | E13: 162696000 | G13: 0.0119925 | H13: 148235000 | J13: C2 | K13: =AVERAGE(E12:E16)/1000000 -> 157.3334 | L13: =AVERAGE('400K_SR40'!Y12:Y16) -> 39520920000000 | M13: =AVERAGE('400K_SR40'!P12:P16) -> 134257600000000 | N13: =Graphs!$B$1*80.9*0.248*SQRT(L13)/1000000 -> 47.298241 | O13: =Graphs!$B$2*80.9*0.248*SQRT(M13)/1000000 -> 11.623573 | P13: =SQRT(N13^2+O13^2) -> 48.705555 | Q13: =K13*0.4707 -> 74.056831 | R13: =Q13/P13 -> 1.5205007 | S13: =L13/M13 -> 0.29436635
A14: 0.0129662 | B14: 111811000 | D14: 0.0130225 | E14: 160067000 | G14: 0.0130106 | H14: 148815000 | J14: C3 | K14: =AVERAGE(H12:H16)/1000000 -> 151.2274 | L14: =AVERAGE('400K_SR40'!AL12:AL16) -> 27470800000000 | M14: =AVERAGE('400K_SR40'!AC12:AC16) -> 130266800000000 | N14: =Graphs!$B$1*80.9*0.248*SQRT(L14)/1000000 -> 39.433663 | O14: =Graphs!$B$2*80.9*0.248*SQRT(M14)/1000000 -> 11.449515 | P14: =SQRT(N14^2+O14^2) -> 41.062211 | Q14: =K14*0.4707 -> 71.182737 | R14: =Q14/P14 -> 1.733534 | S14: =L14/M14 -> 0.21088105
A15: 0.0140695 | B15: 109270000 | D15: 0.0140142 | E15: 150277000 | G15: 0.0139884 | H15: 151277000
A16: 0.0149936 | B16: 115904000 | D16: 0.0150242 | E16: 154148000 | G16: 0.0150131 | H16: 163061000
A17: 0.016024 | B17: 121997000 | D17: 0.0159901 | E17: 162581000 | G17: 0.0160184 | H17: 156100000
A18: 0.0169842 | B18: 132577000 | D18: 0.0170032 | E18: 163499000 | G18: 0.0169489 | H18: 156567000
A19: 0.0180334 | B19: 132284000 | D19: 0.018095 | E19: 155863000 | G19: 0.0178765 | H19: 161906000
A20: 0.0189489 | B20: 131191000 | D20: 0.0189245 | E20: 183422000 | G20: 0.0189507 | H20: 142878000
A21: 0.0200162 | B21: 115842000 | D21: 0.0199117 | E21: 153696000 | G21: 0.0199658 | H21: 149268000
A22: 0.0210149 | B22: 109494000 | D22: 0.0210188 | E22: 162774000 | G22: 0.0209858 | H22: 155621000
A23: 0.0219729 | B23: 114760000 | D23: 0.0219816 | E23: 168143000
A24: 0.0229663 | B24: 112907000 | D24: 0.0229487 | E24: 186968000
A25: 0.0240019 | B25: 118564000 | D25: 0.0240161 | E25: 166789000
A26: 0.0250139 | B26: 130314000 | D26: 0.0249183 | E26: 174276000
A27: 0.0259837 | B27: 128257000 | D27: 0.0260007 | E27: 169098000
A28: 0.0269575 | B28: 131334000 | D28: 0.0271111 | E28: 167883000
A29: 0.0279955 | B29: 128617000 | D29: 0.0281873 | E29: 176573000
A30: 0.0289777 | B30: 136725000 | D30: 0.0290632 | E30: 176899000
A31: 0.0299604 | B31: 128495000 | D31: 0.0300038 | E31: 172483000

Sheet 400K_SR100_Stress
A1: Config | B1: 1 | D1: Config 2 | G1: Config3 | J1: AverageValue of Last 0.5%
A2: 0.00100305 | B2: 133135000 | D2: 0.00096455 | E2: 141072000 | G2: 0.00100922 | H2: 145095000 | K2: TotalStress | L2: RhoI | M2: Rho | N2: TauF1 | O2: TauF2 | P2: TauF | Q2: Tau | R2: Tau/TauF | S2: RhoI/Rho
A3: 0.00195105 | B3: 151436000 | D3: 0.00198499 | E3: 159861000 | G3: 0.00200223 | H3: 157343000 | J3: C1 | K3: =AVERAGE(B27:B31)/1000000 -> 134.5096 | L3: =AVERAGE('400K_SR100'!L28:L32) -> 20713220000000 | M3: =AVERAGE('400K_SR100'!C28:C32) -> 128675600000000 | N3: =Graphs!$B$1*80.9*0.248*SQRT(L3)/1000000 -> 34.241697 | O3: =Graphs!$B$2*80.9*0.248*SQRT(M3)/1000000 -> 11.379372 | P3: =SQRT(N3^2+O3^2) -> 36.083014 | Q3: =K3*0.4707 -> 63.313669 | R3: =Q3/P3 -> 1.7546668 | S3: =L3/M3 -> 0.1609724
A4: 0.00300435 | B4: 147107000 | D4: 0.00298361 | E4: 177334000 | G4: 0.00299889 | H4: 179079000 | J4: C2 | K4: =AVERAGE(E26:E31)/1000000 -> 111.4318 | L4: =AVERAGE('400K_SR100'!Y26:Y31) -> 6.1122033e+13 | M4: =AVERAGE('400K_SR100'!P21:P26) -> 158345500000000 | N4: =Graphs!$B$1*80.9*0.248*SQRT(L4)/1000000 -> 58.820724 | O4: =Graphs!$B$2*80.9*0.248*SQRT(M4)/1000000 -> 12.623305 | P4: =SQRT(N4^2+O4^2) -> 60.159998 | Q4: =K4*0.4707 -> 52.450948 | R4: =Q4/P4 -> 0.87185754 | S4: =L4/M4 -> 0.38600423
A5: 0.00406285 | B5: 152224000 | D5: 0.00405299 | E5: 189427000 | G5: 0.00401574 | H5: 173672000 | J5: C3 | K5: =AVERAGE(H27:H31)/1000000 -> #DIV/0! | L5: =AVERAGE('400K_SR100'!AL28:AL32) -> #DIV/0! | M5: =AVERAGE('400K_SR100'!AC28:AC32) -> #DIV/0! | N5: =Graphs!$B$1*80.9*0.248*SQRT(L5)/1000000 -> #DIV/0! | O5: =Graphs!$B$2*80.9*0.248*SQRT(M5)/1000000 -> #DIV/0! | P5: =SQRT(N5^2+O5^2) -> #DIV/0! | Q5: =K5*0.4707 -> #DIV/0! | R5: =Q5/P5 -> #DIV/0! | S5: =L5/M5 -> #DIV/0!
A6: 0.00491866 | B6: 150657000 | D6: 0.00499286 | E6: 191513000 | G6: 0.00498702 | H6: 179048000
A7: 0.00588823 | B7: 152861000 | D7: 0.00596458 | E7: 188496000 | G7: 0.00606104 | H7: 166694000
A8: 0.00700253 | B8: 148531000 | D8: 0.00703084 | E8: 182395000 | G8: 0.00705237 | H8: 171296000
A9: 0.00808125 | B9: 157635000 | D9: 0.00797811 | E9: 177427000 | G9: 0.00808073 | H9: 171607000
A10: 0.00900344 | B10: 157475000 | D10: 0.00899288 | E10: 184501000 | G10: 0.00908066 | H10: 163539000
A11: 0.00983994 | B11: 159633000 | D11: 0.0099876 | E11: 183676000 | G11: 0.0100073 | H11: 165636000
A12: 0.0109546 | B12: 158334000 | D12: 0.0109844 | E12: 183431000 | G12: 0.0110286 | H12: 164523000
A13: 0.0120175 | B13: 148019000 | D13: 0.0119833 | E13: 177833000 | G13: 0.0120155 | H13: 163538000
A14: 0.0130162 | B14: 138985000 | D14: 0.0130141 | E14: 175879000 | G14: 0.0129099 | H14: 170562000
A15: 0.014014 | B15: 143794000 | D15: 0.0139991 | E15: 172847000 | G15: 0.0139741 | H15: 168225000 | J15: 1-1.5%
A16: 0.015016 | B16: 150247000 | D16: 0.0149295 | E16: 193458000 | G16: 0.0150037 | H16: 152920000 | J16: C1 | K16: =AVERAGE(B12:B16)/1000000 -> 147.8758 | L16: =AVERAGE('400K_SR100'!L12:L16) -> 18017560000000 | M16: =AVERAGE('400K_SR100'!C12:C16) -> 128001000000000 | N16: =Graphs!$B$1*80.9*0.248*SQRT(L16)/1000000 -> 31.935922 | O16: =Graphs!$B$2*80.9*0.248*SQRT(M16)/1000000 -> 11.349504 | P16: =SQRT(N16^2+O16^2) -> 33.892689 | Q16: =K16*0.4707 -> 69.605139 | R16: =Q16/P16 -> 2.0536919 | S16: =L16/M16 -> 0.14076109
A17: 0.0160033 | B17: 146068000 | D17: 0.0160176 | E17: 183819000 | G17: 0.0160084 | H17: 168054000 | J17: C2 | K17: =AVERAGE(E12:E16)/1000000 -> 180.6896 | L17: =AVERAGE('400K_SR100'!Y12:Y16) -> 27495040000000 | M17: =AVERAGE('400K_SR100'!P12:P16) -> 134356400000000 | N17: =Graphs!$B$1*80.9*0.248*SQRT(L17)/1000000 -> 39.451057 | O17: =Graphs!$B$2*80.9*0.248*SQRT(M17)/1000000 -> 11.627849 | P17: =SQRT(N17^2+O17^2) -> 41.128978 | Q17: =K17*0.4707 -> 85.050595 | R17: =Q17/P17 -> 2.0678996 | S17: =L17/M17 -> 0.20464258
A18: 0.0169705 | B18: 141798000 | D18: 0.0169467 | E18: 206434000 | G18: 0.0169991 | H18: 165813000 | J18: C3 | K18: =AVERAGE(H12:H16)/1000000 -> 163.9536 | L18: =AVERAGE('400K_SR100'!AL12:AL16) -> 18663160000000 | M18: =AVERAGE('400K_SR100'!AC12:AC16) -> 130183200000000 | N18: =Graphs!$B$1*80.9*0.248*SQRT(L18)/1000000 -> 32.503046 | O18: =Graphs!$B$2*80.9*0.248*SQRT(M18)/1000000 -> 11.44584 | P18: =SQRT(N18^2+O18^2) -> 34.459472 | Q18: =K18*0.4707 -> 77.17296 | R18: =Q18/P18 -> 2.2395282 | S18: =L18/M18 -> 0.14336074
A19: 0.017963 | B19: 140701000 | D19: 0.0179997 | E19: 201263000 | G19: 0.017996 | H19: 177351000
A20: 0.0190256 | B20: 139286000 | D20: 0.0190322 | E20: 178870000 | G20: 0.0189916 | H20: 173024000
A21: 0.0199899 | B21: 144587000 | D21: 0.0199931 | E21: 178253000 | G21: 0.0199893 | H21: 177340000
A22: 0.0210189 | B22: 136511000 | D22: 0.0209919 | E22: 179369000 | J22: 3.5-4%
A23: 0.0220262 | B23: 141857000 | D23: 0.0220331 | E23: 168658000 | J23: C1 | K23: =AVERAGE(B32:B36)/1000000 -> 126.9044 | L23: =AVERAGE('400K_SR100'!L32:L36) -> 21105500000000 | M23: =AVERAGE('400K_SR100'!C32:C36) -> 126830800000000 | N23: =Graphs!$B$1*80.9*0.248*SQRT(L23)/1000000 -> 34.564422 | O23: =Graphs!$B$2*80.9*0.248*SQRT(M23)/1000000 -> 11.297506 | P23: =SQRT(N23^2+O23^2) -> 36.363895 | Q23: =K23*0.4707 -> 59.733901 | R23: =Q23/P23 -> 1.6426706 | S23: =L23/M23 -> 0.16640674
A24: 0.0230102 | B24: 141320000 | D24: 0.0229667 | E24: 159993000 | J24: C2 | K24: =AVERAGE(E32:E36)/1000000 -> 76.1168 | L24: =AVERAGE('400K_SR100'!Y32:Y36) -> 95539380000000 | M24: =AVERAGE('400K_SR100'!P32:P36) -> 223243000000000 | N24: =Graphs!$B$1*80.9*0.248*SQRT(L24)/1000000 -> 73.53984 | O24: =Graphs!$B$2*80.9*0.248*SQRT(M24)/1000000 -> 14.988533 | P24: =SQRT(N24^2+O24^2) -> 75.051743 | Q24: =K24*0.4707 -> 35.828178 | R24: =Q24/P24 -> 0.47737969 | S24: =L24/M24 -> 0.42796137
A25: 0.0239974 | B25: 145505000 | D25: 0.0239774 | E25: 155129000 | J25: C3 | K25: =AVERAGE(H32:H36)/1000000 -> #DIV/0! | L25: =AVERAGE('400K_SR100'!AL32:AL36) -> #DIV/0! | M25: =AVERAGE('400K_SR100'!AC32:AC36) -> #DIV/0! | N25: =Graphs!$B$1*80.9*0.248*SQRT(L25)/1000000 -> #DIV/0! | O25: =Graphs!$B$2*80.9*0.248*SQRT(M25)/1000000 -> #DIV/0! | P25: =SQRT(N25^2+O25^2) -> #DIV/0! | Q25: =K25*0.4707 -> #DIV/0! | R25: =Q25/P25 -> #DIV/0! | S25: =L25/M25 -> #DIV/0!
A26: 0.0248874 | B26: 143613000 | D26: 0.0250117 | E26: 138106000
A27: 0.0259781 | B27: 139523000 | D27: 0.0259907 | E27: 125283000
A28: 0.0270155 | B28: 131931000 | D28: 0.0269809 | E28: 115659000
A29: 0.0279952 | B29: 133028000 | D29: 0.0281636 | E29: 103274000
A30: 0.0290926 | B30: 135754000 | D30: 0.0289706 | E30: 96426500
A31: 0.0299866 | B31: 132312000 | D31: 0.0299872 | E31: 89842300
A32: 0.0310285 | B32: 132349000 | D32: 0.0310075 | E32: 84823400
A33: 0.0318894 | B33: 132765000 | D33: 0.0320211 | E33: 80287700
A34: 0.0329781 | B34: 126901000 | D34: 0.0330056 | E34: 75223100
A35: 0.0340371 | B35: 122021000 | D35: 0.0339336 | E35: 72612900
A36: 0.0349071 | B36: 120486000 | D36: 0.0349799 | E36: 67636900
A37: 0.0359954 | B37: 123107000 | D37: 0.0359858 | E37: 64497600
... A47: 0.0460726 | B47: 87985000 | D47: 0.0458763 | E47: 46581200
A48: 0.0469727 | B48: 82759600
A49: 0.0479596 | B49: 81393400
...

Sheet 400K_SR100
A1: Config1 | N1: Config2 | AA1: Config3 | AN1: Pstrain | AO1: Total | AP1: Totalmin | AQ1: Totalmax | AR1: Junction | AS1: Junctionmin | AT1: Junctionmax
A2: 0.00100305 | B2: 0.00163748 | C2: 127629000000000 | D2: 8499870000 | E2: 0 | F2: 0 | G2: 2 | H2: 30492100000000 | I2: 30102000000000 | J2: 29643300000000 | K2: 29842100000000 | L2: 7549640000000 | N2: 0.00096455 | O2: 0.0016368 | P2: 127824000000000 | Q2: 22194400000 | R2: 0 | S2: 0 | T2: 2 | U2: 29941100000000 | V2: 29694800000000 | W2: 29994600000000 | X2: 29531300000000 | Y2: 8662350000000 | AA2: 0.00100922 | AB2: 0.00170064 | AC2: 128466000000000 | AD2: 8021510000 | AE2: 0 | AF2: 0 | AG2: 2 | AH2: 30153800000000 | AI2: 30085700000000 | AJ2: 30148700000000 | AK2: 29875900000000 | AL2: 8201610000000 | AN2: =A2 -> 0.00100305 | AO2: =(C2+P2+AC2)/3 -> 127973000000000 | AP2: =MIN(C2,P2,AC2) -> 127629000000000 | AQ2: =MAX(C2,P2,AC2) -> 128466000000000 | AR2: =(L2+Y2+AL2)/3 -> 8.1378667e+12 | AS2: =MIN(L2,Y2,AL2) -> 7549640000000 | AT2: =MAX(L2,Y2,AL2) -> 8662350000000
A3: 0.00195105 | B3: 0.00267269 | C3: 128639000000000 | D3: 44111500000 | E3: 0 | F3: 0 | G3: 2 | H3: 29661300000000 | I3: 29281200000000 | J3: 29318300000000 | K3: 28976300000000 | L3: 11402100000000 | N3: 0.00198499 | O3: 0.00274677 | P3: 129130000000000 | Q3: 17786500000 | R3: 0 | S3: 0 | T3: 2 | U3: 27945600000000 | V3: 28637500000000 | W3: 27757000000000 | X3: 28040000000000 | Y3: 16749800000000 | AA3: 0.00200223 | AB3: 0.00275202 | AC3: 128441000000000 | AD3: 23279500000 | AE3: 0 | AF3: 0 | AG3: 2 | AH3: 28142900000000 | AI3: 28072200000000 | AJ3: 28585900000000 | AK3: 28289600000000 | AL3: 15350800000000 | AN3: =A3 -> 0.00195105 | AO3: =(C3+P3+AC3)/3 -> 128736666666667 | AP3: =MIN(C3,P3,AC3) -> 128441000000000 | AQ3: =MAX(C3,P3,AC3) -> 129130000000000 | AR3: =(L3+Y3+AL3)/3 -> 14500900000000 | AS3: =MIN(L3,Y3,AL3) -> 11402100000000 | AT3: =MAX(L3,Y3,AL3) -> 16749800000000
A4: 0.00300435 | B4: 0.00370536 | C4: 128629000000000 | D4: 7714150000 | E4: 0 | F4: 0 | G4: 2 | H4: 29047700000000 | I4: 28483900000000 | J4: 29001800000000 | K4: 28465900000000 | L4: 13627600000000 | N4: 0.00298361 | O4: 0.00382865 | P4: 129674000000000 | Q4: 12891600000 | R4: 0 | S4: 0 | T4: 2 | U4: 26564200000000 | V4: 27431800000000 | W4: 27337400000000 | X4: 26905400000000 | Y4: 21418300000000 | AA4: 0.00299889 | AB4: 0.00385225 | AC4: 129393000000000 | AD4: 63186600000 | AE4: 0 | AF4: 0 | AG4: 2 | AH4: 27686900000000 | AI4: 27293800000000 | AJ4: 27483300000000 | AK4: 27910400000000 | AL4: 18986000000000 | AN4: =A4 -> 0.00300435 | AO4: =(C4+P4+AC4)/3 -> 129232000000000 | AP4: =MIN(C4,P4,AC4) -> 128629000000000 | AQ4: =MAX(C4,P4,AC4) -> 129674000000000 | AR4: =(L4+Y4+AL4)/3 -> 1.8010633e+13 | AS4: =MIN(L4,Y4,AL4) -> 13627600000000 | AT4: =MAX(L4,Y4,AL4) -> 21418300000000
A5: 0.00406285 | B5: 0.00478823 | C5: 128166000000000 | D5: 8892800000 | E5: 0 | F5: 0 | G5: 2 | H5: 28634400000000 | I5: 27704600000000 | J5: 28504900000000 | K5: 27771900000000 | L5: 15549400000000 | N5: 0.00405299 | O5: 0.00495565 | P5: 129396000000000 | Q5: 6767290000 | R5: 0 | S5: 0 | T5: 2 | U5: 25569800000000 | V5: 25660400000000 | W5: 26315900000000 | X5: 26651200000000 | Y5: 25195200000000 | AA5: 0.00401574 | AB5: 0.00484333 | AC5: 129350000000000 | AD5: 28444600000 | AE5: 0 | AF5: 0 | AG5: 2 | AH5: 27113400000000 | AI5: 26680100000000 | AJ5: 26700800000000 | AK5: 28131300000000 | AL5: 20724900000000 | AN5: =A5 -> 0.00406285 | AO5: =(C5+P5+AC5)/3 -> 128970666666667 | AP5: =MIN(C5,P5,AC5) -> 128166000000000 | AQ5: =MAX(C5,P5,AC5) -> 129396000000000 | AR5: =(L5+Y5+AL5)/3 -> 2.0489833e+13 | AS5: =MIN(L5,Y5,AL5) -> 15549400000000 | AT5: =MAX(L5,Y5,AL5) -> 25195200000000
A6: 0.00491866 | B6: 0.00563657 | C6: 128204000000000 | D6: 32050000000 | E6: 0 | F6: 0 | G6: 2 | H6: 28456700000000 | I6: 27165200000000 | J6: 28315400000000 | K6: 27082100000000 | L6: 17184900000000 | N6: 0.00499286 | O6: 0.00590546 | P6: 131741000000000 | Q6: 13853100000 | R6: 0 | S6: 0 | T6: 2 | U6: 26305100000000 | V6: 25824200000000 | W6: 27228700000000 | X6: 26680000000000 | Y6: 25701700000000 | AA6: 0.00498702 | AB6: 0.00584023 | AC6: 129659000000000 | AD6: 9406510000 | AE6: 0 | AF6: 0 | AG6: 2 | AH6: 27893100000000 | AI6: 26846300000000 | AJ6: 26763100000000 | AK6: 27875100000000 | AL6: 20278600000000 | AN6: =A6 -> 0.00491866 | AO6: =(C6+P6+AC6)/3 -> 129868000000000 | AP6: =MIN(C6,P6,AC6) -> 128204000000000 | AQ6: =MAX(C6,P6,AC6) -> 131741000000000 | AR6: =(L6+Y6+AL6)/3 -> 2.1055067e+13 | AS6: =MIN(L6,Y6,AL6) -> 17184900000000 | AT6: =MAX(L6,Y6,AL6) -> 25701700000000
A7: 0.00588823 | B7: 0.00661664 | C7: 128443000000000 | D7: 13647700000 | E7: 0 | F7: 0 | G7: 2 | H7: 28131300000000 | I7: 27272400000000 | J7: 27409500000000 | K7: 26986200000000 | L7: 18643400000000 | N7: 0.00596458 | O7: 0.00686281 | P7: 132850000000000 | Q7: 8569800000 | R7: 0 | S7: 0 | T7: 2 | U7: 26566000000000 | V7: 25774000000000 | W7: 26656300000000 | X7: 27550600000000 | Y7: 26302500000000 | AA7: 0.00606104 | AB7: 0.00685537 | AC7: 130213000000000 | AD7: 14406400000 | AE7: 0 | AF7: 0 | AG7: 2 | AH7: 27883100000000 | AI7: 27641000000000 | AJ7: 26810000000000 | AK7: 27761100000000 | AL7: 20115700000000 | AN7: =A7 -> 0.00588823 | AO7: =(C7+P7+AC7)/3 -> 130502000000000 | AP7: =MIN(C7,P7,AC7) -> 128443000000000 | AQ7: =MAX(C7,P7,AC7) -> 132850000000000 | AR7: =(L7+Y7+AL7)/3 -> 21687200000000 | AS7: =MIN(L7,Y7,AL7) -> 18643400000000 | AT7: =MAX(L7,Y7,AL7) -> 26302500000000
A8: 0.00700253 | B8: 0.00771032 | C8: 128655000000000 | D8: 37009300000 | E8: 0 | F8: 0 | G8: 2 | H8: 28075100000000 | I8: 26810900000000 | J8: 28166900000000 | K8: 27034800000000 | L8: 18567100000000 | N8: 0.00703084 | O8: 0.00789999 | P8: 131671000000000 | Q8: 199981000000 | R8: 0 | S8: 0 | T8: 2 | U8: 26467300000000 | V8: 24994900000000 | W8: 26125000000000 | X8: 26526300000000 | Y8: 27520500000000 | AA8: 0.00705237 | AB8: 0.00786864 | AC8: 130737000000000 | AD8: 9163660000 | AE8: 0 | AF8: 0 | AG8: 2 | AH8: 28016400000000 | AI8: 27814700000000 | AJ8: 27365200000000 | AK8: 27728100000000 | AL8: 19812200000000 | AN8: =A8 -> 0.00700253 | AO8: =(C8+P8+AC8)/3 -> 130354333333333 | AP8: =MIN(C8,P8,AC8) -> 128655000000000 | AQ8: =MAX(C8,P8,AC8) -> 131671000000000 | AR8: =(L8+Y8+AL8)/3 -> 21966600000000 | AS8: =MIN(L8,Y8,AL8) -> 18567100000000 | AT8: =MAX(L8,Y8,AL8) -> 27520500000000
