Workbook

Sheet Graphs
A1: Factor | B1: 0.5
A2: Factor | B2: 0.05

Sheet 400K_SR40_Stress
A1: Config 1 | D1: Config 2 | G1: Config3 | K1: AverageValue of Last 0.5%
A2: 0.000979836 | B2: 118854000 | D2: 0.000947025 | E2: 105822000 | G2: 0.00101539 | H2: 102117000 | L2: TotalStress | M2: RhoI | N2: Rho | O2: TauF1 | P2: TauF2 | Q2: TauF | R2: Tau | S2: Tau/TauF | T2: RhoI/Rho
A3: 0.00198107 | B3: 130294000 | D3: 0.00197476 | E3: 120664000 | G3: 0.00192514 | H3: 112577000 | K3: Config1 | L3: 132 | M3: 12400000000000 | N3: 44000000000000 | O3: =Graphs!$B$1*80.9*0.248*SQRT(M3)/1000000 -> 35.324909 | P3: =Graphs!$B$2*80.9*0.248*SQRT(N3)/1000000 -> 6.6542106 | Q3: =SQRT(O3^2+P3^2) -> 35.946178 | R3: =L3*0.4395 -> 58.014 | S3: =R3/Q3 -> 1.6139129 | T3: =M3/N3 -> 0.28181818
A4: 0.00300081 | B4: 129021000 | D4: 0.00303845 | E4: 129952000 | G4: 0.00297721 | H4: 122103000 | K4: Config2 | L4: 123 | M4: 12800000000000 | N4: 47800000000000 | O4: =Graphs!$B$1*80.9*0.248*SQRT(M4)/1000000 -> 35.890143 | P4: =Graphs!$B$2*80.9*0.248*SQRT(N4)/1000000 -> 6.9356019 | Q4: =SQRT(O4^2+P4^2) -> 36.554137 | R4: =L4*0.4395 -> 54.0585 | S4: =R4/Q4 -> 1.4788613 | T4: =M4/N4 -> 0.26778243
A5: 0.00399291 | B5: 136490000 | D5: 0.00399765 | E5: 140978000 | G5: 0.00400464 | H5: 125170000 | K5: Config3 | L5: =AVERAGE(H19:H23)/1000000 -> 137.4774 | M5: =AVERAGE('400K_SR40'!AL19:AL23) -> 12413940000000 | N5: =AVERAGE('400K_SR40'!AC19:AC23) -> 46861120000000 | O5: =Graphs!$B$1*80.9*0.248*SQRT(M5)/1000000 -> 35.344759 | P5: =Graphs!$B$2*80.9*0.248*SQRT(N5)/1000000 -> 6.8671501 | Q5: =SQRT(O5^2+P5^2) -> 36.005691 | R5: =L5*0.4395 -> 60.421317 | S5: =R5/Q5 -> 1.6781047 | T5: =M5/N5 -> 0.26490916
A6: 0.00501552 | B6: 134537000 | D6: 0.00502331 | E6: 131905000 | G6: 0.00500943 | H6: 126039000
A7: 0.00600413 | B7: 140146000 | D7: 0.0059798 | E7: 134043000 | G7: 0.00596348 | H7: 121281000
A8: 0.00699409 | B8: 128313000 | D8: 0.00700893 | E8: 133374000 | G8: 0.00695336 | H8: 123483000
A9: 0.00797905 | B9: 136642000 | D9: 0.00801375 | E9: 132694000 | G9: 0.00800524 | H9: 129482000 | K9: Config1 | L9: =AVERAGE(B12:B16)/1000000 -> 134.494 | M9: =AVERAGE('400K_SR40'!L12:L16) -> 13516500000000 | N9: =AVERAGE('400K_SR40'!C12:C16) -> 44671200000000 | O9: =Graphs!$B$1*80.9*0.248*SQRT(M9)/1000000 -> 36.88097 | P9: =Graphs!$B$2*80.9*0.248*SQRT(N9)/1000000 -> 6.704772 | Q9: =SQRT(O9^2+P9^2) -> 37.485462 | R9: =L9*0.4395 -> 59.110113 | S9: =R9/Q9 -> 1.576881 | T9: =M9/N9 -> 0.3025775
A10: 0.00894196 | B10: 139578000 | D10: 0.00904663 | E10: 129155000 | G10: 0.00903004 | H10: 138549000 | K10: Config2 | L10: =AVERAGE(E12:E16)/1000000 -> 135.0286 | M10: =AVERAGE('400K_SR40'!Y12:Y16) -> 12006080000000 | N10: =AVERAGE('400K_SR40'!P12:P16) -> 44355600000000 | O10: =Graphs!$B$1*80.9*0.248*SQRT(M10)/1000000 -> 34.759284 | P10: =Graphs!$B$2*80.9*0.248*SQRT(N10)/1000000 -> 6.6810456 | Q10: =SQRT(O10^2+P10^2) -> 35.395539 | R10: =L10*0.4395 -> 59.34507 | S10: =R10/Q10 -> 1.6766257 | T10: =M10/N10 -> 0.27067789
A11: 0.00998976 | B11: 128502000 | D11: 0.0100531 | E11: 125031000 | G11: 0.0100922 | H11: 135145000 | K11: Config3 | L11: =AVERAGE(H12:H16)/1000000 -> 138.2152 | M11: =AVERAGE('400K_SR40'!L12:AL16) -> 7.778581e+12 | N11: =AVERAGE('400K_SR40'!AC12:AC16) -> 46119140000000 | O11: =Graphs!$B$1*80.9*0.248*SQRT(M11)/1000000 -> 27.97824 | P11: =Graphs!$B$2*80.9*0.248*SQRT(N11)/1000000 -> 6.8125673 | Q11: =SQRT(O11^2+P11^2) -> 28.795712 | R11: =L11*0.4395 -> 60.74558 | S11: =R11/Q11 -> 2.1095357 | T11: =M11/N11 -> 0.16866275
A12: 0.010991 | B12: 116690000 | D12: 0.0109228 | E12: 132171000 | G12: 0.0109426 | H12: 139263000
A13: 0.0118884 | B13: 138173000 | D13: 0.0119744 | E13: 144218000 | G13: 0.0119424 | H13: 147717000
A14: 0.0129353 | B14: 141362000 | D14: 0.0130362 | E14: 135087000 | G14: 0.0130057 | H14: 131315000
A15: 0.0140125 | B15: 139084000 | D15: 0.0138916 | E15: 133739000 | G15: 0.0140601 | H15: 130233000
A16: 0.0149474 | B16: 137161000 | D16: 0.0149472 | E16: 129928000 | G16: 0.0149769 | H16: 142548000
A17: 0.0159852 | B17: 140975000 | D17: 0.0159618 | E17: 127975000 | G17: 0.0160264 | H17: 135267000
A18: 0.0170433 | B18: 133067000 | D18: 0.017007 | E18: 129928000 | G18: 0.0170738 | H18: 131144000
A19: 0.0180584 | B19: 139208000 | D19: 0.0179738 | E19: 136696000 | G19: 0.0179932 | H19: 141961000
A20: 0.0190168 | B20: 144093000 | D20: 0.0189832 | E20: 139332000 | G20: 0.0190361 | H20: 140016000
A21: 0.0199579 | B21: 138513000 | D21: 0.0199541 | E21: 138701000 | G21: 0.0200054 | H21: 135222000
A22: 0.0209887 | B22: 125434000 | D22: 0.0210385 | E22: 127387000 | G22: 0.0210203 | H22: 129881000
A23: 0.021935 | B23: 131318000 | D23: 0.0219496 | E23: 132422000 | G23: 0.0219689 | H23: 140307000
A24: 0.0230163 | B24: 126917000 | D24: 0.0229712 | E24: 136867000
A25: 0.0239765 | B25: 139939000 | D25: 0.0239014 | E25: 133515000
A26: 0.025045 | B26: 125182000 | D26: 0.0249922 | E26: 127254000
A27: 0.0260204 | B27: 129929000 | D27: 0.0260013 | E27: 121010000
A28: 0.0269831 | B28: 132003000 | D28: 0.0270296 | E28: 117707000
A29: 0.0280066 | B29: 140617000 | D29: 0.0279829 | E29: 113330000
A30: 0.0290357 | B30: 129052000
A31: 0.0299908 | B31: 129672000

Sheet 400K_SR40
A1: Config1 | N1: Config2 | AA1: Config 3 | AN1: Pstrain | AO1: Total | AP1: Totalmin | AQ1: Totalmax | AR1: Junction | AS1: Junctionmin | AT1: Junctionmax
A2: 0.000979836 | B2: 0.00154619 | C2: 42132200000000 | D2: 482669000 | E2: 0 | F2: 0 | G2: 2 | H2: 9482760000000 | I2: 9394730000000 | J2: 9411260000000 | K2: 9419010000000 | L2: 4424440000000 | N2: 0.000947025 | O2: 0.00145128 | P2: 41875300000000 | Q2: 441457000 | R2: 0 | S2: 0 | T2: 2 | U2: 9838250000000 | V2: 9830220000000 | W2: 9680460000000 | X2: 9813520000000 | Y2: 2712820000000 | AA2: 0.00101539 | AB2: 0.001502 | AC2: 41962300000000 | AD2: 688832000 | AE2: 0 | AF2: 0 | AG2: 2 | AH2: 9781040000000 | AI2: 9677630000000 | AJ2: 9864480000000 | AK2: 9805440000000 | AL2: 2833650000000 | AN2: =A2 -> 0.000979836 | AO2: =(C2+P2+AC2)/3 -> 4.1989933e+13 | AP2: =MIN(C2,P2,AC2) -> 41875300000000 | AQ2: =MAX(C2,P2,AC2) -> 42132200000000 | AR2: =(L2+Y2+AL2)/3 -> 3.3236367e+12 | AS2: =MIN(L2,Y2,AK2) -> 2712820000000 | AT2: =MAX(L2,Y2,AL2) -> 4424440000000
A3: 0.00198107 | B3: 0.00260194 | C3: 42970700000000 | D3: 537310000 | E3: 0 | F3: 0 | G3: 2 | H3: 9136360000000 | I3: 9311620000000 | J3: 9380620000000 | K3: 9455510000000 | L3: 5686600000000 | N3: 0.00197476 | O3: 0.00254974 | P3: 42206200000000 | Q3: 598696000 | R3: 0 | S3: 0 | T3: 2 | U3: 9294820000000 | V3: 9421240000000 | W3: 9408050000000 | X3: 9232520000000 | Y3: 4849540000000 | AA3: 0.00192514 | AB3: 0.00246158 | AC3: 42426300000000 | AD3: 775545000 | AE3: 0 | AF3: 0 | AG3: 2 | AH3: 9196550000000 | AI3: 9325460000000 | AJ3: 9417160000000 | AK3: 9506430000000 | AL3: 4980560000000 | AN3: =A3 -> 0.00198107 | AO3: =(C3+P3+AC3)/3 -> 42534400000000 | AP3: =MIN(C3,P3,AC3) -> 42206200000000 | AQ3: =MAX(C3,P3,AC3) -> 42970700000000 | AR3: =(L3+Y3+AL3)/3 -> 5.1722333e+12 | AS3: =MIN(L3,Y3,AK3) -> 4849540000000 | AT3: =MAX(L3,Y3,AL3) -> 5686600000000
A4: 0.00300081 | B4: 0.00361562 | C4: 43035700000000 | D4: 583878000 | E4: 0 | F4: 0 | G4: 2 | H4: 9005460000000 | I4: 9105730000000 | J4: 8772300000000 | K4: 8984050000000 | L4: 7168030000000 | N4: 0.00303845 | O4: 0.00365769 | P4: 42576600000000 | Q4: 545023000 | R4: 0 | S4: 0 | T4: 2 | U4: 8899870000000 | V4: 8806510000000 | W4: 8782640000000 | X4: 9034570000000 | Y4: 7052680000000 | AA4: 0.00297721 | AB4: 0.00355904 | AC4: 43011500000000 | AD4: 496670000 | AE4: 0 | AF4: 0 | AG4: 2 | AH4: 9176970000000 | AI4: 9393160000000 | AJ4: 9445280000000 | AK4: 9142690000000 | AL4: 5853180000000 | AN4: =A4 -> 0.00300081 | AO4: =(C4+P4+AC4)/3 -> 42874600000000 | AP4: =MIN(C4,P4,AC4) -> 42576600000000 | AQ4: =MAX(C4,P4,AC4) -> 43035700000000 | AR4: =(L4+Y4+AL4)/3 -> 6.6912967e+12 | AS4: =MIN(L4,Y4,AK4) -> 7052680000000 | AT4: =MAX(L4,Y4,AL4) -> 7168030000000
A5: 0.00399291 | B5: 0.00464331 | C5: 43206800000000 | D5: 1429090000 | E5: 0 | F5: 0 | G5: 2 | H5: 8750780000000 | I5: 9183070000000 | J5: 9208850000000 | K5: 8672620000000 | L5: 7391380000000 | N5: 0.00399765 | O5: 0.00466943 | P5: 43332800000000 | Q5: 1114720000 | R5: 0 | S5: 0 | T5: 2 | U5: 8847290000000 | V5: 8701500000000 | W5: 8621210000000 | X5: 9168080000000 | Y5: 7994410000000 | AA5: 0.00400464 | AB5: 0.00460109 | AC5: 43229400000000 | AD5: 490745000 | AE5: 0 | AF5: 0 | AG5: 2 | AH5: 8957670000000 | AI5: 9193220000000 | AJ5: 9281450000000 | AK5: 9105240000000 | AL5: 6691790000000 | AN5: =A5 -> 0.00399291 | AO5: =(C5+P5+AC5)/3 -> 4.3256333e+13 | AP5: =MIN(C5,P5,AC5) -> 43206800000000 | AQ5: =MAX(C5,P5,AC5) -> 43332800000000 | AR5: =(L5+Y5+AL5)/3 -> 7.3591933e+12 | AS5: =MIN(L5,Y5,AK5) -> 7391380000000 | AT5: =MAX(L5,Y5,AL5) -> 7994410000000
A6: 0.00501552 | B6: 0.00565661 | C6: 43764500000000 | D6: 1020400000 | E6: 0 | F6: 0 | G6: 2 | H6: 9140680000000 | I6: 8744720000000 | J6: 8546250000000 | K6: 8723030000000 | L6: 8609470000000 | N6: 0.00502331 | O6: 0.00565186 | P6: 43372000000000 | Q6: 897811000 | R6: 0 | S6: 0 | T6: 2 | U6: 8793920000000 | V6: 8927510000000 | W6: 8491930000000 | X6: 8848350000000 | Y6: 8307490000000 | AA6: 0.00500943 | AB6: 0.00561003 | AC6: 43248900000000 | AD6: 1100130000 | AE6: 0 | AF6: 0 | AG6: 2 | AH6: 8582430000000 | AI6: 9402560000000 | AJ6: 9414350000000 | AK6: 8587530000000 | AL6: 7261410000000 | AN6: =A6 -> 0.00501552 | AO6: =(C6+P6+AC6)/3 -> 43461800000000 | AP6: =MIN(C6,P6,AC6) -> 43248900000000 | AQ6: =MAX(C6,P6,AC6) -> 43764500000000 | AR6: =(L6+Y6+AL6)/3 -> 8.0594567e+12 | AS6: =MIN(L6,Y6,AK6) -> 8307490000000 | AT6: =MAX(L6,Y6,AL6) -> 8609470000000
A7: 0.00600413 | B7: 0.00667195 | C7: 44621000000000 | D7: 1264490000 | E7: 0 | F7: 0 | G7: 2 | H7: 9042230000000 | I7: 9418260000000 | J7: 8102360000000 | K7: 8639960000000 | L7: 9417820000000 | N7: 0.0059798 | O7: 0.00661853 | P7: 43023800000000 | Q7: 791695000 | R7: 0 | S7: 0 | T7: 2 | U7: 8135420000000 | V7: 8870460000000 | W7: 8328550000000 | X7: 8982530000000 | Y7: 8706210000000 | AA7: 0.00596348 | AB7: 0.0065414 | AC7: 43641600000000 | AD7: 1075440000 | AE7: 0 | AF7: 0 | AG7: 2 | AH7: 8243770000000 | AI7: 9728710000000 | AJ7: 9825060000000 | AK7: 8536250000000 | AL7: 7306170000000 | AN7: =A7 -> 0.00600413 | AO7: =(C7+P7+AC7)/3 -> 4.3762133e+13 | AP7: =MIN(C7,P7,AC7) -> 43023800000000 | AQ7: =MAX(C7,P7,AC7) -> 44621000000000 | AR7: =(L7+Y7+AL7)/3 -> 8.4767333e+12 | AS7: =MIN(L7,Y7,AK7) -> 8536250000000 | AT7: =MAX(L7,Y7,AL7) -> 9417820000000
A8: 0.00699409 | B8: 0.00760552 | C8: 46082700000000 | D8: 1202190000 | E8: 0 | F8: 0 | G8: 2 | H8: 9736010000000 | I8: 9848630000000 | J8: 8431230000000 | K8: 8288730000000 | L8: 9777990000000 | N8: 0.00700893 | O8: 0.00764448 | P8: 43363600000000 | Q8: 964050000 | R8: 0 | S8: 0 | T8: 2 | U8: 8224700000000 | V8: 9042770000000 | W8: 8457360000000 | X8: 9419130000000 | Y8: 8218380000000 | AA8: 0.00695336 | AB8: 0.00754177 | AC8: 43725000000000 | AD8: 922034000 | AE8: 0 | AF8: 0 | AG8: 2 | AH8: 8290260000000 | AI8: 9648920000000 | AJ8: 9797730000000 | AK8: 8348270000000 | AL8: 7639190000000 | AN8: =A8 -> 0.00699409 | AO8: =(C8+P8+AC8)/3 -> 4.4390433e+13 | AP8: =MIN(C8,P8,AC8) -> 43363600000000 | AQ8: =MAX(C8,P8,AC8) -> 46082700000000 | AR8: =(L8+Y8+AL8)/3 -> 8.5451867e+12 | AS8: =MIN(L8,Y8,AK8) -> 8218380000000 | AT8: =MAX(L8,Y8,AL8) -> 9777990000000
A9: 0.00797905 | B9: 0.00863018 | C9: 45312300000000 | D9: 1373680000 | E9: 0 | F9: 0 | G9: 2 | H9: 9405250000000 | I9: 9001050000000 | J9: 7778790000000 | K9: 7647060000000 | L9: 11478300000000 | N9: 0.00801375 | O9: 0.00864607 | P9: 43532600000000 | Q9: 874927000 | R9: 0 | S9: 0 | T9: 2 | U9: 7899240000000 | V9: 8961920000000 | W9: 8172900000000 | X9: 9454740000000 | Y9: 9042510000000 | AA9: 0.00800524 | AB9: 0.00862223 | AC9: 43527400000000 | AD9: 1693300000 | AE9: 0 | AF9: 0 | AG9: 2 | AH9: 7901430000000 | AI9: 9257480000000 | AJ9: 9101840000000 | AK9: 8061460000000 | AL9: 9204730000000 | AN9: =A9 -> 0.00797905 | AO9: =(C9+P9+AC9)/3 -> 44124100000000 | AP9: =MIN(C9,P9,AC9) -> 43527400000000 | AQ9: =MAX(C9,P9,AC9) -> 45312300000000 | AR9: =(L9+Y9+AL9)/3 -> 9.9085133e+12 | AS9: =MIN(L9,Y9,AK9) -> 8061460000000 | AT9: =MAX(L9,Y9,AL9) -> 11478300000000
A10: 0.00894196 | B10: 0.00960707 | C10: 45515900000000 | D10: 1444420000 | E10: 0 | F10: 0 | G10: 2 | H10: 9186950000000 | I10: 8678640000000 | J10: 8007440000000 | K10: 7945290000000 | L10: 11696700000000 | N10: 0.00904663 | O10: 0.00966208 | P10: 43741100000000 | Q10: 856627000 | R10: 0 | S10: 0 | T10: 2 | U10: 7646040000000 | V10: 8544210000000 | W10: 8486490000000 | X10: 9277590000000 | Y10: 9785500000000 | AA10: 0.00903004 | AB10: 0.00969025 | AC10: 44070800000000 | AD10: 1589760000 | AE10: 0 | AF10: 0 | AG10: 2 | AH10: 7489440000000 | AI10: 9248370000000 | AJ10: 9023170000000 | AK10: 7759800000000 | AL10: 10548600000000 | AN10: =A10 -> 0.00894196 | AO10: =(C10+P10+AC10)/3 -> 44442600000000 | AP10: =MIN(C10,P10,AC10) -> 43741100000000 | AQ10: =MAX(C10,P10,AC10) -> 45515900000000 | AR10: =(L10+Y10+AL10)/3 -> 1.0676933e+13 | AS10: =MIN(L10,Y10,AK10) -> 7759800000000 | AT10: =MAX(L10,Y10,AL10) -> 11696700000000
A11: 0.00998976 | B11: 0.0106021 | C11: 46393900000000 | D11: 1673970000 | E11: 0 | F11: 0 | G11: 2 | H11: 9719860000000 | I11: 8902860000000 | J11: 8036600000000 | K11: 8314230000000 | L11: 11417900000000 | N11: 0.0100531 | O11: 0.0106489 | P11: 45107600000000 | Q11: 784828000 | R11: 0 | S11: 0 | T11: 2 | U11: 7501860000000 | V11: 9197030000000 | W11: 7555910000000 | X11: 9750560000000 | Y11: 11099900000000 | AA11: 0.0100922 | AB11: 0.0107362 | AC11: 45240900000000 | AD11: 1100910000 | AE11: 0 | AF11: 0 | AG11: 2 | AH11: 7348580000000 | AI11: 9619040000000 | AJ11: 9300850000000 | AK11: 7683160000000 | AL11: 11284100000000 | AN11: =A11 -> 0.00998976 | AO11: =(C11+P11+AC11)/3 -> 45580800000000 | AP11: =MIN(C11,P11,AC11) -> 45107600000000 | AQ11: =MAX(C11,P11,AC11) -> 46393900000000 | AR11: =(L11+Y11+AL11)/3 -> 11267300000000 | AS11: =MIN(L11,Y11,AK11) -> 7683160000000 | AT11: =MAX(L11,Y11,AL11) -> 11417900000000
A12: 0.010991 | B12: 0.0115471 | C12: 45838200000000 | D12: 1112280000 | E12: 0 | F12: 0 | G12: 2 | H12: 9439470000000 | I12: 8156840000000 | J12: 7998710000000 | K12: 8625060000000 | L12: 11617800000000 | N12: 0.0109228 | O12: 0.0115526 | P12: 44108500000000 | Q12: 1951770000 | R12: 0 | S12: 0 | T12: 2 | U12: 6559770000000 | V12: 8638100000000 | W12: 7326670000000 | X12: 9279280000000 | Y12: 12303700000000 | AA12: 0.0109426 | AB12: 0.0116062 | AC12: 45458600000000 | AD12: 2594470000 | AE12: 0 | AF12: 0 | AG12: 2 | AH12: 7160660000000 | AI12: 9365200000000 | AJ12: 8682940000000 | AK12: 7648420000000 | AL12: 12599800000000 | AN12: =A12 -> 0.010991 | AO12: =(C12+P12+AC12)/3 -> 45135100000000 | AP12: =MIN(C12,P12,AC12) -> 44108500000000 | AQ12: =MAX(C12,P12,AC12) -> 45838200000000 | AR12: =(L12+Y12+AL12)/3 -> 1.2173767e+13 | AS12: =MIN(L12,Y12,AK12) -> 7648420000000 | AT12: =MAX(L12,Y12,AL12) -> 12599800000000
A13: 0.0118884 | B13: 0.0125468 | C13: 44385300000000 | D13: 1615960000 | E13: 0 | F13: 0 | G13: 2 | H13: 8557110000000 | I13: 7442850000000 | J13: 8001320000000 | K13: 7447680000000 | L13: 12935800000000 | N13: 0.0119744 | O13: 0.0126616 | P13: 44209200000000 | Q13: 1931340000 | R13: 0 | S13: 0 | T13: 2 | U13: 6529010000000 | V13: 7782650000000 | W13: 7510790000000 | X13: 9136500000000 | Y13: 13249100000000 | AA13: 0.0119424 | AB13: 0.0126463 | AC13: 46293700000000 | AD13: 1408540000 | AE13: 0 | AF13: 0 | AG13: 2 | AH13: 7703250000000 | AI13: 8936360000000 | AJ13: 8186680000000 | AK13: 9094850000000 | AL13: 12368900000000 | AN13: =A13 -> 0.0118884 | AO13: =(C13+P13+AC13)/3 -> 4.4962733e+13 | AP13: =MIN(C13,P13,AC13) -> 44209200000000 | AQ13: =MAX(C13,P13,AC13) -> 46293700000000 | AR13: =(L13+Y13+AL13)/3 -> 1.2851267e+13 | AS13: =MIN(L13,Y13,AK13) -> 9094850000000 | AT13: =MAX(L13,Y13,AL13) -> 13249100000000
... A23: 0.021935 | B23: 0.0225608 | C23: 43485500000000 | D23: 1190770000 | E23: 0 | F23: 0 | G23: 2 | H23: 7051760000000 | I23: 8077940000000 | J23: 7471430000000 | K23: 6939150000000 | L23: 13944700000000 | N23: 0.0219496 | O23: 0.0225807 | P23: 45076300000000 | Q23: 951517000 | R23: 0 | S23: 0 | T23: 2 | U23: 7318160000000 | V23: 7753400000000 | W23: 8906420000000 | X23: 7805190000000 | Y23: 13291500000000 | AA23: 0.0219689 | AB23: 0.0226375 | AC23: 47836400000000 | AD23: 703926000 | AE23: 0 | AF23: 0 | AG23: 2 | AH23: 7827050000000 | AI23: 8850420000000 | AJ23: 8757890000000 | AK23: 10175300000000 | AL23: 12225600000000 | AN23: =A23 -> 0.021935 | AO23: =(C23+P23+AC23)/3 -> 4.5466067e+13 | AP23: =MIN(C23,P23,AC23) -> 43485500000000 | AQ23: =MAX(C23,P23,AC23) -> 47836400000000 | AR23: =(L23+Y23+AL23)/3 -> 1.3153933e+13 | AS23: =MIN(L23,Y23,AK23) -> 10175300000000 | AT23: =MAX(L23,Y23,AL23) -> 13944700000000
A24: 0.0230163 | B24: 0.0236211 | C24: 43485300000000 | D24: 4919760000 | E24: 0 | F24: 0 | G24: 2 | H24: 7388160000000 | I24: 7749860000000 | J24: 7267160000000 | K24: 7116600000000 | L24: 13962500000000 | N24: 0.0229712 | O24: 0.0236234 | P24: 45044100000000 | Q24: 10610600000 | R24: 0 | S24: 0 | T24: 2 | U24: 7052580000000 | V24: 7787810000000 | W24: 9327550000000 | X24: 8028420000000 | Y24: 12847000000000 | AN24: =A24 -> 0.0230163 | AO24: =(C24+P24+AC24)/3 -> 29509800000000 | AP24: =MIN(C24,P24,AC24) -> 43485300000000 | AQ24: =MAX(C24,P24,AC24) -> 45044100000000 | AR24: =(L24+Y24+AL24)/3 -> 8936500000000 | AS24: =MIN(L24,Y24,AK24) -> 12847000000000 | AT24: =MAX(L24,Y24,AL24) -> 13962500000000
A25: 0.0239765 | B25: 0.0246434 | C25: 44438600000000 | D25: 1388280000 | E25: 0 | F25: 0 | G25: 2 | H25: 7605420000000 | I25: 8263640000000 | J25: 6843300000000 | K25: 7749900000000 | L25: 13975100000000 | N25: 0.0239014 | O25: 0.0245376 | P25: 45613700000000 | Q25: 1294280000 | R25: 0 | S25: 0 | T25: 2 | U25: 7474860000000 | V25: 8055800000000 | W25: 9213240000000 | X25: 8454070000000 | Y25: 12414900000000 | AN25: =A25 -> 0.0239765 | AO25: =(C25+P25+AC25)/3 -> 3.0017433e+13 | AP25: =MIN(C25,P25,AC25) -> 44438600000000 | AQ25: =MAX(C25,P25,AC25) -> 45613700000000 | AR25: =(L25+Y25+AL25)/3 -> 8.7966667e+12 | AS25: =MIN(L25,Y25,AK25) -> 12414900000000 | AT25: =MAX(L25,Y25,AL25) -> 13975100000000
A26: 0.025045 | B26: 0.0256416 | C26: 43992100000000 | D26: 2023990000 | E26: 0 | F26: 0 | G26: 2 | H26: 7623130000000 | I26: 7826160000000 | J26: 7098550000000 | K26: 7595530000000 | L26: 13845900000000 | N26: 0.0249922 | O26: 0.0255986 | P26: 47216600000000 | Q26: 1472890000 | R26: 0 | S26: 0 | T26: 2 | U26: 7924930000000 | V26: 7527790000000 | W26: 9982960000000 | X26: 9030590000000 | Y26: 12749600000000 | AN26: =A26 -> 0.025045 | AO26: =(C26+P26+AC26)/3 -> 30402900000000 | AP26: =MIN(C26,P26,AC26) -> 43992100000000 | AQ26: =MAX(C26,P26,AC26) -> 47216600000000 | AR26: =(L26+Y26+AL26)/3 -> 8.8651667e+12 | AS26: =MIN(L26,Y26,AK26) -> 12749600000000 | AT26: =MAX(L26,Y26,AL26) -> 13845900000000
A27: 0.0260204 | B27: 0.0266395 | C27: 43542000000000 | D27: 4263100000 | E27: 0 | F27: 0 | G27: 2 | H27: 7144480000000 | I27: 7930360000000 | J27: 7215670000000 | K27: 6877310000000 | L27: 14372000000000 | N27: 0.0260013 | O27: 0.026578 | P27: 47911400000000 | Q27: 2270110000 | R27: 0 | S27: 0 | T27: 2 | U27: 7896990000000 | V27: 7957530000000 | W27: 10206000000000 | X27: 9035430000000 | Y27: 12814700000000 | AN27: =A27 -> 0.0260204 | AO27: =(C27+P27+AC27)/3 -> 3.0484467e+13 | AP27: =MIN(C27,P27,AC27) -> 43542000000000 | AQ27: =MAX(C27,P27,AC27) -> 47911400000000 | AR27: =(L27+Y27+AL27)/3 -> 9.0622333e+12 | AS27: =MIN(L27,Y27,AK27) -> 12814700000000 | AT27: =MAX(L27,Y27,AL27) -> 14372000000000
A28: 0.0269831 | B28: 0.0276121 | C28: 43383300000000 | D28: 1572420000 | E28: 0 | F28: 0 | G28: 2 | H28: 7240630000000 | I28: 7761960000000 | J28: 7554110000000 | K28: 6990750000000 | L28: 13834500000000 | N28: 0.0270296 | O28: 0.0275905 | P28: 49270100000000 | Q28: 1503500000 | R28: 0 | S28: 0 | T28: 2 | U28: 7858470000000 | V28: 8482540000000 | W28: 10372300000000 | X28: 9317960000000 | Y28: 13238400000000 | AN28: =A28 -> 0.0269831 | AO28: =(C28+P28+AC28)/3 -> 3.0884467e+13 | AP28: =MIN(C28,P28,AC28) -> 43383300000000 | AQ28: =MAX(C28,P28,AC28) -> 49270100000000 | AR28: =(L28+Y28+AL28)/3 -> 9024300000000 | AS28: =MIN(L28,Y28,AK28) -> 13238400000000 | AT28: =MAX(L28,Y28,AL28) -> 13834500000000
A29: 0.0280066 | B29: 0.0286767 | C29: 44121400000000 | D29: 1879580000 | E29: 0 | F29: 0 | G29: 2 | H29: 7548020000000 | I29: 8552980000000 | J29: 8257090000000 | K29: 7548530000000 | L29: 12212500000000 | N29: 0.0279829 | O29: 0.028523 | P29: 49209900000000 | Q29: 1123130000 | R29: 0 | S29: 0 | T29: 2 | U29: 7684690000000 | V29: 8287380000000 | W29: 10723700000000 | X29: 9544260000000 | Y29: 12964000000000 | AN29: =A29 -> 0.0280066 | AO29: =(C29+P29+AC29)/3 -> 3.1110433e+13 | AP29: =MIN(C29,P29,AC29) -> 44121400000000 | AQ29: =MAX(C29,P29,AC29) -> 49209900000000 | AR29: =(L29+Y29+AL29)/3 -> 8.3921667e+12 | AS29: =MIN(L29,Y29,AK29) -> 12212500000000 | AT29: =MAX(L29,Y29,AL29) -> 12964000000000
A30: 0.0290357 | B30: 0.0296506 | C30: 44421900000000 | D30: 1451060000 | E30: 0 | F30: 0 | G30: 2 | H30: 7748270000000 | I30: 9222060000000 | J30: 8594130000000 | K30: 8195040000000 | L30: 10658500000000 | AN30: =A30 -> 0.0290357 | AO30: =(C30+P30+AC30)/3 -> 14807300000000 | AP30: =MIN(C30,P30,AC30) -> 44421900000000 | AQ30: =MAX(C30,P30,AC30) -> 44421900000000 | AR30: =(L30+Y30+AL30)/3 -> 3.5528333e+12 | AS30: =MIN(L30,Y30,AK30) -> 10658500000000 | AT30: =MAX(L30,Y30,AL30) -> 10658500000000
A31: 0.0299908 | B31: 0.0306087 | C31: 44729500000000 | D31: 1016850000 | E31: 0 | F31: 0 | G31: 2 | H31: 8700130000000 | I31: 8214940000000 | J31: 9011840000000 | K31: 7856110000000 | L31: 10945700000000 | AN31: =A31 -> 0.0299908 | AO31: =(C31+P31+AC31)/3 -> 1.4909833e+13 | AP31: =MIN(C31,P31,AC31) -> 44729500000000 | AQ31: =MAX(C31,P31,AC31) -> 44729500000000 | AR31: =(L31+Y31+AL31)/3 -> 3.6485667e+12 | AS31: =MIN(L31,Y31,AK31) -> 10945700000000 | AT31: =MAX(L31,Y31,AL31) -> 10945700000000

Sheet 400K_SR100_Stress
A1: Config 1 | D1: Config 2 | G1: Config3 | K1: AverageValue of Last 0.5%
A2: 0.000999724 | B2: 115979000 | D2: 0.00100427 | E2: 120854000 | G2: 0.00095142 | H2: 117141000 | L2: TotalStress | M2: RhoI | N2: Rho | O2: TauF1 | P2: TauF2 | Q2: TauF | R2: Tau | S2: Tau/TauF | T2: RhoI/Rho
A3: 0.0019768 | B3: 126519000 | D3: 0.00201175 | E3: 134485000 | G3: 0.00205493 | H3: 120931000 | K3: Config1 | L3: =AVERAGE(B27:B31)/1000000 -> 143.0018 | M3: =AVERAGE('400K_SR100'!L27:L31) -> 8819098000000 | N3: =AVERAGE('400K_SR100'!C27:C31) -> 45230120000000 | O3: =Graphs!$B$1*80.9*0.248*SQRT(M3)/1000000 -> 29.790809 | P3: =Graphs!$B$2*80.9*0.248*SQRT(N3)/1000000 -> 6.7465862 | Q3: =SQRT(O3^2+P3^2) -> 30.545191 | R3: =L3*0.4395 -> 62.849291 | S3: =R3/Q3 -> 2.0575838 | T3: =M3/N3 -> 0.19498286
A4: 0.00298521 | B4: 127630000 | D4: 0.00303869 | E4: 129908000 | G4: 0.00304863 | H4: 131506000 | K4: Config2 | L4: =AVERAGE(E27:E31)/1000000 -> 135.0584 | M4: =AVERAGE('400K_SR100'!Y27:Y31) -> 8562096000000 | N4: =AVERAGE('400K_SR100'!P27:P31) -> 44641760000000 | O4: =Graphs!$B$1*80.9*0.248*SQRT(M4)/1000000 -> 29.353524 | P4: =Graphs!$B$2*80.9*0.248*SQRT(N4)/1000000 -> 6.7025623 | Q4: =SQRT(O4^2+P4^2) -> 30.109031 | R4: =L4*0.4395 -> 59.358167 | S4: =R4/Q4 -> 1.9714406 | T4: =M4/N4 -> 0.19179566
A5: 0.00395737 | B5: 138705000 | D5: 0.0039768 | E5: 148200000 | G5: 0.00403473 | H5: 137738000 | K5: Config3 | L5: =AVERAGE(H27:H31)/1000000 -> 143.095 | M5: =AVERAGE('400K_SR100'!AL27:AL31) -> 9674936000000 | N5: =AVERAGE('400K_SR100'!AC27:AC31) -> 44690420000000 | O5: =Graphs!$B$1*80.9*0.248*SQRT(M5)/1000000 -> 31.20285 | P5: =Graphs!$B$2*80.9*0.248*SQRT(N5)/1000000 -> 6.7062143 | Q5: =SQRT(O5^2+P5^2) -> 31.915375 | R5: =L5*0.4395 -> 62.890253 | S5: =R5/Q5 -> 1.9705316 | T5: =M5/N5 -> 0.21648792
A6: 0.00498979 | B6: 136801000 | D6: 0.00499222 | E6: 149121000 | G6: 0.00499236 | H6: 146845000
A7: 0.00600038 | B7: 141701000 | D7: 0.00600004 | E7: 142967000 | G7: 0.00604712 | H7: 141692000
A8: 0.00698823 | B8: 145200000 | D8: 0.00704415 | E8: 146170000 | G8: 0.00700076 | H8: 142598000
A9: 0.00797659 | B9: 134987000 | D9: 0.00800857 | E9: 141619000 | G9: 0.0080479 | H9: 144257000 | K9: Config1 | L9: =AVERAGE(B12:B16)/1000000 -> 145.4976 | M9: =AVERAGE('400K_SR100'!L12:L16) -> 8283940000000 | N9: =AVERAGE('400K_SR100'!C12:C16) -> 44963840000000 | O9: =Graphs!$B$1*80.9*0.248*SQRT(M9)/1000000 -> 28.872785 | P9: =Graphs!$B$2*80.9*0.248*SQRT(N9)/1000000 -> 6.7266976 | Q9: =SQRT(O9^2+P9^2) -> 29.646015 | R9: =L9*0.4395 -> 63.946195 | S9: =R9/Q9 -> 2.1569913 | T9: =M9/N9 -> 0.1842356
A10: 0.00898825 | B10: 144067000 | D10: 0.00900841 | E10: 141051000 | G10: 0.00898676 | H10: 146075000 | K10: Config2 | L10: =AVERAGE(E12:E16)/1000000 -> 140.897 | M10: =AVERAGE('400K_SR100'!Y12:Y16) -> 8017882000000 | N10: =AVERAGE('400K_SR100'!P12:P16) -> 45286840000000 | O10: =Graphs!$B$1*80.9*0.248*SQRT(M10)/1000000 -> 28.405343 | P10: =Graphs!$B$2*80.9*0.248*SQRT(N10)/1000000 -> 6.7508151 | Q10: =SQRT(O10^2+P10^2) -> 29.196524 | R10: =L10*0.4395 -> 61.924231 | S10: =R10/Q10 -> 2.1209453 | T10: =M10/N10 -> 0.17704662
A11: 0.0100224 | B11: 140420000 | D11: 0.00997998 | E11: 150729000 | G11: 0.0101114 | H11: 144329000 | K11: Config3 | L11: =AVERAGE(H12:H16)/1000000 -> 143.1368 | M11: =AVERAGE('400K_SR100'!L12:AL16) -> 7.6170342e+12 | N11: =AVERAGE('400K_SR100'!AC12:AC16) -> 45781960000000 | O11: =Graphs!$B$1*80.9*0.248*SQRT(M11)/1000000 -> 27.686188 | P11: =Graphs!$B$2*80.9*0.248*SQRT(N11)/1000000 -> 6.7876181 | Q11: =SQRT(O11^2+P11^2) -> 28.506083 | R11: =L11*0.4395 -> 62.908624 | S11: =R11/Q11 -> 2.2068491 | T11: =M11/N11 -> 0.16637632
A12: 0.0110035 | B12: 139083000 | D12: 0.0110223 | E12: 147359000 | G12: 0.0109915 | H12: 148838000
A13: 0.0120144 | B13: 141718000 | D13: 0.0119868 | E13: 147942000 | G13: 0.0120397 | H13: 149773000
A14: 0.0129708 | B14: 153641000 | D14: 0.0130168 | E14: 139638000 | G14: 0.0130128 | H14: 143800000
A15: 0.0140085 | B15: 145588000 | D15: 0.0140074 | E15: 136349000 | G15: 0.0139734 | H15: 144448000
A16: 0.0149926 | B16: 147458000 | D16: 0.0149746 | E16: 133197000 | G16: 0.0150051 | H16: 128825000
A17: 0.0160169 | B17: 141520000 | D17: 0.0159461 | E17: 140828000 | G17: 0.0160267 | H17: 138416000
A18: 0.0169616 | B18: 141083000 | D18: 0.0169679 | E18: 139953000 | G18: 0.0169967 | H18: 133483000
A19: 0.0179688 | B19: 139499000 | D19: 0.0179549 | E19: 141964000 | G19: 0.0180007 | H19: 147728000
A20: 0.0189679 | B20: 154252000 | D20: 0.0190017 | E20: 143654000 | G20: 0.0189863 | H20: 145468000
A21: 0.0200246 | B21: 146406000 | D21: 0.0200063 | E21: 139472000 | G21: 0.0200033 | H21: 145859000
A22: 0.0210283 | B22: 151066000 | D22: 0.0209319 | E22: 145937000 | G22: 0.020987 | H22: 135525000
A23: 0.0219753 | B23: 152284000 | D23: 0.0220358 | E23: 139596000 | G23: 0.0220287 | H23: 133871000
... A31: 0.0299707 | B31: 139347000 | D31: 0.0300075 | E31: 137646000 | G31: 0.0299979 | H31: 132871000

Sheet 400K_SR100
A1: Config1 | N1: Config2 | AA1: Config3 | AN1: Pstrain | AO1: Total | AP1: Totalmin | AQ1: Totalmax | AR1: Junction | AS1: Junctionmin | AT1: Junctionmax
A2: 0.000999724 | B2: 0.00155238 | C2: 42156600000000 | D2: 961663000 | E2: 0 | F2: 0 | G2: 2 | H2: 9849780000000 | I2: 9897400000000 | J2: 10032800000000 | K2: 9845430000000 | L2: 2531120000000 | N2: 0.00100427 | O2: 0.00158017 | P2: 42305600000000 | Q2: 1001130000 | R2: 0 | S2: 0 | T2: 2 | U2: 10179200000000 | V2: 9946590000000 | W2: 9780490000000 | X2: 9869800000000 | Y2: 2529280000000 | AA2: 0.00095142 | AB2: 0.00150962 | AC2: 42155500000000 | AD2: 525627000 | AE2: 0 | AF2: 0 | AG2: 2 | AH2: 10037700000000 | AI2: 10016700000000 | AJ2: 9992960000000 | AK2: 9990350000000 | AL2: 2117820000000 | AN2: =A2 -> 0.000999724 | AO2: =(C2+P2+AC2)/3 -> 42205900000000 | AP2: =MIN(C2,P2,AC2) -> 42155500000000 | AQ2: =MAX(C2,P2,AC2) -> 42305600000000 | AR2: =(L2+Y2+AL2)/3 -> 2392740000000 | AS2: =MIN(L2,Y2,AL2) -> 2117820000000 | AT2: =MAX(L2,Y2,AL2) -> 2531120000000
A3: 0.0019768 | B3: 0.00257969 | C3: 43658800000000 | D3: 869481000 | E3: 0 | F3: 0 | G3: 2 | H3: 9611230000000 | I3: 10075900000000 | J3: 9976450000000 | K3: 10117100000000 | L3: 3877940000000 | N3: 0.00201175 | O3: 0.00265259 | P3: 43343900000000 | Q3: 1036710000 | R3: 0 | S3: 0 | T3: 2 | U3: 9827870000000 | V3: 9380860000000 | W3: 9686330000000 | X3: 9700850000000 | Y3: 4747150000000 | AA3: 0.00205493 | AB3: 0.00263119 | AC3: 43542700000000 | AD3: 991693000 | AE3: 0 | AF3: 0 | AG3: 2 | AH3: 10377600000000 | AI3: 9951940000000 | AJ3: 9712570000000 | AK3: 9724790000000 | AL3: 3775700000000 | AN3: =A3 -> 0.0019768 | AO3: =(C3+P3+AC3)/3 -> 4.3515133e+13 | AP3: =MIN(C3,P3,AC3) -> 43343900000000 | AQ3: =MAX(C3,P3,AC3) -> 43658800000000 | AR3: =(L3+Y3+AL3)/3 -> 4.1335967e+12 | AS3: =MIN(L3,Y3,AL3) -> 3775700000000 | AT3: =MAX(L3,Y3,AL3) -> 4747150000000
A4: 0.00298521 | B4: 0.00359339 | C4: 44475600000000 | D4: 1097860000 | E4: 0 | F4: 0 | G4: 2 | H4: 9250950000000 | I4: 9937950000000 | J4: 9699800000000 | K4: 10287900000000 | L4: 5298970000000 | N4: 0.00303869 | O4: 0.00365773 | P4: 44751000000000 | Q4: 3203480000 | R4: 0 | S4: 0 | T4: 2 | U4: 10543300000000 | V4: 9459330000000 | W4: 9769220000000 | X4: 9222820000000 | Y4: 5756260000000 | AA4: 0.00304863 | AB4: 0.00367528 | AC4: 44371200000000 | AD4: 1850710000 | AE4: 0 | AF4: 0 | AG4: 2 | AH4: 10654100000000 | AI4: 9684270000000 | AJ4: 9867990000000 | AK4: 9412370000000 | AL4: 4752090000000 | AN4: =A4 -> 0.00298521 | AO4: =(C4+P4+AC4)/3 -> 44532600000000 | AP4: =MIN(C4,P4,AC4) -> 44371200000000 | AQ4: =MAX(C4,P4,AC4) -> 44751000000000 | AR4: =(L4+Y4+AL4)/3 -> 5.2691067e+12 | AS4: =MIN(L4,Y4,AL4) -> 4752090000000 | AT4: =MAX(L4,Y4,AL4) -> 5756260000000
A5: 0.00395737 | B5: 0.00461832 | C5: 44850600000000 | D5: 2062860000 | E5: 0 | F5: 0 | G5: 2 | H5: 9384630000000 | I5: 9841860000000 | J5: 9711330000000 | K5: 9647970000000 | L5: 6264800000000 | N5: 0.0039768 | O5: 0.004683 | P5: 44815900000000 | Q5: 3463030000 | R5: 0 | S5: 0 | T5: 2 | U5: 9414380000000 | V5: 9527330000000 | W5: 8883010000000 | X5: 8958500000000 | Y5: 8032460000000 | AA5: 0.00403473 | AB5: 0.00469107 | AC5: 44681800000000 | AD5: 2806670000 | AE5: 0 | AF5: 0 | AG5: 2 | AH5: 9526080000000 | AI5: 9913790000000 | AJ5: 9814080000000 | AK5: 9264230000000 | AL5: 6163510000000 | AN5: =A5 -> 0.00395737 | AO5: =(C5+P5+AC5)/3 -> 4.4782767e+13 | AP5: =MIN(C5,P5,AC5) -> 44681800000000 | AQ5: =MAX(C5,P5,AC5) -> 44850600000000 | AR5: =(L5+Y5+AL5)/3 -> 6.8202567e+12 | AS5: =MIN(L5,Y5,AL5) -> 6163510000000 | AT5: =MAX(L5,Y5,AL5) -> 8032460000000
A6: 0.00498979 | B6: 0.00564167 | C6: 44332500000000 | D6: 3296200000 | E6: 0 | F6: 0 | G6: 2 | H6: 9369020000000 | I6: 9506270000000 | J6: 9677470000000 | K6: 9248530000000 | L6: 6530770000000 | N6: 0.00499222 | O6: 0.0057028 | P6: 44502900000000 | Q6: 4559830000 | R6: 0 | S6: 0 | T6: 2 | U6: 9473020000000 | V6: 9381470000000 | W6: 8658220000000 | X6: 8828280000000 | Y6: 8160140000000 | AA6: 0.00499236 | AB6: 0.0056921 | AC6: 45422800000000 | AD6: 3023020000 | AE6: 0 | AF6: 0 | AG6: 2 | AH6: 9465090000000 | AI6: 8986800000000 | AJ6: 9467480000000 | AK6: 9719680000000 | AL6: 7783410000000 | AN6: =A6 -> 0.00498979 | AO6: =(C6+P6+AC6)/3 -> 4.4752733e+13 | AP6: =MIN(C6,P6,AC6) -> 44332500000000 | AQ6: =MAX(C6,P6,AC6) -> 45422800000000 | AR6: =(L6+Y6+AL6)/3 -> 7491440000000 | AS6: =MIN(L6,Y6,AL6) -> 6530770000000 | AT6: =MAX(L6,Y6,AL6) -> 8160140000000
A7: 0.00600038 | B7: 0.0066756 | C7: 44501100000000 | D7: 2050560000 | E7: 0 | F7: 0 | G7: 2 | H7: 8861750000000 | I7: 9848620000000 | J7: 9080860000000 | K7: 9671060000000 | L7: 7037910000000 | N7: 0.00600004 | O7: 0.0066813 | P7: 44332300000000 | Q7: 3455620000 | R7: 0 | S7: 0 | T7: 2 | U7: 9214800000000 | V7: 9585150000000 | W7: 9067990000000 | X7: 8661420000000 | Y7: 7802170000000 | AA7: 0.00604712 | AB7: 0.0067223 | AC7: 45567900000000 | AD7: 3802820000 | AE7: 0 | AF7: 0 | AG7: 2 | AH7: 9340810000000 | AI7: 9284240000000 | AJ7: 9134820000000 | AK7: 9814340000000 | AL7: 7993310000000 | AN7: =A7 -> 0.00600038 | AO7: =(C7+P7+AC7)/3 -> 4.4800433e+13 | AP7: =MIN(C7,P7,AC7) -> 44332300000000 | AQ7: =MAX(C7,P7,AC7) -> 45567900000000 | AR7: =(L7+Y7+AL7)/3 -> 7611130000000 | AS7: =MIN(L7,Y7,AL7) -> 7037910000000 | AT7: =MAX(L7,Y7,AL7) -> 7993310000000
A8: 0.00698823 | B8: 0.00768013 | C8: 44928400000000 | D8: 2478550000 | E8: 0 | F8: 0 | G8: 2 | H8: 9302720000000 | I8: 9662300000000 | J8: 9116040000000 | K8: 10358600000000 | L8: 6487710000000 | N8: 0.00704415 | O8: 0.00774068 | P8: 45983700000000 | Q8: 4316950000 | R8: 0 | S8: 0 | T8: 2 | U8: 9388900000000 | V8: 9711310000000 | W8: 9626500000000 | X8: 8574700000000 | Y8: 8681550000000 | AA8: 0.00700076 | AB8: 0.00768026 | AC8: 44562500000000 | AD8: 3003700000 | AE8: 0 | AF8: 0 | AG8: 2 | AH8: 8846310000000 | AI8: 9278900000000 | AJ8: 9052660000000 | AK8: 9086140000000 | AL8: 8295780000000 | AN8: =A8 -> 0.00698823 | AO8: =(C8+P8+AC8)/3 -> 45158200000000 | AP8: =MIN(C8,P8,AC8) -> 44562500000000 | AQ8: =MAX(C8,P8,AC8) -> 45983700000000 | AR8: =(L8+Y8+AL8)/3 -> 7821680000000 | AS8: =MIN(L8,Y8,AL8) -> 6487710000000 | AT8: =MAX(L8,Y8,AL8) -> 8681550000000
A9: 0.00797659 | B9: 0.00861983 | C9: 44771500000000 | D9: 4849650000 | E9: 0 | F9: 0 | G9: 2 | H9: 9242840000000 | I9: 9338920000000 | J9: 9054800000000 | K9: 11063700000000 | L9: 6070730000000 | N9: 0.00800857 | O9: 0.00868341 | P9: 46548400000000 | Q9: 4520760000 | R9: 0 | S9: 0 | T9: 2 | U9: 10784800000000 | V9: 8973770000000 | W9: 9519460000000 | X9: 8506740000000 | Y9: 8761210000000 | AA9: 0.0080479 | AB9: 0.00873531 | AC9: 44119800000000 | AD9: 2280000000 | AE9: 0 | AF9: 0 | AG9: 2 | AH9: 8828660000000 | AI9: 9076310000000 | AJ9: 8673430000000 | AK9: 8662250000000 | AL9: 8876490000000 | AN9: =A9 -> 0.00797659 | AO9: =(C9+P9+AC9)/3 -> 4.5146567e+13 | AP9: =MIN(C9,P9,AC9) -> 44119800000000 | AQ9: =MAX(C9,P9,AC9) -> 46548400000000 | AR9: =(L9+Y9+AL9)/3 -> 7902810000000 | AS9: =MIN(L9,Y9,AL9) -> 6070730000000 | AT9: =MAX(L9,Y9,AL9) -> 8876490000000
A10: 0.00898825 | B10: 0.00967476 | C10: 44780900000000 | D10: 1867930000 | E10: 0 | F10: 0 | G10: 2 | H10: 8957080000000 | I10: 9163110000000 | J10: 9571440000000 | K10: 9975870000000 | L10: 7112780000000 | N10: 0.00900841 | O10: 0.00968054 | P10: 45052000000000 | Q10: 5663880000 | R10: 0 | S10: 0 | T10: 2 | U10: 9627270000000 | V10: 8779710000000 | W10: 9203730000000 | X10: 8966380000000 | Y10: 8474650000000 | AA10: 0.00898676 | AB10: 0.00968283 | AC10: 45145600000000 | AD10: 4405360000 | AE10: 0 | AF10: 0 | AG10: 2 | AH10: 9067840000000 | AI10: 8812240000000 | AJ10: 8535220000000 | AK10: 9362230000000 | AL10: 9365690000000 | AN10: =A10 -> 0.00898825 | AO10: =(C10+P10+AC10)/3 -> 4.4992833e+13 | AP10: =MIN(C10,P10,AC10) -> 44780900000000 | AQ10: =MAX(C10,P10,AC10) -> 45145600000000 | AR10: =(L10+Y10+AL10)/3 -> 8.3177067e+12 | AS10: =MIN(L10,Y10,AL10) -> 7112780000000 | AT10: =MAX(L10,Y10,AL10) -> 9365690000000
A11: 0.0100224 | B11: 0.0106916 | C11: 45571600000000 | D11: 3770470000 | E11: 0 | F11: 0 | G11: 2 | H11: 8628010000000 | I11: 9628960000000 | J11: 9344410000000 | K11: 10467200000000 | L11: 7502860000000 | N11: 0.00997998 | O11: 0.0106982 | P11: 46044600000000 | Q11: 3509030000 | R11: 0 | S11: 0 | T11: 2 | U11: 9618180000000 | V11: 9009150000000 | W11: 9574780000000 | X11: 9526210000000 | Y11: 8315850000000 | AA11: 0.0101114 | AB11: 0.0107992 | AC11: 45161900000000 | AD11: 1986760000 | AE11: 0 | AF11: 0 | AG11: 2 | AH11: 8689330000000 | AI11: 9626830000000 | AJ11: 7886870000000 | AK11: 9101280000000 | AL11: 9854820000000 | AN11: =A11 -> 0.0100224 | AO11: =(C11+P11+AC11)/3 -> 45592700000000 | AP11: =MIN(C11,P11,AC11) -> 45161900000000 | AQ11: =MAX(C11,P11,AC11) -> 46044600000000 | AR11: =(L11+Y11+AL11)/3 -> 8.5578433e+12 | AS11: =MIN(L11,Y11,AL11) -> 7502860000000 | AT11: =MAX(L11,Y11,AL11) -> 9854820000000
A12: 0.0110035 | B12: 0.0116662 | C12: 44721100000000 | D12: 4013200000 | E12: 0 | F12: 0 | G12: 2 | H12: 8539230000000 | I12: 8980550000000 | J12: 9494540000000 | K12: 10038500000000 | L12: 7667600000000 | N12: 0.0110223 | O12: 0.0117245 | P12: 46017000000000 | Q12: 4969870000 | R12: 0 | S12: 0 | T12: 2 | U12: 9238600000000 | V12: 10548000000000 | W12: 8854220000000 | X12: 8440660000000 | Y12: 8935440000000 | AA12: 0.0109915 | AB12: 0.0117008 | AC12: 45037700000000 | AD12: 3771410000 | AE12: 0 | AF12: 0 | AG12: 2 | AH12: 8969820000000 | AI12: 9282210000000 | AJ12: 8267850000000 | AK12: 8652300000000 | AL12: 9865090000000 | AN12: =A12 -> 0.0110035 | AO12: =(C12+P12+AC12)/3 -> 45258600000000 | AP12: =MIN(C12,P12,AC12) -> 44721100000000 | AQ12: =MAX(C12,P12,AC12) -> 46017000000000 | AR12: =(L12+Y12+AL12)/3 -> 8822710000000 | AS12: =MIN(L12,Y12,AL12) -> 7667600000000 | AT12: =MAX(L12,Y12,AL12) -> 9865090000000
A13: 0.0120144 | B13: 0.0126897 | C13: 44629900000000 | D13: 2988620000 | E13: 0 | F13: 0 | G13: 2 | H13: 9088720000000 | I13: 8712160000000 | J13: 9304090000000 | K13: 9708210000000 | L13: 7815690000000 | N13: 0.0119868 | O13: 0.0126918 | P13: 44983000000000 | Q13: 4684850000 | R13: 0 | S13: 0 | T13: 2 | U13: 9275220000000 | V13: 9726330000000 | W13: 8972420000000 | X13: 8542460000000 | Y13: 8458700000000 | AA13: 0.0120397 | AB13: 0.0127534 | AC13: 46041100000000 | AD13: 5258560000 | AE13: 0 | AF13: 0 | AG13: 2 | AH13: 8705640000000 | AI13: 8966060000000 | AJ13: 9406450000000 | AK13: 8760140000000 | AL13: 10200500000000 | AN13: =A13 -> 0.0120144 | AO13: =(C13+P13+AC13)/3 -> 45218000000000 | AP13: =MIN(C13,P13,AC13) -> 44629900000000 | AQ13: =MAX(C13,P13,AC13) -> 46041100000000 | AR13: =(L13+Y13+AL13)/3 -> 8.8249633e+12 | AS13: =MIN(L13,Y13,AL13) -> 7815690000000 | AT13: =MAX(L13,Y13,AL13) -> 10200500000000
... A31: 0.0299707 | B31: 0.0306348 | C31: 45755600000000 | D31: 2969970000 | E31: 0 | F31: 0 | G31: 2 | H31: 9095110000000 | I31: 9299850000000 | J31: 9360670000000 | K31: 9068380000000 | L31: 8931000000000 | N31: 0.0300075 | O31: 0.0306634 | P31: 44456300000000 | Q31: 2906560000 | R31: 0 | S31: 0 | T31: 2 | U31: 8016650000000 | V31: 9018900000000 | W31: 8754070000000 | X31: 9702690000000 | Y31: 8963520000000 | AA31: 0.0299979 | AB31: 0.0306311 | AC31: 45101700000000 | AD31: 2818010000 | AE31: 0 | AF31: 0 | AG31: 2 | AH31: 8682750000000 | AI31: 9571390000000 | AJ31: 8111120000000 | AK31: 9164070000000 | AL31: 9570560000000 | AN31: =A31 -> 0.0299707 | AO31: =(C31+P31+AC31)/3 -> 4.5104533e+13 | AP31: =MIN(C31,P31,AC31) -> 44456300000000 | AQ31: =MAX(C31,P31,AC31) -> 45755600000000 | AR31: =(L31+Y31+AL31)/3 -> 9.1550267e+12 | AS31: =MIN(L31,Y31,AL31) -> 8931000000000 | AT31: =MAX(L31,Y31,AL31) -> 9570560000000

Sheet 400K_SR1000_Stress
A1: Config 1 | D1: Config 2 | G1: Config3 | K1: AverageValue of Last 0.5%
A2: 0.000979904 | B2: 140597000 | D2: 0.00101728 | E2: 147984000 | G2: 0.000995499 | H2: 151102000 | L2: TotalStress | M2: RhoI | N2: Rho | O2: TauF1 | P2: TauF2 | Q2: TauF | R2: Tau | S2: Tau/TauF | T2: RhoI/Rho
A3: 0.00196847 | B3: 152377000 | D3: 0.00198146 | E3: 153781000 | G3: 0.00199454 | H3: 150415000 | K3: Config1 | L3: =AVERAGE(B27:B31)/1000000 -> 178.431 | M3: =AVERAGE('400K_SR1000'!L27:L31) -> 7293454000000 | N3: =AVERAGE('400K_SR1000'!C27:C31) -> 58909940000000 | O3: =Graphs!$B$1*80.9*0.248*SQRT(M3)/1000000 -> 27.091736 | P3: =Graphs!$B$2*80.9*0.248*SQRT(N3)/1000000 -> 7.699535 | Q3: =SQRT(O3^2+P3^2) -> 28.164605 | R3: =L3*0.4395 -> 78.420424 | S3: =R3/Q3 -> 2.7843609 | T3: =M3/N3 -> 0.12380685
A4: 0.0030397 | B4: 147925000 | D4: 0.00301624 | E4: 158093000 | G4: 0.00302321 | H4: 154241000 | K4: Config2 | L4: =AVERAGE(E26:E30)/1000000 -> 177.8704 | M4: =AVERAGE('400K_SR1000'!Y26:Y30) -> 8113342000000 | N4: =AVERAGE('400K_SR1000'!P26:P30) -> 61431140000000 | O4: =Graphs!$B$1*80.9*0.248*SQRT(M4)/1000000 -> 28.573938 | P4: =Graphs!$B$2*80.9*0.248*SQRT(N4)/1000000 -> 7.8625694 | Q4: =SQRT(O4^2+P4^2) -> 29.635957 | R4: =L4*0.4395 -> 78.174041 | S4: =R4/Q4 -> 2.6378106 | T4: =M4/N4 -> 0.13207214
A5: 0.00401209 | B5: 163982000 | D5: 0.00402841 | E5: 157542000 | G5: 0.00398153 | H5: 159568000 | K5: Config3 | L5: =AVERAGE(H26:H31)/1000000 -> 170.1625 | M5: =AVERAGE('400K_SR1000'!AL28:AL32) -> 7535020000000 | N5: =AVERAGE('400K_SR1000'!AC28:AC32) -> 57875100000000 | O5: =Graphs!$B$1*80.9*0.248*SQRT(M5)/1000000 -> 27.536733 | P5: =Graphs!$B$2*80.9*0.248*SQRT(N5)/1000000 -> 7.6316085 | Q5: =SQRT(O5^2+P5^2) -> 28.574693 | R5: =L5*0.4395 -> 74.786419 | S5: =R5/Q5 -> 2.6172256 | T5: =M5/N5 -> 0.13019451
A6: 0.00503251 | B6: 160727000 | D6: 0.00502035 | E6: 166716000 | G6: 0.00502584 | H6: 156162000
A7: 0.00600189 | B7: 160651000 | D7: 0.00601763 | E7: 166469000 | G7: 0.00600714 | H7: 161100000
A8: 0.00697987 | B8: 172701000 | D8: 0.00699796 | E8: 175762000 | G8: 0.00697276 | H8: 158784000
A9: 0.00801645 | B9: 166362000 | D9: 0.00796272 | E9: 176344000 | G9: 0.00803637 | H9: 164709000 | K9: Config1 | L9: =AVERAGE(B12:B16)/1000000 -> 166.9544 | M9: =AVERAGE('400K_SR1000'!L12:L16) -> 7033894000000 | N9: =AVERAGE('400K_SR1000'!C12:C16) -> 56413900000000 | O9: =Graphs!$B$1*80.9*0.248*SQRT(M9)/1000000 -> 26.605297 | P9: =Graphs!$B$2*80.9*0.248*SQRT(N9)/1000000 -> 7.5346532 | Q9: =SQRT(O9^2+P9^2) -> 27.651634 | R9: =L9*0.4395 -> 73.376459 | S9: =R9/Q9 -> 2.653603 | T9: =M9/N9 -> 0.1246837
A10: 0.00899478 | B10: 177642000 | D10: 0.0090644 | E10: 175082000 | G10: 0.00903575 | H10: 167107000 | K10: Config2 | L10: =AVERAGE(E12:E16)/1000000 -> 170.1218 | M10: =AVERAGE('400K_SR1000'!Y12:Y16) -> 7046376000000 | N10: =AVERAGE('400K_SR1000'!P12:P16) -> 56020720000000 | O10: =Graphs!$B$1*80.9*0.248*SQRT(M10)/1000000 -> 26.628893 | P10: =Graphs!$B$2*80.9*0.248*SQRT(N10)/1000000 -> 7.5083507 | Q10: =SQRT(O10^2+P10^2) -> 27.667188 | R10: =L10*0.4395 -> 74.768531 | S10: =R10/Q10 -> 2.7024261 | T10: =M10/N10 -> 0.1257816
A11: 0.0100591 | B11: 168360000 | D11: 0.0100301 | E11: 173729000 | G11: 0.0100164 | H11: 162991000 | K11: Config3 | L11: =AVERAGE(H12:H16)/1000000 -> 167.3048 | M11: =AVERAGE('400K_SR1000'!L12:AL16) -> 9.1488181e+12 | N11: =AVERAGE('400K_SR1000'!AC12:AC16) -> 54793140000000 | O11: =Graphs!$B$1*80.9*0.248*SQRT(M11)/1000000 -> 30.342594 | P11: =Graphs!$B$2*80.9*0.248*SQRT(N11)/1000000 -> 7.4256299 | Q11: =SQRT(O11^2+P11^2) -> 31.238005 | R11: =L11*0.4395 -> 73.53046 | S11: =R11/Q11 -> 2.3538782 | T11: =M11/N11 -> 0.16697014
A12: 0.0109141 | B12: 173991000 | D12: 0.0110056 | E12: 171986000 | G12: 0.0110178 | H12: 165128000
A13: 0.0120248 | B13: 161794000 | D13: 0.0119554 | E13: 161086000 | G13: 0.011999 | H13: 161020000
A14: 0.0129734 | B14: 171911000 | D14: 0.0130504 | E14: 166451000 | G14: 0.0129744 | H14: 174721000
A15: 0.0140469 | B15: 157581000 | D15: 0.0140123 | E15: 178217000 | G15: 0.0140462 | H15: 163579000
A16: 0.0149845 | B16: 169495000 | D16: 0.0150372 | E16: 172869000 | G16: 0.0150106 | H16: 172076000
A17: 0.0160343 | B17: 169170000 | D17: 0.0159988 | E17: 183878000 | G17: 0.0160407 | H17: 174862000
A18: 0.0169874 | B18: 162591000 | D18: 0.0170456 | E18: 161343000 | G18: 0.0169689 | H18: 173868000
A19: 0.0179785 | B19: 175408000 | D19: 0.0179584 | E19: 177485000 | G19: 0.0179876 | H19: 171178000
A20: 0.0189928 | B20: 167104000 | D20: 0.0190197 | E20: 175343000 | G20: 0.0189815 | H20: 169410000
A21: 0.0200125 | B21: 174610000 | D21: 0.0199671 | E21: 171104000 | G21: 0.0200014 | H21: 166538000
A22: 0.0209558 | B22: 165411000 | D22: 0.0210252 | E22: 174408000 | G22: 0.0209995 | H22: 166364000
A23: 0.0219752 | B23: 169240000 | D23: 0.0219862 | E23: 185361000 | G23: 0.0219478 | H23: 167297000
... A30: 0.0290126 | B30: 179336000 | D30: 0.0287795 | E30: 175820000 | G30: 0.0289376 | H30: 171092000
A31: 0.029978 | B31: 175508000 | G31: 0.0300001 | H31: 169205000

Sheet 400K_SR1000
A1: Config1 | N1: Config2 | AA1: Config3 | AN1: Pstrain | AO1: Total | AP1: Totalmin | AQ1: Totalmax | AR1: Junction | AS1: Junctionmin | AT1: Junctionmax
A2: 0.000979904 | B2: 0.00164989 | C2: 42956200000000 | D2: 2988760000 | E2: 0 | F2: 0 | G2: 2 | H2: 10476700000000 | I2: 10608300000000 | J2: 10449300000000 | K2: 10658100000000 | L2: 763760000000 | N2: 0.00101728 | O2: 0.00172248 | P2: 43124700000000 | Q2: 7275630000 | R2: 0 | S2: 0 | T2: 2 | U2: 10536800000000 | V2: 10622500000000 | W2: 10334300000000 | X2: 10506400000000 | Y2: 1124550000000 | AA2: 0.000995499 | AB2: 0.00171554 | AC2: 43690300000000 | AD2: 7607240000 | AE2: 0 | AF2: 0 | AG2: 2 | AH2: 10333800000000 | AI2: 10562900000000 | AJ2: 10494000000000 | AK2: 10915700000000 | AL2: 1383950000000 | AN2: =N2 -> 0.00101728 | AO2: =AVERAGE(P2,C2,AC2) -> 4.3257067e+13 | AP2: =MIN(C2,P2,AC2) -> 42956200000000 | AQ2: =MAX(C2,P2,AC2) -> 43690300000000 | AR2: =AVERAGE(L2,Y2,AL2) -> 1.0907533e+12 | AS2: =MIN(L2,Y2,AL2) -> 763760000000 | AT2: =MAX(L2,Y2,AL2) -> 1383950000000
A3: 0.00196847 | B3: 0.00269461 | C3: 44898500000000 | D3: 8606990000 | E3: 0 | F3: 0 | G3: 2 | H3: 10848300000000 | I3: 10860200000000 | J3: 10627900000000 | K3: 10860500000000 | L3: 1701650000000 | N3: 0.00198146 | O3: 0.00271428 | P3: 44878200000000 | Q3: 5813890000 | R3: 0 | S3: 0 | T3: 2 | U3: 10635800000000 | V3: 10871500000000 | W3: 10869900000000 | X3: 11015200000000 | Y3: 1485860000000 | AA3: 0.00199454 | AB3: 0.00271133 | AC3: 45080500000000 | AD3: 9214290000 | AE3: 0 | AF3: 0 | AG3: 2 | AH3: 10834000000000 | AI3: 10768500000000 | AJ3: 10635100000000 | AK3: 11177200000000 | AL3: 1665460000000 | AN3: =N3 -> 0.00198146 | AO3: =AVERAGE(P3,C3,AC3) -> 44952400000000 | AP3: =MIN(C3,P3,AC3) -> 44878200000000 | AQ3: =MAX(C3,P3,AC3) -> 45080500000000 | AR3: =AVERAGE(L3,Y3,AL3) -> 1.6176567e+12 | AS3: =MIN(L3,Y3,AL3) -> 1485860000000 | AT3: =MAX(L3,Y3,AL3) -> 1701650000000
A4: 0.0030397 | B4: 0.00374461 | C4: 46827900000000 | D4: 11341500000 | E4: 0 | F4: 0 | G4: 2 | H4: 10819900000000 | I4: 10996000000000 | J4: 10888900000000 | K4: 11765300000000 | L4: 2357800000000 | N4: 0.00301624 | O4: 0.00376962 | P4: 48489100000000 | Q4: 18197700000 | R4: 0 | S4: 0 | T4: 2 | U4: 11000400000000 | V4: 11129300000000 | W4: 11349300000000 | X4: 12362000000000 | Y4: 2648180000000 | AA4: 0.00302321 | AB4: 0.00375822 | AC4: 45679000000000 | AD4: 11935300000 | AE4: 0 | AF4: 0 | AG4: 2 | AH4: 10751100000000 | AI4: 11034200000000 | AJ4: 10927000000000 | AK4: 11037000000000 | AL4: 1929750000000 | AN4: =N4 -> 0.00301624 | AO4: =AVERAGE(P4,C4,AC4) -> 4.6998667e+13 | AP4: =MIN(C4,P4,AC4) -> 45679000000000 | AQ4: =MAX(C4,P4,AC4) -> 48489100000000 | AR4: =AVERAGE(L4,Y4,AL4) -> 2311910000000 | AS4: =MIN(L4,Y4,AL4) -> 1929750000000 | AT4: =MAX(L4,Y4,AL4) -> 2648180000000
A5: 0.00401209 | B5: 0.00479352 | C5: 48137500000000 | D5: 16983500000 | E5: 0 | F5: 0 | G5: 2 | H5: 11040600000000 | I5: 11340200000000 | J5: 10784800000000 | K5: 11903300000000 | L5: 3068430000000 | N5: 0.00402841 | O5: 0.00477916 | P5: 48818400000000 | Q5: 17668600000 | R5: 0 | S5: 0 | T5: 2 | U5: 11017500000000 | V5: 10860600000000 | W5: 11821000000000 | X5: 12224200000000 | Y5: 2895200000000 | AA5: 0.00398153 | AB5: 0.00474194 | AC5: 47240700000000 | AD5: 12771200000 | AE5: 0 | AF5: 0 | AG5: 2 | AH5: 11094800000000 | AI5: 11513000000000 | AJ5: 10960400000000 | AK5: 11139100000000 | AL5: 2533490000000 | AN5: =N5 -> 0.00402841 | AO5: =AVERAGE(P5,C5,AC5) -> 4.8065533e+13 | AP5: =MIN(C5,P5,AC5) -> 47240700000000 | AQ5: =MAX(C5,P5,AC5) -> 48818400000000 | AR5: =AVERAGE(L5,Y5,AL5) -> 2.8323733e+12 | AS5: =MIN(L5,Y5,AL5) -> 2533490000000 | AT5: =MAX(L5,Y5,AL5) -> 3068430000000
A6: 0.00503251 | B6: 0.00579844 | C6: 49527400000000 | D6: 13382500000 | E6: 0 | F6: 0 | G6: 2 | H6: 10872300000000 | I6: 11889900000000 | J6: 10899900000000 | K6: 12833900000000 | L6: 3031320000000 | N6: 0.00502035 | O6: 0.00581481 | P6: 52156500000000 | Q6: 17790300000 | R6: 0 | S6: 0 | T6: 2 | U6: 11466900000000 | V6: 11324100000000 | W6: 13066800000000 | X6: 12061000000000 | Y6: 4237660000000 | AA6: 0.00502584 | AB6: 0.00577002 | AC6: 48752400000000 | AD6: 17144000000 | AE6: 0 | AF6: 0 | AG6: 2 | AH6: 11934100000000 | AI6: 11974100000000 | AJ6: 10792300000000 | AK6: 11339700000000 | AL6: 2712280000000 | AN6: =N6 -> 0.00502035 | AO6: =AVERAGE(P6,C6,AC6) -> 5.0145433e+13 | AP6: =MIN(C6,P6,AC6) -> 48752400000000 | AQ6: =MAX(C6,P6,AC6) -> 52156500000000 | AR6: =AVERAGE(L6,Y6,AL6) -> 3.3270867e+12 | AS6: =MIN(L6,Y6,AL6) -> 2712280000000 | AT6: =MAX(L6,Y6,AL6) -> 4237660000000
A7: 0.00600189 | B7: 0.00676744 | C7: 50513600000000 | D7: 20472300000 | E7: 0 | F7: 0 | G7: 2 | H7: 11391000000000 | I7: 12124200000000 | J7: 11476000000000 | K7: 11653800000000 | L7: 3868780000000 | N7: 0.00601763 | O7: 0.0068109 | P7: 52182400000000 | Q7: 17412300000 | R7: 0 | S7: 0 | T7: 2 | U7: 11418100000000 | V7: 10852700000000 | W7: 12723300000000 | X7: 12314200000000 | Y7: 4874130000000 | AA7: 0.00600714 | AB7: 0.00677485 | AC7: 51282800000000 | AD7: 21708800000 | AE7: 0 | AF7: 0 | AG7: 2 | AH7: 11829200000000 | AI7: 12273700000000 | AJ7: 11991000000000 | AK7: 12007700000000 | AL7: 3181210000000 | AN7: =N7 -> 0.00601763 | AO7: =AVERAGE(P7,C7,AC7) -> 5.1326267e+13 | AP7: =MIN(C7,P7,AC7) -> 50513600000000 | AQ7: =MAX(C7,P7,AC7) -> 52182400000000 | AR7: =AVERAGE(L7,Y7,AL7) -> 3.9747067e+12 | AS7: =MIN(L7,Y7,AL7) -> 3181210000000 | AT7: =MAX(L7,Y7,AL7) -> 4874130000000
A8: 0.00697987 | B8: 0.00780286 | C8: 51561200000000 | D8: 23381000000 | E8: 0 | F8: 0 | G8: 2 | H8: 11541600000000 | I8: 12351600000000 | J8: 11918100000000 | K8: 10970200000000 | L8: 4779700000000 | N8: 0.00699796 | O8: 0.00783552 | P8: 53626200000000 | Q8: 31037700000 | R8: 0 | S8: 0 | T8: 2 | U8: 11531700000000 | V8: 11638200000000 | W8: 12295300000000 | X8: 12466500000000 | Y8: 5694290000000 | AA8: 0.00697276 | AB8: 0.00772942 | AC8: 49877900000000 | AD8: 22473700000 | AE8: 0 | AF8: 0 | AG8: 2 | AH8: 11202800000000 | AI8: 11993000000000 | AJ8: 11853200000000 | AK8: 11569700000000 | AL8: 3259140000000 | AN8: =N8 -> 0.00699796 | AO8: =AVERAGE(P8,C8,AC8) -> 5.1688433e+13 | AP8: =MIN(C8,P8,AC8) -> 49877900000000 | AQ8: =MAX(C8,P8,AC8) -> 53626200000000 | AR8: =AVERAGE(L8,Y8,AL8) -> 4577710000000 | AS8: =MIN(L8,Y8,AL8) -> 3259140000000 | AT8: =MAX(L8,Y8,AL8) -> 5694290000000
A9: 0.00801645 | B9: 0.00880923 | C9: 54463300000000 | D9: 37939700000 | E9: 0 | F9: 0 | G9: 2 | H9: 10499600000000 | I9: 12826800000000 | J9: 12877200000000 | K9: 12346500000000 | L9: 5913330000000 | N9: 0.00796272 | O9: 0.00880306 | P9: 54219100000000 | Q9: 36617800000 | R9: 0 | S9: 0 | T9: 2 | U9: 11720900000000 | V9: 12526100000000 | W9: 11761400000000 | X9: 11348700000000 | Y9: 6861930000000 | AA9: 0.00803637 | AB9: 0.00882128 | AC9: 49211000000000 | AD9: 21797100000 | AE9: 0 | AF9: 0 | AG9: 2 | AH9: 10624300000000 | AI9: 11670400000000 | AJ9: 11478300000000 | AK9: 11667900000000 | AL9: 3770120000000 | AN9: =N9 -> 0.00796272 | AO9: =AVERAGE(P9,C9,AC9) -> 5.2631133e+13 | AP9: =MIN(C9,P9,AC9) -> 49211000000000 | AQ9: =MAX(C9,P9,AC9) -> 54463300000000 | AR9: =AVERAGE(L9,Y9,AL9) -> 5.5151267e+12 | AS9: =MIN(L9,Y9,AL9) -> 3770120000000 | AT9: =MAX(L9,Y9,AL9) -> 6861930000000
A10: 0.00899478 | B10: 0.00984131 | C10: 55272500000000 | D10: 30040800000 | E10: 0 | F10: 0 | G10: 2 | H10: 11145000000000 | I10: 12362400000000 | J10: 11902200000000 | K10: 13406300000000 | L10: 6456660000000 | N10: 0.0090644 | O10: 0.00989872 | P10: 55072000000000 | Q10: 21976100000 | R10: 0 | S10: 0 | T10: 2 | U10: 10994000000000 | V10: 12902200000000 | W10: 11359000000000 | X10: 13202000000000 | Y10: 6614790000000 | AA10: 0.00903575 | AB10: 0.00983207 | AC10: 52175100000000 | AD10: 22517100000 | AE10: 0 | AF10: 0 | AG10: 2 | AH10: 11742100000000 | AI10: 12232900000000 | AJ10: 11544400000000 | AK10: 12132800000000 | AL10: 4522880000000 | AN10: =N10 -> 0.0090644 | AO10: =AVERAGE(P10,C10,AC10) -> 54173200000000 | AP10: =MIN(C10,P10,AC10) -> 52175100000000 | AQ10: =MAX(C10,P10,AC10) -> 55272500000000 | AR10: =AVERAGE(L10,Y10,AL10) -> 5.8647767e+12 | AS10: =MIN(L10,Y10,AL10) -> 4522880000000 | AT10: =MAX(L10,Y10,AL10) -> 6614790000000
A11: 0.0100591 | B11: 0.0108614 | C11: 57509100000000 | D11: 26921700000 | E11: 0 | F11: 0 | G11: 2 | H11: 11119600000000 | I11: 13379600000000 | J11: 12082600000000 | K11: 14081000000000 | L11: 6846350000000 | N11: 0.0100301 | O11: 0.010858 | P11: 55358500000000 | Q11: 29085600000 | R11: 0 | S11: 0 | T11: 2 | U11: 10754500000000 | V11: 13024100000000 | W11: 11055700000000 | X11: 13358300000000 | Y11: 7165310000000 | AA11: 0.0100164 | AB11: 0.0107931 | AC11: 53031800000000 | AD11: 24260800000 | AE11: 0 | AF11: 0 | AG11: 2 | AH11: 12567600000000 | AI11: 11721500000000 | AJ11: 12370500000000 | AK11: 11900700000000 | AL11: 4471520000000 | AN11: =N11 -> 0.0100301 | AO11: =AVERAGE(P11,C11,AC11) -> 55299800000000 | AP11: =MIN(C11,P11,AC11) -> 53031800000000 | AQ11: =MAX(C11,P11,AC11) -> 57509100000000 | AR11: =AVERAGE(L11,Y11,AL11) -> 6161060000000 | AS11: =MIN(L11,Y11,AL11) -> 4471520000000 | AT11: =MAX(L11,Y11,AL11) -> 7165310000000
A12: 0.0109141 | B12: 0.0117432 | C12: 58562000000000 | D12: 26244200000 | E12: 0 | F12: 0 | G12: 2 | H12: 10439100000000 | I12: 13494300000000 | J12: 12431900000000 | K12: 15101300000000 | L12: 7095040000000 | N12: 0.0110056 | O12: 0.0118252 | P12: 54636300000000 | Q12: 41609300000 | R12: 0 | S12: 0 | T12: 2 | U12: 10355800000000 | V12: 12631600000000 | W12: 11940500000000 | X12: 12581100000000 | Y12: 7127190000000 | AA12: 0.0110178 | AB12: 0.0118047 | AC12: 54887700000000 | AD12: 17997800000 | AE12: 0 | AF12: 0 | AG12: 2 | AH12: 12866600000000 | AI12: 11095900000000 | AJ12: 12899900000000 | AK12: 13202000000000 | AL12: 4823150000000 | AN12: =N12 -> 0.0110056 | AO12: =AVERAGE(P12,C12,AC12) -> 5.6028667e+13 | AP12: =MIN(C12,P12,AC12) -> 54636300000000 | AQ12: =MAX(C12,P12,AC12) -> 58562000000000 | AR12: =AVERAGE(L12,Y12,AL12) -> 6348460000000 | AS12: =MIN(L12,Y12,AL12) -> 4823150000000 | AT12: =MAX(L12,Y12,AL12) -> 7127190000000
A13: 0.0120248 | B13: 0.0127958 | C13: 56234900000000 | D13: 23819700000 | E13: 0 | F13: 0 | G13: 2 | H13: 9545860000000 | I13: 13219300000000 | J13: 12834800000000 | K13: 13642300000000 | L13: 6992590000000 | N13: 0.0119554 | O13: 0.012723 | P13: 54183100000000 | Q13: 35882600000 | R13: 0 | S13: 0 | T13: 2 | U13: 10884600000000 | V13: 12466900000000 | W13: 11536500000000 | X13: 12350900000000 | Y13: 6944020000000 | AA13: 0.011999 | AB13: 0.0127663 | AC13: 53905400000000 | AD13: 32308700000 | AE13: 0 | AF13: 0 | AG13: 2 | AH13: 12953700000000 | AI13: 11229500000000 | AJ13: 12795500000000 | AK13: 11787300000000 | AL13: 5139410000000 | AN13: =N13 -> 0.0119554 | AO13: =AVERAGE(P13,C13,AC13) -> 5.4774467e+13 | AP13: =MIN(C13,P13,AC13) -> 53905400000000 | AQ13: =MAX(C13,P13,AC13) -> 56234900000000 | AR13: =AVERAGE(L13,Y13,AL13) -> 6.3586733e+12 | AS13: =MIN(L13,Y13,AL13) -> 5139410000000 | AT13: =MAX(L13,Y13,AL13) -> 6992590000000
... A30: 0.0290126 | B30: 0.0298672 | C30: 58411100000000 | D30: 30936000000 | E30: 0 | F30: 0 | G30: 2 | H30: 13092100000000 | I30: 12081600000000 | J30: 12787900000000 | K30: 13346000000000 | L30: 7103560000000 | N30: 0.0287795 | O30: 0.0296173 | P30: 60186000000000 | Q30: 38294700000 | R30: 0 | S30: 0 | T30: 2 | U30: 12855400000000 | V30: 12879900000000 | W30: 13828900000000 | X30: 13095900000000 | Y30: 7525940000000 | AA30: 0.0289376 | AB30: 0.0297529 | AC30: 57496300000000 | AD30: 22074400000 | AE30: 0 | AF30: 0 | AG30: 2 | AH30: 11429900000000 | AI30: 12910400000000 | AJ30: 13873700000000 | AK30: 12050100000000 | AL30: 7229880000000 | AN30: =N30 -> 0.0287795 | AO30: =AVERAGE(P30,C30,AC30) -> 58697800000000 | AP30: =MIN(C30,P30,AC30) -> 57496300000000 | AQ30: =MAX(C30,P30,AC30) -> 60186000000000 | AR30: =AVERAGE(L30,Y30,AL30) -> 7286460000000 | AS30: =MIN(L30,Y30,AL30) -> 7103560000000 | AT30: =MAX(L30,Y30,AL30) -> 7525940000000
A31: 0.029978 | B31: 0.0308143 | C31: 58702000000000 | D31: 43539900000 | E31: 0 | F31: 0 | G31: 2 | H31: 12834500000000 | I31: 13397800000000 | J31: 13315500000000 | K31: 12438800000000 | L31: 6715410000000 | AA31: 0.0300001 | AB31: 0.0308064 | AC31: 57672900000000 | AD31: 21436300000 | AE31: 0 | AF31: 0 | AG31: 2 | AH31: 10886600000000 | AI31: 11764700000000 | AJ31: 14433600000000 | AK31: 13220300000000 | AL31: 7367570000000 | AN31: =N31 -> 0 | AO31: =AVERAGE(P31,C31,AC31) -> 58187450000000 | AP31: =MIN(C31,P31,AC31) -> 57672900000000 | AQ31: =MAX(C31,P31,AC31) -> 58702000000000 | AR31: =AVERAGE(L31,Y31,AL31) -> 7041490000000 | AS31: =MIN(L31,Y31,AL31) -> 6715410000000 | AT31: =MAX(L31,Y31,AL31) -> 7367570000000
AA32: 0.0309944 | AB32: 0.031799 | AC32: 57337600000000 | AD32: 23663800000 | AE32: 0 | AF32: 0 | AG32: 2 | AH32: 10193900000000 | AI32: 11013000000000 | AJ32: 14381800000000 | AK32: 13777800000000 | AL32: 7969420000000 | AN32: =N32 -> 0 | AO32: =AVERAGE(P32,C32,AC32) -> 57337600000000 | AP32: =MIN(C32,P32,AC32) -> 57337600000000 | AQ32: =MAX(C32,P32,AC32) -> 57337600000000 | AR32: =AVERAGE(L32,Y32,AL32) -> 7969420000000 | AS32: =MIN(L32,Y32,AL32) -> 7969420000000 | AT32: =MAX(L32,Y32,AL32) -> 7969420000000

Sheet 400K_SR1e4_Stress
A1: Config 1 | D1: Config 2 | G1: Config3 | K1: AverageValue of Last 0.5%
A2: 0.000961428 | B2: 297615000 | D2: 0.000978781 | E2: 297508000 | G2: 0.000946522 | H2: 293675000 | L2: TotalStress | M2: RhoI | N2: Rho | O2: TauF1 | P2: TauF2 | Q2: TauF | R2: Tau | S2: Tau/TauF | T2: RhoI/Rho
A3: 0.00197879 | B3: 293360000 | D3: 0.0020169 | E3: 289740000 | G3: 0.00195901 | H3: 288650000 | K3: Config1 | L3: =AVERAGE(B27:B31)/1000000 -> 242.842 | M3: =AVERAGE('400K_SR1e4'!L28:L32) -> 4298785000000 | N3: =AVERAGE('400K_SR1e4'!C28:C32) -> 78952675000000 | O3: =Graphs!$B$1*80.9*0.248*SQRT(M3)/1000000 -> 20.799029 | P3: =Graphs!$B$2*80.9*0.248*SQRT(N3)/1000000 -> 8.9136101 | Q3: =SQRT(O3^2+P3^2) -> 22.628568 | R3: =L3*0.4395 -> 106.72906 | S3: =R3/Q3 -> 4.7165628 | T3: =M3/N3 -> 0.054447617
A4: 0.0029856 | B4: 270817000 | D4: 0.00306237 | E4: 268566000 | G4: 0.0030105 | H4: 263250000 | K4: Config2 | L4: =AVERAGE(E28:E32)/1000000 -> 244.0168 | M4: =AVERAGE('400K_SR1e4'!Y28:Y32) -> 5893312000000 | N4: =AVERAGE('400K_SR1e4'!P28:P32) -> 83760920000000 | O4: =Graphs!$B$1*80.9*0.248*SQRT(M4)/1000000 -> 24.352857 | P4: =Graphs!$B$2*80.9*0.248*SQRT(N4)/1000000 -> 9.1810198 | Q4: =SQRT(O4^2+P4^2) -> 26.026002 | R4: =L4*0.4395 -> 107.24538 | S4: =R4/Q4 -> 4.1207014 | T4: =M4/N4 -> 0.070358731
A5: 0.0040217 | B5: 248573000 | D5: 0.00401287 | E5: 267113000 | G5: 0.00402887 | H5: 243432000 | K5: Config3 | L5: =AVERAGE(H27:H31)/1000000 -> 235.3676 | M5: =AVERAGE('400K_SR1e4'!AL28:AL32) -> 6053390000000 | N5: =AVERAGE('400K_SR1e4'!AC28:AC32) -> 86374625000000 | O5: =Graphs!$B$1*80.9*0.248*SQRT(M5)/1000000 -> 24.681385 | P5: =Graphs!$B$2*80.9*0.248*SQRT(N5)/1000000 -> 9.3231634 | Q5: =SQRT(O5^2+P5^2) -> 26.383559 | R5: =L5*0.4395 -> 103.44406 | S5: =R5/Q5 -> 3.9207774 | T5: =M5/N5 -> 0.070082967
A6: 0.00501896 | B6: 258475000 | D6: 0.0049895 | E6: 260332000 | G6: 0.00500115 | H6: 238593000
A7: 0.00600786 | B7: 259737000 | D7: 0.00599212 | E7: 257539000 | G7: 0.00598643 | H7: 248724000
A8: 0.00701564 | B8: 243262000 | D8: 0.00701721 | E8: 241310000 | G8: 0.0070246 | H8: 243077000
A9: 0.0079717 | B9: 235536000 | D9: 0.00802938 | E9: 235785000 | G9: 0.00801348 | H9: 240348000 | K9: Config1 | L9: =AVERAGE(B12:B16)/1000000 -> 243.199 | M9: =AVERAGE('400K_SR1e4'!L12:L16) -> 3041830000000 | N9: =AVERAGE('400K_SR1e4'!C12:C16) -> 70358500000000 | O9: =Graphs!$B$1*80.9*0.248*SQRT(M9)/1000000 -> 17.495956 | P9: =Graphs!$B$2*80.9*0.248*SQRT(N9)/1000000 -> 8.4145034 | Q9: =SQRT(O9^2+P9^2) -> 19.41423 | R9: =L9*0.4395 -> 106.88596 | S9: =R9/Q9 -> 5.5055471 | T9: =M9/N9 -> 0.043233298
