Workbook

Sheet Graphs
A1: Factor1 | B1: 0.5
A2: Factor2 | B2: 0.05

Sheet 400K_SR10
A1: Config1 | N1: Config2 | AA1: Config3 | AN1: Pstrain | AO1: Total | AP1: Totalmin | AQ1: Totalmax | AR1: Junction | AS1: Junctionmin | AT1: Junctionmax
A2: 0.000201725 | B2: 0.000422716 | C2: 19784300000000 | D2: 2074680000 | E2: 0 | F2: 0 | G2: 2 | H2: 5327440000000 | I2: 4581790000000 | J2: 4561620000000 | K2: 4620780000000 | L2: 692685000000 | N2: 0.000198126 | O2: 0.000407161 | P2: 19784600000000 | Q2: 1364640000 | R2: 0 | S2: 0 | T2: 2 | U2: 5437170000000 | V2: 4597220000000 | W2: 4650030000000 | X2: 4625750000000 | Y2: 474391000000 | AA2: 0.000189158 | AB2: 0.000435539 | AC2: 19901100000000 | AD2: 398723000 | AE2: 0 | AF2: 0 | AG2: 2 | AH2: 5406520000000 | AI2: 4612180000000 | AJ2: 4663520000000 | AK2: 4650010000000 | AL2: 568832000000 | AN2: =A2 -> 0.000201725 | AO2: =(C2+P2+AC2)/3 -> 1.9823333e+13 | AP2: =MIN(C2,P2,AC2) -> 19784300000000 | AQ2: =MAX(C2,P2,AC2) -> 19901100000000 | AR2: =(L2+Y2+AL2)/3 -> 578636000000 | AS2: =MIN(L2,Y2,AL2) -> 474391000000 | AT2: =MAX(L2,Y2,AL2) -> 692685000000
A3: 0.0010314 | B3: 0.00132838 | C3: 20013800000000 | D3: 225095000 | E3: 0 | F3: 0 | G3: 2 | H3: 5297230000000 | I3: 4484640000000 | J3: 4532790000000 | K3: 4538610000000 | L3: 1160500000000 | N3: 0.000988084 | O3: 0.00126713 | P3: 19868900000000 | Q3: 632835000 | R3: 0 | S3: 0 | T3: 2 | U3: 5405230000000 | V3: 4465940000000 | W3: 4532880000000 | X3: 4541970000000 | Y3: 922859000000 | AA3: 0.000960296 | AB3: 0.0013579 | AC3: 20535200000000 | AD3: 220653000 | AE3: 0 | AF3: 0 | AG3: 2 | AH3: 5273730000000 | AI3: 4269380000000 | AJ3: 4408490000000 | AK3: 4420210000000 | AL3: 2163370000000 | AN3: =A3 -> 0.0010314 | AO3: =(C3+P3+AC3)/3 -> 20139300000000 | AP3: =MIN(C3,P3,AC3) -> 19868900000000 | AQ3: =MAX(C3,P3,AC3) -> 20535200000000 | AR3: =(L3+Y3+AL3)/3 -> 1.4155763e+12 | AS3: =MIN(L3,Y3,AL3) -> 922859000000 | AT3: =MAX(L3,Y3,AL3) -> 2163370000000
A4: 0.0019802 | B4: 0.00230752 | C4: 20141200000000 | D4: 378395000 | E4: 0 | F4: 0 | G4: 2 | H4: 5250520000000 | I4: 4441070000000 | J4: 4502860000000 | K4: 4458200000000 | L4: 1488500000000 | N4: 0.00203421 | O4: 0.00229227 | P4: 19865500000000 | Q4: 1197830000 | R4: 0 | S4: 0 | T4: 2 | U4: 5392860000000 | V4: 4372260000000 | W4: 4422630000000 | X4: 4573730000000 | Y4: 1104000000000 | AA4: 0.00199204 | AB4: 0.00240817 | AC4: 20792600000000 | AD4: 321967000 | AE4: 0 | AF4: 0 | AG4: 2 | AH4: 5061140000000 | AI4: 4144840000000 | AJ4: 4152770000000 | AK4: 4264250000000 | AL4: 3169600000000 | AN4: =A4 -> 0.0019802 | AO4: =(C4+P4+AC4)/3 -> 2.0266433e+13 | AP4: =MIN(C4,P4,AC4) -> 19865500000000 | AQ4: =MAX(C4,P4,AC4) -> 20792600000000 | AR4: =(L4+Y4+AL4)/3 -> 1920700000000 | AS4: =MIN(L4,Y4,AL4) -> 1104000000000 | AT4: =MAX(L4,Y4,AL4) -> 3169600000000
A5: 0.00301019 | B5: 0.0033391 | C5: 20018700000000 | D5: 349721000 | E5: 0 | F5: 0 | G5: 2 | H5: 5102480000000 | I5: 4267940000000 | J5: 4316440000000 | K5: 4290430000000 | L5: 2041400000000 | N5: 0.0030135 | O5: 0.00331924 | P5: 19927700000000 | Q5: 803691000 | R5: 0 | S5: 0 | T5: 2 | U5: 5231050000000 | V5: 4258890000000 | W5: 4204050000000 | X5: 4391270000000 | Y5: 1842420000000 | AA5: 0.0029811 | AB5: 0.00343351 | AC5: 20523100000000 | AD5: 183026000 | AE5: 0 | AF5: 0 | AG5: 2 | AH5: 4985290000000 | AI5: 3887750000000 | AJ5: 3937340000000 | AK5: 3602020000000 | AL5: 4110600000000 | AN5: =A5 -> 0.00301019 | AO5: =(C5+P5+AC5)/3 -> 20156500000000 | AP5: =MIN(C5,P5,AC5) -> 19927700000000 | AQ5: =MAX(C5,P5,AC5) -> 20523100000000 | AR5: =(L5+Y5+AL5)/3 -> 2.6648067e+12 | AS5: =MIN(L5,Y5,AL5) -> 1842420000000 | AT5: =MAX(L5,Y5,AL5) -> 4110600000000
A6: 0.00399264 | B6: 0.00430762 | C6: 19956900000000 | D6: 709843000 | E6: 0 | F6: 0 | G6: 2 | H6: 4960940000000 | I6: 4161020000000 | J6: 4239450000000 | K6: 4084390000000 | L6: 2511110000000 | N6: 0.00400784 | O6: 0.00433181 | P6: 20040800000000 | Q6: 210134000 | R6: 0 | S6: 0 | T6: 2 | U6: 5041320000000 | V6: 4188310000000 | W6: 4324730000000 | X6: 4223450000000 | Y6: 2262940000000 | AA6: 0.00400162 | AB6: 0.00443568 | AC6: 20590700000000 | AD6: 376490000 | AE6: 0 | AF6: 0 | AG6: 2 | AH6: 4961840000000 | AI6: 4206250000000 | AJ6: 3897760000000 | AK6: 3746000000000 | AL6: 3778700000000 | AN6: =A6 -> 0.00399264 | AO6: =(C6+P6+AC6)/3 -> 2.0196133e+13 | AP6: =MIN(C6,P6,AC6) -> 19956900000000 | AQ6: =MAX(C6,P6,AC6) -> 20590700000000 | AR6: =(L6+Y6+AL6)/3 -> 2.8509167e+12 | AS6: =MIN(L6,Y6,AL6) -> 2262940000000 | AT6: =MAX(L6,Y6,AL6) -> 3778700000000
A7: 0.00497829 | B7: 0.00533422 | C7: 20067900000000 | D7: 604516000 | E7: 0 | F7: 0 | G7: 2 | H7: 4966450000000 | I7: 4089530000000 | J7: 4173280000000 | K7: 4027520000000 | L7: 2811000000000 | N7: 0.00500666 | O7: 0.00532555 | P7: 20001800000000 | Q7: 397202000 | R7: 0 | S7: 0 | T7: 2 | U7: 4954620000000 | V7: 4066150000000 | W7: 4281820000000 | X7: 4118610000000 | Y7: 2580570000000 | AA7: 0.00501609 | AB7: 0.00540544 | AC7: 20211400000000 | AD7: 597070000 | AE7: 0 | AF7: 0 | AG7: 2 | AH7: 4826070000000 | AI7: 3901110000000 | AJ7: 3708390000000 | AK7: 3794610000000 | AL7: 3980490000000 | AN7: =A7 -> 0.00497829 | AO7: =(C7+P7+AC7)/3 -> 20093700000000 | AP7: =MIN(C7,P7,AC7) -> 20001800000000 | AQ7: =MAX(C7,P7,AC7) -> 20211400000000 | AR7: =(L7+Y7+AL7)/3 -> 3124020000000 | AS7: =MIN(L7,Y7,AL7) -> 2580570000000 | AT7: =MAX(L7,Y7,AL7) -> 3980490000000
A8: 0.00597872 | B8: 0.00635327 | C8: 20243500000000 | D8: 292155000 | E8: 0 | F8: 0 | G8: 2 | H8: 5069240000000 | I8: 4121010000000 | J8: 4177620000000 | K8: 4120440000000 | L8: 2755070000000 | N8: 0.00598976 | O8: 0.00629911 | P8: 19809000000000 | Q8: 316074000 | R8: 0 | S8: 0 | T8: 2 | U8: 5014060000000 | V8: 4026610000000 | W8: 4122060000000 | X8: 3930940000000 | Y8: 2715360000000 | AA8: 0.00601132 | AB8: 0.00643712 | AC8: 20453100000000 | AD8: 796153000 | AE8: 0 | AF8: 0 | AG8: 2 | AH8: 4675950000000 | AI8: 3953360000000 | AJ8: 3781480000000 | AK8: 4068200000000 | AL8: 3973980000000 | AN8: =A8 -> 0.00597872 | AO8: =(C8+P8+AC8)/3 -> 2.0168533e+13 | AP8: =MIN(C8,P8,AC8) -> 19809000000000 | AQ8: =MAX(C8,P8,AC8) -> 20453100000000 | AR8: =(L8+Y8+AL8)/3 -> 3.1481367e+12 | AS8: =MIN(L8,Y8,AL8) -> 2715360000000 | AT8: =MAX(L8,Y8,AL8) -> 3973980000000
A9: 0.00702629 | B9: 0.00740712 | C9: 20216500000000 | D9: 703006000 | E9: 0 | F9: 0 | G9: 2 | H9: 4898880000000 | I9: 4089060000000 | J9: 3927020000000 | K9: 3905460000000 | L9: 3396060000000 | N9: 0.00702113 | O9: 0.00734609 | P9: 19852600000000 | Q9: 335786000 | R9: 0 | S9: 0 | T9: 2 | U9: 5037310000000 | V9: 4039810000000 | W9: 4220710000000 | X9: 4098080000000 | Y9: 2456740000000 | AA9: 0.00710354 | AB9: 0.00753921 | AC9: 20597800000000 | AD9: 166069000 | AE9: 0 | AF9: 0 | AG9: 2 | AH9: 4700070000000 | AI9: 3851210000000 | AJ9: 3797160000000 | AK9: 3848270000000 | AL9: 4401000000000 | AN9: =A9 -> 0.00702629 | AO9: =(C9+P9+AC9)/3 -> 20222300000000 | AP9: =MIN(C9,P9,AC9) -> 19852600000000 | AQ9: =MAX(C9,P9,AC9) -> 20597800000000 | AR9: =(L9+Y9+AL9)/3 -> 3.4179333e+12 | AS9: =MIN(L9,Y9,AL9) -> 2456740000000 | AT9: =MAX(L9,Y9,AL9) -> 4401000000000
A10: 0.0079974 | B10: 0.00842568 | C10: 20328900000000 | D10: 506835000 | E10: 0 | F10: 0 | G10: 2 | H10: 4547080000000 | I10: 4006850000000 | J10: 3668750000000 | K10: 3547230000000 | L10: 4558870000000 | N10: 0.00800662 | O10: 0.00835702 | P10: 20078500000000 | Q10: 414348000 | R10: 0 | S10: 0 | T10: 2 | U10: 5135530000000 | V10: 4202790000000 | W10: 4332540000000 | X10: 4140970000000 | Y10: 2266650000000 | AA10: 0.00802118 | AB10: 0.00848847 | AC10: 20718800000000 | AD10: 335073000 | AE10: 0 | AF10: 0 | AG10: 2 | AH10: 4684190000000 | AI10: 3957160000000 | AJ10: 3522380000000 | AK10: 3564600000000 | AL10: 4989940000000 | AN10: =A10 -> 0.0079974 | AO10: =(C10+P10+AC10)/3 -> 20375400000000 | AP10: =MIN(C10,P10,AC10) -> 20078500000000 | AQ10: =MAX(C10,P10,AC10) -> 20718800000000 | AR10: =(L10+Y10+AL10)/3 -> 3.9384867e+12 | AS10: =MIN(L10,Y10,AL10) -> 2266650000000 | AT10: =MAX(L10,Y10,AL10) -> 4989940000000
A11: 0.00901321 | B11: 0.0094265 | C11: 20351000000000 | D11: 703777000 | E11: 0 | F11: 0 | G11: 2 | H11: 4667780000000 | I11: 3921700000000 | J11: 3700000000000 | K11: 3769040000000 | L11: 4292370000000 | N11: 0.00898227 | O11: 0.00939848 | P11: 20405000000000 | Q11: 274152000 | R11: 0 | S11: 0 | T11: 2 | U11: 5153770000000 | V11: 4130460000000 | W11: 4362180000000 | X11: 4151580000000 | Y11: 2606990000000 | AA11: 0.00904358 | AB11: 0.00947837 | AC11: 20692400000000 | AD11: 378981000 | AE11: 0 | AF11: 0 | AG11: 2 | AH11: 4736060000000 | AI11: 4052820000000 | AJ11: 3563180000000 | AK11: 3500640000000 | AL11: 4839440000000 | AN11: =A11 -> 0.00901321 | AO11: =(C11+P11+AC11)/3 -> 20482800000000 | AP11: =MIN(C11,P11,AC11) -> 20351000000000 | AQ11: =MAX(C11,P11,AC11) -> 20692400000000 | AR11: =(L11+Y11+AL11)/3 -> 3.9129333e+12 | AS11: =MIN(L11,Y11,AL11) -> 2606990000000 | AT11: =MAX(L11,Y11,AL11) -> 4839440000000
A12: 0.010019 | B12: 0.010448 | C12: 20243400000000 | D12: 208817000 | E12: 0 | F12: 0 | G12: 2 | H12: 4577750000000 | I12: 4039750000000 | J12: 3754690000000 | K12: 3822210000000 | L12: 4048940000000 | N12: 0.00999001 | O12: 0.0104295 | P12: 20574700000000 | Q12: 262144000 | R12: 0 | S12: 0 | T12: 2 | U12: 4792430000000 | V12: 4067420000000 | W12: 4110050000000 | X12: 4085370000000 | Y12: 3519420000000 | AA12: 0.00998583 | AB12: 0.0104635 | AC12: 21155200000000 | AD12: 595902000 | AE12: 0 | AF12: 0 | AG12: 2 | AH12: 4783860000000 | AI12: 4042480000000 | AJ12: 3387220000000 | AK12: 3347530000000 | AL12: 5594000000000 | AN12: =A12 -> 0.010019 | AO12: =(C12+P12+AC12)/3 -> 2.0657767e+13 | AP12: =MIN(C12,P12,AC12) -> 20243400000000 | AQ12: =MAX(C12,P12,AC12) -> 21155200000000 | AR12: =(L12+Y12+AL12)/3 -> 4.3874533e+12 | AS12: =MIN(L12,Y12,AL12) -> 3519420000000 | AT12: =MAX(L12,Y12,AL12) -> 5594000000000
A13: 0.0110126 | B13: 0.011473 | C13: 20606900000000 | D13: 240015000 | E13: 0 | F13: 0 | G13: 2 | H13: 4822960000000 | I13: 3777890000000 | J13: 3905960000000 | K13: 3707370000000 | L13: 4392630000000 | N13: 0.0109735 | O13: 0.0114089 | P13: 20428100000000 | Q13: 221355000 | R13: 0 | S13: 0 | T13: 2 | U13: 4896110000000 | V13: 4129470000000 | W13: 3892850000000 | X13: 4037530000000 | Y13: 3472150000000 | AA13: 0.0109949 | AB13: 0.011468 | AC13: 21352900000000 | AD13: 314469000 | AE13: 0 | AF13: 0 | AG13: 2 | AH13: 4542340000000 | AI13: 4209810000000 | AJ13: 3238210000000 | AK13: 3465830000000 | AL13: 5896370000000 | AN13: =A13 -> 0.0110126 | AO13: =(C13+P13+AC13)/3 -> 2.0795967e+13 | AP13: =MIN(C13,P13,AC13) -> 20428100000000 | AQ13: =MAX(C13,P13,AC13) -> 21352900000000 | AR13: =(L13+Y13+AL13)/3 -> 4587050000000 | AS13: =MIN(L13,Y13,AL13) -> 3472150000000 | AT13: =MAX(L13,Y13,AL13) -> 5896370000000
... A49: 0.0469861 | B49: 0.0474074 | C49: 20055900000000 | D49: 624894000 | E49: 0 | F49: 0 | G49: 2 | H49: 4137410000000 | I49: 3178900000000 | J49: 3526860000000 | K49: 3261860000000 | L49: 5950570000000 | N49: 0.0470029 | O49: 0.0472804 | P49: 18674800000000 | Q49: 531971000 | R49: 0 | S49: 0 | T49: 2 | U49: 3385060000000 | V49: 2541780000000 | W49: 2646060000000 | X49: 2576790000000 | Y49: 7525000000000 | AA49: 0.0469977 | AB49: 0.0474296 | AC49: 20796600000000 | AD49: 241896000 | AE49: 0 | AF49: 0 | AG49: 2 | AH49: 5025650000000 | AI49: 3980130000000 | AJ49: 3998410000000 | AK49: 4016110000000 | AL49: 3776280000000 | AN49: =A49 -> 0.0469861 | AO49: =(C49+P49+AC49)/3 -> 1.9842433e+13 | AP49: =MIN(C49,P49,AC49) -> 18674800000000 | AQ49: =MAX(C49,P49,AC49) -> 20796600000000 | AR49: =(L49+Y49+AL49)/3 -> 5.7506167e+12 | AS49: =MIN(L49,Y49,AL49) -> 3776280000000 | AT49: =MAX(L49,Y49,AL49) -> 7525000000000
A50: 0.0479583 | B50: 0.0483923 | C50: 20286000000000 | D50: 528429000 | E50: 0 | F50: 0 | G50: 2 | H50: 4104900000000 | I50: 3449000000000 | J50: 3535760000000 | K50: 3323460000000 | L50: 5872500000000 | AA50: 0.0480466 | AB50: 0.0484929 | AC50: 20850100000000 | AD50: 245680000 | AE50: 0 | AF50: 0 | AG50: 2 | AH50: 4881040000000 | AI50: 4072800000000 | AJ50: 3723700000000 | AK50: 4015840000000 | AL50: 4156430000000
A51: 0.0489754 | B51: 0.0494256 | C51: 20281600000000 | D51: 495288000 | E51: 0 | F51: 0 | G51: 2 | H51: 4121650000000 | I51: 3157860000000 | J51: 3424170000000 | K51: 3218360000000 | L51: 6355790000000 | AA51: 0.049015 | AB51: 0.0494472 | AC51: 20829100000000 | AD51: 603963000 | AE51: 0 | AF51: 0 | AG51: 2 | AH51: 4955950000000 | AI51: 3927990000000 | AJ51: 3513670000000 | AK51: 3696200000000 | AL51: 4735150000000
A52: 0.0499946 | B52: 0.0504531 | C52: 20058400000000 | D52: 292716000 | E52: 0 | F52: 0 | G52: 2 | H52: 3979580000000 | I52: 3205280000000 | J52: 3357560000000 | K52: 3145460000000 | L52: 6370130000000 | AA52: 0.05004 | AB52: 0.0504657 | AC52: 21085600000000 | AD52: 358860000 | AE52: 0 | AF52: 0 | AG52: 2 | AH52: 5008270000000 | AI52: 3826160000000 | AJ52: 3464520000000 | AK52: 3950270000000 | AL52: 4836230000000
AA53: 0.0510182 | AB53: 0.051458 | AC53: 20532900000000 | AD53: 867616000 | AE53: 0 | AF53: 0 | AG53: 2 | AH53: 4106630000000 | AI53: 3698850000000 | AJ53: 3519840000000 | AK53: 3331490000000 | AL53: 5875840000000
AA54: 0.0520225 | AB54: 0.0524518 | AC54: 20416600000000 | AD54: 673243000 | AE54: 0 | AF54: 0 | AG54: 2 | AH54: 4120460000000 | AI54: 3418490000000 | AJ54: 3290140000000 | AK54: 3221010000000 | AL54: 6366250000000
AA55: 0.0527637 | AB55: 0.0531927 | AC55: 20359200000000 | AD55: 339564000 | AE55: 0 | AF55: 0 | AG55: 2 | AH55: 4603150000000 | AI55: 3639700000000 | AJ55: 3150010000000 | AK55: 3548760000000 | AL55: 5417430000000

Sheet 400K_SR10_Stress
A1: Config 1 | D1: Config 2 | G1: Config4 | J1: AverageValue of Last 2.5-3%
A2: 0.000201725 | B2: 46376300 | D2: 0.000198126 | E2: 43867500 | G2: 0.000189158 | H2: 51704800 | K2: TotalStress | L2: RhoI | M2: Rho | N2: TauF1 | O2: TauF2 | P2: TauF | Q2: Tau | R2: Tau/TauF | S2: RhoI/Rho
A3: 0.0010314 | B3: 62324200 | D3: 0.000988084 | E3: 58560500 | G3: 0.000960296 | H3: 83440100 | J3: Config1 | K3: =AVERAGE(B28:B32)/1000000 -> 89.29032 | L3: =AVERAGE('400K_SR10'!L28:L32) -> 5880148000000 | M3: =AVERAGE('400K_SR10'!C28:C32) -> 20251720000000 | N3: =Graphs!$B$1*80.9*0.248*SQRT(L3)/1000000 -> 24.325643 | O3: =Graphs!$B$2*80.9*0.248*SQRT(M3)/1000000 -> 4.5144117 | P3: =SQRT(N3^2+O3^2) -> 24.740995 | Q3: =K3*0.4707 -> 42.028954 | R3: =Q3/P3 -> 1.6987576 | S3: =L3/M3 -> 0.29035302
A4: 0.0019802 | B4: 68689300 | D4: 0.00203421 | E4: 54155700 | G4: 0.00199204 | H4: 87327800 | J4: Config2 | K4: =AVERAGE(E28:E32)/1000000 -> 86.35624 | L4: =AVERAGE('400K_SR10'!Y28:Y32) -> 6780100000000 | M4: =AVERAGE('400K_SR10'!P28:P32) -> 19622720000000 | N4: =Graphs!$B$1*80.9*0.248*SQRT(L4)/1000000 -> 26.120907 | O4: =Graphs!$B$2*80.9*0.248*SQRT(M4)/1000000 -> 4.443752 | P4: =SQRT(N4^2+O4^2) -> 26.496202 | Q4: =K4*0.4707 -> 40.647882 | R4: =Q4/P4 -> 1.5341022 | S4: =L4/M4 -> 0.34552294
A5: 0.00301019 | B5: 69022800 | D5: 0.0030135 | E5: 64160200 | G5: 0.0029811 | H5: 94942400 | J5: Config4 | K5: =AVERAGE(H28:H32)/1000000 -> 92.06938 | L5: =AVERAGE('400K_SR10'!AL28:AL32) -> 4760780000000 | M5: =AVERAGE('400K_SR10'!AC28:AC32) -> 21211240000000 | N5: =Graphs!$B$1*80.9*0.248*SQRT(L5)/1000000 -> 21.88816 | O5: =Graphs!$B$2*80.9*0.248*SQRT(M5)/1000000 -> 4.6201198 | P5: =SQRT(N5^2+O5^2) -> 22.370451 | Q5: =K5*0.4707 -> 43.337057 | R5: =Q5/P5 -> 1.9372456 | S5: =L5/M5 -> 0.2244461
A6: 0.00399264 | B6: 66097900 | D6: 0.00400784 | E6: 67989200 | G6: 0.00400162 | H6: 91091000
A7: 0.00497829 | B7: 74695300 | D7: 0.00500666 | E7: 66921000 | G7: 0.00501609 | H7: 81708100
A8: 0.00597872 | B8: 78600600 | D8: 0.00598976 | E8: 64919600 | G8: 0.00601132 | H8: 89358000
A9: 0.00702629 | B9: 79916700 | D9: 0.00702113 | E9: 68194600 | G9: 0.00710354 | H9: 91430300
A10: 0.0079974 | B10: 89876800 | D10: 0.00800662 | E10: 73534400 | G10: 0.00802118 | H10: 98063400 | K10: TotalStress | L10: RhoI | M10: Rho | N10: TauF1 | O10: TauF2 | P10: TauF | Q10: Tau | R10: Tau/TauF | S10: RhoI/Rho
A11: 0.00901321 | B11: 86731500 | D11: 0.00898227 | E11: 87343400 | G11: 0.00904358 | H11: 91245400 | J11: Config1 | K11: =AVERAGE(B12:B16)/1000000 -> 94.37036 | L11: =AVERAGE('400K_SR10'!L12:L16) -> 4569306000000 | M11: =AVERAGE('400K_SR10'!C12:C16) -> 20488720000000 | N11: =Graphs!$B$1*80.9*0.248*SQRT(L11)/1000000 -> 21.443483 | O11: =Graphs!$B$2*80.9*0.248*SQRT(M11)/1000000 -> 4.5407503 | P11: =SQRT(N11^2+O11^2) -> 21.918973 | Q11: =K11*0.4707 -> 44.420128 | R11: =Q11/P11 -> 2.0265607 | S11: =L11/M11 -> 0.22301569
A12: 0.010019 | B12: 90015900 | D12: 0.00999001 | E12: 92227600 | G12: 0.00998583 | H12: 100254000 | J12: Config2 | K12: =AVERAGE(E12:E16)/1000000 -> 91.44112 | L12: =AVERAGE('400K_SR10'!Y12:Y16) -> 3620590000000 | M12: =AVERAGE('400K_SR10'!P12:P16) -> 20585040000000 | N12: =Graphs!$B$1*80.9*0.248*SQRT(L12)/1000000 -> 19.087976 | O12: =Graphs!$B$2*80.9*0.248*SQRT(M12)/1000000 -> 4.5514111 | P12: =SQRT(N12^2+O12^2) -> 19.623103 | Q12: =K12*0.4707 -> 43.041335 | R12: =Q12/P12 -> 2.1934011 | S12: =L12/M12 -> 0.17588453
A13: 0.0110126 | B13: 96619700 | D13: 0.0109735 | E13: 91369100 | G13: 0.0109949 | H13: 99287700 | J13: Config4 | K13: =AVERAGE(H12:H16)/1000000 -> 95.77348 | L13: =AVERAGE('400K_SR10'!AL12:AL16) -> 5796698000000 | M13: =AVERAGE('400K_SR10'!AC12:AC16) -> 21355680000000 | N13: =Graphs!$B$1*80.9*0.248*SQRT(L13)/1000000 -> 24.152414 | O13: =Graphs!$B$2*80.9*0.248*SQRT(M13)/1000000 -> 4.6358237 | P13: =SQRT(N13^2+O13^2) -> 24.593291 | Q13: =K13*0.4707 -> 45.080577 | R13: =Q13/P13 -> 1.8330437 | S13: =L13/M13 -> 0.27143589
A14: 0.0120309 | B14: 93811000 | D14: 0.0119855 | E14: 95143200 | G14: 0.0120428 | H14: 95545600
A15: 0.0130007 | B15: 95761900 | D15: 0.0130202 | E15: 85735200 | G15: 0.0130079 | H15: 90375800
A16: 0.0140228 | B16: 95643300 | D16: 0.0140046 | E16: 92730500 | G16: 0.0139963 | H16: 93404300
A17: 0.0149987 | B17: 96126500 | D17: 0.0150129 | E17: 96498100 | G17: 0.0150105 | H17: 102510000
A18: 0.0160003 | B18: 98195300 | D18: 0.0159849 | E18: 99397200 | G18: 0.0159918 | H18: 90405900
A19: 0.0169947 | B19: 93481500 | D19: 0.017002 | E19: 94830300 | G19: 0.0169953 | H19: 95584100
A20: 0.0180069 | B20: 90597600 | D20: 0.0180037 | E20: 100693000 | G20: 0.0179875 | H20: 100091000
A21: 0.0190033 | B21: 92279400 | D21: 0.0190219 | E21: 98947300 | G21: 0.0190178 | H21: 89594100
A22: 0.0199878 | B22: 97440700 | D22: 0.0200239 | E22: 92099400 | G22: 0.0200189 | H22: 79981200
A23: 0.0210526 | B23: 91810000 | D23: 0.0210344 | E23: 95491600 | G23: 0.0210033 | H23: 85780300
A24: 0.0220272 | B24: 86584900 | D24: 0.0220483 | E24: 86397100 | G24: 0.0220039 | H24: 88698100
A25: 0.0230008 | B25: 90634000 | D25: 0.0229973 | E25: 93152800 | G25: 0.0230299 | H25: 85462400
... A49: 0.0469861 | B49: 88399200 | D49: 0.0470029 | E49: 58229700 | G49: 0.0469977 | H49: 90636100
A50: 0.0479583 | B50: 91078300 | G50: 0.0480466 | H50: 93681700
A51: 0.0489754 | B51: 94474700 | G51: 0.049015 | H51: 90705300
A52: 0.0499946 | B52: 96228300 | G52: 0.05004 | H52: 89335800
G53: 0.0510182 | H53: 92287500
G54: 0.0520225 | H54: 90084100
G55: 0.0527637 | H55: 90019000

Sheet 400K_SR20_Stress
A1: Config 1 | D1: Config 2 | G1: Config3 | J1: AverageValue of Last 0.5%
A2: 0.000214671 | B2: 56263800 | D2: 0.000207118 | E2: 57153800 | G2: 0.000223905 | H2: 57141400 | K2: TotalStress | L2: RhoI | M2: Rho | N2: TauF1 | O2: TauF2 | P2: TauF | Q2: Tau | R2: Tau/TauF | S2: RhoI/Rho
A3: 0.000979536 | B3: 81516300 | D3: 0.00101975 | E3: 81812800 | G3: 0.00102224 | H3: 74603000 | J3: Config1 | K3: =AVERAGE(B28:B32)/1000000 -> 106.2344 | L3: =AVERAGE('400K_SR20'!L28:L32) -> 4341056000000 | M3: =AVERAGE('400K_SR20'!C28:C32) -> 21060120000000 | N3: =Graphs!$B$1*80.9*0.248*SQRT(L3)/1000000 -> 20.90104 | O3: =Graphs!$B$2*80.9*0.248*SQRT(M3)/1000000 -> 4.6036323 | P3: =SQRT(N3^2+O3^2) -> 21.402031 | Q3: =K3*0.4707 -> 50.004532 | R3: =Q3/P3 -> 2.3364387 | S3: =L3/M3 -> 0.20612684
A4: 0.00197987 | B4: 92883900 | D4: 0.00202976 | E4: 94538800 | G4: 0.00199238 | H4: 86249400 | J4: Config2 | K4: =AVERAGE(E28:E32)/1000000 -> 100.18022 | L4: =AVERAGE('400K_SR20'!Y28:Y32) -> 5103916000000 | M4: =AVERAGE('400K_SR20'!P28:P32) -> 21109080000000 | N4: =Graphs!$B$1*80.9*0.248*SQRT(L4)/1000000 -> 22.663238 | O4: =Graphs!$B$2*80.9*0.248*SQRT(M4)/1000000 -> 4.6089804 | P4: =SQRT(N4^2+O4^2) -> 23.12715 | Q4: =K4*0.4707 -> 47.15483 | R4: =Q4/P4 -> 2.0389382 | S4: =L4/M4 -> 0.2417877
A5: 0.00297193 | B5: 103305000 | D5: 0.0030084 | E5: 98387700 | G5: 0.00301052 | H5: 91386600 | J5: Config4 | K5: =AVERAGE(H28:H32)/1000000 -> 104.2784 | L5: =AVERAGE('400K_SR20'!AL28:AL32) -> 4007330000000 | M5: =AVERAGE('400K_SR20'!AC28:AC32) -> 21192760000000 | N5: =Graphs!$B$1*80.9*0.248*SQRT(L5)/1000000 -> 20.081574 | O5: =Graphs!$B$2*80.9*0.248*SQRT(M5)/1000000 -> 4.6181067 | P5: =SQRT(N5^2+O5^2) -> 20.605741 | Q5: =K5*0.4707 -> 49.083843 | R5: =Q5/P5 -> 2.382047 | S5: =L5/M5 -> 0.18908958
A6: 0.00397339 | B6: 100983000 | D6: 0.00400344 | E6: 90691500 | G6: 0.00398633 | H6: 98603200
A7: 0.00500065 | B7: 91066000 | D7: 0.00499299 | E7: 92490000 | G7: 0.00499157 | H7: 99848400
A8: 0.00594836 | B8: 99849700 | D8: 0.00599919 | E8: 99841600 | G8: 0.00598184 | H8: 100131000
A9: 0.00697824 | B9: 97951600 | D9: 0.00699065 | E9: 109162000 | G9: 0.00702116 | H9: 102970000
A10: 0.00802007 | B10: 97679900 | D10: 0.00798197 | E10: 97294700 | G10: 0.00800037 | H10: 106845000 | J10: Config1 | K10: =AVERAGE(B12:B16)/1000000 -> 105.8598 | L10: =AVERAGE('400K_SR20'!L12:L16) -> 4665850000000 | M10: =AVERAGE('400K_SR20'!C12:C16) -> 21184560000000 | N10: =Graphs!$B$1*80.9*0.248*SQRT(L10)/1000000 -> 21.668837 | O10: =Graphs!$B$2*80.9*0.248*SQRT(M10)/1000000 -> 4.6172132 | P10: =SQRT(N10^2+O10^2) -> 22.155296 | Q10: =K10*0.4707 -> 49.828208 | R10: =Q10/P10 -> 2.2490428 | S10: =L10/M10 -> 0.22024767
A11: 0.00900566 | B11: 104115000 | D11: 0.00896409 | E11: 104036000 | G11: 0.00897995 | H11: 107716000 | J11: Config2 | K11: =AVERAGE(E12:E16)/1000000 -> 103.65422 | L11: =AVERAGE('400K_SR20'!Y12:Y16) -> 4177888000000 | M11: =AVERAGE('400K_SR20'!P12:P16) -> 21163880000000 | N11: =Graphs!$B$1*80.9*0.248*SQRT(L11)/1000000 -> 20.504473 | O11: =Graphs!$B$2*80.9*0.248*SQRT(M11)/1000000 -> 4.6149591 | P11: =SQRT(N11^2+O11^2) -> 21.017403 | Q11: =K11*0.4707 -> 48.790041 | R11: =Q11/P11 -> 2.3214115 | S11: =L11/M11 -> 0.19740652
A12: 0.0099903 | B12: 105237000 | D12: 0.0100335 | E12: 104276000 | G12: 0.00992246 | H12: 105101000 | J12: Config4 | K12: =AVERAGE(H12:H16)/1000000 -> 103.3674 | L12: =AVERAGE('400K_SR20'!AL12:AL16) -> 3938012000000 | M12: =AVERAGE('400K_SR20'!AC12:AC16) -> 21127760000000 | N12: =Graphs!$B$1*80.9*0.248*SQRT(L12)/1000000 -> 19.907133 | O12: =Graphs!$B$2*80.9*0.248*SQRT(M12)/1000000 -> 4.6110192 | P12: =SQRT(N12^2+O12^2) -> 20.434174 | Q12: =K12*0.4707 -> 48.655035 | R12: =Q12/P12 -> 2.381062 | S12: =L12/M12 -> 0.18639042
A13: 0.0110013 | B13: 105309000 | D13: 0.0109727 | E13: 105351000 | G13: 0.0110035 | H13: 100783000
A14: 0.0120149 | B14: 108900000 | D14: 0.0119895 | E14: 103328000 | G14: 0.0119864 | H14: 104502000
A15: 0.0130014 | B15: 108628000 | D15: 0.0129959 | E15: 106347000 | G15: 0.0130056 | H15: 105302000
A16: 0.0140061 | B16: 101225000 | D16: 0.0140073 | E16: 98969100 | G16: 0.0140047 | H16: 101149000
A17: 0.0149829 | B17: 104601000 | D17: 0.0150149 | E17: 100759000 | G17: 0.0149778 | H17: 104714000
A18: 0.0160063 | B18: 96012600 | D18: 0.0160005 | E18: 98480100 | G18: 0.015973 | H18: 108941000
A19: 0.0169875 | B19: 99229400 | D19: 0.0169995 | E19: 103280000 | G19: 0.016993 | H19: 105498000
A20: 0.0180264 | B20: 99254600 | D20: 0.0180493 | E20: 105577000 | G20: 0.0180102 | H20: 105766000
A21: 0.0190506 | B21: 95242300 | D21: 0.0190446 | E21: 103330000 | G21: 0.0190019 | H21: 103877000
A22: 0.0200326 | B22: 95225900 | D22: 0.0199774 | E22: 108127000 | G22: 0.0199888 | H22: 104053000
A23: 0.0210018 | B23: 101420000 | D23: 0.0210063 | E23: 99079800 | G23: 0.0210403 | H23: 102477000
A24: 0.0220033 | B24: 101743000 | D24: 0.022 | E24: 96833400 | G24: 0.0219884 | H24: 105586000
... A49: 0.0470347 | B49: 96067600 | D49: 0.0469776 | E49: 110189000 | G49: 0.0469929 | H49: 102989000
A50: 0.047976 | B50: 96534900 | G50: 0.0480313 | H50: 102956000
A51: 0.0489749 | B51: 107712000 | G51: 0.048999 | H51: 103188000
A52: 0.0500052 | B52: 100198000 | G52: 0.049981 | H52: 113481000
G53: 0.051024 | H53: 111700000
G54: 0.0520175 | H54: 105857000
G55: 0.0529076 | H55: 105656000

Sheet 400K_SR20
A1: Config1 | N1: Config2 | AA1: Config3 | AN1: Pstrain | AO1: Total | AP1: Totalmin | AQ1: Totalmax | AR1: Junction | AS1: Junctionmin | AT1: Junctionmax
A2: 0.000214671 | B2: 0.000482777 | C2: 19848800000000 | D2: 2789680000 | E2: 0 | F2: 0 | G2: 2 | H2: 5352470000000 | I2: 4596080000000 | J2: 4578060000000 | K2: 4604460000000 | L2: 717679000000 | N2: 0.000207118 | O2: 0.000479465 | P2: 19885600000000 | Q2: 733856000 | R2: 0 | S2: 0 | T2: 2 | U2: 5408980000000 | V2: 4644980000000 | W2: 4643070000000 | X2: 4641660000000 | Y2: 546923000000 | AA2: 0.000223905 | AB2: 0.000496194 | AC2: 19793600000000 | AD2: 2375710000 | AE2: 0 | AF2: 0 | AG2: 2 | AH2: 4854800000000 | AI2: 4817360000000 | AJ2: 4829670000000 | AK2: 4836630000000 | AL2: 455193000000 | AN2: =A2 -> 0.000214671 | AO2: =(C2+P2+AC2)/3 -> 1.9842667e+13 | AP2: =MIN(C2,P2,AC2) -> 19793600000000 | AQ2: =MAX(C2,P2,AC2) -> 19885600000000 | AR2: =(L2+Y2+AL2)/3 -> 573265000000 | AS2: =MIN(L2,Y2,AL2) -> 455193000000 | AT2: =MAX(L2,Y2,AL2) -> 717679000000
A3: 0.000979536 | B3: 0.00136797 | C3: 20228100000000 | D3: 178475000 | E3: 0 | F3: 0 | G3: 2 | H3: 5314150000000 | I3: 4561620000000 | J3: 4543250000000 | K3: 4543470000000 | L3: 1265520000000 | N3: 0.00101975 | O3: 0.0014096 | P3: 20174500000000 | Q3: 604978000 | R3: 0 | S3: 0 | T3: 2 | U3: 5334140000000 | V3: 4532020000000 | W3: 4487830000000 | X3: 4598470000000 | Y3: 1222030000000 | AA3: 0.00102224 | AB3: 0.00137774 | AC3: 20168000000000 | AD3: 1355670000 | AE3: 0 | AF3: 0 | AG3: 2 | AH3: 4849520000000 | AI3: 4699260000000 | AJ3: 4797000000000 | AK3: 4881170000000 | AL3: 941012000000 | AN3: =A3 -> 0.000979536 | AO3: =(C3+P3+AC3)/3 -> 20190200000000 | AP3: =MIN(C3,P3,AC3) -> 20168000000000 | AQ3: =MAX(C3,P3,AC3) -> 20228100000000 | AR3: =(L3+Y3+AL3)/3 -> 1142854000000 | AS3: =MIN(L3,Y3,AL3) -> 941012000000 | AT3: =MAX(L3,Y3,AL3) -> 1265520000000
A4: 0.00197987 | B4: 0.00242247 | C4: 20798000000000 | D4: 275881000 | E4: 0 | F4: 0 | G4: 2 | H4: 5045460000000 | I4: 4451140000000 | J4: 4329550000000 | K4: 4496790000000 | L4: 2475070000000 | N4: 0.00202976 | O4: 0.00248025 | P4: 20680600000000 | Q4: 491885000 | R4: 0 | S4: 0 | T4: 2 | U4: 5231830000000 | V4: 4201570000000 | W4: 4572470000000 | X4: 4497870000000 | Y4: 2176840000000 | AA4: 0.00199238 | AB4: 0.00240337 | AC4: 20296200000000 | AD4: 505278000 | AE4: 0 | AF4: 0 | AG4: 2 | AH4: 4756650000000 | AI4: 4557950000000 | AJ4: 4585850000000 | AK4: 4503190000000 | AL4: 1892430000000 | AN4: =A4 -> 0.00197987 | AO4: =(C4+P4+AC4)/3 -> 20591600000000 | AP4: =MIN(C4,P4,AC4) -> 20296200000000 | AQ4: =MAX(C4,P4,AC4) -> 20798000000000 | AR4: =(L4+Y4+AL4)/3 -> 2.1814467e+12 | AS4: =MIN(L4,Y4,AL4) -> 1892430000000 | AT4: =MAX(L4,Y4,AL4) -> 2475070000000
A5: 0.00297193 | B5: 0.00346419 | C5: 21002700000000 | D5: 817219000 | E5: 0 | F5: 0 | G5: 2 | H5: 4824350000000 | I5: 4174700000000 | J5: 3956210000000 | K5: 4265430000000 | L5: 3781840000000 | N5: 0.0030084 | O5: 0.00347723 | P5: 21295500000000 | Q5: 706425000 | R5: 0 | S5: 0 | T5: 2 | U5: 5109600000000 | V5: 4276210000000 | W5: 4247010000000 | X5: 4499770000000 | Y5: 3162850000000 | AA5: 0.00301052 | AB5: 0.00344599 | AC5: 20598800000000 | AD5: 311673000 | AE5: 0 | AF5: 0 | AG5: 2 | AH5: 4718040000000 | AI5: 4698140000000 | AJ5: 4353040000000 | AK5: 4352980000000 | AL5: 2476560000000 | AN5: =A5 -> 0.00297193 | AO5: =(C5+P5+AC5)/3 -> 2.0965667e+13 | AP5: =MIN(C5,P5,AC5) -> 20598800000000 | AQ5: =MAX(C5,P5,AC5) -> 21295500000000 | AR5: =(L5+Y5+AL5)/3 -> 3.1404167e+12 | AS5: =MIN(L5,Y5,AL5) -> 2476560000000 | AT5: =MAX(L5,Y5,AL5) -> 3781840000000
A6: 0.00397339 | B6: 0.00445459 | C6: 20869700000000 | D6: 475129000 | E6: 0 | F6: 0 | G6: 2 | H6: 5106220000000 | I6: 3784680000000 | J6: 3856790000000 | K6: 3896660000000 | L6: 4225300000000 | N6: 0.00400344 | O6: 0.0044356 | P6: 20691500000000 | Q6: 822505000 | R6: 0 | S6: 0 | T6: 2 | U6: 4977880000000 | V6: 4218040000000 | W6: 4151000000000 | X6: 4156780000000 | Y6: 3187740000000 | AA6: 0.00398633 | AB6: 0.00445618 | AC6: 20806300000000 | AD6: 473911000 | AE6: 0 | AF6: 0 | AG6: 2 | AH6: 4610070000000 | AI6: 4683980000000 | AJ6: 4398360000000 | AK6: 4441140000000 | AL6: 2672570000000 | AN6: =A6 -> 0.00397339 | AO6: =(C6+P6+AC6)/3 -> 2.0789167e+13 | AP6: =MIN(C6,P6,AC6) -> 20691500000000 | AQ6: =MAX(C6,P6,AC6) -> 20869700000000 | AR6: =(L6+Y6+AL6)/3 -> 3361870000000 | AS6: =MIN(L6,Y6,AL6) -> 2672570000000 | AT6: =MAX(L6,Y6,AL6) -> 4225300000000
A7: 0.00500065 | B7: 0.00543459 | C7: 21144800000000 | D7: 472095000 | E7: 0 | F7: 0 | G7: 2 | H7: 4933350000000 | I7: 4155220000000 | J7: 4135760000000 | K7: 3968790000000 | L7: 3951650000000 | N7: 0.00499299 | O7: 0.00543371 | P7: 20515500000000 | Q7: 538150000 | R7: 0 | S7: 0 | T7: 2 | U7: 4977720000000 | V7: 4046650000000 | W7: 4305910000000 | X7: 4143990000000 | Y7: 3041150000000 | AA7: 0.00499157 | AB7: 0.00546736 | AC7: 20758300000000 | AD7: 516826000 | AE7: 0 | AF7: 0 | AG7: 2 | AH7: 4530450000000 | AI7: 4408180000000 | AJ7: 4242930000000 | AK7: 4399820000000 | AL7: 3176700000000 | AN7: =A7 -> 0.00500065 | AO7: =(C7+P7+AC7)/3 -> 20806200000000 | AP7: =MIN(C7,P7,AC7) -> 20515500000000 | AQ7: =MAX(C7,P7,AC7) -> 21144800000000 | AR7: =(L7+Y7+AL7)/3 -> 3.3898333e+12 | AS7: =MIN(L7,Y7,AL7) -> 3041150000000 | AT7: =MAX(L7,Y7,AL7) -> 3951650000000
A8: 0.00594836 | B8: 0.00642416 | C8: 21086700000000 | D8: 661525000 | E8: 0 | F8: 0 | G8: 2 | H8: 5098270000000 | I8: 4074880000000 | J8: 4060550000000 | K8: 3873540000000 | L8: 3979190000000 | N8: 0.00599919 | O8: 0.00647495 | P8: 20806900000000 | Q8: 572974000 | R8: 0 | S8: 0 | T8: 2 | U8: 5081380000000 | V8: 4034080000000 | W8: 4141060000000 | X8: 4237790000000 | Y8: 3312620000000 | AA8: 0.00598184 | AB8: 0.00645897 | AC8: 20645500000000 | AD8: 385632000 | AE8: 0 | AF8: 0 | AG8: 2 | AH8: 4335190000000 | AI8: 4423010000000 | AJ8: 4295620000000 | AK8: 4371430000000 | AL8: 3216460000000 | AN8: =A8 -> 0.00594836 | AO8: =(C8+P8+AC8)/3 -> 2.0846367e+13 | AP8: =MIN(C8,P8,AC8) -> 20645500000000 | AQ8: =MAX(C8,P8,AC8) -> 21086700000000 | AR8: =(L8+Y8+AL8)/3 -> 3.5027567e+12 | AS8: =MIN(L8,Y8,AL8) -> 3216460000000 | AT8: =MAX(L8,Y8,AL8) -> 3979190000000
A9: 0.00697824 | B9: 0.007445 | C9: 20710600000000 | D9: 526081000 | E9: 0 | F9: 0 | G9: 2 | H9: 5041090000000 | I9: 4215870000000 | J9: 4121690000000 | K9: 3735780000000 | L9: 3595360000000 | N9: 0.00699065 | O9: 0.00751082 | P9: 20972700000000 | Q9: 561006000 | R9: 0 | S9: 0 | T9: 2 | U9: 4959060000000 | V9: 4205390000000 | W9: 4124200000000 | X9: 4085200000000 | Y9: 3598710000000 | AA9: 0.00702116 | AB9: 0.00751183 | AC9: 21043200000000 | AD9: 504647000 | AE9: 0 | AF9: 0 | AG9: 2 | AH9: 4688520000000 | AI9: 4496130000000 | AJ9: 4539380000000 | AK9: 4203180000000 | AL9: 3116020000000 | AN9: =A9 -> 0.00697824 | AO9: =(C9+P9+AC9)/3 -> 2.0908833e+13 | AP9: =MIN(C9,P9,AC9) -> 20710600000000 | AQ9: =MAX(C9,P9,AC9) -> 21043200000000 | AR9: =(L9+Y9+AL9)/3 -> 3.4366967e+12 | AS9: =MIN(L9,Y9,AL9) -> 3116020000000 | AT9: =MAX(L9,Y9,AL9) -> 3598710000000
A10: 0.00802007 | B10: 0.00848553 | C10: 21228800000000 | D10: 582731000 | E10: 0 | F10: 0 | G10: 2 | H10: 4794650000000 | I10: 3934640000000 | J10: 4430960000000 | K10: 3949550000000 | L10: 4118700000000 | N10: 0.00798197 | O10: 0.00844559 | P10: 20960100000000 | Q10: 922266000 | R10: 0 | S10: 0 | T10: 2 | U10: 5008800000000 | V10: 4059400000000 | W10: 4217190000000 | X10: 3927040000000 | Y10: 3747700000000 | AA10: 0.00800037 | AB10: 0.0085095 | AC10: 21069300000000 | AD10: 605722000 | AE10: 0 | AF10: 0 | AG10: 2 | AH10: 4327180000000 | AI10: 4137120000000 | AJ10: 4503730000000 | AK10: 4221890000000 | AL10: 3878980000000 | AN10: =A10 -> 0.00802007 | AO10: =(C10+P10+AC10)/3 -> 2.1086067e+13 | AP10: =MIN(C10,P10,AC10) -> 20960100000000 | AQ10: =MAX(C10,P10,AC10) -> 21228800000000 | AR10: =(L10+Y10+AL10)/3 -> 3.9151267e+12 | AS10: =MIN(L10,Y10,AL10) -> 3747700000000 | AT10: =MAX(L10,Y10,AL10) -> 4118700000000
A11: 0.00900566 | B11: 0.00950179 | C11: 21274500000000 | D11: 976153000 | E11: 0 | F11: 0 | G11: 2 | H11: 4978570000000 | I11: 3868250000000 | J11: 3788180000000 | K11: 3996860000000 | L11: 4642470000000 | N11: 0.00896409 | O11: 0.00945983 | P11: 21117000000000 | Q11: 545714000 | R11: 0 | S11: 0 | T11: 2 | U11: 4897360000000 | V11: 4048250000000 | W11: 4000920000000 | X11: 3933180000000 | Y11: 4237230000000 | AA11: 0.00897995 | AB11: 0.00949323 | AC11: 21365600000000 | AD11: 486525000 | AE11: 0 | AF11: 0 | AG11: 2 | AH11: 4523070000000 | AI11: 4516720000000 | AJ11: 4544050000000 | AK11: 4576180000000 | AL11: 3205490000000 | AN11: =A11 -> 0.00900566 | AO11: =(C11+P11+AC11)/3 -> 2.1252367e+13 | AP11: =MIN(C11,P11,AC11) -> 21117000000000 | AQ11: =MAX(C11,P11,AC11) -> 21365600000000 | AR11: =(L11+Y11+AL11)/3 -> 4.0283967e+12 | AS11: =MIN(L11,Y11,AL11) -> 3205490000000 | AT11: =MAX(L11,Y11,AL11) -> 4642470000000
A12: 0.0099903 | B12: 0.0104918 | C12: 21322400000000 | D12: 806413000 | E12: 0 | F12: 0 | G12: 2 | H12: 4906360000000 | I12: 3930400000000 | J12: 3798740000000 | K12: 3923850000000 | L12: 4762710000000 | N12: 0.0100335 | O12: 0.0105304 | P12: 21614000000000 | Q12: 833056000 | R12: 0 | S12: 0 | T12: 2 | U12: 4580360000000 | V12: 4299230000000 | W12: 4434940000000 | X12: 3940500000000 | Y12: 4358930000000 | AA12: 0.00992246 | AB12: 0.0104233 | AC12: 21134500000000 | AD12: 872521000 | AE12: 0 | AF12: 0 | AG12: 2 | AH12: 4580880000000 | AI12: 4303280000000 | AJ12: 4059870000000 | AK12: 4329580000000 | AL12: 3860740000000 | AN12: =A12 -> 0.0099903 | AO12: =(C12+P12+AC12)/3 -> 2.1356967e+13 | AP12: =MIN(C12,P12,AC12) -> 21134500000000 | AQ12: =MAX(C12,P12,AC12) -> 21614000000000 | AR12: =(L12+Y12+AL12)/3 -> 4327460000000 | AS12: =MIN(L12,Y12,AL12) -> 3860740000000 | AT12: =MAX(L12,Y12,AL12) -> 4762710000000
A13: 0.0110013 | B13: 0.0115031 | C13: 20847300000000 | D13: 539465000 | E13: 0 | F13: 0 | G13: 2 | H13: 4482090000000 | I13: 3852600000000 | J13: 3657040000000 | K13: 3720780000000 | L13: 5132140000000 | N13: 0.0109727 | O13: 0.0114747 | P13: 21325900000000 | Q13: 645656000 | R13: 0 | S13: 0 | T13: 2 | U13: 4535160000000 | V13: 3938970000000 | W13: 4212380000000 | X13: 4410920000000 | Y13: 4227370000000 | AA13: 0.0110035 | AB13: 0.0114838 | AC13: 21037100000000 | AD13: 479838000 | AE13: 0 | AF13: 0 | AG13: 2 | AH13: 4583120000000 | AI13: 4246800000000 | AJ13: 4143080000000 | AK13: 4224510000000 | AL13: 3839100000000 | AN13: =A13 -> 0.0110013 | AO13: =(C13+P13+AC13)/3 -> 21070100000000 | AP13: =MIN(C13,P13,AC13) -> 20847300000000 | AQ13: =MAX(C13,P13,AC13) -> 21325900000000 | AR13: =(L13+Y13+AL13)/3 -> 4.3995367e+12 | AS13: =MIN(L13,Y13,AL13) -> 3839100000000 | AT13: =MAX(L13,Y13,AL13) -> 5132140000000
... A52: 0.0500052 | B52: 0.0504826 | C52: 20938100000000 | D52: 913599000 | E52: 0 | F52: 0 | G52: 2 | H52: 4243340000000 | I52: 3611200000000 | J52: 3446160000000 | K52: 4036590000000 | L52: 5600470000000 | N52: 0.0499872 | O52: 0.0504323 | P52: 22199000000000 | Q52: 490599000 | R52: 0 | S52: 0 | T52: 2 | U52: 4316230000000 | V52: 4383660000000 | W52: 4684290000000 | X52: 4156470000000 | Y52: 4656760000000 | AA52: 0.049981 | AB52: 0.0505218 | AC52: 21419100000000 | AD52: 585893000 | AE52: 0 | AF52: 0 | AG52: 2 | AH52: 3968960000000 | AI52: 4193830000000 | AJ52: 4358950000000 | AK52: 4274710000000 | AL52: 4622630000000 | AN52: =A52 -> 0.0500052 | AO52: =(C52+P52+AC52)/3 -> 2.1518733e+13 | AP52: =MIN(C52,P52,AC52) -> 20938100000000 | AQ52: =MAX(C52,P52,AC52) -> 22199000000000 | AR52: =(L52+Y52+AL52)/3 -> 4.9599533e+12 | AS52: =MIN(L52,Y52,AL52) -> 4622630000000 | AT52: =MAX(L52,Y52,AL52) -> 5600470000000
N53: 0.0509776 | O53: 0.0514773 | P53: 21823500000000 | Q53: 521126000 | R53: 0 | S53: 0 | T53: 2 | U53: 4575850000000 | V53: 4211480000000 | W53: 4143720000000 | X53: 4117340000000 | Y53: 4773810000000 | AA53: 0.051024 | AB53: 0.0515562 | AC53: 21278600000000 | AD53: 662330000 | AE53: 0 | AF53: 0 | AG53: 2 | AH53: 4063310000000 | AI53: 4231860000000 | AJ53: 3977630000000 | AK53: 4238840000000 | AL53: 4766860000000
N54: 0.0520144 | O54: 0.0524722 | P54: 21506500000000 | Q54: 416250000 | R54: 0 | S54: 0 | T54: 2 | U54: 4735230000000 | V54: 4474170000000 | W54: 4215310000000 | X54: 4584230000000 | Y54: 3497440000000 | AA54: 0.0520175 | AB54: 0.0525219 | AC54: 21165900000000 | AD54: 774633000 | AE54: 0 | AF54: 0 | AG54: 2 | AH54: 4090300000000 | AI54: 4009300000000 | AJ54: 3890360000000 | AK54: 4352620000000 | AL54: 4823170000000
N55: 0.0529575 | O55: 0.0534361 | P55: 21062000000000 | Q55: 370373000 | R55: 0 | S55: 0 | T55: 2 | U55: 4984110000000 | V55: 4250200000000 | W55: 4106840000000 | X55: 4143750000000 | Y55: 3577080000000 | AA55: 0.0529076 | AB55: 0.0534111 | AC55: 21106300000000 | AD55: 401509000 | AE55: 0 | AF55: 0 | AG55: 2 | AH55: 4088000000000 | AI55: 3730990000000 | AJ55: 4021670000000 | AK55: 4475560000000 | AL55: 4790090000000
N56: 0.0539645 | O56: 0.0544469 | P56: 21370100000000 | Q56: 464447000 | R56: 0 | S56: 0 | T56: 2 | U56: 4906740000000 | V56: 4279600000000 | W56: 4065550000000 | X56: 4234450000000 | Y56: 3883680000000
N57: 0.0550027 | O57: 0.0554879 | P57: 21613300000000 | Q57: 556232000 | R57: 0 | S57: 0 | T57: 2 | U57: 5089640000000 | V57: 4281390000000 | W57: 4380260000000 | X57: 4293240000000 | Y57: 3568720000000
N58: 0.0560003 | O58: 0.0565048 | P58: 21835400000000 | Q58: 501897000 | R58: 0 | S58: 0 | T58: 2 | U58: 5091820000000 | V58: 4314830000000 | W58: 4229640000000 | X58: 4188630000000 | Y58: 4010480000000

Sheet 400K_SR40_Stress
A1: Config 1 | D1: Config 2 | G1: Config3 | J1: AverageValue of Last 0.5%
A2: 0.000200299 | B2: 61877100 | D2: 0.00018897 | E2: 64572300 | G2: 0.000188535 | H2: 59298700 | K2: TotalStress | L2: RhoI | M2: Rho | N2: TauF1 | O2: TauF2 | P2: TauF | Q2: Tau | R2: Tau/TauF | S2: RhoI/Rho
A3: 0.0009834 | B3: 92521100 | D3: 0.00103417 | E3: 91879500 | G3: 0.000998393 | H3: 88800400 | J3: Config1 | K3: =AVERAGE(B28:B32)/1000000 -> 109.8856 | L3: =AVERAGE('400K_SR40'!L28:L32) -> 3536872000000 | M3: =AVERAGE('400K_SR40'!C28:C32) -> 21882200000000 | N3: =Graphs!$B$1*80.9*0.248*SQRT(L3)/1000000 -> 18.866002 | O3: =Graphs!$B$2*80.9*0.248*SQRT(M3)/1000000 -> 4.6926234 | P3: =SQRT(N3^2+O3^2) -> 19.440853 | Q3: =K3*0.4707 -> 51.723152 | R3: =Q3/P3 -> 2.6605393 | S3: =L3/M3 -> 0.16163238
A4: 0.0020135 | B4: 102228000 | D4: 0.00199645 | E4: 105048000 | G4: 0.00201971 | H4: 95055400 | J4: Config2 | K4: =AVERAGE(E28:E32)/1000000 -> 111.0328 | L4: =AVERAGE('400K_SR40'!Y28:Y32) -> 3978228000000 | M4: =AVERAGE('400K_SR40'!P28:P32) -> 21689660000000 | N4: =Graphs!$B$1*80.9*0.248*SQRT(L4)/1000000 -> 20.008523 | O4: =Graphs!$B$2*80.9*0.248*SQRT(M4)/1000000 -> 4.6719327 | P4: =SQRT(N4^2+O4^2) -> 20.546726 | Q4: =K4*0.4707 -> 52.263139 | R4: =Q4/P4 -> 2.5436236 | S4: =L4/M4 -> 0.18341588
A5: 0.00298985 | B5: 107563000 | D5: 0.0029962 | E5: 104653000 | G5: 0.00301403 | H5: 109357000 | J5: Config3 | K5: =AVERAGE(H28:H32)/1000000 -> 110.4832 | L5: =AVERAGE('400K_SR40'!AL28:AL32) -> 3661616000000 | M5: =AVERAGE('400K_SR40'!AC28:AC32) -> 21628540000000 | N5: =Graphs!$B$1*80.9*0.248*SQRT(L5)/1000000 -> 19.195817 | O5: =Graphs!$B$2*80.9*0.248*SQRT(M5)/1000000 -> 4.6653455 | P5: =SQRT(N5^2+O5^2) -> 19.754616 | Q5: =K5*0.4707 -> 52.004442 | R5: =Q5/P5 -> 2.6325211 | S5: =L5/M5 -> 0.16929557
A6: 0.00397897 | B6: 103191000 | D6: 0.00400079 | E6: 110949000 | G6: 0.00399261 | H6: 109618000
A7: 0.00499823 | B7: 109701000 | D7: 0.0049942 | E7: 109139000 | G7: 0.00501898 | H7: 112882000
A8: 0.00598766 | B8: 109110000 | D8: 0.00597956 | E8: 110451000 | G8: 0.00599668 | H8: 107767000
A9: 0.00697675 | B9: 109040000 | D9: 0.00697128 | E9: 112591000 | G9: 0.00700269 | H9: 104616000 | J9: Config1 | K9: =AVERAGE(B12:B16)/1000000 -> 114.3706 | L9: =AVERAGE('400K_SR40'!L12:L16) -> 4072418000000 | M9: =AVERAGE('400K_SR40'!C12:C16) -> 22298520000000 | N9: =Graphs!$B$1*80.9*0.248*SQRT(L9)/1000000 -> 20.244002 | O9: =Graphs!$B$2*80.9*0.248*SQRT(M9)/1000000 -> 4.7370528 | P9: =SQRT(N9^2+O9^2) -> 20.790847 | Q9: =K9*0.4707 -> 53.834241 | R9: =Q9/P9 -> 2.5893242 | S9: =L9/M9 -> 0.18263176
A10: 0.00799115 | B10: 103822000 | D10: 0.00803373 | E10: 107173000 | G10: 0.00799832 | H10: 110260000 | J10: Config2 | K10: =AVERAGE(E12:E16)/1000000 -> 109.9654 | L10: =AVERAGE('400K_SR40'!Y12:Y16) -> 4449282000000 | M10: =AVERAGE('400K_SR40'!P12:P16) -> 21780640000000 | N10: =Graphs!$B$1*80.9*0.248*SQRT(L10)/1000000 -> 21.159976 | O10: =Graphs!$B$2*80.9*0.248*SQRT(M10)/1000000 -> 4.681721 | P10: =SQRT(N10^2+O10^2) -> 21.671712 | Q10: =K10*0.4707 -> 51.760714 | R10: =Q10/P10 -> 2.3883999 | S10: =L10/M10 -> 0.20427692
A11: 0.00897785 | B11: 107802000 | D11: 0.00899369 | E11: 112009000 | G11: 0.00902476 | H11: 104703000 | J11: Config3 | K11: =AVERAGE(H12:H16)/1000000 -> 108.7624 | L11: =AVERAGE('400K_SR40'!AL12:AL16) -> 3497148000000 | M11: =AVERAGE('400K_SR40'!AC12:AC16) -> 21628180000000 | N11: =Graphs!$B$1*80.9*0.248*SQRT(L11)/1000000 -> 18.759757 | O11: =Graphs!$B$2*80.9*0.248*SQRT(M11)/1000000 -> 4.6653066 | P11: =SQRT(N11^2+O11^2) -> 19.331156 | Q11: =K11*0.4707 -> 51.194462 | R11: =Q11/P11 -> 2.6482877 | S11: =L11/M11 -> 0.16169405
A12: 0.00998248 | B12: 113139000 | D12: 0.00999467 | E12: 114148000 | G12: 0.00990508 | H12: 108161000
A13: 0.011009 | B13: 114756000 | D13: 0.0110127 | E13: 106705000 | G13: 0.0109868 | H13: 115082000
A14: 0.0119627 | B14: 114934000 | D14: 0.0119983 | E14: 109162000 | G14: 0.0120279 | H14: 109536000
A15: 0.0130151 | B15: 114829000 | D15: 0.0130203 | E15: 109481000 | G15: 0.0130108 | H15: 106847000
A16: 0.014013 | B16: 114195000 | D16: 0.0140089 | E16: 110331000 | G16: 0.0139805 | H16: 104186000
A17: 0.0149773 | B17: 112053000 | D17: 0.0149751 | E17: 114153000 | G17: 0.0150274 | H17: 105637000
A18: 0.0159849 | B18: 103202000 | D18: 0.0160076 | E18: 113801000 | G18: 0.0159683 | H18: 117937000
A19: 0.0170388 | B19: 110739000 | D19: 0.0170012 | E19: 109639000 | G19: 0.0169766 | H19: 109520000
A20: 0.0180022 | B20: 113532000 | D20: 0.0180101 | E20: 116822000 | G20: 0.0179848 | H20: 107745000
A21: 0.0189797 | B21: 115660000 | D21: 0.0189844 | E21: 115760000 | G21: 0.0190148 | H21: 111717000
A22: 0.0199746 | B22: 103959000 | D22: 0.0200084 | E22: 106761000 | G22: 0.0200384 | H22: 113895000
A23: 0.0210202 | B23: 101769000 | D23: 0.0210205 | E23: 99571100 | G23: 0.0209673 | H23: 111274000
... A26: 0.0240501 | B26: 109118000 | D26: 0.0239685 | E26: 108950000 | G26: 0.0239929 | H26: 116840000
A27: 0.0249972 | B27: 108735000 | D27: 0.024996 | E27: 102799000 | G27: 0.0249534 | H27: 121137000 | W27: =200*1.414 -> 282.8
A28: 0.0259852 | B28: 111239000 | D28: 0.026019 | E28: 108831000 | G28: 0.0260011 | H28: 110771000
A29: 0.0270025 | B29: 112307000 | D29: 0.0269998 | E29: 113819000 | G29: 0.0270144 | H29: 109934000
A30: 0.0280224 | B30: 107355000 | D30: 0.0280511 | E30: 110155000 | G30: 0.028009 | H30: 111191000
A31: 0.0289825 | B31: 113734000 | D31: 0.0289441 | E31: 115041000 | G31: 0.0289967 | H31: 110755000
A32: 0.030026 | B32: 104793000 | D32: 0.0299154 | E32: 107318000 | G32: 0.0300111 | H32: 109765000
A33: 0.0309942 | B33: 111043000 | D33: 0.0310391 | E33: 105588000 | G33: 0.0310224 | H33: 105937000
A34: 0.0319944 | B34: 110893000 | D34: 0.0319526 | E34: 106055000 | G34: 0.0319385 | H34: 115716000
A35: 0.0329684 | B35: 111268000 | D35: 0.0330534 | E35: 115095000 | G35: 0.0329802 | H35: 112921000
A36: 0.0339924 | B36: 108177000 | D36: 0.0340329 | E36: 116873000 | G36: 0.0340239 | H36: 107891000
A37: 0.0350067 | B37: 110273000 | D37: 0.0349998 | E37: 105915000 | G37: 0.0350149 | H37: 99848200
A38: 0.036004 | B38: 110577000 | D38: 0.0359996 | E38: 110306000 | G38: 0.0358873 | H38: 106590000
A39: 0.0370332 | B39: 111254000 | D39: 0.0369998 | E39: 112688000 | G39: 0.036997 | H39: 108853000
... A53: 0.0509594 | B53: 112887000 | D53: 0.0510062 | E53: 113886000 | G53: 0.0510305 | H53: 102758000
D54: 0.0519854 | E54: 115625000 | G54: 0.0520006 | H54: 98599800
D55: 0.0529953 | E55: 108235000 | G55: 0.0529762 | H55: 103948000
...

Sheet 400K_SR40
A1: Config1 | N1: Config2 | AA1: Config 3 | AN1: Pstrain | AO1: Total | AP1: Totalmin | AQ1: Totalmax | AR1: Junction | AS1: Junctionmin | AT1: Junctionmax
A2: 0.000200299 | B2: 0.000495157 | C2: 19882000000000 | D2: 2078150000 | E2: 0 | F2: 0 | G2: 2 | H2: 5382190000000 | I2: 4625540000000 | J2: 4585540000000 | K2: 4605530000000 | L2: 683216000000 | N2: 0.00018897 | O2: 0.00049667 | P2: 19971000000000 | Q2: 1626590000 | R2: 0 | S2: 0 | T2: 2 | U2: 5488770000000 | V2: 4622050000000 | W2: 4665590000000 | X2: 4644580000000 | Y2: 550056000000 | AA2: 0.000188535 | AB2: 0.000471108 | AC2: 19741400000000 | AD2: 1848110000 | AE2: 0 | AF2: 0 | AG2: 2 | AH2: 4860410000000 | AI2: 4830070000000 | AJ2: 4813430000000 | AK2: 4850540000000 | AL2: 386960000000 | AN2: =A2 -> 0.000200299 | AO2: =(C2+P2+AC2)/3 -> 19864800000000 | AP2: =MIN(C2,P2,AC2) -> 19741400000000 | AQ2: =MAX(C2,P2,AC2) -> 19971000000000 | AR2: =(L2+Y2+AL2)/3 -> 5.4007733e+11 | AS2: =MIN(L2,Y2,AK2) -> 550056000000 | AT2: =MAX(L2,Y2,AL2) -> 683216000000
A3: 0.0009834 | B3: 0.00142428 | C3: 20362700000000 | D3: 295244000 | E3: 0 | F3: 0 | G3: 2 | H3: 5363940000000 | I3: 4620450000000 | J3: 4559380000000 | K3: 4659850000000 | L3: 1159060000000 | N3: 0.00103417 | O3: 0.00147199 | P3: 20396300000000 | Q3: 344362000 | R3: 0 | S3: 0 | T3: 2 | U3: 5479300000000 | V3: 4644920000000 | W3: 4573990000000 | X3: 4536950000000 | Y3: 1161040000000 | AA3: 0.000998393 | AB3: 0.00142154 | AC3: 20183600000000 | AD3: 354239000 | AE3: 0 | AF3: 0 | AG3: 2 | AH3: 4849310000000 | AI3: 4713800000000 | AJ3: 4814610000000 | AK3: 4822120000000 | AL3: 983760000000 | AN3: =A3 -> 0.0009834 | AO3: =(C3+P3+AC3)/3 -> 20314200000000 | AP3: =MIN(C3,P3,AC3) -> 20183600000000 | AQ3: =MAX(C3,P3,AC3) -> 20396300000000 | AR3: =(L3+Y3+AL3)/3 -> 1.1012867e+12 | AS3: =MIN(L3,Y3,AK3) -> 1159060000000 | AT3: =MAX(L3,Y3,AL3) -> 1161040000000
A4: 0.0020135 | B4: 0.00250063 | C4: 21344300000000 | D4: 394713000 | E4: 0 | F4: 0 | G4: 2 | H4: 5242790000000 | I4: 4545990000000 | J4: 4609620000000 | K4: 4762700000000 | L4: 2183230000000 | N4: 0.00199645 | O4: 0.00249702 | P4: 21446100000000 | Q4: 881915000 | R4: 0 | S4: 0 | T4: 2 | U4: 5686400000000 | V4: 4539670000000 | W4: 4408240000000 | X4: 4396100000000 | Y4: 2415550000000 | AA4: 0.00201971 | AB4: 0.00247266 | AC4: 20893100000000 | AD4: 947903000 | AE4: 0 | AF4: 0 | AG4: 2 | AH4: 4883500000000 | AI4: 4660640000000 | AJ4: 4903300000000 | AK4: 4824010000000 | AL4: 1621620000000 | AN4: =A4 -> 0.0020135 | AO4: =(C4+P4+AC4)/3 -> 2.1227833e+13 | AP4: =MIN(C4,P4,AC4) -> 20893100000000 | AQ4: =MAX(C4,P4,AC4) -> 21446100000000 | AR4: =(L4+Y4+AL4)/3 -> 2.0734667e+12 | AS4: =MIN(L4,Y4,AK4) -> 2183230000000 | AT4: =MAX(L4,Y4,AL4) -> 2415550000000
A5: 0.00298985 | B5: 0.0035024 | C5: 22069300000000 | D5: 1228010000 | E5: 0 | F5: 0 | G5: 2 | H5: 5544420000000 | I5: 4177240000000 | J5: 4491980000000 | K5: 4874040000000 | L5: 2981640000000 | N5: 0.0029962 | O5: 0.00349488 | P5: 21539100000000 | Q5: 630920000 | R5: 0 | S5: 0 | T5: 2 | U5: 5277950000000 | V5: 4450700000000 | W5: 4645260000000 | X5: 4196270000000 | Y5: 2968840000000 | AA5: 0.00301403 | AB5: 0.00353513 | AC5: 21769500000000 | AD5: 895175000 | AE5: 0 | AF5: 0 | AG5: 2 | AH5: 4438780000000 | AI5: 4385940000000 | AJ5: 4925560000000 | AK5: 4977090000000 | AL5: 3042030000000 | AN5: =A5 -> 0.00298985 | AO5: =(C5+P5+AC5)/3 -> 2.1792633e+13 | AP5: =MIN(C5,P5,AC5) -> 21539100000000 | AQ5: =MAX(C5,P5,AC5) -> 22069300000000 | AR5: =(L5+Y5+AL5)/3 -> 2.9975033e+12 | AS5: =MIN(L5,Y5,AK5) -> 2968840000000 | AT5: =MAX(L5,Y5,AL5) -> 3042030000000
A6: 0.00397897 | B6: 0.00447069 | C6: 21781500000000 | D6: 1236180000 | E6: 0 | F6: 0 | G6: 2 | H6: 5436630000000 | I6: 4350520000000 | J6: 4402140000000 | K6: 4349540000000 | L6: 3242550000000 | N6: 0.00400079 | O6: 0.00452947 | P6: 21609200000000 | Q6: 629654000 | R6: 0 | S6: 0 | T6: 2 | U6: 5162540000000 | V6: 4640090000000 | W6: 4333300000000 | X6: 4163250000000 | Y6: 3309760000000 | AA6: 0.00399261 | AB6: 0.00451496 | AC6: 21429000000000 | AD6: 1172250000 | AE6: 0 | AF6: 0 | AG6: 2 | AH6: 4629380000000 | AI6: 4437790000000 | AJ6: 4658330000000 | AK6: 4541800000000 | AL6: 3161550000000 | AN6: =A6 -> 0.00397897 | AO6: =(C6+P6+AC6)/3 -> 2.1606567e+13 | AP6: =MIN(C6,P6,AC6) -> 21429000000000 | AQ6: =MAX(C6,P6,AC6) -> 21781500000000 | AR6: =(L6+Y6+AL6)/3 -> 3.2379533e+12 | AS6: =MIN(L6,Y6,AK6) -> 3242550000000 | AT6: =MAX(L6,Y6,AL6) -> 3309760000000
A7: 0.00499823 | B7: 0.00552097 | C7: 21668000000000 | D7: 1061690000 | E7: 0 | F7: 0 | G7: 2 | H7: 5371370000000 | I7: 4162530000000 | J7: 4213800000000 | K7: 4527200000000 | L7: 3393060000000 | N7: 0.0049942 | O7: 0.00551426 | P7: 22092500000000 | Q7: 1122910000 | R7: 0 | S7: 0 | T7: 2 | U7: 5115200000000 | V7: 4673930000000 | W7: 4464230000000 | X7: 4105640000000 | Y7: 3733380000000 | AA7: 0.00501898 | AB7: 0.00555689 | AC7: 21812200000000 | AD7: 779386000 | AE7: 0 | AF7: 0 | AG7: 2 | AH7: 4228520000000 | AI7: 4931040000000 | AJ7: 4415330000000 | AK7: 4478930000000 | AL7: 3758060000000 | AN7: =A7 -> 0.00499823 | AO7: =(C7+P7+AC7)/3 -> 2.1857567e+13 | AP7: =MIN(C7,P7,AC7) -> 21668000000000 | AQ7: =MAX(C7,P7,AC7) -> 22092500000000 | AR7: =(L7+Y7+AL7)/3 -> 3.6281667e+12 | AS7: =MIN(L7,Y7,AK7) -> 3393060000000 | AT7: =MAX(L7,Y7,AL7) -> 3758060000000
A8: 0.00598766 | B8: 0.00650759 | C8: 22036400000000 | D8: 1026910000 | E8: 0 | F8: 0 | G8: 2 | H8: 5730010000000 | I8: 4036100000000 | J8: 4117780000000 | K8: 4344930000000 | L8: 3807540000000 | N8: 0.00597956 | O8: 0.00650587 | P8: 21665400000000 | Q8: 825541000 | R8: 0 | S8: 0 | T8: 2 | U8: 5452290000000 | V8: 4339100000000 | W8: 4349320000000 | X8: 3936530000000 | Y8: 3588180000000 | AA8: 0.00599668 | AB8: 0.0065102 | AC8: 21935500000000 | AD8: 954836000 | AE8: 0 | AF8: 0 | AG8: 2 | AH8: 4405180000000 | AI8: 4872010000000 | AJ8: 4319140000000 | AK8: 4796210000000 | AL8: 3542880000000 | AN8: =A8 -> 0.00598766 | AO8: =(C8+P8+AC8)/3 -> 21879100000000 | AP8: =MIN(C8,P8,AC8) -> 21665400000000 | AQ8: =MAX(C8,P8,AC8) -> 22036400000000 | AR8: =(L8+Y8+AL8)/3 -> 3646200000000 | AS8: =MIN(L8,Y8,AK8) -> 3588180000000 | AT8: =MAX(L8,Y8,AL8) -> 3807540000000
A9: 0.00697675 | B9: 0.00749634 | C9: 21909100000000 | D9: 1122460000 | E9: 0 | F9: 0 | G9: 2 | H9: 5159370000000 | I9: 3712380000000 | J9: 4006880000000 | K9: 4774480000000 | L9: 4255480000000 | N9: 0.00697128 | O9: 0.00750779 | P9: 21403800000000 | Q9: 825579000 | R9: 0 | S9: 0 | T9: 2 | U9: 5387220000000 | V9: 4249660000000 | W9: 3899050000000 | X9: 4084260000000 | Y9: 3783390000000 | AA9: 0.00700269 | AB9: 0.0075012 | AC9: 21502500000000 | AD9: 991293000 | AE9: 0 | AF9: 0 | AG9: 2 | AH9: 4331640000000 | AI9: 4828810000000 | AJ9: 4515400000000 | AK9: 4625080000000 | AL9: 3200660000000 | AN9: =A9 -> 0.00697675 | AO9: =(C9+P9+AC9)/3 -> 2.1605133e+13 | AP9: =MIN(C9,P9,AC9) -> 21403800000000 | AQ9: =MAX(C9,P9,AC9) -> 21909100000000 | AR9: =(L9+Y9+AL9)/3 -> 3746510000000 | AS9: =MIN(L9,Y9,AK9) -> 3783390000000 | AT9: =MAX(L9,Y9,AL9) -> 4255480000000
A10: 0.00799115 | B10: 0.00848588 | C10: 21446700000000 | D10: 1118930000 | E10: 0 | F10: 0 | G10: 2 | H10: 5368010000000 | I10: 3888400000000 | J10: 3910550000000 | K10: 4416990000000 | L10: 3862640000000 | N10: 0.00803373 | O10: 0.00854442 | P10: 21263900000000 | Q10: 2246770000 | R10: 0 | S10: 0 | T10: 2 | U10: 5361400000000 | V10: 4281720000000 | W10: 3810400000000 | X10: 3861810000000 | Y10: 3948470000000 | AA10: 0.00799832 | AB10: 0.00852373 | AC10: 21879600000000 | AD10: 750342000 | AE10: 0 | AF10: 0 | AG10: 2 | AH10: 4369840000000 | AI10: 4971560000000 | AJ10: 4792760000000 | AK10: 4302940000000 | AL10: 3442490000000 | AN10: =A10 -> 0.00799115 | AO10: =(C10+P10+AC10)/3 -> 2.1530067e+13 | AP10: =MIN(C10,P10,AC10) -> 21263900000000 | AQ10: =MAX(C10,P10,AC10) -> 21879600000000 | AR10: =(L10+Y10+AL10)/3 -> 3751200000000 | AS10: =MIN(L10,Y10,AK10) -> 3862640000000 | AT10: =MAX(L10,Y10,AL10) -> 3948470000000
A11: 0.00897785 | B11: 0.00949155 | C11: 21495000000000 | D11: 1088540000 | E11: 0 | F11: 0 | G11: 2 | H11: 5318180000000 | I11: 4022040000000 | J11: 4190940000000 | K11: 4387870000000 | L11: 3575810000000 | N11: 0.00899369 | O11: 0.00952743 | P11: 21726700000000 | Q11: 3588300000 | R11: 0 | S11: 0 | T11: 2 | U11: 5233030000000 | V11: 4666010000000 | W11: 4009720000000 | X11: 4260760000000 | Y11: 3557000000000 | AA11: 0.00902476 | AB11: 0.00952368 | AC11: 21854800000000 | AD11: 784806000 | AE11: 0 | AF11: 0 | AG11: 2 | AH11: 4501710000000 | AI11: 4589560000000 | AJ11: 4722600000000 | AK11: 4483620000000 | AL11: 3555600000000 | AN11: =A11 -> 0.00897785 | AO11: =(C11+P11+AC11)/3 -> 2.1692167e+13 | AP11: =MIN(C11,P11,AC11) -> 21495000000000 | AQ11: =MAX(C11,P11,AC11) -> 21854800000000 | AR11: =(L11+Y11+AL11)/3 -> 3.5628033e+12 | AS11: =MIN(L11,Y11,AK11) -> 3557000000000 | AT11: =MAX(L11,Y11,AL11) -> 3575810000000
A12: 0.00998248 | B12: 0.0105216 | C12: 21738400000000 | D12: 995518000 | E12: 0 | F12: 0 | G12: 2 | H12: 5094540000000 | I12: 4161670000000 | J12: 4307980000000 | K12: 4322920000000 | L12: 3851230000000 | N12: 0.00999467 | O12: 0.0105386 | P12: 21688400000000 | Q12: 1433810000 | R12: 0 | S12: 0 | T12: 2 | U12: 5378610000000 | V12: 4437540000000 | W12: 3891420000000 | X12: 4005390000000 | Y12: 3974810000000 | AA12: 0.00990508 | AB12: 0.0104205 | AC12: 21603200000000 | AD12: 825785000 | AE12: 0 | AF12: 0 | AG12: 2 | AH12: 4250440000000 | AI12: 4917610000000 | AJ12: 4576420000000 | AK12: 4419730000000 | AL12: 3435980000000 | AN12: =A12 -> 0.00998248 | AO12: =(C12+P12+AC12)/3 -> 2.1676667e+13 | AP12: =MIN(C12,P12,AC12) -> 21603200000000 | AQ12: =MAX(C12,P12,AC12) -> 21738400000000 | AR12: =(L12+Y12+AL12)/3 -> 3.7540067e+12 | AS12: =MIN(L12,Y12,AK12) -> 3851230000000 | AT12: =MAX(L12,Y12,AL12) -> 3974810000000
A13: 0.011009 | B13: 0.0115558 | C13: 22583400000000 | D13: 1180490000 | E13: 0 | F13: 0 | G13: 2 | H13: 5828980000000 | I13: 4134390000000 | J13: 4124270000000 | K13: 4034150000000 | L13: 4461590000000 | N13: 0.0110127 | O13: 0.0115212 | P13: 21771300000000 | Q13: 995590000 | R13: 0 | S13: 0 | T13: 2 | U13: 5302450000000 | V13: 4377920000000 | W13: 4227870000000 | X13: 3925520000000 | Y13: 3937560000000 | AA13: 0.0109868 | AB13: 0.0115351 | AC13: 21938800000000 | AD13: 1255450000 | AE13: 0 | AF13: 0 | AG13: 2 | AH13: 4241100000000 | AI13: 4802020000000 | AJ13: 4253890000000 | AK13: 4314540000000 | AL13: 4326640000000 | AN13: =A13 -> 0.011009 | AO13: =(C13+P13+AC13)/3 -> 2.2097833e+13 | AP13: =MIN(C13,P13,AC13) -> 21771300000000 | AQ13: =MAX(C13,P13,AC13) -> 22583400000000 | AR13: =(L13+Y13+AL13)/3 -> 4241930000000 | AS13: =MIN(L13,Y13,AK13) -> 3937560000000 | AT13: =MAX(L13,Y13,AL13) -> 4461590000000
... A52: 0.050023 | B52: 0.0505353 | C52: 21626000000000 | D52: 3982790000 | E52: 0 | F52: 0 | G52: 2 | H52: 4784800000000 | I52: 4240540000000 | J52: 3998080000000 | K52: 4039190000000 | L52: 4561020000000 | N52: 0.0499969 | O52: 0.0505512 | P52: 21674600000000 | Q52: 1119630000 | R52: 0 | S52: 0 | T52: 2 | U52: 4957810000000 | V52: 3954740000000 | W52: 4134970000000 | X52: 3779570000000 | Y52: 4847420000000 | AA52: 0.049996 | AB52: 0.0505242 | AC52: 21617200000000 | AD52: 1244460000 | AE52: 0 | AF52: 0 | AG52: 2 | AH52: 4200850000000 | AI52: 4619840000000 | AJ52: 4187950000000 | AK52: 4380370000000 | AL52: 4227910000000 | AN52: =A52 -> 0.050023 | AO52: =(C52+P52+AC52)/3 -> 2.1639267e+13 | AP52: =MIN(C52,P52,AC52) -> 21617200000000 | AQ52: =MAX(C52,P52,AC52) -> 21674600000000 | AR52: =(L52+Y52+AL52)/3 -> 4545450000000 | AS52: =MIN(L52,Y52,AK52) -> 4380370000000 | AT52: =MAX(L52,Y52,AL52) -> 4847420000000
A53: 0.0509594 | B53: 0.0514973 | C53: 21801400000000 | D53: 869461000 | E53: 0 | F53: 0 | G53: 2 | H53: 4983640000000 | I53: 4282490000000 | J53: 4349750000000 | K53: 4014690000000 | L53: 4170720000000 | N53: 0.0510062 | O53: 0.0515489 | P53: 22733700000000 | Q53: 1331900000 | R53: 0 | S53: 0 | T53: 2 | U53: 5242850000000 | V53: 4626500000000 | W53: 3822170000000 | X53: 4192820000000 | Y53: 4848380000000 | AA53: 0.0510305 | AB53: 0.0515201 | AC53: 21492900000000 | AD53: 647570000 | AE53: 0 | AF53: 0 | AG53: 2 | AH53: 4490720000000 | AI53: 4778630000000 | AJ53: 4575710000000 | AK53: 4521580000000 | AL53: 3126190000000
N54: 0.0519854 | O54: 0.0525364 | P54: 22274300000000 | Q54: 2082310000 | R54: 0 | S54: 0 | T54: 2 | U54: 4885910000000 | V54: 3994690000000 | W54: 4378280000000 | X54: 4379820000000 | Y54: 4635240000000 | AA54: 0.0520006 | AB54: 0.0524705 | AC54: 21478300000000 | AD54: 1259810000 | AE54: 0 | AF54: 0 | AG54: 2 | AH54: 4554460000000 | AI54: 4730560000000 | AJ54: 4483520000000 | AK54: 4581830000000 | AL54: 3127910000000
N55: 0.0529953 | O55: 0.053511 | P55: 22229500000000 | Q55: 2130220000 | R55: 0 | S55: 0 | T55: 2 | U55: 5044830000000 | V55: 3934380000000 | W55: 4345270000000 | X55: 4541380000000 | Y55: 4363640000000 | AA55: 0.0529762 | AB55: 0.0534715 | AC55: 21709800000000 | AD55: 1496670000 | AE55: 0 | AF55: 0 | AG55: 2 | AH55: 4499960000000 | AI55: 4676160000000 | AJ55: 4437840000000 | AK55: 4594340000000 | AL55: 3501280000000
N56: 0.0540649 | O56: 0.0545529 | P56: 21875100000000 | Q56: 681027000 | R56: 0 | S56: 0 | T56: 2 | U56: 5426830000000 | V56: 4137810000000 | W56: 4009680000000 | X56: 3845200000000 | Y56: 4455360000000 | AA56: 0.0540117 | AB56: 0.0545099 | AC56: 22221000000000 | AD56: 2328690000 | AE56: 0 | AF56: 0 | AG56: 2 | AH56: 4615880000000 | AI56: 4348530000000 | AJ56: 4223380000000 | AK56: 4849300000000 | AL56: 4183240000000
N57: 0.0549954 | O57: 0.0555544 | P57: 22541300000000 | Q57: 829673000 | R57: 0 | S57: 0 | T57: 2 | U57: 5353300000000 | V57: 4338680000000 | W57: 4273910000000 | X57: 3972290000000 | Y57: 4603000000000 | AA57: 0.05498 | AB57: 0.0555046 | AC57: 21417800000000 | AD57: 2153540000 | AE57: 0 | AF57: 0 | AG57: 2 | AH57: 4274790000000 | AI57: 4182760000000 | AJ57: 4283360000000 | AK57: 4578510000000 | AL57: 4097860000000
N58: 0.0560102 | O58: 0.0565396 | P58: 22715100000000 | Q58: 1575290000 | R58: 0 | S58: 0 | T58: 2 | U58: 5580390000000 | V58: 4395590000000 | W58: 4432030000000 | X58: 3891340000000 | Y58: 4415690000000 | AA58: 0.0559271 | AB58: 0.0564474 | AC58: 21917400000000 | AD58: 1133770000 | AE58: 0 | AF58: 0 | AG58: 2 | AH58: 4506650000000 | AI58: 4416370000000 | AJ58: 4081720000000 | AK58: 4890350000000 | AL58: 4022040000000
N59: 0.0570144 | O59: 0.0575244 | P59: 23280400000000 | Q59: 1560060000 | R59: 0 | S59: 0 | T59: 2 | U59: 5442950000000 | V59: 4812290000000 | W59: 4534540000000 | X59: 4220450000000 | Y59: 4269660000000

Sheet 400K_SR100_Stress
A1: Config 1 | D1: Config 2 | G1: Config3 | J1: AverageValue of Last 0.5%
A2: 0.000155883 | B2: 69729500 | D2: 0.000196169 | E2: 73268700 | G2: 0.000179591 | H2: 71795600 | K2: TotalStress | L2: RhoI | M2: Rho | N2: TauF1 | O2: TauF2 | P2: TauF | Q2: Tau | R2: Tau/TauF | S2: RhoI/Rho
A3: 0.00102797 | B3: 94937300 | D3: 0.0010481 | E3: 105376000 | G3: 0.00102515 | H3: 93099300 | J3: Config1 | K3: =AVERAGE(B28:B32)/1000000 -> 123.277 | L3: =AVERAGE('400K_SR100'!L28:L32) -> 3903980000000 | M3: =AVERAGE('400K_SR100'!C28:C32) -> 23728400000000 | N3: =Graphs!$B$1*80.9*0.248*SQRT(L3)/1000000 -> 19.820929 | O3: =Graphs!$B$2*80.9*0.248*SQRT(M3)/1000000 -> 4.8865735 | P3: =SQRT(N3^2+O3^2) -> 20.414402 | Q3: =K3*0.4707 -> 58.026484 | R3: =Q3/P3 -> 2.8424288 | S3: =L3/M3 -> 0.16452774
