Workbook

Sheet 300K_SR10_Stress
A1: Config1 | D1: Config2 | G1: Config3 | K1: AverageValue of Last 0.5%
A2: 0.000217211 | B2: 76872000 | D2: 0.000196448 | E2: 72888400 | G2: 0.000179529 | H2: 71476700 | L2: TotalStress | M2: RhoI | N2: Rho | O2: TauF1 | P2: TauF2 | Q2: TauF | R2: Tau | S2: Tau/TauF | T2: RhoI/Rho
A3: 0.000993712 | B3: 97295100 | D3: 0.00104168 | E3: 96476800 | G3: 0.00102323 | H3: 100551000 | K3: Config1 | L3: 119 | M3: 3730000000000 | N3: 20700000000000 | O3: =0.5*80.9*0.248*SQRT(M3)/1000000 -> 19.374238 | P3: =0.05*80.9*0.248*SQRT(N3)/1000000 -> 4.5641024 | Q3: =SQRT(O3^2+P3^2) -> 19.904575 | R3: =L3*0.4395 -> 52.3005 | S3: =R3/Q3 -> 2.6275617 | T3: =M3/N3 -> 0.18019324
A4: 0.00198844 | B4: 105118000 | D4: 0.0020034 | E4: 101966000 | G4: 0.0019956 | H4: 106311000 | K4: Config2 | L4: 118 | M4: 3890000000000 | N4: 21100000000000 | O4: =0.5*80.9*0.248*SQRT(M4)/1000000 -> 19.785408 | P4: =0.05*80.9*0.248*SQRT(N4)/1000000 -> 4.607989 | Q4: =SQRT(O4^2+P4^2) -> 20.314919 | R4: =L4*0.4395 -> 51.861 | S4: =R4/Q4 -> 2.5528529 | T4: =M4/N4 -> 0.18436019
A5: 0.00302431 | B5: 114216000 | D5: 0.0029941 | E5: 109160000 | G5: 0.00300174 | H5: 107785000 | K5: Config4 | L5: 116 | M5: =3510000000000 -> 3510000000000 | N5: 21200000000000 | O5: =0.5*80.9*0.248*SQRT(M5)/1000000 -> 18.794197 | P5: =0.05*80.9*0.248*SQRT(N5)/1000000 -> 4.6188955 | Q5: =SQRT(O5^2+P5^2) -> 19.35345 | R5: =L5*0.4395 -> 50.982 | S5: =R5/Q5 -> 2.634259 | T5: =M5/N5 -> 0.16556604
A6: 0.00399791 | B6: 123370000 | D6: 0.003975 | E6: 117914000 | G6: 0.00400185 | H6: 110129000
A7: 0.00498949 | B7: 121019000 | D7: 0.0049408 | E7: 124227000 | G7: 0.0049864 | H7: 118701000
A8: 0.00600716 | B8: 118668000 | D8: 0.00600813 | E8: 115665000 | G8: 0.00598994 | H8: 119520000
A9: 0.00701054 | B9: 118499000 | D9: 0.00699492 | E9: 120950000 | G9: 0.00700943 | H9: 118569000
A10: 0.00804502 | B10: 116157000 | D10: 0.00801427 | E10: 121050000 | G10: 0.007979 | H10: 116670000
A11: 0.00899793 | B11: 117234000 | D11: 0.0090004 | E11: 117340000 | G11: 0.00898807 | H11: 115362000
A12: 0.0100028 | B12: 116328000 | D12: 0.00999633 | E12: 119851000 | G12: 0.0100066 | H12: 115592000
A13: 0.0110063 | B13: 120617000 | D13: 0.0109481 | E13: 120386000 | G13: 0.0109937 | H13: 123682000
A14: 0.0119928 | B14: 124932000 | D14: 0.0120238 | E14: 122144000 | G14: 0.012001 | H14: 121615000
A15: 0.0129821 | B15: 131056000 | D15: 0.0130066 | E15: 117344000 | G15: 0.013014 | H15: 123263000
A16: 0.0140108 | B16: 121805000 | D16: 0.0139897 | E16: 121514000 | G16: 0.013987 | H16: 115573000
A17: 0.0150129 | B17: 115657000 | D17: 0.0150329 | E17: 114964000 | G17: 0.015003 | H17: 115612000
... A46: 0.0439973 | B46: 119444000 | D46: 0.0439993 | E46: 118468000 | G46: 0.0438273 | H46: 116933000
A47: 0.0450104 | B47: 115899000 | D47: 0.0449989 | E47: 117639000
A48: 0.0459809 | B48: 122210000
A49: 0.0469965 | B49: 120924000
A50: 0.0479956 | B50: 120236000
A51: 0.0490005 | B51: 114674000

Sheet 300K_SR10
A1: Config 1 | N1: Config 2 | AA1: Config 3 | AN1: Pstrain | AO1: Total | AR1: Junction | AS1: JunctionMin | AT1: JunctionMax
A2: 0.000217211 | B2: 0.000576027 | C2: 19853200000000 | D2: 1193530000 | E2: 0 | F2: 0 | G2: 2 | H2: 5344060000000 | I2: 4611560000000 | J2: 4558050000000 | K2: 4649590000000 | L2: 689922000000 | N2: 0.000196448 | O2: 0.000536669 | P2: 19830000000000 | Q2: 1042280000 | R2: 0 | S2: 0 | T2: 2 | U2: 5411490000000 | V2: 4644970000000 | W2: 4664430000000 | X2: 4640910000000 | Y2: 468218000000 | AA2: 0.000179529 | AB2: 0.00051316 | AC2: 19849400000000 | AD2: 840556000 | AE2: 0 | AF2: 0 | AG2: 2 | AH2: 5458370000000 | AI2: 4637250000000 | AJ2: 4661000000000 | AK2: 4639220000000 | AL2: 453507000000 | AN2: =A2 -> 0.000217211 | AO2: =(C2+P2)/2 -> 19841600000000 | AR2: =(Y2+L2)/2 -> 579070000000 | AS2: =MIN(Y2,L2) -> 468218000000 | AT2: =MAX(Y2,L2) -> 689922000000
A3: 0.000993712 | B3: 0.00144786 | C3: 20149100000000 | D3: 134476000 | E3: 0 | F3: 0 | G3: 2 | H3: 5373710000000 | I3: 4616710000000 | J3: 4551320000000 | K3: 4682300000000 | L3: 925030000000 | N3: 0.00104168 | O3: 0.001492 | P3: 20020900000000 | Q3: 824781000 | R3: 0 | S3: 0 | T3: 2 | U3: 5422870000000 | V3: 4610660000000 | W3: 4579760000000 | X3: 4603890000000 | Y3: 803660000000 | AA3: 0.00102323 | AB3: 0.00149257 | AC3: 20202800000000 | AD3: 219656000 | AE3: 0 | AF3: 0 | AG3: 2 | AH3: 5388140000000 | AI3: 4587540000000 | AJ3: 4613010000000 | AK3: 4605360000000 | AL3: 1008740000000 | AN3: =A3 -> 0.000993712 | AO3: =(C3+P3)/2 -> 20085000000000 | AR3: =(Y3+L3)/2 -> 864345000000 | AS3: =MIN(Y3,L3) -> 803660000000 | AT3: =MAX(Y3,L3) -> 925030000000
A4: 0.00198844 | B4: 0.00247909 | C4: 20260200000000 | D4: 95715600 | E4: 0 | F4: 0 | G4: 2 | H4: 5447190000000 | I4: 4385240000000 | J4: 4494500000000 | K4: 4538660000000 | L4: 1394590000000 | N4: 0.0020034 | O4: 0.00247934 | P4: 20264100000000 | Q4: 1525310000 | R4: 0 | S4: 0 | T4: 2 | U4: 5326820000000 | V4: 4479040000000 | W4: 4666130000000 | X4: 4540480000000 | Y4: 1251580000000 | AA4: 0.0019956 | AB4: 0.00249183 | AC4: 20405400000000 | AD4: 256708000 | AE4: 0 | AF4: 0 | AG4: 2 | AH4: 5239740000000 | AI4: 4423960000000 | AJ4: 4522890000000 | AK4: 4460860000000 | AL4: 1757870000000 | AN4: =A4 -> 0.00198844 | AO4: =(C4+P4)/2 -> 20262150000000 | AR4: =(Y4+L4)/2 -> 1323085000000 | AS4: =MIN(Y4,L4) -> 1251580000000 | AT4: =MAX(Y4,L4) -> 1394590000000
A5: 0.00302431 | B5: 0.00355743 | C5: 20754600000000 | D5: 494265000 | E5: 0 | F5: 0 | G5: 2 | H5: 5207040000000 | I5: 4485300000000 | J5: 4198050000000 | K5: 4456430000000 | L5: 2407720000000 | N5: 0.0029941 | O5: 0.00350362 | P5: 20442900000000 | Q5: 221068000 | R5: 0 | S5: 0 | T5: 2 | U5: 5244840000000 | V5: 4306360000000 | W5: 4361550000000 | X5: 4276290000000 | Y5: 2252090000000 | AA5: 0.00300174 | AB5: 0.00350485 | AC5: 20655300000000 | AD5: 244284000 | AE5: 0 | AF5: 0 | AG5: 2 | AH5: 5231700000000 | AI5: 4452180000000 | AJ5: 4390580000000 | AK5: 4444700000000 | AL5: 2136070000000 | AN5: =A5 -> 0.00302431 | AO5: =(C5+P5)/2 -> 20598750000000 | AR5: =(Y5+L5)/2 -> 2329905000000 | AS5: =MIN(Y5,L5) -> 2252090000000 | AT5: =MAX(Y5,L5) -> 2407720000000
A6: 0.00399791 | B6: 0.00457377 | C6: 21114100000000 | D6: 133820000 | E6: 0 | F6: 0 | G6: 2 | H6: 5030590000000 | I6: 4457310000000 | J6: 4170630000000 | K6: 4363540000000 | L6: 3091970000000 | N6: 0.003975 | O6: 0.00452538 | P6: 20632300000000 | Q6: 208075000 | R6: 0 | S6: 0 | T6: 2 | U6: 4986050000000 | V6: 4405010000000 | W6: 3909500000000 | X6: 3905800000000 | Y6: 3424870000000 | AA6: 0.00400185 | AB6: 0.00451589 | AC6: 20825500000000 | AD6: 162222000 | AE6: 0 | AF6: 0 | AG6: 2 | AH6: 5167570000000 | AI6: 4464510000000 | AJ6: 4210450000000 | AK6: 4388120000000 | AL6: 2594720000000 | AN6: =A6 -> 0.00399791 | AO6: =(C6+P6)/2 -> 20873200000000 | AR6: =(Y6+L6)/2 -> 3258420000000 | AS6: =MIN(Y6,L6) -> 3091970000000 | AT6: =MAX(Y6,L6) -> 3424870000000
A7: 0.00498949 | B7: 0.00555437 | C7: 20834100000000 | D7: 140742000 | E7: 0 | F7: 0 | G7: 2 | H7: 4866330000000 | I7: 4005120000000 | J7: 3935630000000 | K7: 4134110000000 | L7: 3892870000000 | N7: 0.0049408 | O7: 0.00552065 | P7: 20860700000000 | Q7: 176396000 | R7: 0 | S7: 0 | T7: 2 | U7: 4971570000000 | V7: 4274320000000 | W7: 3869170000000 | X7: 3940650000000 | Y7: 3804990000000 | AA7: 0.0049864 | AB7: 0.00554045 | AC7: 21145000000000 | AD7: 344220000 | AE7: 0 | AF7: 0 | AG7: 2 | AH7: 4861070000000 | AI7: 4184030000000 | AJ7: 4211760000000 | AK7: 4537070000000 | AL7: 3351040000000 | AN7: =A7 -> 0.00498949 | AO7: =(C7+P7)/2 -> 20847400000000 | AR7: =(Y7+L7)/2 -> 3848930000000 | AS7: =MIN(Y7,L7) -> 3804990000000 | AT7: =MAX(Y7,L7) -> 3892870000000
A8: 0.00600716 | B8: 0.00656107 | C8: 21049900000000 | D8: 308233000 | E8: 0 | F8: 0 | G8: 2 | H8: 4783470000000 | I8: 4163990000000 | J8: 3952120000000 | K8: 4078040000000 | L8: 4072250000000 | N8: 0.00600813 | O8: 0.00654801 | P8: 21301700000000 | Q8: 323003000 | R8: 0 | S8: 0 | T8: 2 | U8: 4888250000000 | V8: 4058820000000 | W8: 4187460000000 | X8: 3958980000000 | Y8: 4208160000000 | AA8: 0.00598994 | AB8: 0.00654782 | AC8: 20861700000000 | AD8: 243380000 | AE8: 0 | AF8: 0 | AG8: 2 | AH8: 4718360000000 | AI8: 3961040000000 | AJ8: 4172140000000 | AK8: 4223670000000 | AL8: 3786070000000 | AN8: =A8 -> 0.00600716 | AO8: =(C8+P8)/2 -> 21175800000000 | AR8: =(Y8+L8)/2 -> 4140205000000 | AS8: =MIN(Y8,L8) -> 4072250000000 | AT8: =MAX(Y8,L8) -> 4208160000000
A9: 0.00701054 | B9: 0.00756366 | C9: 21004500000000 | D9: 358271000 | E9: 0 | F9: 0 | G9: 2 | H9: 4712920000000 | I9: 3901740000000 | J9: 3822410000000 | K9: 4024330000000 | L9: 4542890000000 | N9: 0.00699492 | O9: 0.00755948 | P9: 20863100000000 | Q9: 259112000 | R9: 0 | S9: 0 | T9: 2 | U9: 4893470000000 | V9: 4154020000000 | W9: 3968110000000 | X9: 4098970000000 | Y9: 3748400000000 | AA9: 0.00700943 | AB9: 0.00756287 | AC9: 21062600000000 | AD9: 360590000 | AE9: 0 | AF9: 0 | AG9: 2 | AH9: 4925870000000 | AI9: 4308190000000 | AJ9: 4274160000000 | AK9: 4270900000000 | AL9: 3283440000000 | AN9: =A9 -> 0.00701054 | AO9: =(C9+P9)/2 -> 20933800000000 | AR9: =(Y9+L9)/2 -> 4145645000000 | AS9: =MIN(Y9,L9) -> 3748400000000 | AT9: =MAX(Y9,L9) -> 4542890000000
A10: 0.00804502 | B10: 0.0085872 | C10: 21478000000000 | D10: 282317000 | E10: 0 | F10: 0 | G10: 2 | H10: 4607500000000 | I10: 4248050000000 | J10: 3968660000000 | K10: 4487580000000 | L10: 4166140000000 | N10: 0.00801427 | O10: 0.00857929 | P10: 21010700000000 | Q10: 162699000 | R10: 0 | S10: 0 | T10: 2 | U10: 4918170000000 | V10: 4140620000000 | W10: 3966890000000 | X10: 4163870000000 | Y10: 3819970000000 | AA10: 0.007979 | AB10: 0.00852359 | AC10: 21375800000000 | AD10: 236029000 | AE10: 0 | AF10: 0 | AG10: 2 | AH10: 4944420000000 | AI10: 4222100000000 | AJ10: 4057810000000 | AK10: 4599450000000 | AL10: 3551970000000 | AN10: =A10 -> 0.00804502 | AO10: =(C10+P10)/2 -> 21244350000000 | AR10: =(Y10+L10)/2 -> 3993055000000 | AS10: =MIN(Y10,L10) -> 3819970000000 | AT10: =MAX(Y10,L10) -> 4166140000000
A11: 0.00899793 | B11: 0.00954515 | C11: 21369600000000 | D11: 236510000 | E11: 0 | F11: 0 | G11: 2 | H11: 4562990000000 | I11: 4166980000000 | J11: 4299710000000 | K11: 4187960000000 | L11: 4151860000000 | N11: 0.0090004 | O11: 0.00954811 | P11: 21077100000000 | Q11: 311202000 | R11: 0 | S11: 0 | T11: 2 | U11: 5111860000000 | V11: 3849190000000 | W11: 3893940000000 | X11: 3990580000000 | Y11: 4231460000000 | AA11: 0.00898807 | AB11: 0.00952654 | AC11: 21137800000000 | AD11: 243453000 | AE11: 0 | AF11: 0 | AG11: 2 | AH11: 4884590000000 | AI11: 4057350000000 | AJ11: 4112200000000 | AK11: 4172820000000 | AL11: 3910730000000 | AN11: =A11 -> 0.00899793 | AO11: =(C11+P11)/2 -> 21223350000000 | AR11: =(Y11+L11)/2 -> 4191660000000 | AS11: =MIN(Y11,L11) -> 4151860000000 | AT11: =MAX(Y11,L11) -> 4231460000000
A12: 0.0100028 | B12: 0.0105458 | C12: 20730100000000 | D12: 451707000 | E12: 0 | F12: 0 | G12: 2 | H12: 4852100000000 | I12: 4179910000000 | J12: 4161980000000 | K12: 4199720000000 | L12: 3336340000000 | N12: 0.00999633 | O12: 0.0105558 | P12: 21190900000000 | Q12: 386500000 | R12: 0 | S12: 0 | T12: 2 | U12: 4836210000000 | V12: 4124570000000 | W12: 3789820000000 | X12: 4009180000000 | Y12: 4431040000000 | AA12: 0.0100066 | AB12: 0.0105462 | AC12: 21015200000000 | AD12: 301891000 | AE12: 0 | AF12: 0 | AG12: 2 | AH12: 5159770000000 | AI12: 4361830000000 | AJ12: 4177520000000 | AK12: 4045510000000 | AL12: 3269840000000 | AN12: =A12 -> 0.0100028 | AO12: =(C12+P12)/2 -> 20960500000000 | AR12: =(Y12+L12)/2 -> 3883690000000 | AS12: =MIN(Y12,L12) -> 3336340000000 | AT12: =MAX(Y12,L12) -> 4431040000000
A13: 0.0110063 | B13: 0.0115693 | C13: 21207300000000 | D13: 178728000 | E13: 0 | F13: 0 | G13: 2 | H13: 4911550000000 | I13: 3960710000000 | J13: 4399770000000 | K13: 4113360000000 | L13: 3821860000000 | N13: 0.0109481 | O13: 0.01151 | P13: 20920500000000 | Q13: 181128000 | R13: 0 | S13: 0 | T13: 2 | U13: 4577230000000 | V13: 4096710000000 | W13: 4002240000000 | X13: 3968040000000 | Y13: 4276240000000 | AA13: 0.0109937 | AB13: 0.011571 | AC13: 20884700000000 | AD13: 200927000 | AE13: 0 | AF13: 0 | AG13: 2 | AH13: 4916510000000 | AI13: 4228160000000 | AJ13: 4028610000000 | AK13: 3797840000000 | AL13: 3912620000000 | AN13: =A13 -> 0.0110063 | AO13: =(C13+P13)/2 -> 21063900000000 | AR13: =(Y13+L13)/2 -> 4049050000000 | AS13: =MIN(Y13,L13) -> 3821860000000 | AT13: =MAX(Y13,L13) -> 4276240000000
... A46: 0.0439973 | B46: 0.0445549 | C46: 20882400000000 | D46: 295675000 | E46: 0 | F46: 0 | G46: 2 | H46: 4839410000000 | I46: 4232040000000 | J46: 4130280000000 | K46: 4170400000000 | L46: 3510170000000 | N46: 0.0439993 | O46: 0.0445523 | P46: 21143400000000 | Q46: 236641000 | R46: 0 | S46: 0 | T46: 2 | U46: 5058480000000 | V46: 4217800000000 | W46: 4392050000000 | X46: 4244840000000 | Y46: 3230190000000 | AA46: 0.0438273 | AB46: 0.0443731 | AC46: 20831500000000 | AD46: 246859000 | AE46: 0 | AF46: 0 | AG46: 2 | AH46: 4921530000000 | AI46: 4066460000000 | AJ46: 4125570000000 | AK46: 4144290000000 | AL46: 3573520000000 | AN46: =A46 -> 0.0439973 | AO46: =(C46+P46)/2 -> 21012900000000 | AR46: =(Y46+L46)/2 -> 3370180000000 | AS46: =MIN(Y46,L46) -> 3230190000000 | AT46: =MAX(Y46,L46) -> 3510170000000
A47: 0.0450104 | B47: 0.0455514 | C47: 20681900000000 | D47: 307958000 | E47: 0 | F47: 0 | G47: 2 | H47: 4784300000000 | I47: 4046430000000 | J47: 3945270000000 | K47: 4479250000000 | L47: 3426630000000 | N47: 0.0449989 | O47: 0.045548 | P47: 20950500000000 | Q47: 225047000 | R47: 0 | S47: 0 | T47: 2 | U47: 4995770000000 | V47: 4183510000000 | W47: 4056550000000 | X47: 4266580000000 | Y47: 3447990000000
A48: 0.0459809 | B48: 0.0465514 | C48: 21163400000000 | D48: 204260000 | E48: 0 | F48: 0 | G48: 2 | H48: 5009220000000 | I48: 4181610000000 | J48: 4404090000000 | K48: 4392050000000 | L48: 3176410000000
A49: 0.0469965 | B49: 0.0475609 | C49: 20780700000000 | D49: 216798000 | E49: 0 | F49: 0 | G49: 2 | H49: 4956150000000 | I49: 4099290000000 | J49: 4016980000000 | K49: 4257630000000 | L49: 3450660000000
A50: 0.0479956 | B50: 0.0485568 | C50: 20787700000000 | D50: 165996000 | E50: 0 | F50: 0 | G50: 2 | H50: 4979550000000 | I50: 4134570000000 | J50: 4170470000000 | K50: 4333910000000 | L50: 3168930000000
A51: 0.0490005 | B51: 0.0495358 | C51: 20628800000000 | D51: 187455000 | E51: 0 | F51: 0 | G51: 2 | H51: 5029090000000 | I51: 4321350000000 | J51: 4326900000000 | K51: 4119680000000 | L51: 2831810000000

Sheet 300K_SR20_Stress
A1: Config1 | D1: Config2 | G1: Config3 | K1: AverageValue of Last 0.5%
A2: 0.000217904 | B2: 90326800 | D2: 0.000175086 | E2: 82694600 | G2: 0.000201766 | H2: 84358500 | L2: TotalStress | M2: RhoI | N2: Rho | O2: TauF1 | P2: TauF2 | Q2: TauF | R2: Tau | S2: Tau/TauF | T2: RhoI/Rho
A3: 0.00101758 | B3: 111428000 | D3: 0.00101665 | E3: 104825000 | G3: 0.00101327 | H3: 114010000 | K3: Config1 | L3: 132 | M3: 3740000000000 | N3: 22100000000000 | O3: =0.5*80.9*0.248*SQRT(M3)/1000000 -> 19.400191 | P3: =0.05*80.9*0.248*SQRT(N3)/1000000 -> 4.7159191 | Q3: =SQRT(O3^2+P3^2) -> 19.965152 | R3: =L3*0.4395 -> 58.014 | S3: =R3/Q3 -> 2.905763 | T3: =M3/N3 -> 0.16923077
A4: 0.00196209 | B4: 113317000 | D4: 0.00199834 | E4: 113314000 | G4: 0.00200906 | H4: 118470000 | K4: Config2 | L4: 127 | M4: 3240000000000 | N4: 21800000000000 | O4: =0.5*80.9*0.248*SQRT(M4)/1000000 -> 18.05688 | P4: =0.05*80.9*0.248*SQRT(N4)/1000000 -> 4.6838012 | Q4: =SQRT(O4^2+P4^2) -> 18.654461 | R4: =L4*0.4395 -> 55.8165 | S4: =R4/Q4 -> 2.9921261 | T4: =M4/N4 -> 0.14862385
A5: 0.00300524 | B5: 112915000 | D5: 0.00299421 | E5: 119173000 | G5: 0.00298592 | H5: 116651000 | K5: Config4 | L5: 125 | M5: 2600000000000 | N5: 21000000000000 | O5: =0.5*80.9*0.248*SQRT(M5)/1000000 -> 16.175469 | P5: =0.05*80.9*0.248*SQRT(N5)/1000000 -> 4.5970566 | Q5: =SQRT(O5^2+P5^2) -> 16.816026 | R5: =L5*0.4395 -> 54.9375 | S5: =R5/Q5 -> 3.2669729 | T5: =M5/N5 -> 0.12380952
A6: 0.00401159 | B6: 115487000 | D6: 0.00400249 | E6: 120672000 | G6: 0.00400594 | H6: 122301000
A7: 0.00504132 | B7: 116457000 | D7: 0.0049987 | E7: 121707000 | G7: 0.00503626 | H7: 119311000
A8: 0.00596342 | B8: 124585000 | D8: 0.00600173 | E8: 120835000 | G8: 0.00599367 | H8: 130673000
A9: 0.00698525 | B9: 125080000 | D9: 0.00695968 | E9: 119794000 | G9: 0.00701428 | H9: 128127000
A10: 0.00802571 | B10: 118507000 | D10: 0.0079782 | E10: 130072000 | G10: 0.00798885 | H10: 133436000
A11: 0.00902825 | B11: 126885000 | D11: 0.00898474 | E11: 131293000 | G11: 0.0090261 | H11: 127660000
A12: 0.0099968 | B12: 130065000 | D12: 0.0100095 | E12: 126642000 | G12: 0.0100356 | H12: 126977000
A13: 0.0110157 | B13: 122120000 | D13: 0.0109939 | E13: 127654000 | G13: 0.0110037 | H13: 118724000
A14: 0.0119749 | B14: 127325000 | D14: 0.0120259 | E14: 129465000 | G14: 0.0119718 | H14: 129890000
A15: 0.0129916 | B15: 125828000 | D15: 0.0129887 | E15: 128765000 | G15: 0.0129294 | H15: 130008000
A16: 0.0139521 | B16: 134678000 | D16: 0.0140115 | E16: 122121000 | G16: 0.0140224 | H16: 126467000
A17: 0.0149306 | B17: 124654000 | D17: 0.0149665 | E17: 135250000 | G17: 0.0149863 | H17: 133369000
... A50: 0.0479895 | B50: 127844000 | D50: 0.0479489 | E50: 126511000 | G50: 0.0480004 | H50: 136070000
A51: 0.0490416 | B51: 125591000
A52: 0.0499931 | B52: 131528000
A53: 0.050997 | B53: 127550000
A54: 0.051779 | B54: 127654000

Sheet 300K_SR20
A1: Config 1 | N1: Config 2 | AA1: Config 3 | AN1: Pstrain | AO1: Total | AR1: Junction | AS1: JunctionMin | AT1: JunctionMax
A2: 0.000217904 | B2: 0.000639524 | C2: 19904600000000 | D2: 4280180000 | E2: 0 | F2: 0 | G2: 2 | H2: 5377250000000 | I2: 4617790000000 | J2: 4609950000000 | K2: 4687510000000 | L2: 612113000000 | N2: 0.000175086 | O2: 0.00056108 | P2: 19852200000000 | Q2: 663674000 | R2: 0 | S2: 0 | T2: 2 | U2: 5445280000000 | V2: 4656240000000 | W2: 4683930000000 | X2: 4669700000000 | Y2: 397010000000 | AA2: 0.000201766 | AB2: 0.000595527 | AC2: 19706200000000 | AD2: 2408710000 | AE2: 0 | AF2: 0 | AG2: 2 | AH2: 4827900000000 | AI2: 4837060000000 | AJ2: 4830900000000 | AK2: 4851320000000 | AL2: 359082000000 | AN2: =A2 -> 0.000217904 | AO2: =AVERAGE(C2,P2,AC2) -> 19821000000000 | AR2: =AVERAGE(L2,Y2,AL2) -> 4.5606833e+11 | AS2: =MIN(L2,Y2,AL2) -> 359082000000 | AT2: =MAX(L2,Y2,AL2) -> 612113000000
A3: 0.00101758 | B3: 0.00153769 | C3: 20254800000000 | D3: 270106000 | E3: 0 | F3: 0 | G3: 2 | H3: 5458810000000 | I3: 4705650000000 | J3: 4631080000000 | K3: 4753790000000 | L3: 705491000000 | N3: 0.00101665 | O3: 0.00150593 | P3: 19990500000000 | Q3: 177925000 | R3: 0 | S3: 0 | T3: 2 | U3: 5461810000000 | V3: 4679510000000 | W3: 4669510000000 | X3: 4631980000000 | Y3: 547659000000 | AA3: 0.00101327 | AB3: 0.00154543 | AC3: 20008400000000 | AD3: 247120000 | AE3: 0 | AF3: 0 | AG3: 2 | AH3: 4850700000000 | AI3: 4841230000000 | AJ3: 4859280000000 | AK3: 4842280000000 | AL3: 614873000000 | AN3: =A3 -> 0.00101758 | AO3: =AVERAGE(C3,P3,AC3) -> 2.0084567e+13 | AR3: =AVERAGE(L3,Y3,AL3) -> 6.2267433e+11 | AS3: =MIN(L3,Y3,AL3) -> 547659000000 | AT3: =MAX(L3,Y3,AL3) -> 705491000000
A4: 0.00196209 | B4: 0.00249102 | C4: 20200000000000 | D4: 190054000 | E4: 0 | F4: 0 | G4: 2 | H4: 5373500000000 | I4: 4740720000000 | J4: 4590100000000 | K4: 4677140000000 | L4: 818507000000 | N4: 0.00199834 | O4: 0.00252725 | P4: 20302800000000 | Q4: 334857000 | R4: 0 | S4: 0 | T4: 2 | U4: 5407460000000 | V4: 4632740000000 | W4: 4657280000000 | X4: 4648140000000 | Y4: 957163000000 | AA4: 0.00200906 | AB4: 0.00256204 | AC4: 20306000000000 | AD4: 203758000 | AE4: 0 | AF4: 0 | AG4: 2 | AH4: 4739580000000 | AI4: 4689160000000 | AJ4: 4775670000000 | AK4: 4736900000000 | AL4: 1364650000000 | AN4: =A4 -> 0.00196209 | AO4: =AVERAGE(C4,P4,AC4) -> 20269600000000 | AR4: =AVERAGE(L4,Y4,AL4) -> 1.0467733e+12 | AS4: =MIN(L4,Y4,AL4) -> 818507000000 | AT4: =MAX(L4,Y4,AL4) -> 1364650000000
A5: 0.00300524 | B5: 0.0035323 | C5: 20351100000000 | D5: 269403000 | E5: 0 | F5: 0 | G5: 2 | H5: 5369140000000 | I5: 4681610000000 | J5: 4590580000000 | K5: 4701990000000 | L5: 1007750000000 | N5: 0.00299421 | O5: 0.00355047 | P5: 20501600000000 | Q5: 205711000 | R5: 0 | S5: 0 | T5: 2 | U5: 5395630000000 | V5: 4609970000000 | W5: 4556190000000 | X5: 4765200000000 | Y5: 1174610000000 | AA5: 0.00298592 | AB5: 0.00353041 | AC5: 20616900000000 | AD5: 226545000 | AE5: 0 | AF5: 0 | AG5: 2 | AH5: 4644360000000 | AI5: 4677400000000 | AJ5: 4787740000000 | AK5: 4784340000000 | AL5: 1723010000000 | AN5: =A5 -> 0.00300524 | AO5: =AVERAGE(C5,P5,AC5) -> 2.0489867e+13 | AR5: =AVERAGE(L5,Y5,AL5) -> 1301790000000 | AS5: =MIN(L5,Y5,AL5) -> 1007750000000 | AT5: =MAX(L5,Y5,AL5) -> 1723010000000
A6: 0.00401159 | B6: 0.00455065 | C6: 20933300000000 | D6: 798069000 | E6: 0 | F6: 0 | G6: 2 | H6: 5470610000000 | I6: 4731050000000 | J6: 4561530000000 | K6: 4700260000000 | L6: 1469790000000 | N6: 0.00400249 | O6: 0.00456574 | P6: 20617700000000 | Q6: 252612000 | R6: 0 | S6: 0 | T6: 2 | U6: 5339000000000 | V6: 4599080000000 | W6: 4339350000000 | X6: 4421680000000 | Y6: 1918470000000 | AA6: 0.00400594 | AB6: 0.0045768 | AC6: 20826000000000 | AD6: 201766000 | AE6: 0 | AF6: 0 | AG6: 2 | AH6: 4829960000000 | AI6: 4620970000000 | AJ6: 4505710000000 | AK6: 4626360000000 | AL6: 2243010000000 | AN6: =A6 -> 0.00401159 | AO6: =AVERAGE(C6,P6,AC6) -> 2.0792333e+13 | AR6: =AVERAGE(L6,Y6,AL6) -> 1877090000000 | AS6: =MIN(L6,Y6,AL6) -> 1469790000000 | AT6: =MAX(L6,Y6,AL6) -> 2243010000000
A7: 0.00504132 | B7: 0.0055849 | C7: 20765400000000 | D7: 469269000 | E7: 0 | F7: 0 | G7: 2 | H7: 5556780000000 | I7: 4470060000000 | J7: 4378530000000 | K7: 4586130000000 | L7: 1773910000000 | N7: 0.0049987 | O7: 0.00556679 | P7: 20778200000000 | Q7: 375204000 | R7: 0 | S7: 0 | T7: 2 | U7: 5220210000000 | V7: 4510160000000 | W7: 4359870000000 | X7: 4609970000000 | Y7: 2077950000000 | AA7: 0.00503626 | AB7: 0.00559317 | AC7: 21717800000000 | AD7: 423950000 | AE7: 0 | AF7: 0 | AG7: 2 | AH7: 5258140000000 | AI7: 4775850000000 | AJ7: 4525610000000 | AK7: 4661320000000 | AL7: 2496730000000 | AN7: =A7 -> 0.00504132 | AO7: =AVERAGE(C7,P7,AC7) -> 2.1087133e+13 | AR7: =AVERAGE(L7,Y7,AL7) -> 2.1161967e+12 | AS7: =MIN(L7,Y7,AL7) -> 1773910000000 | AT7: =MAX(L7,Y7,AL7) -> 2496730000000
A8: 0.00596342 | B8: 0.00654495 | C8: 20793000000000 | D8: 298340000 | E8: 0 | F8: 0 | G8: 2 | H8: 5069880000000 | I8: 4512290000000 | J8: 4392270000000 | K8: 4573540000000 | L8: 2244760000000 | N8: 0.00600173 | O8: 0.00656575 | P8: 20676400000000 | Q8: 307793000 | R8: 0 | S8: 0 | T8: 2 | U8: 4968930000000 | V8: 4443450000000 | W8: 4319940000000 | X8: 4478690000000 | Y8: 2465150000000 | AA8: 0.00599367 | AB8: 0.00660361 | AC8: 21761400000000 | AD8: 387697000 | AE8: 0 | AF8: 0 | AG8: 2 | AH8: 4767770000000 | AI8: 4730900000000 | AJ8: 4584700000000 | AK8: 4552010000000 | AL8: 3126050000000 | AN8: =A8 -> 0.00596342 | AO8: =AVERAGE(C8,P8,AC8) -> 2.1076933e+13 | AR8: =AVERAGE(L8,Y8,AL8) -> 2.6119867e+12 | AS8: =MIN(L8,Y8,AL8) -> 2244760000000 | AT8: =MAX(L8,Y8,AL8) -> 3126050000000
A9: 0.00698525 | B9: 0.00756909 | C9: 21051000000000 | D9: 529226000 | E9: 0 | F9: 0 | G9: 2 | H9: 4929850000000 | I9: 4321610000000 | J9: 4279360000000 | K9: 4815120000000 | L9: 2705100000000 | N9: 0.00695968 | O9: 0.00751884 | P9: 20686800000000 | Q9: 346052000 | R9: 0 | S9: 0 | T9: 2 | U9: 5131150000000 | V9: 4457110000000 | W9: 4458840000000 | X9: 4323950000000 | Y9: 2315750000000 | AA9: 0.00701428 | AB9: 0.00761233 | AC9: 21255200000000 | AD9: 623641000 | AE9: 0 | AF9: 0 | AG9: 2 | AH9: 4357670000000 | AI9: 4670040000000 | AJ9: 4226920000000 | AK9: 4762510000000 | AL9: 3237890000000 | AN9: =A9 -> 0.00698525 | AO9: =AVERAGE(C9,P9,AC9) -> 2.0997667e+13 | AR9: =AVERAGE(L9,Y9,AL9) -> 2.7529133e+12 | AS9: =MIN(L9,Y9,AL9) -> 2315750000000 | AT9: =MAX(L9,Y9,AL9) -> 3237890000000
A10: 0.00802571 | B10: 0.00857886 | C10: 22620800000000 | D10: 405124000 | E10: 0 | F10: 0 | G10: 2 | H10: 4896140000000 | I10: 4360200000000 | J10: 4389590000000 | K10: 6162190000000 | L10: 2812630000000 | N10: 0.0079782 | O10: 0.00858534 | P10: 21259300000000 | Q10: 246276000 | R10: 0 | S10: 0 | T10: 2 | U10: 5130150000000 | V10: 4630660000000 | W10: 4361450000000 | X10: 4186510000000 | Y10: 2950550000000 | AA10: 0.00798885 | AB10: 0.00861169 | AC10: 21885400000000 | AD10: 319941000 | AE10: 0 | AF10: 0 | AG10: 2 | AH10: 4276840000000 | AI10: 4513300000000 | AJ10: 4526600000000 | AK10: 5226310000000 | AL10: 3342310000000 | AN10: =A10 -> 0.00802571 | AO10: =AVERAGE(C10,P10,AC10) -> 2.1921833e+13 | AR10: =AVERAGE(L10,Y10,AL10) -> 3.0351633e+12 | AS10: =MIN(L10,Y10,AL10) -> 2812630000000 | AT10: =MAX(L10,Y10,AL10) -> 3342310000000
A11: 0.00902825 | B11: 0.00962051 | C11: 21819800000000 | D11: 561069000 | E11: 0 | F11: 0 | G11: 2 | H11: 4697150000000 | I11: 4189050000000 | J11: 4165750000000 | K11: 5447150000000 | L11: 3320630000000 | N11: 0.00898474 | O11: 0.00959757 | P11: 21211600000000 | Q11: 491134000 | R11: 0 | S11: 0 | T11: 2 | U11: 5051720000000 | V11: 4437000000000 | W11: 4405970000000 | X11: 4106630000000 | Y11: 3210220000000 | AA11: 0.0090261 | AB11: 0.00962197 | AC11: 21233900000000 | AD11: 673857000 | AE11: 0 | AF11: 0 | AG11: 2 | AH11: 4361610000000 | AI11: 4330950000000 | AJ11: 4751010000000 | AK11: 4599680000000 | AL11: 3190490000000 | AN11: =A11 -> 0.00902825 | AO11: =AVERAGE(C11,P11,AC11) -> 2.1421767e+13 | AR11: =AVERAGE(L11,Y11,AL11) -> 3.2404467e+12 | AS11: =MIN(L11,Y11,AL11) -> 3190490000000 | AT11: =MAX(L11,Y11,AL11) -> 3320630000000
A12: 0.0099968 | B12: 0.0106039 | C12: 21201200000000 | D12: 531153000 | E12: 0 | F12: 0 | G12: 2 | H12: 5125170000000 | I12: 4082770000000 | J12: 4263780000000 | K12: 4303170000000 | L12: 3426310000000 | N12: 0.0100095 | O12: 0.0106007 | P12: 21418500000000 | Q12: 493932000 | R12: 0 | S12: 0 | T12: 2 | U12: 5121650000000 | V12: 4442690000000 | W12: 4396890000000 | X12: 4187500000000 | Y12: 3268290000000 | AA12: 0.0100356 | AB12: 0.0106283 | AC12: 21114400000000 | AD12: 398309000 | AE12: 0 | AF12: 0 | AG12: 2 | AH12: 4549460000000 | AI12: 4588540000000 | AJ12: 4408730000000 | AK12: 4712990000000 | AL12: 2854570000000 | AN12: =A12 -> 0.0099968 | AO12: =AVERAGE(C12,P12,AC12) -> 21244700000000 | AR12: =AVERAGE(L12,Y12,AL12) -> 3.1830567e+12 | AS12: =MIN(L12,Y12,AL12) -> 2854570000000 | AT12: =MAX(L12,Y12,AL12) -> 3426310000000
A13: 0.0110157 | B13: 0.0115857 | C13: 21201800000000 | D13: 216497000 | E13: 0 | F13: 0 | G13: 2 | H13: 5168810000000 | I13: 4404740000000 | J13: 4419580000000 | K13: 4101490000000 | L13: 3107110000000 | N13: 0.0109939 | O13: 0.0115898 | P13: 21550700000000 | Q13: 464452000 | R13: 0 | S13: 0 | T13: 2 | U13: 4919900000000 | V13: 4375060000000 | W13: 4593680000000 | X13: 4299520000000 | Y13: 3362230000000 | AA13: 0.0110037 | AB13: 0.0115578 | AC13: 21766300000000 | AD13: 367717000 | AE13: 0 | AF13: 0 | AG13: 2 | AH13: 4466590000000 | AI13: 5258450000000 | AJ13: 4397600000000 | AK13: 4762730000000 | AL13: 2880910000000 | AN13: =A13 -> 0.0110157 | AO13: =AVERAGE(C13,P13,AC13) -> 2.1506267e+13 | AR13: =AVERAGE(L13,Y13,AL13) -> 3116750000000 | AS13: =MIN(L13,Y13,AL13) -> 2880910000000 | AT13: =MAX(L13,Y13,AL13) -> 3362230000000
... A49: 0.0469954 | B49: 0.0475682 | C49: 22019800000000 | D49: 588625000 | E49: 0 | F49: 0 | G49: 2 | H49: 5819360000000 | I49: 4491140000000 | J49: 4280100000000 | K49: 4362880000000 | L49: 3066270000000 | N49: 0.0470013 | O49: 0.0475789 | P49: 21485100000000 | Q49: 349350000 | R49: 0 | S49: 0 | T49: 2 | U49: 5524370000000 | V49: 3973630000000 | W49: 4212940000000 | X49: 4163450000000 | Y49: 3610650000000 | AA49: 0.0469694 | AB49: 0.0475721 | AC49: 21522600000000 | AD49: 591080000 | AE49: 0 | AF49: 0 | AG49: 2 | AH49: 4278300000000 | AI49: 4760620000000 | AJ49: 4647570000000 | AK49: 4677250000000 | AL49: 3158890000000 | AN49: =A49 -> 0.0469954 | AO49: =AVERAGE(C49,P49,AC49) -> 2.1675833e+13 | AR49: =AVERAGE(L49,Y49,AL49) -> 3.2786033e+12 | AS49: =MIN(L49,Y49,AL49) -> 3066270000000 | AT49: =MAX(L49,Y49,AL49) -> 3610650000000
A50: 0.0479895 | B50: 0.0485863 | C50: 21210400000000 | D50: 235482000 | E50: 0 | F50: 0 | G50: 2 | H50: 5072670000000 | I50: 4227700000000 | J50: 4101790000000 | K50: 4538510000000 | L50: 3269760000000 | N50: 0.0479489 | O50: 0.0485394 | P50: 21171900000000 | Q50: 593345000 | R50: 0 | S50: 0 | T50: 2 | U50: 5410830000000 | V50: 4224480000000 | W50: 4164580000000 | X50: 4111420000000 | Y50: 3260360000000 | AA50: 0.0480004 | AB50: 0.0486355 | AC50: 21198400000000 | AD50: 302110000 | AE50: 0 | AF50: 0 | AG50: 2 | AH50: 4395700000000 | AI50: 4577420000000 | AJ50: 4412640000000 | AK50: 4366380000000 | AL50: 3446090000000
A51: 0.0490416 | B51: 0.0496279 | C51: 21684400000000 | D51: 571153000 | E51: 0 | F51: 0 | G51: 2 | H51: 5607470000000 | I51: 4213690000000 | J51: 4377890000000 | K51: 4474690000000 | L51: 3010600000000
A52: 0.0499931 | B52: 0.0506071 | C52: 21624100000000 | D52: 434474000 | E52: 0 | F52: 0 | G52: 2 | H52: 5801300000000 | I52: 4097460000000 | J52: 4131020000000 | K52: 4277850000000 | L52: 3316450000000
A53: 0.050997 | B53: 0.0515924 | C53: 22110100000000 | D53: 495654000 | E53: 0 | F53: 0 | G53: 2 | H53: 6033540000000 | I53: 4595530000000 | J53: 4204200000000 | K53: 4121940000000 | L53: 3154830000000
A54: 0.051779 | B54: 0.0523749 | C54: 21586600000000 | D54: 538166000 | E54: 0 | F54: 0 | G54: 2 | H54: 5421200000000 | I54: 4303590000000 | J54: 4296720000000 | K54: 4342020000000 | L54: 3222860000000

Sheet 300K_SR40_Stress
A1: Config1 | D1: Config2 | G1: Config3 | J1: AverageValue of Last 0.5%
A2: 0.000211378 | B2: 102502000 | D2: 0.000154734 | E2: 90153300 | G2: 0.000211382 | H2: 100435000 | K2: TotalStress | L2: RhoI | M2: Rho | N2: TauF1 | O2: TauF2 | P2: TauF | Q2: Tau | R2: Tau/TauF | S2: RhoI/Rho
A3: 0.00097298 | B3: 128817000 | D3: 0.00100671 | E3: 120372000 | G3: 0.00101828 | H3: 127757000 | J3: Config1 | K3: 137 | L3: 2740000000000 | M3: 22500000000000 | N3: =0.5*80.9*0.248*SQRT(L3)/1000000 -> 16.605253 | O3: =0.05*80.9*0.248*SQRT(M3)/1000000 -> 4.7584057 | P3: =SQRT(N3^2+O3^2) -> 17.273588 | Q3: =K3*0.4395 -> 60.2115 | R3: =Q3/P3 -> 3.4857553 | S3: =L3/M3 -> 0.12177778
A4: 0.00197206 | B4: 129504000 | D4: 0.00199666 | E4: 127810000 | G4: 0.00201683 | H4: 125236000 | J4: Config2 | K4: 139 | L4: 2920000000000 | M4: 23100000000000 | N4: =0.5*80.9*0.248*SQRT(L4)/1000000 -> 17.142006 | O4: =0.05*80.9*0.248*SQRT(M4)/1000000 -> 4.8214337 | P4: =SQRT(N4^2+O4^2) -> 17.80715 | Q4: =K4*0.4395 -> 61.0905 | R4: =Q4/P4 -> 3.4306726 | S4: =L4/M4 -> 0.12640693
A5: 0.00297197 | B5: 126628000 | D5: 0.0030161 | E5: 129788000 | G5: 0.00300325 | H5: 125289000 | J5: Config4 | K5: 130 | L5: 2950000000000 | M5: 23400000000000 | N5: =0.5*80.9*0.248*SQRT(L5)/1000000 -> 17.229839 | O5: =0.05*80.9*0.248*SQRT(M5)/1000000 -> 4.8526407 | P5: =SQRT(N5^2+O5^2) -> 17.900153 | Q5: =K5*0.4395 -> 57.135 | R5: =Q5/P5 -> 3.1918722 | S5: =L5/M5 -> 0.12606838
A6: 0.00399284 | B6: 127533000 | D6: 0.00399379 | E6: 127326000 | G6: 0.00397696 | H6: 128084000
A7: 0.00501817 | B7: 135184000 | D7: 0.00496968 | E7: 127066000 | G7: 0.00500527 | H7: 124334000
A8: 0.00600417 | B8: 131400000 | D8: 0.00599355 | E8: 130515000 | G8: 0.00598043 | H8: 126789000
A9: 0.00697331 | B9: 136357000 | D9: 0.0069824 | E9: 131554000 | G9: 0.00699662 | H9: 126153000
A10: 0.00800211 | B10: 134929000 | D10: 0.00799455 | E10: 130010000 | G10: 0.00801184 | H10: 126152000
A11: 0.00897935 | B11: 145126000 | D11: 0.0090061 | E11: 125733000 | G11: 0.00901695 | H11: 126149000
A12: 0.0100225 | B12: 128064000 | D12: 0.0100658 | E12: 134373000 | G12: 0.0100127 | H12: 130347000
A13: 0.0109492 | B13: 126573000 | D13: 0.0110219 | E13: 133512000 | G13: 0.0109858 | H13: 129925000
A14: 0.0119489 | B14: 131302000 | D14: 0.0119948 | E14: 132495000 | G14: 0.0119511 | H14: 133057000
A15: 0.0129717 | B15: 128019000 | D15: 0.013008 | E15: 138144000 | G15: 0.0129556 | H15: 129201000
A16: 0.0139519 | B16: 139693000 | D16: 0.0140382 | E16: 138465000 | G16: 0.0139792 | H16: 124709000
A17: 0.0150085 | B17: 138611000 | D17: 0.0150125 | E17: 141296000 | G17: 0.0149735 | H17: 135834000
... A52: 0.0499716 | B52: 139404000 | D52: 0.0499045 | E52: 127717000 | G52: 0.0500183 | H52: 146189000
A53: 0.0510131 | B53: 137008000 | G53: 0.0508411 | H53: 139098000
A54: 0.0520037 | B54: 137986000
A55: 0.0529856 | B55: 132427000
A56: 0.0540033 | B56: 141826000

Sheet 300K_SR40
A1: Config 1 | N1: Config 2 | AA1: Config 3 | AN1: Pstrain | AO1: Total | AR1: Junction | AS1: JunctionMin | AT1: JunctionMax
A2: 0.000211378 | B2: 0.000689828 | C2: 19934100000000 | D2: 436924000 | E2: 0 | F2: 0 | G2: 2 | H2: 5427390000000 | I2: 4622760000000 | J2: 4630080000000 | K2: 4718490000000 | L2: 535362000000 | N2: 0.000154734 | O2: 0.000575544 | P2: 19869900000000 | Q2: 228377000 | R2: 0 | S2: 0 | T2: 2 | U2: 5466010000000 | V2: 4689330000000 | W2: 4683220000000 | X2: 4691890000000 | Y2: 339475000000 | AA2: 0.000211382 | AB2: 0.000680187 | AC2: 19726200000000 | AD2: 1314070000 | AE2: 0 | AF2: 0 | AG2: 2 | AH2: 4865430000000 | AI2: 4858190000000 | AJ2: 4851750000000 | AK2: 4882500000000 | AL2: 268367000000 | AN2: =A2 -> 0.000211378 | AO2: =AVERAGE(C2,P2,AC2) -> 19843400000000 | AR2: =AVERAGE(L2,Y2,AL2) -> 381068000000 | AS2: =MIN(L2,Y2,AL2) -> 268367000000 | AT2: =MAX(L2,Y2,AL2) -> 535362000000
A3: 0.00097298 | B3: 0.00157426 | C3: 20333400000000 | D3: 534374000 | E3: 0 | F3: 0 | G3: 2 | H3: 5466630000000 | I3: 4755100000000 | J3: 4731670000000 | K3: 4741390000000 | L3: 638610000000 | N3: 0.00100671 | O3: 0.00156857 | P3: 19963400000000 | Q3: 373117000 | R3: 0 | S3: 0 | T3: 2 | U3: 5472480000000 | V3: 4741700000000 | W3: 4684640000000 | X3: 4732850000000 | Y3: 331732000000 | AA3: 0.00101828 | AB3: 0.00161462 | AC3: 19921000000000 | AD3: 155182000 | AE3: 0 | AF3: 0 | AG3: 2 | AH3: 4921230000000 | AI3: 4857480000000 | AJ3: 4873020000000 | AK3: 4894150000000 | AL3: 375126000000 | AN3: =A3 -> 0.00097298 | AO3: =AVERAGE(C3,P3,AC3) -> 20072600000000 | AR3: =AVERAGE(L3,Y3,AL3) -> 4.4848933e+11 | AS3: =MIN(L3,Y3,AL3) -> 331732000000 | AT3: =MAX(L3,Y3,AL3) -> 638610000000
A4: 0.00197206 | B4: 0.00257655 | C4: 20371000000000 | D4: 315644000 | E4: 0 | F4: 0 | G4: 2 | H4: 5490390000000 | I4: 4731140000000 | J4: 4711080000000 | K4: 4704280000000 | L4: 734150000000 | N4: 0.00199666 | O4: 0.00259323 | P4: 20136700000000 | Q4: 124379000 | R4: 0 | S4: 0 | T4: 2 | U4: 5510190000000 | V4: 4756610000000 | W4: 4671860000000 | X4: 4708930000000 | Y4: 489134000000 | AA4: 0.00201683 | AB4: 0.00260139 | AC4: 19991200000000 | AD4: 232647000 | AE4: 0 | AF4: 0 | AG4: 2 | AH4: 4906700000000 | AI4: 4891860000000 | AJ4: 4877160000000 | AK4: 4919640000000 | AL4: 395851000000 | AN4: =A4 -> 0.00197206 | AO4: =AVERAGE(C4,P4,AC4) -> 20166300000000 | AR4: =AVERAGE(L4,Y4,AL4) -> 5.3971167e+11 | AS4: =MIN(L4,Y4,AL4) -> 395851000000 | AT4: =MAX(L4,Y4,AL4) -> 734150000000
A5: 0.00297197 | B5: 0.00356303 | C5: 20522100000000 | D5: 547082000 | E5: 0 | F5: 0 | G5: 2 | H5: 5515970000000 | I5: 4684060000000 | J5: 4648420000000 | K5: 4712010000000 | L5: 961652000000 | N5: 0.0030161 | O5: 0.00362191 | P5: 20476900000000 | Q5: 127953000 | R5: 0 | S5: 0 | T5: 2 | U5: 5441720000000 | V5: 4746440000000 | W5: 4713530000000 | X5: 4775690000000 | Y5: 799489000000 | AA5: 0.00300325 | AB5: 0.00358806 | AC5: 20113200000000 | AD5: 68070200 | AE5: 0 | AF5: 0 | AG5: 2 | AH5: 4926330000000 | AI5: 4886870000000 | AJ5: 4938990000000 | AK5: 4874460000000 | AL5: 486597000000 | AN5: =A5 -> 0.00297197 | AO5: =AVERAGE(C5,P5,AC5) -> 2.0370733e+13 | AR5: =AVERAGE(L5,Y5,AL5) -> 749246000000 | AS5: =MIN(L5,Y5,AL5) -> 486597000000 | AT5: =MAX(L5,Y5,AL5) -> 961652000000
A6: 0.00399284 | B6: 0.00458812 | C6: 20514300000000 | D6: 347041000 | E6: 0 | F6: 0 | G6: 2 | H6: 5462460000000 | I6: 4581550000000 | J6: 4661060000000 | K6: 4619600000000 | L6: 1189560000000 | N6: 0.00399379 | O6: 0.00458811 | P6: 20596000000000 | Q6: 432429000 | R6: 0 | S6: 0 | T6: 2 | U6: 5554020000000 | V6: 4699630000000 | W6: 4630450000000 | X6: 4793430000000 | Y6: 918426000000 | AA6: 0.00397696 | AB6: 0.00457483 | AC6: 20142100000000 | AD6: 454968000 | AE6: 0 | AF6: 0 | AG6: 2 | AH6: 4884910000000 | AI6: 4907090000000 | AJ6: 4891950000000 | AK6: 4855880000000 | AL6: 602294000000 | AN6: =A6 -> 0.00399284 | AO6: =AVERAGE(C6,P6,AC6) -> 2.0417467e+13 | AR6: =AVERAGE(L6,Y6,AL6) -> 9.0342667e+11 | AS6: =MIN(L6,Y6,AL6) -> 602294000000 | AT6: =MAX(L6,Y6,AL6) -> 1189560000000
A7: 0.00501817 | B7: 0.00564917 | C7: 20845400000000 | D7: 153962000 | E7: 0 | F7: 0 | G7: 2 | H7: 5523230000000 | I7: 4593010000000 | J7: 4666330000000 | K7: 4746490000000 | L7: 1316310000000 | N7: 0.00496968 | O7: 0.00556279 | P7: 20878700000000 | Q7: 232280000 | R7: 0 | S7: 0 | T7: 2 | U7: 5410130000000 | V7: 4711500000000 | W7: 4681250000000 | X7: 5112450000000 | Y7: 963347000000 | AA7: 0.00500527 | AB7: 0.00558562 | AC7: 20259500000000 | AD7: 443993000 | AE7: 0 | AF7: 0 | AG7: 2 | AH7: 4902700000000 | AI7: 4861460000000 | AJ7: 5008850000000 | AK7: 4859350000000 | AL7: 627169000000 | AN7: =A7 -> 0.00501817 | AO7: =AVERAGE(C7,P7,AC7) -> 20661200000000 | AR7: =AVERAGE(L7,Y7,AL7) -> 968942000000 | AS7: =MIN(L7,Y7,AL7) -> 627169000000 | AT7: =MAX(L7,Y7,AL7) -> 1316310000000
A8: 0.00600417 | B8: 0.0066175 | C8: 21312700000000 | D8: 642434000 | E8: 0 | F8: 0 | G8: 2 | H8: 5399840000000 | I8: 4776170000000 | J8: 4628240000000 | K8: 4649500000000 | L8: 1858940000000 | N8: 0.00599355 | O8: 0.00660275 | P8: 20921200000000 | Q8: 357126000 | R8: 0 | S8: 0 | T8: 2 | U8: 5388780000000 | V8: 4708050000000 | W8: 4648140000000 | X8: 4961800000000 | Y8: 1214440000000 | AA8: 0.00598043 | AB8: 0.00657224 | AC8: 20128900000000 | AD8: 242918000 | AE8: 0 | AF8: 0 | AG8: 2 | AH8: 4906630000000 | AI8: 4838590000000 | AJ8: 4887340000000 | AK8: 4874560000000 | AL8: 621822000000 | AN8: =A8 -> 0.00600417 | AO8: =AVERAGE(C8,P8,AC8) -> 20787600000000 | AR8: =AVERAGE(L8,Y8,AL8) -> 1231734000000 | AS8: =MIN(L8,Y8,AL8) -> 621822000000 | AT8: =MAX(L8,Y8,AL8) -> 1858940000000
A9: 0.00697331 | B9: 0.00760979 | C9: 21793500000000 | D9: 572082000 | E9: 0 | F9: 0 | G9: 2 | H9: 5521570000000 | I9: 5317730000000 | J9: 4464800000000 | K9: 4297520000000 | L9: 2191890000000 | N9: 0.0069824 | O9: 0.00759646 | P9: 20707200000000 | Q9: 155691000 | R9: 0 | S9: 0 | T9: 2 | U9: 5494580000000 | V9: 4760440000000 | W9: 4661240000000 | X9: 4726640000000 | Y9: 1064300000000 | AA9: 0.00699662 | AB9: 0.00758547 | AC9: 20084900000000 | AD9: 158588000 | AE9: 0 | AF9: 0 | AG9: 2 | AH9: 4888500000000 | AI9: 4874400000000 | AJ9: 4870380000000 | AK9: 4885720000000 | AL9: 565912000000 | AN9: =A9 -> 0.00697331 | AO9: =AVERAGE(C9,P9,AC9) -> 2.0861867e+13 | AR9: =AVERAGE(L9,Y9,AL9) -> 1274034000000 | AS9: =MIN(L9,Y9,AL9) -> 565912000000 | AT9: =MAX(L9,Y9,AL9) -> 2191890000000
A10: 0.00800211 | B10: 0.00863191 | C10: 21768300000000 | D10: 1090090000 | E10: 0 | F10: 0 | G10: 2 | H10: 5816920000000 | I10: 4586920000000 | J10: 4723490000000 | K10: 4330980000000 | L10: 2309980000000 | N10: 0.00799455 | O10: 0.00860139 | P10: 20537100000000 | Q10: 335020000 | R10: 0 | S10: 0 | T10: 2 | U10: 5484970000000 | V10: 4701160000000 | W10: 4670330000000 | X10: 4715930000000 | Y10: 964690000000 | AA10: 0.00801184 | AB10: 0.00860068 | AC10: 20112400000000 | AD10: 520554000 | AE10: 0 | AF10: 0 | AG10: 2 | AH10: 4892540000000 | AI10: 4900950000000 | AJ10: 4897140000000 | AK10: 4917920000000 | AL10: 503843000000 | AN10: =A10 -> 0.00800211 | AO10: =AVERAGE(C10,P10,AC10) -> 2.0805933e+13 | AR10: =AVERAGE(L10,Y10,AL10) -> 1.2595043e+12 | AS10: =MIN(L10,Y10,AL10) -> 503843000000 | AT10: =MAX(L10,Y10,AL10) -> 2309980000000
A11: 0.00897935 | B11: 0.00965677 | C11: 22378800000000 | D11: 690980000 | E11: 0 | F11: 0 | G11: 2 | H11: 5620930000000 | I11: 4528450000000 | J11: 4901240000000 | K11: 4564410000000 | L11: 2763740000000 | N11: 0.0090061 | O11: 0.00959298 | P11: 21102600000000 | Q11: 358445000 | R11: 0 | S11: 0 | T11: 2 | U11: 6005890000000 | V11: 4682900000000 | W11: 4570050000000 | X11: 4696210000000 | Y11: 1147500000000 | AA11: 0.00901695 | AB11: 0.00960578 | AC11: 20250000000000 | AD11: 278185000 | AE11: 0 | AF11: 0 | AG11: 2 | AH11: 4845390000000 | AI11: 4847380000000 | AJ11: 4854190000000 | AK11: 4885640000000 | AL11: 817398000000 | AN11: =A11 -> 0.00897935 | AO11: =AVERAGE(C11,P11,AC11) -> 21243800000000 | AR11: =AVERAGE(L11,Y11,AL11) -> 1.5762127e+12 | AS11: =MIN(L11,Y11,AL11) -> 817398000000 | AT11: =MAX(L11,Y11,AL11) -> 2763740000000
A12: 0.0100225 | B12: 0.0106203 | C12: 24434800000000 | D12: 1628920000 | E12: 0 | F12: 0 | G12: 2 | H12: 5690760000000 | I12: 6044440000000 | J12: 5057930000000 | K12: 4587730000000 | L12: 3053890000000 | N12: 0.0100658 | O12: 0.010693 | P12: 21125300000000 | Q12: 1297440000 | R12: 0 | S12: 0 | T12: 2 | U12: 5718860000000 | V12: 4509780000000 | W12: 4594680000000 | X12: 4506740000000 | Y12: 1795250000000 | AA12: 0.0100127 | AB12: 0.0106212 | AC12: 20423900000000 | AD12: 437838000 | AE12: 0 | AF12: 0 | AG12: 2 | AH12: 4833690000000 | AI12: 4849580000000 | AJ12: 4841490000000 | AK12: 4737920000000 | AL12: 1161200000000 | AN12: =A12 -> 0.0100225 | AO12: =AVERAGE(C12,P12,AC12) -> 2.1994667e+13 | AR12: =AVERAGE(L12,Y12,AL12) -> 2.0034467e+12 | AS12: =MIN(L12,Y12,AL12) -> 1161200000000 | AT12: =MAX(L12,Y12,AL12) -> 3053890000000
A13: 0.0109492 | B13: 0.0115401 | C13: 24407200000000 | D13: 844240000 | E13: 0 | F13: 0 | G13: 2 | H13: 5858320000000 | I13: 5550190000000 | J13: 5571600000000 | K13: 4768090000000 | L13: 2658430000000 | N13: 0.0110219 | O13: 0.0116451 | P13: 21349800000000 | Q13: 545690000 | R13: 0 | S13: 0 | T13: 2 | U13: 5398850000000 | V13: 4579110000000 | W13: 4657010000000 | X13: 4484160000000 | Y13: 2230640000000 | AA13: 0.0109858 | AB13: 0.0115922 | AC13: 20412400000000 | AD13: 476372000 | AE13: 0 | AF13: 0 | AG13: 2 | AH13: 4853410000000 | AI13: 4649540000000 | AJ13: 4779850000000 | AK13: 4766050000000 | AL13: 1363340000000 | AN13: =A13 -> 0.0109492 | AO13: =AVERAGE(C13,P13,AC13) -> 2.2056467e+13 | AR13: =AVERAGE(L13,Y13,AL13) -> 2.0841367e+12 | AS13: =MIN(L13,Y13,AL13) -> 1363340000000 | AT13: =MAX(L13,Y13,AL13) -> 2658430000000
... A52: 0.0499716 | B52: 0.0506223 | C52: 22837000000000 | D52: 1053730000 | E52: 0 | F52: 0 | G52: 2 | H52: 5463830000000 | I52: 4414520000000 | J52: 5634010000000 | K52: 4792390000000 | L52: 2532220000000 | N52: 0.0499045 | O52: 0.0505007 | P52: 23333100000000 | Q52: 651539000 | R52: 0 | S52: 0 | T52: 2 | U52: 5201070000000 | V52: 5902350000000 | W52: 4966900000000 | X52: 4375440000000 | Y52: 2887340000000 | AA52: 0.0500183 | AB52: 0.0507007 | AC52: 21895900000000 | AD52: 615989000 | AE52: 0 | AF52: 0 | AG52: 2 | AH52: 4664520000000 | AI52: 4639780000000 | AJ52: 4804240000000 | AK52: 4614280000000 | AL52: 3173070000000 | AN52: =A52 -> 0.0499716 | AO52: =AVERAGE(C52,P52,AC52) -> 2.2688667e+13 | AR52: =AVERAGE(L52,Y52,AL52) -> 2864210000000 | AS52: =MIN(L52,Y52,AL52) -> 2532220000000 | AT52: =MAX(L52,Y52,AL52) -> 3173070000000
A53: 0.0510131 | B53: 0.0516527 | C53: 22350100000000 | D53: 795597000 | E53: 0 | F53: 0 | G53: 2 | H53: 5484860000000 | I53: 4626460000000 | J53: 5163260000000 | K53: 4576780000000 | L53: 2498760000000 | AA53: 0.0508411 | AB53: 0.0514904 | AC53: 21648500000000 | AD53: 859980000 | AE53: 0 | AF53: 0 | AG53: 2 | AH53: 4459860000000 | AI53: 4696310000000 | AJ53: 4701940000000 | AK53: 5048790000000 | AL53: 2741570000000 | AN53: =A53 -> 0.0510131 | AO53: =AVERAGE(C53,P53,AC53) -> 21999300000000 | AR53: =AVERAGE(L53,Y53,AL53) -> 2620165000000 | AS53: =MIN(L53,Y53,AL53) -> 2498760000000 | AT53: =MAX(L53,Y53,AL53) -> 2741570000000
A54: 0.0520037 | B54: 0.0526478 | C54: 22341100000000 | D54: 806574000 | E54: 0 | F54: 0 | G54: 2 | H54: 5733340000000 | I54: 4715930000000 | J54: 4686970000000 | K54: 4516340000000 | L54: 2688510000000
A55: 0.0529856 | B55: 0.0536038 | C55: 22664700000000 | D55: 1259670000 | E55: 0 | F55: 0 | G55: 2 | H55: 6020080000000 | I55: 4438640000000 | J55: 4834910000000 | K55: 4555850000000 | L55: 2815080000000
A56: 0.0540033 | B56: 0.0546653 | C56: 23069400000000 | D56: 1081160000 | E56: 0 | F56: 0 | G56: 2 | H56: 5477910000000 | I56: 4310460000000 | J56: 4668570000000 | K56: 5154580000000 | L56: 3457710000000
C59: =AVERAGE(C28:C32) -> 22543600000000 | L59: =AVERAGE(L28:L32) -> 2735326000000 | P59: =AVERAGE(P28:P32) -> 23056260000000 | Y59: =AVERAGE(Y28:Y32) -> 2919746000000 | AC59: =AVERAGE(AC28:AC32) -> 23398880000000 | AL59: =AVERAGE(AL28:AL32) -> 2946768000000

Sheet 300K_SR100_Stress
A1: Config1 | D1: Config2 | G1: Config3 | J1: AverageValue of Last 0.5%
A2: 0.000179423 | B2: 116025000 | D2: 0.000149957 | E2: 110025000 | G2: 0.000169795 | H2: 106240000 | K2: TotalStress | L2: RhoI | M2: Rho | N2: TauF1 | O2: TauF2 | P2: TauF | Q2: Tau | R2: Tau/TauF | S2: RhoI/Rho
A3: 0.00102473 | B3: 149080000 | D3: 0.00101315 | E3: 151427000 | G3: 0.00102785 | H3: 151972000 | J3: Config1 | K3: 147 | L3: 284000000000 | M3: 20000000000000 | N3: =0.5*80.9*0.248*SQRT(L3)/1000000 -> 5.3460052 | O3: =0.05*80.9*0.248*SQRT(M3)/1000000 -> 4.4862679 | P3: =SQRT(N3^2+O3^2) -> 6.978995 | Q3: =K3*0.4395 -> 64.6065 | R3: =Q3/P3 -> 9.2572784 | S3: =L3/M3 -> 0.0142
A4: 0.00202215 | B4: 146446000 | D4: 0.00202284 | E4: 147871000 | G4: 0.00199475 | H4: 147123000 | J4: Config2 | K4: 147 | L4: 326000000000 | M4: 20100000000000 | N4: =0.5*80.9*0.248*SQRT(L4)/1000000 -> 5.7276834 | O4: =0.05*80.9*0.248*SQRT(M4)/1000000 -> 4.4974696 | P4: =SQRT(N4^2+O4^2) -> 7.2824165 | Q4: =K4*0.4395 -> 64.6065 | R4: =Q4/P4 -> 8.8715744 | S4: =L4/M4 -> 0.016218905
A5: 0.00300973 | B5: 145357000 | D5: 0.0030001 | E5: 149364000 | G5: 0.00296564 | H5: 150963000 | J5: Config4 | K5: 148 | L5: 300000000000 | M5: 20100000000000 | N5: =0.5*80.9*0.248*SQRT(L5)/1000000 -> 5.4945336 | O5: =0.05*80.9*0.248*SQRT(M5)/1000000 -> 4.4974696 | P5: =SQRT(N5^2+O5^2) -> 7.1005023 | Q5: =K5*0.4395 -> 65.046 | R5: =Q5/P5 -> 9.1607604 | S5: =L5/M5 -> 0.014925373
A6: 0.00397296 | B6: 147506000 | D6: 0.00400961 | E6: 144515000 | G6: 0.00403862 | H6: 146054000
A7: 0.00501557 | B7: 146042000 | D7: 0.00494308 | E7: 145421000 | G7: 0.00502587 | H7: 146773000
A8: 0.00599917 | B8: 148477000 | D8: 0.00597295 | E8: 151358000 | G8: 0.00598598 | H8: 147392000
A9: 0.00700747 | B9: 146665000 | D9: 0.0069798 | E9: 148263000 | G9: 0.00697691 | H9: 148324000
A10: 0.00802983 | B10: 147195000 | D10: 0.00802353 | E10: 146590000 | G10: 0.0079513 | H10: 148428000
A11: 0.0090006 | B11: 148007000 | D11: 0.00899122 | E11: 146015000 | G11: 0.00901626 | H11: 147581000
A12: 0.0100111 | B12: 147672000 | D12: 0.0100051 | E12: 148251000 | G12: 0.0100257 | H12: 145056000
A13: 0.0109899 | B13: 145680000 | D13: 0.0109804 | E13: 143175000 | G13: 0.0110172 | H13: 145539000
A14: 0.0120068 | B14: 144527000 | D14: 0.0119974 | E14: 144986000 | G14: 0.0119765 | H14: 147360000
A15: 0.0129769 | B15: 145566000 | D15: 0.0129288 | E15: 147750000 | G15: 0.0129495 | H15: 147950000
A16: 0.01399 | B16: 146263000 | D16: 0.0139889 | E16: 147178000 | G16: 0.0139916 | H16: 145274000
A17: 0.0150222 | B17: 146788000 | D17: 0.0150401 | E17: 146775000 | G17: 0.0149879 | H17: 146896000
... A52: 0.0499874 | B52: 149079000 | D52: 0.0499603 | E52: 149629000 | G52: 0.0500142 | H52: 148445000

Sheet 300K_SR100
A1: Config 1 | N1: Config 2 | AA1: Config 3 | AN1: Pstrain | AO1: Total | AR1: Junction | AS1: JunctionMin | AT1: JunctionMax
A2: 0.000179423 | B2: 0.000721001 | C2: 19885600000000 | D2: 1009430000 | E2: 0 | F2: 0 | G2: 2 | H2: 5478290000000 | I2: 4679780000000 | J2: 4687320000000 | K2: 4737970000000 | L2: 302216000000 | N2: 0.000149957 | O2: 0.000663531 | P2: 19873600000000 | Q2: 1423150000 | R2: 0 | S2: 0 | T2: 2 | U2: 5497770000000 | V2: 4709180000000 | W2: 4695150000000 | X2: 4718420000000 | Y2: 253126000000 | AA2: 0.000169795 | AB2: 0.000665701 | AC2: 19676800000000 | AD2: 277356000 | AE2: 0 | AF2: 0 | AG2: 2 | AH2: 4871030000000 | AI2: 4864820000000 | AJ2: 4870090000000 | AK2: 4879760000000 | AL2: 191101000000 | AN2: =A2 -> 0.000179423 | AO2: =AVERAGE(C2,P2,AC2) -> 19812000000000 | AR2: =AVERAGE(L2,Y2,AL2) -> 2.4881433e+11 | AS2: =MIN(L2,Y2,AL2) -> 191101000000 | AT2: =MAX(L2,Y2,AL2) -> 302216000000
A3: 0.00102473 | B3: 0.00172059 | C3: 20059300000000 | D3: 192236000 | E3: 0 | F3: 0 | G3: 2 | H3: 5536440000000 | I3: 4767710000000 | J3: 4756020000000 | K3: 4747620000000 | L3: 251507000000 | N3: 0.00101315 | O3: 0.00171997 | P3: 20024000000000 | Q3: 286648000 | R3: 0 | S3: 0 | T3: 2 | U3: 5551470000000 | V3: 4716510000000 | W3: 4727520000000 | X3: 4772620000000 | Y3: 255876000000 | AA3: 0.00102785 | AB3: 0.00173722 | AC3: 19832500000000 | AD3: 153520000 | AE3: 0 | AF3: 0 | AG3: 2 | AH3: 4906550000000 | AI3: 4887760000000 | AJ3: 4885140000000 | AK3: 4898320000000 | AL3: 254734000000 | AN3: =A3 -> 0.00102473 | AO3: =AVERAGE(C3,P3,AC3) -> 1.9971933e+13 | AR3: =AVERAGE(L3,Y3,AL3) -> 254039000000 | AS3: =MIN(L3,Y3,AL3) -> 251507000000 | AT3: =MAX(L3,Y3,AL3) -> 255876000000
A4: 0.00202215 | B4: 0.00270572 | C4: 20106800000000 | D4: 591380000 | E4: 0 | F4: 0 | G4: 2 | H4: 5540240000000 | I4: 4755620000000 | J4: 4797370000000 | K4: 4763230000000 | L4: 250308000000 | N4: 0.00202284 | O4: 0.00271306 | P4: 20391500000000 | Q4: 697706000 | R4: 0 | S4: 0 | T4: 2 | U4: 5530530000000 | V4: 4775090000000 | W4: 4819260000000 | X4: 4828540000000 | Y4: 438080000000 | AA4: 0.00199475 | AB4: 0.00268147 | AC4: 19928000000000 | AD4: 573867000 | AE4: 0 | AF4: 0 | AG4: 2 | AH4: 4947330000000 | AI4: 4908750000000 | AJ4: 4919560000000 | AK4: 4924140000000 | AL4: 228231000000 | AN4: =A4 -> 0.00202215 | AO4: =AVERAGE(C4,P4,AC4) -> 20142100000000 | AR4: =AVERAGE(L4,Y4,AL4) -> 3.0553967e+11 | AS4: =MIN(L4,Y4,AL4) -> 228231000000 | AT4: =MAX(L4,Y4,AL4) -> 438080000000
A5: 0.00300973 | B5: 0.00368822 | C5: 20127800000000 | D5: 188981000 | E5: 0 | F5: 0 | G5: 2 | H5: 5556330000000 | I5: 4737970000000 | J5: 4762570000000 | K5: 4792830000000 | L5: 278072000000 | N5: 0.0030001 | O5: 0.00369729 | P5: 20317900000000 | Q5: 347682000 | R5: 0 | S5: 0 | T5: 2 | U5: 5626720000000 | V5: 4755890000000 | W5: 4743820000000 | X5: 4837870000000 | Y5: 353624000000 | AA5: 0.00296564 | AB5: 0.0036703 | AC5: 19918500000000 | AD5: 455728000 | AE5: 0 | AF5: 0 | AG5: 2 | AH5: 4916080000000 | AI5: 4924650000000 | AJ5: 4895420000000 | AK5: 4925550000000 | AL5: 256778000000 | AN5: =A5 -> 0.00300973 | AO5: =AVERAGE(C5,P5,AC5) -> 20121400000000 | AR5: =AVERAGE(L5,Y5,AL5) -> 296158000000 | AS5: =MIN(L5,Y5,AL5) -> 256778000000 | AT5: =MAX(L5,Y5,AL5) -> 353624000000
A6: 0.00397296 | B6: 0.00466147 | C6: 20131100000000 | D6: 203330000 | E6: 0 | F6: 0 | G6: 2 | H6: 5519180000000 | I6: 4779230000000 | J6: 4769870000000 | K6: 4781240000000 | L6: 281600000000 | N6: 0.00400961 | O6: 0.00468417 | P6: 19978400000000 | Q6: 293240000 | R6: 0 | S6: 0 | T6: 2 | U6: 5562910000000 | V6: 4739140000000 | W6: 4763170000000 | X6: 4742320000000 | Y6: 170876000000 | AA6: 0.00403862 | AB6: 0.00472037 | AC6: 19867100000000 | AD6: 137128000 | AE6: 0 | AF6: 0 | AG6: 2 | AH6: 4909120000000 | AI6: 4948910000000 | AJ6: 4908850000000 | AK6: 4899720000000 | AL6: 200513000000 | AN6: =A6 -> 0.00397296 | AO6: =AVERAGE(C6,P6,AC6) -> 19992200000000 | AR6: =AVERAGE(L6,Y6,AL6) -> 217663000000 | AS6: =MIN(L6,Y6,AL6) -> 170876000000 | AT6: =MAX(L6,Y6,AL6) -> 281600000000
A7: 0.00501557 | B7: 0.00569725 | C7: 20150800000000 | D7: 62065200 | E7: 0 | F7: 0 | G7: 2 | H7: 5533380000000 | I7: 4763720000000 | J7: 4729770000000 | K7: 4783930000000 | L7: 339974000000 | N7: 0.00494308 | O7: 0.00562186 | P7: 20055800000000 | Q7: 146830000 | R7: 0 | S7: 0 | T7: 2 | U7: 5541760000000 | V7: 4763550000000 | W7: 4774080000000 | X7: 4743390000000 | Y7: 232995000000 | AA7: 0.00502587 | AB7: 0.00571096 | AC7: 19832000000000 | AD7: 446568000 | AE7: 0 | AF7: 0 | AG7: 2 | AH7: 4897420000000 | AI7: 4903320000000 | AJ7: 4900320000000 | AK7: 4905140000000 | AL7: 225759000000 | AN7: =A7 -> 0.00501557 | AO7: =AVERAGE(C7,P7,AC7) -> 2.0012867e+13 | AR7: =AVERAGE(L7,Y7,AL7) -> 2.6624267e+11 | AS7: =MIN(L7,Y7,AL7) -> 225759000000 | AT7: =MAX(L7,Y7,AL7) -> 339974000000
A8: 0.00599917 | B8: 0.00669222 | C8: 20281100000000 | D8: 661115000 | E8: 0 | F8: 0 | G8: 2 | H8: 5535420000000 | I8: 4839210000000 | J8: 4774130000000 | K8: 4781870000000 | L8: 350477000000 | N8: 0.00597295 | O8: 0.00667944 | P8: 20251100000000 | Q8: 734975000 | R8: 0 | S8: 0 | T8: 2 | U8: 5538480000000 | V8: 4761100000000 | W8: 4821410000000 | X8: 4747840000000 | Y8: 382008000000 | AA8: 0.00598598 | AB8: 0.00667397 | AC8: 19906600000000 | AD8: 459041000 | AE8: 0 | AF8: 0 | AG8: 2 | AH8: 4902750000000 | AI8: 4946390000000 | AJ8: 4906150000000 | AK8: 4925050000000 | AL8: 226280000000 | AN8: =A8 -> 0.00599917 | AO8: =AVERAGE(C8,P8,AC8) -> 2.0146267e+13 | AR8: =AVERAGE(L8,Y8,AL8) -> 3.1958833e+11 | AS8: =MIN(L8,Y8,AL8) -> 226280000000 | AT8: =MAX(L8,Y8,AL8) -> 382008000000
A9: 0.00700747 | B9: 0.00769206 | C9: 20039800000000 | D9: 527180000 | E9: 0 | F9: 0 | G9: 2 | H9: 5532370000000 | I9: 4754880000000 | J9: 4747270000000 | K9: 4758380000000 | L9: 246864000000 | N9: 0.0069798 | O9: 0.00767185 | P9: 20166900000000 | Q9: 603936000 | R9: 0 | S9: 0 | T9: 2 | U9: 5545520000000 | V9: 4779210000000 | W9: 4775080000000 | X9: 4768060000000 | Y9: 299021000000 | AA9: 0.00697691 | AB9: 0.00766925 | AC9: 19883700000000 | AD9: 399521000 | AE9: 0 | AF9: 0 | AG9: 2 | AH9: 4928600000000 | AI9: 4900550000000 | AJ9: 4908940000000 | AK9: 4922240000000 | AL9: 223406000000 | AN9: =A9 -> 0.00700747 | AO9: =AVERAGE(C9,P9,AC9) -> 2.0030133e+13 | AR9: =AVERAGE(L9,Y9,AL9) -> 2.5643033e+11 | AS9: =MIN(L9,Y9,AL9) -> 223406000000 | AT9: =MAX(L9,Y9,AL9) -> 299021000000
A10: 0.00802983 | B10: 0.00871689 | C10: 20057000000000 | D10: 176238000 | E10: 0 | F10: 0 | G10: 2 | H10: 5560460000000 | I10: 4751900000000 | J10: 4761850000000 | K10: 4731920000000 | L10: 250834000000 | N10: 0.00802353 | O10: 0.00870777 | P10: 20028400000000 | Q10: 168618000 | R10: 0 | S10: 0 | T10: 2 | U10: 5546540000000 | V10: 4743930000000 | W10: 4755010000000 | X10: 4747660000000 | Y10: 235248000000 | AA10: 0.0079513 | AB10: 0.00864413 | AC10: 19983800000000 | AD10: 126266000 | AE10: 0 | AF10: 0 | AG10: 2 | AH10: 4928640000000 | AI10: 4934100000000 | AJ10: 4897310000000 | AK10: 4915810000000 | AL10: 307952000000 | AN10: =A10 -> 0.00802983 | AO10: =AVERAGE(C10,P10,AC10) -> 2.0023067e+13 | AR10: =AVERAGE(L10,Y10,AL10) -> 264678000000 | AS10: =MIN(L10,Y10,AL10) -> 235248000000 | AT10: =MAX(L10,Y10,AL10) -> 307952000000
A11: 0.0090006 | B11: 0.00969145 | C11: 20118500000000 | D11: 329515000 | E11: 0 | F11: 0 | G11: 2 | H11: 5555690000000 | I11: 4743380000000 | J11: 4747990000000 | K11: 4766510000000 | L11: 304819000000 | N11: 0.00899122 | O11: 0.00967278 | P11: 20021300000000 | Q11: 63488400 | R11: 0 | S11: 0 | T11: 2 | U11: 5551110000000 | V11: 4753140000000 | W11: 4750220000000 | X11: 4756050000000 | Y11: 210771000000 | AA11: 0.00901626 | AB11: 0.00970513 | AC11: 19916400000000 | AD11: 144024000 | AE11: 0 | AF11: 0 | AG11: 2 | AH11: 4927970000000 | AI11: 4901840000000 | AJ11: 4917480000000 | AK11: 4909240000000 | AL11: 259872000000 | AN11: =A11 -> 0.0090006 | AO11: =AVERAGE(C11,P11,AC11) -> 2.0018733e+13 | AR11: =AVERAGE(L11,Y11,AL11) -> 2.5848733e+11 | AS11: =MIN(L11,Y11,AL11) -> 210771000000 | AT11: =MAX(L11,Y11,AL11) -> 304819000000
A12: 0.0100111 | B12: 0.0107004 | C12: 20101300000000 | D12: 705282000 | E12: 0 | F12: 0 | G12: 2 | H12: 5553260000000 | I12: 4749260000000 | J12: 4754560000000 | K12: 4744840000000 | L12: 299350000000 | N12: 0.0100051 | O12: 0.0106971 | P12: 20091800000000 | Q12: 269038000 | R12: 0 | S12: 0 | T12: 2 | U12: 5568160000000 | V12: 4753650000000 | W12: 4718850000000 | X12: 4763370000000 | Y12: 287795000000 | AA12: 0.0100257 | AB12: 0.0107028 | AC12: 19892400000000 | AD12: 192442000 | AE12: 0 | AF12: 0 | AG12: 2 | AH12: 4955430000000 | AI12: 4897500000000 | AJ12: 4918100000000 | AK12: 4872020000000 | AL12: 249349000000 | AN12: =A12 -> 0.0100111 | AO12: =AVERAGE(C12,P12,AC12) -> 20028500000000 | AR12: =AVERAGE(L12,Y12,AL12) -> 2.7883133e+11 | AS12: =MIN(L12,Y12,AL12) -> 249349000000 | AT12: =MAX(L12,Y12,AL12) -> 299350000000
A13: 0.0109899 | B13: 0.0116699 | C13: 20030000000000 | D13: 405510000 | E13: 0 | F13: 0 | G13: 2 | H13: 5545840000000 | I13: 4755100000000 | J13: 4774720000000 | K13: 4746850000000 | L13: 207454000000 | N13: 0.0109804 | O13: 0.0116487 | P13: 20091500000000 | Q13: 589334000 | R13: 0 | S13: 0 | T13: 2 | U13: 5571410000000 | V13: 4769420000000 | W13: 4772800000000 | X13: 4728620000000 | Y13: 249284000000 | AA13: 0.0110172 | AB13: 0.0116966 | AC13: 19873400000000 | AD13: 219743000 | AE13: 0 | AF13: 0 | AG13: 2 | AH13: 4917100000000 | AI13: 4909180000000 | AJ13: 4913510000000 | AK13: 4916870000000 | AL13: 216700000000 | AN13: =A13 -> 0.0109899 | AO13: =AVERAGE(C13,P13,AC13) -> 19998300000000 | AR13: =AVERAGE(L13,Y13,AL13) -> 2.2447933e+11 | AS13: =MIN(L13,Y13,AL13) -> 207454000000 | AT13: =MAX(L13,Y13,AL13) -> 249284000000
... A52: 0.0499874 | B52: 0.0506832 | C52: 20170000000000 | D52: 348508000 | E52: 0 | F52: 0 | G52: 2 | H52: 5542770000000 | I52: 4753250000000 | J52: 4754230000000 | K52: 4796400000000 | L52: 323345000000 | N52: 0.0499603 | O52: 0.0506587 | P52: 20321800000000 | Q52: 448687000 | R52: 0 | S52: 0 | T52: 2 | U52: 5533150000000 | V52: 4845640000000 | W52: 4793620000000 | X52: 4770560000000 | Y52: 378839000000 | AA52: 0.0500142 | AB52: 0.0507071 | AC52: 20020500000000 | AD52: 463265000 | AE52: 0 | AF52: 0 | AG52: 2 | AH52: 4877580000000 | AI52: 4893100000000 | AJ52: 4938530000000 | AK52: 4958130000000 | AL52: 353139000000 | AN52: =A52 -> 0.0499874 | AO52: =AVERAGE(C52,P52,AC52) -> 2.0170767e+13 | AR52: =AVERAGE(L52,Y52,AL52) -> 3.5177433e+11 | AS52: =MIN(L52,Y52,AL52) -> 323345000000 | AT52: =MAX(L52,Y52,AL52) -> 378839000000
C55: =AVERAGE(C24:C28) -> 20119920000000 | L55: =AVERAGE(L24:L28) -> 285177600000 | P55: =AVERAGE(P24:P28) -> 20189560000000 | Y55: =AVERAGE(Y24:Y28) -> 325717200000 | AC55: =AVERAGE(AC24:AC28) -> 20003260000000 | AL55: =AVERAGE(AL24:AL28) -> 299316600000

Sheet 300K_SR10000_Stress
A1: Config1 | D1: Config2 | G1: Config3 | J1: AverageValue of Last 0.5%
A2: 0.000211826 | B2: 376174000 | K2: TotalStress | L2: RhoI | M2: Rho | N2: TauF1 | O2: TauF2 | P2: TauF | Q2: Tau | R2: Tau/TauF | S2: RhoI/Rho
A3: 0.000970022 | B3: 527861000 | J3: Config1
A4: 0.00194907 | B4: 491036000 | J4: Config2 | K4: 295 | L4: 3880000000000 | M4: 84500000000000 | N4: =0.5*80.9*0.248*SQRT(L4)/1000000 -> 19.75996 | O4: =0.05*80.9*0.248*SQRT(M4)/1000000 -> 9.2214361 | P4: =SQRT(N4^2+O4^2) -> 21.805754 | Q4: =K4*0.4395 -> 129.6525 | R4: =Q4/P4 -> 5.945793 | S4: =L4/M4 -> 0.04591716
A5: 0.00296565 | B5: 415538000 | J5: Config4
A6: 0.00405558 | B6: 370221000
A7: 0.00500736 | B7: 348030000
A8: 0.00605242 | B8: 336269000
A9: 0.00707176 | B9: 326749000
A10: 0.0080071 | B10: 319738000
A11: 0.00894306 | B11: 319051000
A12: 0.00996431 | B12: 326411000
A13: 0.0109914 | B13: 317824000
A14: 0.0119824 | B14: 304167000
A15: 0.0130658 | B15: 299639000
A16: 0.0139003 | B16: 306127000
A17: 0.0150533 | B17: 299804000
... A47: 0.0450472 | B47: 306469000

Sheet 300K_SR10000
A1: Config 1 | N1: Config 2 | AA1: Config 3 | AN1: Pstrain | AO1: Total | AR1: Junction | AS1: JunctionMin | AT1: JunctionMax
A2: 0.000211826 | B2: 0.00196803 | C2: 20056500000000 | D2: 3978650000 | E2: 0 | F2: 0 | G2: 2 | H2: 5619250000000 | I2: 4794820000000 | J2: 4775840000000 | K2: 4830300000000 | L2: 36247800000 | AN2: =A2 -> 0.000211826 | AO2: =AVERAGE(C2,P2,AC2) -> 20056500000000 | AR2: =AVERAGE(L2,Y2,AL2) -> 36247800000 | AS2: =MIN(L2,Y2,AL2) -> 36247800000 | AT2: =MAX(L2,Y2,AL2) -> 36247800000
A3: 0.000970022 | B3: 0.00343402 | C3: 24449900000000 | D3: 11757500000 | E3: 0 | F3: 0 | G3: 2 | H3: 5653650000000 | I3: 5701800000000 | J3: 6569370000000 | K3: 6498950000000 | L3: 26109000000 | AN3: =A3 -> 0.000970022 | AO3: =AVERAGE(C3,P3,AC3) -> 24449900000000 | AR3: =AVERAGE(L3,Y3,AL3) -> 26109000000 | AS3: =MIN(L3,Y3,AL3) -> 26109000000 | AT3: =MAX(L3,Y3,AL3) -> 26109000000
