Workbook

Sheet Graphs
A1: Factor | B1: 0.325
A2: Factor | B2: 0.05

Sheet 400K_SR20
A1: Config1 | N1: Config2 | AA1: Config4 | AN1: Pstrain | AO1: Total | AP1: Totalmin | AQ1: Totalmax | AR1: Junction | AS1: Junctionmin | AT1: Junctionmax
A2: 0.000974606 | B2: 0.00150155 | C2: 127284000000000 | D2: 14477900000 | E2: 0 | F2: 0 | G2: 2 | H2: 29639100000000 | I2: 28593800000000 | J2: 29237100000000 | K2: 29314100000000 | L2: 10500100000000 | N2: 0.000990369 | O2: 0.00146597 | P2: 127455000000000 | Q2: 12050900000 | R2: 0 | S2: 0 | T2: 2 | U2: 30201100000000 | V2: 30221000000000 | W2: 30057900000000 | X2: 29634800000000 | Y2: 7340730000000 | AA2: 0.000989107 | AB2: 0.00149807 | AC2: 127202000000000 | AD2: 11494000000 | AE2: 0 | AF2: 0 | AG2: 2 | AH2: 28941700000000 | AI2: 29024000000000 | AJ2: 29174000000000 | AK2: 28900200000000 | AL2: 11161900000000 | AN2: =A2 -> 0.000974606 | AO2: =(C2) -> 127284000000000 | AP2: =MIN(C2,P2,AC2) -> 127202000000000 | AQ2: =MAX(C2,P2,AC2) -> 127455000000000 | AR2: =(L2) -> 10500100000000 | AS2: =MIN(L2,Y2,AL2) -> 7340730000000 | AT2: =MAX(L2,Y2,AL2) -> 11161900000000
A3: 0.00204321 | B3: 0.0025157 | C3: 126680000000000 | D3: 14707700000 | E3: 0 | F3: 0 | G3: 2 | H3: 28920900000000 | I3: 27950400000000 | J3: 28479100000000 | K3: 27912600000000 | L3: 13417100000000 | N3: 0.002124 | O3: 0.0025927 | P3: 127113000000000 | Q3: 29148300000 | R3: 0 | S3: 0 | T3: 2 | U3: 28811800000000 | V3: 29214300000000 | W3: 29156000000000 | X3: 28961900000000 | Y3: 10968700000000 | AA3: 0.00201989 | AB3: 0.00256861 | AC3: 127651000000000 | AD3: 2929670000 | AE3: 0 | AF3: 0 | AG3: 2 | AH3: 27792100000000 | AI3: 28187900000000 | AJ3: 28398300000000 | AK3: 27951000000000 | AL3: 15321700000000 | AN3: =A3 -> 0.00204321 | AO3: =(C3) -> 126680000000000 | AP3: =MIN(C3,P3,AC3) -> 126680000000000 | AQ3: =MAX(C3,P3,AC3) -> 127651000000000 | AR3: =(L3) -> 13417100000000 | AS3: =MIN(L3,Y3,AL3) -> 10968700000000 | AT3: =MAX(L3,Y3,AL3) -> 15321700000000
A4: 0.00297351 | B4: 0.00347727 | C4: 127092000000000 | D4: 16262200000 | E4: 0 | F4: 0 | G4: 2 | H4: 28458200000000 | I4: 27950600000000 | J4: 28270700000000 | K4: 27270000000000 | L4: 15141500000000 | N4: 0.00306679 | O4: 0.00347771 | P4: 126808000000000 | Q4: 19662500000 | R4: 0 | S4: 0 | T4: 2 | U4: 28172400000000 | V4: 29271600000000 | W4: 29072500000000 | X4: 29351600000000 | Y4: 10940300000000 | AA4: 0.00323733 | AB4: 0.00381179 | AC4: 127281000000000 | AD4: 10309000000 | AE4: 0 | AF4: 0 | AG4: 2 | AH4: 27188400000000 | AI4: 27115500000000 | AJ4: 27814300000000 | AK4: 28420900000000 | AL4: 16741700000000 | AN4: =A4 -> 0.00297351 | AO4: =(C4) -> 127092000000000 | AP4: =MIN(C4,P4,AC4) -> 126808000000000 | AQ4: =MAX(C4,P4,AC4) -> 127281000000000 | AR4: =(L4) -> 15141500000000 | AS4: =MIN(L4,Y4,AL4) -> 10940300000000 | AT4: =MAX(L4,Y4,AL4) -> 16741700000000
A5: 0.00403768 | B5: 0.00456 | C5: 126962000000000 | D5: 5676670000 | E5: 0 | F5: 0 | G5: 2 | H5: 28519900000000 | I5: 27585700000000 | J5: 27891000000000 | K5: 26837900000000 | L5: 16127400000000 | N5: 0.00400013 | O5: 0.00443865 | P5: 126542000000000 | Q5: 16871300000 | R5: 0 | S5: 0 | T5: 2 | U5: 27236400000000 | V5: 28773400000000 | W5: 27638900000000 | X5: 28423700000000 | Y5: 14469200000000 | AA5: 0.00398168 | AB5: 0.00455409 | AC5: 127170000000000 | AD5: 8632600000 | AE5: 0 | AF5: 0 | AG5: 2 | AH5: 27577500000000 | AI5: 28033400000000 | AJ5: 27536500000000 | AK5: 27789200000000 | AL5: 16233100000000 | AN5: =A5 -> 0.00403768 | AO5: =(C5) -> 126962000000000 | AP5: =MIN(C5,P5,AC5) -> 126542000000000 | AQ5: =MAX(C5,P5,AC5) -> 127170000000000 | AR5: =(L5) -> 16127400000000 | AS5: =MIN(L5,Y5,AL5) -> 14469200000000 | AT5: =MAX(L5,Y5,AL5) -> 16233100000000
A6: 0.00499008 | B6: 0.0055361 | C6: 127211000000000 | D6: 15526300000 | E6: 0 | F6: 0 | G6: 2 | H6: 28434800000000 | I6: 27310900000000 | J6: 27788700000000 | K6: 26949300000000 | L6: 16726800000000 | N6: 0.0050262 | O6: 0.00545315 | P6: 125886000000000 | Q6: 30786600000 | R6: 0 | S6: 0 | T6: 2 | U6: 26663400000000 | V6: 28167600000000 | W6: 26617200000000 | X6: 27957700000000 | Y6: 16479700000000 | AA6: 0.00498484 | AB6: 0.0055331 | AC6: 127370000000000 | AD6: 16666600000 | AE6: 0 | AF6: 0 | AG6: 2 | AH6: 27484800000000 | AI6: 28263000000000 | AJ6: 27943400000000 | AK6: 27551400000000 | AL6: 16127600000000 | AN6: =A6 -> 0.00499008 | AO6: =(C6) -> 127211000000000 | AP6: =MIN(C6,P6,AC6) -> 125886000000000 | AQ6: =MAX(C6,P6,AC6) -> 127370000000000 | AR6: =(L6) -> 16726800000000 | AS6: =MIN(L6,Y6,AL6) -> 16127600000000 | AT6: =MAX(L6,Y6,AL6) -> 16726800000000
A7: 0.00601634 | B7: 0.00653276 | C7: 127545000000000 | D7: 19131200000 | E7: 0 | F7: 0 | G7: 2 | H7: 28981100000000 | I7: 27552800000000 | J7: 27562500000000 | K7: 27778700000000 | L7: 15669800000000 | N7: 0.00609306 | O7: 0.00650958 | P7: 125931000000000 | Q7: 11745000000 | R7: 0 | S7: 0 | T7: 2 | U7: 26652600000000 | V7: 28343900000000 | W7: 27105800000000 | X7: 28229000000000 | Y7: 15599800000000 | AA7: 0.00600329 | AB7: 0.00656032 | AC7: 127498000000000 | AD7: 12154900000 | AE7: 0 | AF7: 0 | AG7: 2 | AH7: 27468900000000 | AI7: 28286400000000 | AJ7: 27587100000000 | AK7: 27444800000000 | AL7: 16710800000000 | AN7: =A7 -> 0.00601634 | AO7: =(C7) -> 127545000000000 | AP7: =MIN(C7,P7,AC7) -> 125931000000000 | AQ7: =MAX(C7,P7,AC7) -> 127545000000000 | AR7: =(L7) -> 15669800000000 | AS7: =MIN(L7,Y7,AL7) -> 15599800000000 | AT7: =MAX(L7,Y7,AL7) -> 16710800000000
A8: 0.00699688 | B8: 0.00755531 | C8: 128202000000000 | D8: 5368550000 | E8: 0 | F8: 0 | G8: 2 | H8: 27688200000000 | I8: 27815100000000 | J8: 27630400000000 | K8: 27648000000000 | L8: 17417300000000 | N8: 0.00699312 | O8: 0.0073905 | P8: 125813000000000 | Q8: 10788600000 | R8: 0 | S8: 0 | T8: 2 | U8: 27055400000000 | V8: 28463700000000 | W8: 27591200000000 | X8: 28462100000000 | Y8: 14240600000000 | AA8: 0.00695664 | AB8: 0.00745313 | AC8: 126872000000000 | AD8: 13096600000 | AE8: 0 | AF8: 0 | AG8: 2 | AH8: 27337100000000 | AI8: 28922800000000 | AJ8: 27489700000000 | AK8: 27514800000000 | AL8: 15607900000000 | AN8: =A8 -> 0.00699688 | AO8: =(C8) -> 128202000000000 | AP8: =MIN(C8,P8,AC8) -> 125813000000000 | AQ8: =MAX(C8,P8,AC8) -> 128202000000000 | AR8: =(L8) -> 17417300000000 | AS8: =MIN(L8,Y8,AL8) -> 14240600000000 | AT8: =MAX(L8,Y8,AL8) -> 17417300000000
A9: 0.00803321 | B9: 0.0086379 | C9: 128691000000000 | D9: 9487620000 | E9: 0 | F9: 0 | G9: 2 | H9: 27040000000000 | I9: 26634600000000 | J9: 27421100000000 | K9: 26684300000000 | L9: 20891300000000 | N9: 0.0080631 | O9: 0.00847194 | P9: 125469000000000 | Q9: 9402100000 | R9: 0 | S9: 0 | T9: 2 | U9: 26835500000000 | V9: 27714700000000 | W9: 27044200000000 | X9: 27929200000000 | Y9: 15945000000000 | AA9: 0.00812375 | AB9: 0.00861937 | AC9: 126697000000000 | AD9: 6717800000 | AE9: 0 | AF9: 0 | AG9: 2 | AH9: 27664900000000 | AI9: 28583300000000 | AJ9: 27820300000000 | AK9: 27585500000000 | AL9: 15040600000000 | AN9: =A9 -> 0.00803321 | AO9: =(C9) -> 128691000000000 | AP9: =MIN(C9,P9,AC9) -> 125469000000000 | AQ9: =MAX(C9,P9,AC9) -> 128691000000000 | AR9: =(L9) -> 20891300000000 | AS9: =MIN(L9,Y9,AL9) -> 15040600000000 | AT9: =MAX(L9,Y9,AL9) -> 20891300000000
A10: 0.00900416 | B10: 0.00960398 | C10: 129237000000000 | D10: 28134000000 | E10: 0 | F10: 0 | G10: 2 | H10: 26029900000000 | I10: 26062800000000 | J10: 27337600000000 | K10: 26065500000000 | L10: 23740700000000 | N10: 0.00900432 | O10: 0.0093911 | P10: 125539000000000 | Q10: 59222400000 | R10: 0 | S10: 0 | T10: 2 | U10: 27160000000000 | V10: 27980400000000 | W10: 27384600000000 | X10: 28259000000000 | Y10: 14755000000000 | AA10: 0.0090335 | AB10: 0.00953471 | AC10: 126930000000000 | AD10: 7955250000 | AE10: 0 | AF10: 0 | AG10: 2 | AH10: 27742300000000 | AI10: 28216400000000 | AJ10: 27764000000000 | AK10: 27665100000000 | AL10: 15542000000000 | AN10: =A10 -> 0.00900416 | AO10: =(C10) -> 129237000000000 | AP10: =MIN(C10,P10,AC10) -> 125539000000000 | AQ10: =MAX(C10,P10,AC10) -> 129237000000000 | AR10: =(L10) -> 23740700000000 | AS10: =MIN(L10,Y10,AL10) -> 14755000000000 | AT10: =MAX(L10,Y10,AL10) -> 23740700000000
A11: 0.0100131 | B11: 0.010564 | C11: 128056000000000 | D11: 14017500000 | E11: 0 | F11: 0 | G11: 2 | H11: 24064100000000 | I11: 24332800000000 | J11: 26391200000000 | K11: 24953100000000 | L11: 28314100000000 | N11: 0.0100997 | O11: 0.0105104 | P11: 125822000000000 | Q11: 20807200000 | R11: 0 | S11: 0 | T11: 2 | U11: 27419900000000 | V11: 28433800000000 | W11: 27329100000000 | X11: 28258700000000 | Y11: 14380900000000 | AA11: 0.0100048 | AB11: 0.0104919 | AC11: 126540000000000 | AD11: 20161000000 | AE11: 0 | AF11: 0 | AG11: 2 | AH11: 27881200000000 | AI11: 28150200000000 | AJ11: 27968400000000 | AK11: 27167200000000 | AL11: 15371900000000 | AN11: =A11 -> 0.0100131 | AO11: =(C11) -> 128056000000000 | AP11: =MIN(C11,P11,AC11) -> 125822000000000 | AQ11: =MAX(C11,P11,AC11) -> 128056000000000 | AR11: =(L11) -> 28314100000000 | AS11: =MIN(L11,Y11,AL11) -> 14380900000000 | AT11: =MAX(L11,Y11,AL11) -> 28314100000000
A12: 0.0110256 | B12: 0.0115959 | C12: 125926000000000 | D12: 4236480000 | E12: 0 | F12: 0 | G12: 2 | H12: 21301800000000 | I12: 21342400000000 | J12: 23043300000000 | K12: 23131700000000 | L12: 37106700000000 | N12: 0.0110179 | O12: 0.0114791 | P12: 125620000000000 | Q12: 83262400000 | R12: 0 | S12: 0 | T12: 2 | U12: 26405200000000 | V12: 27683500000000 | W12: 26885100000000 | X12: 27755500000000 | Y12: 16890300000000 | AA12: 0.0110689 | AB12: 0.0115566 | AC12: 126321000000000 | AD12: 6206200000 | AE12: 0 | AF12: 0 | AG12: 2 | AH12: 27960700000000 | AI12: 28684800000000 | AJ12: 28077200000000 | AK12: 27054400000000 | AL12: 14543500000000 | AN12: =A12 -> 0.0110256 | AO12: =(C12) -> 125926000000000 | AP12: =MIN(C12,P12,AC12) -> 125620000000000 | AQ12: =MAX(C12,P12,AC12) -> 126321000000000 | AR12: =(L12) -> 37106700000000 | AS12: =MIN(L12,Y12,AL12) -> 14543500000000 | AT12: =MAX(L12,Y12,AL12) -> 37106700000000
A13: 0.0120005 | B13: 0.0126315 | C13: 125953000000000 | D13: 26522100000 | E13: 0 | F13: 0 | G13: 2 | H13: 19266000000000 | I13: 19611800000000 | J13: 21347700000000 | K13: 21523900000000 | L13: 44200400000000 | N13: 0.0120621 | O13: 0.0126571 | P13: 126069000000000 | Q13: 14940500000 | R13: 0 | S13: 0 | T13: 2 | U13: 26420700000000 | V13: 26983700000000 | W13: 26345500000000 | X13: 27731800000000 | Y13: 18585700000000 | AA13: 0.0119677 | AB13: 0.0124856 | AC13: 126727000000000 | AD13: 21211400000 | AE13: 0 | AF13: 0 | AG13: 2 | AH13: 27798100000000 | AI13: 28201100000000 | AJ13: 28200100000000 | AK13: 26905200000000 | AL13: 15616500000000 | AN13: =A13 -> 0.0120005 | AO13: =(C13) -> 125953000000000 | AP13: =MIN(C13,P13,AC13) -> 125953000000000 | AQ13: =MAX(C13,P13,AC13) -> 126727000000000 | AR13: =(L13) -> 44200400000000 | AS13: =MIN(L13,Y13,AL13) -> 15616500000000 | AT13: =MAX(L13,Y13,AL13) -> 44200400000000
... A28: 0.0269637 | B28: 0.0278059 | C28: 121279000000000 | D28: 9068360000 | E28: 0 | F28: 0 | G28: 2 | H28: 13043900000000 | I28: 12027800000000 | J28: 10982700000000 | K28: 12850300000000 | L28: 72296900000000 | N28: 0.0269885 | O28: 0.027681 | P28: 123503000000000 | Q28: 8702430000 | R28: 0 | S28: 0 | T28: 2 | U28: 14944700000000 | V28: 13835600000000 | W28: 14091200000000 | X28: 14806700000000 | Y28: 65685200000000 | AA28: 0.0270004 | AB28: 0.0273913 | AC28: 126914000000000 | AD28: 4088190000 | AE28: 0 | AF28: 0 | AG28: 2 | AH28: 27684900000000 | AI28: 30619700000000 | AJ28: 31336800000000 | AK28: 27988000000000 | AL28: 9284870000000 | AN28: =A28 -> 0.0269637 | AO28: =(C28) -> 121279000000000 | AP28: =MIN(C28,P28,AC28) -> 121279000000000 | AQ28: =MAX(C28,P28,AC28) -> 126914000000000 | AR28: =(L28) -> 72296900000000 | AS28: =MIN(L28,Y28,AL28) -> 9284870000000 | AT28: =MAX(L28,Y28,AL28) -> 72296900000000
A29: 0.0281025 | B29: 0.0288026 | C29: 123207000000000 | D29: 14636000000 | E29: 0 | F29: 0 | G29: 2 | H29: 14827400000000 | I29: 12804400000000 | J29: 12448200000000 | K29: 15888900000000 | L29: 67157700000000 | N29: 0.0279744 | O29: 0.0288481 | P29: 122132000000000 | Q29: 22808200000 | R29: 0 | S29: 0 | T29: 2 | U29: 14123500000000 | V29: 12182400000000 | W29: 12663600000000 | X29: 12687900000000 | Y29: 70368800000000 | AN29: =A29 -> 0.0281025 | AO29: =(C29) -> 123207000000000 | AP29: =MIN(C29,P29,AC29) -> 122132000000000 | AQ29: =MAX(C29,P29,AC29) -> 123207000000000 | AR29: =(L29) -> 67157700000000 | AS29: =MIN(L29,Y29,AL29) -> 67157700000000 | AT29: =MAX(L29,Y29,AL29) -> 70368800000000
A30: 0.0289868 | B30: 0.0297027 | C30: 122664000000000 | D30: 12460700000 | E30: 0 | F30: 0 | G30: 2 | H30: 13944700000000 | I30: 13730800000000 | J30: 13215600000000 | K30: 13881000000000 | L30: 67795300000000 | AN30: =A30 -> 0.0289868 | AO30: =(C30) -> 122664000000000 | AP30: =MIN(C30,P30,AC30) -> 122664000000000 | AQ30: =MAX(C30,P30,AC30) -> 122664000000000 | AR30: =(L30) -> 67795300000000 | AS30: =MIN(L30,Y30,AL30) -> 67795300000000 | AT30: =MAX(L30,Y30,AL30) -> 67795300000000
AN31: =A31 -> 0 | AO31: =(C31) -> 0 | AP31: =MIN(C31,P31,AC31) -> 0 | AQ31: =MAX(C31,P31,AC31) -> 0 | AR31: =(L31) -> 0 | AS31: =MIN(L31,Y31,AL31) -> 0 | AT31: =MAX(L31,Y31,AL31) -> 0

Sheet 400K_SR20_Stress
A1: Config 1 | D1: Config 2 | G1: Config4 | K1: AverageValue of Last 0.5%
A2: 0.000974606 | B2: 110579000 | D2: 0.000990369 | E2: 99805500 | G2: 0.000989107 | H2: 106808000 | K2: TotalStress | L2: RhoI | M2: Rho | N2: TauF1 | O2: TauF2 | P2: TauF | Q2: Tau | R2: Tau/TauF | S2: RhoI/Rho
A3: 0.00204321 | B3: 99151100 | D3: 0.002124 | E3: 98356300 | G3: 0.00201989 | H3: 115151000 | J3: Config1 | K3: =AVERAGE(B25:B30)/1000000 -> 155.94133 | L3: =AVERAGE('400K_SR20'!L28:L32) -> 69083300000000 | M3: =AVERAGE('400K_SR20'!C28:C32) -> 122383333333333 | N3: =Graphs!$B$1*80.9*0.248*SQRT(L3)/1000000 -> 54.196358 | O3: =Graphs!$B$2*80.9*0.248*SQRT(M3)/1000000 -> 11.097658 | P3: =SQRT(N3^2+O3^2) -> 55.320911 | Q3: =K3*0.4707 -> 73.401586 | R3: =Q3/P3 -> 1.3268325 | S3: =L3/M3 -> 0.56448291
A4: 0.00297351 | B4: 105715000 | D4: 0.00306679 | E4: 86227800 | G4: 0.00323733 | H4: 120553000 | J4: Config2 | K4: =AVERAGE(E25:E30)/1000000 -> 167.2634 | L4: =AVERAGE('400K_SR20'!Y28:Y32) -> 68027000000000 | M4: =AVERAGE('400K_SR20'!P28:P32) -> 122817500000000 | N4: =Graphs!$B$1*80.9*0.248*SQRT(L4)/1000000 -> 53.780424 | O4: =Graphs!$B$2*80.9*0.248*SQRT(M4)/1000000 -> 11.117326 | P4: =SQRT(N4^2+O4^2) -> 54.917474 | Q4: =K4*0.4707 -> 78.730882 | R4: =Q4/P4 -> 1.4336217 | S4: =L4/M4 -> 0.55388686
A5: 0.00403768 | B5: 109610000 | D5: 0.00400013 | E5: 92019400 | G5: 0.00398168 | H5: 120121000 | J5: Config4 | K5: =AVERAGE(H24:H28)/1000000 -> 87.40314 | L5: =AVERAGE('400K_SR20'!AL28:AL32) -> 9284870000000 | M5: =AVERAGE('400K_SR20'!AC28:AC32) -> 126914000000000 | N5: =Graphs!$B$1*80.9*0.248*SQRT(L5)/1000000 -> 19.868793 | O5: =Graphs!$B$2*80.9*0.248*SQRT(M5)/1000000 -> 11.301211 | P5: =SQRT(N5^2+O5^2) -> 22.857959 | Q5: =K5*0.4707 -> 41.140658 | R5: =Q5/P5 -> 1.7998395 | S5: =L5/M5 -> 0.073158753
A6: 0.00499008 | B6: 114582000 | D6: 0.0050262 | E6: 89592500 | G6: 0.00498484 | H6: 115054000
A7: 0.00601634 | B7: 108370000 | D7: 0.00609306 | E7: 87400300 | G7: 0.00600329 | H7: 116893000
A8: 0.00699688 | B8: 117188000 | D8: 0.00699312 | E8: 83381600 | G8: 0.00695664 | H8: 104188000
A9: 0.00803321 | B9: 126894000 | D9: 0.0080631 | E9: 85785500 | G9: 0.00812375 | H9: 104007000
A10: 0.00900416 | B10: 125873000 | D10: 0.00900432 | E10: 81150900 | G10: 0.0090335 | H10: 105178000
A11: 0.0100131 | B11: 115600000 | D11: 0.0100997 | E11: 86188000 | G11: 0.0100048 | H11: 102231000 | J11: 1-1.5%
A12: 0.0110256 | B12: 119675000 | D12: 0.0110179 | E12: 96758900 | G12: 0.0110689 | H12: 102355000 | K12: TotalStress | L12: RhoI | M12: Rho | N12: TauF1 | O12: TauF2 | P12: TauF | Q12: Tau | R12: Tau/TauF | S12: RhoI/Rho
A13: 0.0120005 | B13: 132414000 | D13: 0.0120621 | E13: 124863000 | G13: 0.0119677 | H13: 108677000 | J13: Config1 | K13: =AVERAGE(B12:B16)/1000000 -> 136.4098 | L13: =AVERAGE('400K_SR20'!L12:L16) -> 47569620000000 | M13: =AVERAGE('400K_SR20'!C12:C16) -> 125554400000000 | N13: =Graphs!$B$1*80.9*0.248*SQRT(L13)/1000000 -> 44.972642 | O13: =Graphs!$B$2*80.9*0.248*SQRT(M13)/1000000 -> 11.240514 | P13: =SQRT(N13^2+O13^2) -> 46.356097 | Q13: =K13*0.4707 -> 64.208093 | R13: =Q13/P13 -> 1.3851057 | S13: =L13/M13 -> 0.37887657
A14: 0.0131082 | B14: 146766000 | D14: 0.0130452 | E14: 145691000 | G14: 0.0129759 | H14: 108822000 | J14: Config2 | K14: =AVERAGE(E12:E16)/1000000 -> 131.75038 | L14: =AVERAGE('400K_SR20'!Y12:Y16) -> 20649040000000 | M14: =AVERAGE('400K_SR20'!P12:P16) -> 127375000000000 | N14: =Graphs!$B$1*80.9*0.248*SQRT(L14)/1000000 -> 29.630126 | O14: =Graphs!$B$2*80.9*0.248*SQRT(M14)/1000000 -> 11.321717 | P14: =SQRT(N14^2+O14^2) -> 31.719484 | Q14: =K14*0.4707 -> 62.014904 | R14: =Q14/P14 -> 1.9551045 | S14: =L14/M14 -> 0.16211219
A15: 0.0140191 | B15: 142697000 | D15: 0.0139858 | E15: 151131000 | G15: 0.0141253 | H15: 108317000 | J15: Config4 | K15: =AVERAGE(H12:H16)/1000000 -> 106.4906 | L15: =AVERAGE('400K_SR20'!AL12:AL16) -> 15820340000000 | M15: =AVERAGE('400K_SR20'!AC12:AC16) -> 126562200000000 | N15: =Graphs!$B$1*80.9*0.248*SQRT(L15)/1000000 -> 25.935312 | O15: =Graphs!$B$2*80.9*0.248*SQRT(M15)/1000000 -> 11.285537 | P15: =SQRT(N15^2+O15^2) -> 28.284337 | Q15: =K15*0.4707 -> 50.125125 | R15: =Q15/P15 -> 1.7721867 | S15: =L15/M15 -> 0.12500051
A16: 0.0150061 | B16: 140497000 | D16: 0.0150132 | E16: 140308000 | G16: 0.0148874 | H16: 104282000
A17: 0.0160272 | B17: 134553000 | D17: 0.0160216 | E17: 141558000 | G17: 0.0161202 | H17: 98637500
A18: 0.0169018 | B18: 196898000 | D18: 0.0171345 | E18: 135206000 | G18: 0.0170747 | H18: 96121700
A19: 0.0180332 | B19: 173200000 | D19: 0.0180138 | E19: 140272000 | G19: 0.0179877 | H19: 93269500
A20: 0.0189849 | B20: 197333000 | D20: 0.0189339 | E20: 139626000 | G20: 0.0189791 | H20: 91531900
A21: 0.0199998 | B21: 167221000 | D21: 0.0200167 | E21: 123552000 | G21: 0.0199769 | H21: 88576400
A22: 0.0207894 | B22: 192091000 | D22: 0.0209944 | E22: 134096000 | G22: 0.0210492 | H22: 83583500
A23: 0.0218755 | B23: 187385000 | D23: 0.0220424 | E23: 129314000 | G23: 0.0220476 | H23: 87511800
A24: 0.0228839 | B24: 165898000 | D24: 0.0229543 | E24: 132968000 | G24: 0.0229617 | H24: 93218600
A25: 0.0240288 | B25: 134088000 | D25: 0.0238307 | E25: 159191000 | G25: 0.0240296 | H25: 87847100
A26: 0.0249402 | B26: 170641000 | D26: 0.0249625 | E26: 193321000 | G26: 0.0250661 | H26: 89130200
A27: 0.0259639 | B27: 157028000 | D27: 0.0260463 | E27: 155163000 | G27: 0.0259647 | H27: 84810000
A28: 0.0269637 | B28: 176730000 | D28: 0.0269885 | E28: 145296000 | G28: 0.0270004 | H28: 82009800
A29: 0.0281025 | B29: 146932000 | D29: 0.0279744 | E29: 183346000
A30: 0.0289868 | B30: 150229000

Sheet 400K_SR40
A1: Config1 | N1: Config2 | AA1: Config3 | AN1: Pstrain | AO1: Total | AP1: Totalmin | AQ1: Totalmax | AR1: Junction | AS1: Junctionmin | AT1: Junctionmax
A2: 0.00092756 | B2: 0.00166508 | C2: 426798000000000 | D2: 103435000000 | E2: 0 | F2: 0 | G2: 2 | H2: 99987000000000 | I2: 100913000000000 | J2: 100151000000000 | K2: 102203000000000 | L2: 23543800000000 | N2: 0.00104593 | O2: 0.00160097 | P2: 426026000000000 | Q2: 101645000000 | R2: 0 | S2: 0 | T2: 2 | U2: 100682000000000 | V2: 102856000000000 | W2: 99339300000000 | X2: 101126000000000 | Y2: 22022500000000 | AA2: 0.000972836 | AB2: 0.00151735 | AC2: 426160000000000 | AD2: 121656000000 | AE2: 0 | AF2: 0 | AG2: 2 | AH2: 102358000000000 | AI2: 102693000000000 | AJ2: 102554000000000 | AK2: 102581000000000 | AL2: 15973500000000 | AN2: =A2 -> 0.00092756 | AO2: =(C2+P2+AC2)/3 -> 426328000000000 | AP2: =MIN(C2,P2,AC2) -> 426026000000000 | AQ2: =MAX(C2,P2,AC2) -> 426798000000000 | AR2: =(L2+Y2+AL2)/3 -> 2.0513267e+13 | AS2: =MIN(L2,Y2,AL2) -> 15973500000000 | AT2: =MAX(L2,Y2,AL2) -> 23543800000000
A3: 0.00207021 | B3: 0.00289902 | C3: 426831000000000 | D3: 30039400000 | E3: 0 | F3: 0 | G3: 2 | H3: 94889400000000 | I3: 96215600000000 | J3: 94588200000000 | K3: 95483600000000 | L3: 45653700000000 | N3: 0.00200804 | O3: 0.00264248 | P3: 427597000000000 | Q3: 83562700000 | R3: 0 | S3: 0 | T3: 2 | U3: 100179000000000 | V3: 100055000000000 | W3: 98136000000000 | X3: 99920900000000 | Y3: 29306600000000 | AA3: 0.0019911 | AB3: 0.00254648 | AC3: 427028000000000 | AD3: 123708000000 | AE3: 0 | AF3: 0 | AG3: 2 | AH3: 101020000000000 | AI3: 102761000000000 | AJ3: 101580000000000 | AK3: 100279000000000 | AL3: 21387600000000 | AN3: =A3 -> 0.00207021 | AO3: =(C3+P3+AC3)/3 -> 427152000000000 | AP3: =MIN(C3,P3,AC3) -> 426831000000000 | AQ3: =MAX(C3,P3,AC3) -> 427597000000000 | AR3: =(L3+Y3+AL3)/3 -> 3.2115967e+13 | AS3: =MIN(L3,Y3,AL3) -> 21387600000000 | AT3: =MAX(L3,Y3,AL3) -> 45653700000000
A4: 0.00294065 | B4: 0.00380009 | C4: 426001000000000 | D4: 140076000000 | E4: 0 | F4: 0 | G4: 2 | H4: 93912100000000 | I4: 93889200000000 | J4: 91761800000000 | K4: 94234600000000 | L4: 52203700000000 | N4: 0.00305486 | O4: 0.00375572 | P4: 429517000000000 | Q4: 24601400000 | R4: 0 | S4: 0 | T4: 2 | U4: 99012300000000 | V4: 99022600000000 | W4: 97028800000000 | X4: 98229700000000 | Y4: 36223300000000 | AA4: 0.00296189 | AB4: 0.00363299 | AC4: 428277000000000 | AD4: 72849900000 | AE4: 0 | AF4: 0 | AG4: 2 | AH4: 99034600000000 | AI4: 100426000000000 | AJ4: 98719700000000 | AK4: 96996800000000 | AL4: 33098500000000 | AN4: =A4 -> 0.00294065 | AO4: =(C4+P4+AC4)/3 -> 427931666666667 | AP4: =MIN(C4,P4,AC4) -> 426001000000000 | AQ4: =MAX(C4,P4,AC4) -> 429517000000000 | AR4: =(L4+Y4+AL4)/3 -> 40508500000000 | AS4: =MIN(L4,Y4,AL4) -> 33098500000000 | AT4: =MAX(L4,Y4,AL4) -> 52203700000000
A5: 0.00401055 | B5: 0.00484524 | C5: 426355000000000 | D5: 55627700000 | E5: 0 | F5: 0 | G5: 2 | H5: 92962800000000 | I5: 93047100000000 | J5: 91651700000000 | K5: 94209400000000 | L5: 54483800000000 | N5: 0.00403945 | O5: 0.00476058 | P5: 428513000000000 | Q5: 53663900000 | R5: 0 | S5: 0 | T5: 2 | U5: 97118400000000 | V5: 97896200000000 | W5: 94869100000000 | X5: 95304800000000 | Y5: 43324000000000 | AA5: 0.00400461 | AB5: 0.00465129 | AC5: 426357000000000 | AD5: 52615300000 | AE5: 0 | AF5: 0 | AG5: 2 | AH5: 96481000000000 | AI5: 97599600000000 | AJ5: 96109600000000 | AK5: 94279500000000 | AL5: 41887300000000 | AN5: =A5 -> 0.00401055 | AO5: =(C5+P5+AC5)/3 -> 427075000000000 | AP5: =MIN(C5,P5,AC5) -> 426355000000000 | AQ5: =MAX(C5,P5,AC5) -> 428513000000000 | AR5: =(L5+Y5+AL5)/3 -> 4.6565033e+13 | AS5: =MIN(L5,Y5,AL5) -> 41887300000000 | AT5: =MAX(L5,Y5,AL5) -> 54483800000000
A6: 0.00498831 | B6: 0.00585458 | C6: 426586000000000 | D6: 61887700000 | E6: 0 | F6: 0 | G6: 2 | H6: 91619500000000 | I6: 92488000000000 | J6: 91200700000000 | K6: 93985400000000 | L6: 57291800000000 | N6: 0.00497604 | O6: 0.0057015 | P6: 429006000000000 | Q6: 18092400000 | R6: 0 | S6: 0 | T6: 2 | U6: 95566600000000 | V6: 97740600000000 | W6: 95787600000000 | X6: 95839400000000 | Y6: 44071500000000 | AA6: 0.00495574 | AB6: 0.00560869 | AC6: 426759000000000 | AD6: 117305000000 | AE6: 0 | AF6: 0 | AG6: 2 | AH6: 95478000000000 | AI6: 96463800000000 | AJ6: 94872000000000 | AK6: 93820500000000 | AL6: 46124500000000 | AN6: =A6 -> 0.00498831 | AO6: =(C6+P6+AC6)/3 -> 427450333333333 | AP6: =MIN(C6,P6,AC6) -> 426586000000000 | AQ6: =MAX(C6,P6,AC6) -> 429006000000000 | AR6: =(L6+Y6+AL6)/3 -> 49162600000000 | AS6: =MIN(L6,Y6,AL6) -> 44071500000000 | AT6: =MAX(L6,Y6,AL6) -> 57291800000000
A7: 0.00597565 | B7: 0.00683091 | C7: 427087000000000 | D7: 37621800000 | E7: 0 | F7: 0 | G7: 2 | H7: 90970300000000 | I7: 93348200000000 | J7: 91497000000000 | K7: 93046800000000 | L7: 58225000000000 | N7: 0.00601587 | O7: 0.00670384 | P7: 427680000000000 | Q7: 75848300000 | R7: 0 | S7: 0 | T7: 2 | U7: 94933100000000 | V7: 97067300000000 | W7: 93800700000000 | X7: 93655700000000 | Y7: 48223200000000 | AA7: 0.00603446 | AB7: 0.0066778 | AC7: 425971000000000 | AD7: 79127400000 | AE7: 0 | AF7: 0 | AG7: 2 | AH7: 94193500000000 | AI7: 96145500000000 | AJ7: 93100400000000 | AK7: 92193100000000 | AL7: 50334400000000 | AN7: =A7 -> 0.00597565 | AO7: =(C7+P7+AC7)/3 -> 426912666666667 | AP7: =MIN(C7,P7,AC7) -> 425971000000000 | AQ7: =MAX(C7,P7,AC7) -> 427680000000000 | AR7: =(L7+Y7+AL7)/3 -> 5.2260867e+13 | AS7: =MIN(L7,Y7,AL7) -> 48223200000000 | AT7: =MAX(L7,Y7,AL7) -> 58225000000000
A8: 0.00709854 | B8: 0.00796757 | C8: 426872000000000 | D8: 40821900000 | E8: 0 | F8: 0 | G8: 2 | H8: 91191100000000 | I8: 91690300000000 | J8: 90807500000000 | K8: 92378500000000 | L8: 60804600000000 | N8: 0.00699331 | O8: 0.00771232 | P8: 427251000000000 | Q8: 72436200000 | R8: 0 | S8: 0 | T8: 2 | U8: 93130100000000 | V8: 95514300000000 | W8: 92190700000000 | X8: 92985700000000 | Y8: 53426800000000 | AA8: 0.00695306 | AB8: 0.00759704 | AC8: 425625000000000 | AD8: 134973000000 | AE8: 0 | AF8: 0 | AG8: 2 | AH8: 94199300000000 | AI8: 95708600000000 | AJ8: 91863300000000 | AK8: 91208200000000 | AL8: 52645600000000 | AN8: =A8 -> 0.00709854 | AO8: =(C8+P8+AC8)/3 -> 426582666666667 | AP8: =MIN(C8,P8,AC8) -> 425625000000000 | AQ8: =MAX(C8,P8,AC8) -> 427251000000000 | AR8: =(L8+Y8+AL8)/3 -> 5.5625667e+13 | AS8: =MIN(L8,Y8,AL8) -> 52645600000000 | AT8: =MAX(L8,Y8,AL8) -> 60804600000000
A9: 0.00793644 | B9: 0.00881452 | C9: 427156000000000 | D9: 46980400000 | E9: 0 | F9: 0 | G9: 2 | H9: 91336700000000 | I9: 93902300000000 | J9: 90876500000000 | K9: 90173700000000 | L9: 60865100000000 | N9: 0.00792334 | O9: 0.0086905 | P9: 427637000000000 | Q9: 12962600000 | R9: 0 | S9: 0 | T9: 2 | U9: 91827900000000 | V9: 95326500000000 | W9: 92216800000000 | X9: 93851100000000 | Y9: 54414800000000 | AA9: 0.00806867 | AB9: 0.00865025 | AC9: 424781000000000 | AD9: 86132900000 | AE9: 0 | AF9: 0 | AG9: 2 | AH9: 93505700000000 | AI9: 95341400000000 | AJ9: 90613800000000 | AK9: 90906900000000 | AL9: 54412800000000 | AN9: =A9 -> 0.00793644 | AO9: =(C9+P9+AC9)/3 -> 426524666666667 | AP9: =MIN(C9,P9,AC9) -> 424781000000000 | AQ9: =MAX(C9,P9,AC9) -> 427637000000000 | AR9: =(L9+Y9+AL9)/3 -> 5.6564233e+13 | AS9: =MIN(L9,Y9,AL9) -> 54412800000000 | AT9: =MAX(L9,Y9,AL9) -> 60865100000000
A10: 0.00903514 | B10: 0.0099377 | C10: 426093000000000 | D10: 45858100000 | E10: 0 | F10: 0 | G10: 2 | H10: 88392900000000 | I10: 90359800000000 | J10: 88978900000000 | K10: 89309100000000 | L10: 69051700000000 | N10: 0.00881076 | O10: 0.00953985 | P10: 426658000000000 | Q10: 37273800000 | R10: 0 | S10: 0 | T10: 2 | U10: 90765700000000 | V10: 96456200000000 | W10: 91880800000000 | X10: 94416400000000 | Y10: 53137700000000 | AA10: 0.00896638 | AB10: 0.00955562 | AC10: 425653000000000 | AD10: 65120500000 | AE10: 0 | AF10: 0 | AG10: 2 | AH10: 94338100000000 | AI10: 96431400000000 | AJ10: 92563200000000 | AK10: 91787200000000 | AL10: 50532900000000 | AN10: =A10 -> 0.00903514 | AO10: =(C10+P10+AC10)/3 -> 426134666666667 | AP10: =MIN(C10,P10,AC10) -> 425653000000000 | AQ10: =MAX(C10,P10,AC10) -> 426658000000000 | AR10: =(L10+Y10+AL10)/3 -> 57574100000000 | AS10: =MIN(L10,Y10,AL10) -> 50532900000000 | AT10: =MAX(L10,Y10,AL10) -> 69051700000000
A11: 0.00989916 | B11: 0.0109142 | C11: 424868000000000 | D11: 31072400000 | E11: 0 | F11: 0 | G11: 2 | H11: 86836800000000 | I11: 88812400000000 | J11: 87059200000000 | K11: 86278000000000 | L11: 75878400000000 | N11: 0.00995094 | O11: 0.0106353 | P11: 425045000000000 | Q11: 41526700000 | R11: 0 | S11: 0 | T11: 2 | U11: 89044600000000 | V11: 96576500000000 | W11: 90869500000000 | X11: 93370600000000 | Y11: 55183500000000 | AA11: 0.00999492 | AB11: 0.0105861 | AC11: 425339000000000 | AD11: 78018700000 | AE11: 0 | AF11: 0 | AG11: 2 | AH11: 93197800000000 | AI11: 95035800000000 | AJ11: 93049800000000 | AK11: 93479400000000 | AL11: 50575400000000 | AN11: =A11 -> 0.00989916 | AO11: =(C11+P11+AC11)/3 -> 425084000000000 | AP11: =MIN(C11,P11,AC11) -> 424868000000000 | AQ11: =MAX(C11,P11,AC11) -> 425339000000000 | AR11: =(L11+Y11+AL11)/3 -> 6.0545767e+13 | AS11: =MIN(L11,Y11,AL11) -> 50575400000000 | AT11: =MAX(L11,Y11,AL11) -> 75878400000000
A12: 0.011033 | B12: 0.0120921 | C12: 427678000000000 | D12: 50264200000 | E12: 0 | F12: 0 | G12: 2 | H12: 87958100000000 | I12: 90160400000000 | J12: 88656400000000 | K12: 86907400000000 | L12: 73995900000000 | N12: 0.0109953 | O12: 0.0117122 | P12: 425881000000000 | Q12: 65118700000 | R12: 0 | S12: 0 | T12: 2 | U12: 88347300000000 | V12: 95216200000000 | W12: 90102300000000 | X12: 92238400000000 | Y12: 59976100000000 | AA12: 0.0109973 | AB12: 0.0116045 | AC12: 427468000000000 | AD12: 22279200000 | AE12: 0 | AF12: 0 | AG12: 2 | AH12: 94836500000000 | AI12: 95127500000000 | AJ12: 93659300000000 | AK12: 95043700000000 | AL12: 48800600000000 | AN12: =A12 -> 0.011033 | AO12: =(C12+P12+AC12)/3 -> 427009000000000 | AP12: =MIN(C12,P12,AC12) -> 425881000000000 | AQ12: =MAX(C12,P12,AC12) -> 427678000000000 | AR12: =(L12+Y12+AL12)/3 -> 60924200000000 | AS12: =MIN(L12,Y12,AL12) -> 48800600000000 | AT12: =MAX(L12,Y12,AL12) -> 73995900000000
A13: 0.0120692 | B13: 0.0130836 | C13: 433527000000000 | D13: 29086300000 | E13: 0 | F13: 0 | G13: 2 | H13: 88424300000000 | I13: 91809500000000 | J13: 90442700000000 | K13: 87539400000000 | L13: 75311300000000 | N13: 0.0119229 | O13: 0.0126483 | P13: 426680000000000 | Q13: 156475000000 | R13: 0 | S13: 0 | T13: 2 | U13: 87887000000000 | V13: 93503200000000 | W13: 91092900000000 | X13: 92625400000000 | Y13: 61571500000000 | AA13: 0.0118829 | AB13: 0.0124741 | AC13: 428948000000000 | AD13: 75337300000 | AE13: 0 | AF13: 0 | AG13: 2 | AH13: 95388000000000 | AI13: 95090500000000 | AJ13: 95047700000000 | AK13: 96825900000000 | AL13: 46595900000000 | AN13: =A13 -> 0.0120692 | AO13: =(C13+P13+AC13)/3 -> 429718333333333 | AP13: =MIN(C13,P13,AC13) -> 426680000000000 | AQ13: =MAX(C13,P13,AC13) -> 433527000000000 | AR13: =(L13+Y13+AL13)/3 -> 6.1159567e+13 | AS13: =MIN(L13,Y13,AL13) -> 46595900000000 | AT13: =MAX(L13,Y13,AL13) -> 75311300000000
A14: 0.0129993 | B14: 0.0139225 | C14: 433934000000000 | D14: 36217400000 | E14: 0 | F14: 0 | G14: 2 | H14: 89026100000000 | I14: 93444400000000 | J14: 89837200000000 | K14: 87928600000000 | L14: 73697100000000 | N14: 0.0130019 | O14: 0.0137577 | P14: 430886000000000 | Q14: 36814800000 | R14: 0 | S14: 0 | T14: 2 | U14: 92247200000000 | V14: 95813900000000 | W14: 93682400000000 | X14: 96886800000000 | Y14: 52226900000000
A15: 0.0139792 | B15: 0.0149485 | C15: 437935000000000 | D15: 245402000000 | E15: 0 | F15: 0 | G15: 2 | H15: 89858100000000 | I15: 93447800000000 | J15: 89342000000000 | K15: 89989300000000 | L15: 75290500000000 | N15: 0.0139389 | O15: 0.0146734 | P15: 433970000000000 | Q15: 42872200000 | R15: 0 | S15: 0 | T15: 2 | U15: 93550000000000 | V15: 95782000000000 | W15: 94483200000000 | X15: 98406200000000 | Y15: 51741000000000
A16: 0.0149929 | B16: 0.0159238 | C16: 438146000000000 | D16: 98373300000 | E16: 0 | F16: 0 | G16: 2 | H16: 89877200000000 | I16: 93685600000000 | J16: 89656200000000 | K16: 88648900000000 | L16: 76230300000000 | N16: 0.0149368 | O16: 0.0155838 | P16: 430022000000000 | Q16: 38016700000 | R16: 0 | S16: 0 | T16: 2 | U16: 92280400000000 | V16: 95065800000000 | W16: 91801800000000 | X16: 99069500000000 | Y16: 51804000000000
A17: 0.016016 | B17: 0.0169913 | C17: 438720000000000 | D17: 21216400000 | E17: 0 | F17: 0 | G17: 2 | H17: 91411400000000 | I17: 93361600000000 | J17: 88646200000000 | K17: 84640500000000 | L17: 80659200000000 | N17: 0.0159799 | O17: 0.0166055 | P17: 428223000000000 | Q17: 59568400000 | R17: 0 | S17: 0 | T17: 2 | U17: 92341000000000 | V17: 95749300000000 | W17: 92078700000000 | X17: 100293000000000 | Y17: 47759900000000
A18: 0.0169786 | B18: 0.017931 | C18: 442566000000000 | D18: 21890200000 | E18: 0 | F18: 0 | G18: 2 | H18: 89228100000000 | I18: 94784700000000 | J18: 88200800000000 | K18: 82846100000000 | L18: 87504700000000 | N18: 0.0168151 | O18: 0.0174534 | P18: 426984000000000 | Q18: 27899900000 | R18: 0 | S18: 0 | T18: 2 | U18: 91930100000000 | V18: 95686500000000 | W18: 91560500000000 | X18: 99392900000000 | Y18: 48414200000000
A19: 0.0179804 | B19: 0.0188459 | C19: 442975000000000 | D19: 104545000000 | E19: 0 | F19: 0 | G19: 2 | H19: 86272000000000 | I19: 94620500000000 | J19: 86475100000000 | K19: 81325900000000 | L19: 94280900000000 | N19: 0.0180751 | O19: 0.0186838 | P19: 426533000000000 | Q19: 28166200000 | R19: 0 | S19: 0 | T19: 2 | U19: 92185000000000 | V19: 96600800000000 | W19: 91485800000000 | X19: 99265300000000 | Y19: 46995700000000
A20: 0.0189697 | B20: 0.0198232 | C20: 443934000000000 | D20: 195012000000 | E20: 0 | F20: 0 | G20: 2 | H20: 85765500000000 | I20: 91886900000000 | J20: 83678200000000 | K20: 76183200000000 | L20: 106419000000000 | N20: 0.0189972 | O20: 0.0195913 | P20: 426631000000000 | Q20: 59676400000 | R20: 0 | S20: 0 | T20: 2 | U20: 91134400000000 | V20: 97657500000000 | W20: 91501200000000 | X20: 99429800000000 | Y20: 46908000000000
A21: 0.0199925 | B21: 0.0208121 | C21: 446450000000000 | D21: 18354900000 | E21: 0 | F21: 0 | G21: 2 | H21: 86340300000000 | I21: 89205800000000 | J21: 77236100000000 | K21: 70076000000000 | L21: 123591000000000 | N21: 0.0200119 | O21: 0.0206231 | P21: 426978000000000 | Q21: 43326700000 | R21: 0 | S21: 0 | T21: 2 | U21: 90872200000000 | V21: 98225900000000 | W21: 91372100000000 | X21: 100396000000000 | Y21: 46112700000000
A22: 0.0210047 | B22: 0.0218439 | C22: 451170000000000 | D22: 21980600000 | E22: 0 | F22: 0 | G22: 2 | H22: 87844100000000 | I22: 89055900000000 | J22: 73307600000000 | K22: 64914900000000 | L22: 136047000000000 | N22: 0.0210762 | O22: 0.0216367 | P22: 426435000000000 | Q22: 63666200000 | R22: 0 | S22: 0 | T22: 2 | U22: 89991800000000 | V22: 98621900000000 | W22: 90651500000000 | X22: 100889000000000 | Y22: 46280700000000
A23: 0.0219883 | B23: 0.0227907 | C23: 452909000000000 | D23: 19734300000 | E23: 0 | F23: 0 | G23: 2 | H23: 86265700000000 | I23: 88247400000000 | J23: 68153900000000 | K23: 59948400000000 | L23: 150291000000000 | N23: 0.0220045 | O23: 0.0226135 | P23: 426987000000000 | Q23: 29901200000 | R23: 0 | S23: 0 | T23: 2 | U23: 90821500000000 | V23: 98542400000000 | W23: 91856600000000 | X23: 101542000000000 | Y23: 44224500000000
A24: 0.022975 | B24: 0.0237708 | C24: 450390000000000 | D24: 47770600000 | E24: 0 | F24: 0 | G24: 2 | H24: 83764400000000 | I24: 88461300000000 | J24: 65843100000000 | K24: 57156100000000 | L24: 155157000000000 | N24: 0.0230589 | O24: 0.0236232 | P24: 426639000000000 | Q24: 110103000000 | R24: 0 | S24: 0 | T24: 2 | U24: 90238400000000 | V24: 99244900000000 | W24: 91047600000000 | X24: 101630000000000 | Y24: 44478700000000
A25: 0.0240369 | B25: 0.0248436 | C25: 450504000000000 | D25: 11123000000 | E25: 0 | F25: 0 | G25: 2 | H25: 82589100000000 | I25: 88940500000000 | J25: 64523400000000 | K25: 55824900000000 | L25: 158613000000000 | N25: 0.023955 | O25: 0.0245178 | P25: 425812000000000 | Q25: 48950700000 | R25: 0 | S25: 0 | T25: 2 | U25: 89974800000000 | V25: 99345900000000 | W25: 90318300000000 | X25: 100430000000000 | Y25: 45742200000000
A26: 0.0249957 | B26: 0.0258231 | C26: 447228000000000 | D26: 7859280000 | E26: 0 | F26: 0 | G26: 2 | H26: 83496900000000 | I26: 88635500000000 | J26: 61993500000000 | K26: 54625500000000 | L26: 158416000000000
A27: 0.0260109 | B27: 0.0268427 | C27: 448039000000000 | D27: 19420000000 | E27: 0 | F27: 0 | G27: 2 | H27: 84205700000000 | I27: 88948700000000 | J27: 61148400000000 | K27: 54657900000000 | L27: 158939000000000
A28: 0.0270271 | B28: 0.0278565 | C28: 450273000000000 | D28: 4210070000 | E28: 0 | F28: 0 | G28: 2 | H28: 85141600000000 | I28: 91151100000000 | J28: 61786200000000 | K28: 55177100000000 | L28: 157005000000000
A29: 0.0280122 | B29: 0.028878 | C29: 449674000000000 | D29: 6378550000 | E29: 0 | F29: 0 | G29: 2 | H29: 85567200000000 | I29: 92209200000000 | J29: 61021200000000 | K29: 53534400000000 | L29: 157327000000000
A30: 0.0289998 | B30: 0.0299018 | C30: 450277000000000 | D30: 50948800000 | E30: 0 | F30: 0 | G30: 2 | H30: 84907000000000 | I30: 92204900000000 | J30: 60588500000000 | K30: 52855600000000 | L30: 159717000000000
A31: 0.0300117 | B31: 0.0309265 | C31: 449963000000000 | D31: 61029700000 | E31: 0 | F31: 0 | G31: 2 | H31: 84101300000000 | I31: 90755000000000 | J31: 60213900000000 | K31: 51292800000000 | L31: 163595000000000
A32: 0.0309902 | B32: 0.0318482 | C32: 450102000000000 | D32: 13332300000 | E32: 0 | F32: 0 | G32: 2 | H32: 85453600000000 | I32: 91333700000000 | J32: 61144700000000 | K32: 52329700000000 | L32: 159834000000000
A33: 0.0319913 | B33: 0.0328654 | C33: 445042000000000 | D33: 51051500000 | E33: 0 | F33: 0 | G33: 2 | H33: 83432200000000 | I33: 87390100000000 | J33: 60354800000000 | K33: 47303000000000 | L33: 166546000000000
A34: 0.0330492 | B34: 0.0339931 | C34: 441458000000000 | D34: 46896700000 | E34: 0 | F34: 0 | G34: 2 | H34: 83315400000000 | I34: 82751100000000 | J34: 62603200000000 | K34: 46143100000000 | L34: 166634000000000
A35: 0.0341097 | B35: 0.0350778 | C35: 438482000000000 | D35: 17911500000 | E35: 0 | F35: 0 | G35: 2 | H35: 82668600000000 | I35: 78574300000000 | J35: 60673500000000 | K35: 42424000000000 | L35: 174133000000000

Sheet 400K_SR40_Stress
A1: Config | B1: 1 | D1: Config 2 | G1: Config3 | J1: AverageValue of Last 0.5%
A2: 0.00092756 | B2: 154770000 | D2: 0.00104593 | E2: 116475000 | G2: 0.000972836 | H2: 114268000 | K2: TotalStress | L2: RhoI | M2: Rho | N2: TauF1 | O2: TauF2 | P2: TauF | Q2: Tau | R2: Tau/TauF | S2: RhoI/Rho
A3: 0.00207021 | B3: 173930000 | D3: 0.00200804 | E3: 133135000 | G3: 0.0019911 | H3: 116546000 | J3: C1 | K3: =AVERAGE(B26:B31)/1000000 -> 180.86117 | L3: =AVERAGE('400K_SR40'!L28:L32) -> 159495600000000 | M3: =AVERAGE('400K_SR40'!C28:C32) -> 450057800000000 | N3: =Graphs!$B$1*80.9*0.248*SQRT(L3)/1000000 -> 82.348922 | O3: =Graphs!$B$2*80.9*0.248*SQRT(M3)/1000000 -> 21.281604 | P3: =SQRT(N3^2+O3^2) -> 85.054404 | Q3: =K3*0.4707 -> 85.131351 | R3: =Q3/P3 -> 1.0009047 | S3: =L3/M3 -> 0.35438915
A4: 0.00294065 | B4: 180359000 | D4: 0.00305486 | E4: 147073000 | G4: 0.00296189 | H4: 140825000 | J4: C2 | K4: =AVERAGE(E26:E31)/1000000 -> #DIV/0! | L4: =AVERAGE('400K_SR40'!Y28:Y32) -> #DIV/0! | M4: =AVERAGE('400K_SR40'!P28:P32) -> #DIV/0! | N4: =Graphs!$B$1*80.9*0.248*SQRT(L4)/1000000 -> #DIV/0! | O4: =Graphs!$B$2*80.9*0.248*SQRT(M4)/1000000 -> #DIV/0! | P4: =SQRT(N4^2+O4^2) -> #DIV/0! | Q4: =K4*0.4707 -> #DIV/0! | R4: =Q4/P4 -> #DIV/0! | S4: =L4/M4 -> #DIV/0!
A5: 0.00401055 | B5: 175163000 | D5: 0.00403945 | E5: 151326000 | G5: 0.00400461 | H5: 135698000 | J5: C3 | K5: =AVERAGE(H26:H29)/1000000 -> #DIV/0! | L5: =AVERAGE('400K_SR40'!AL28:AL32) -> #DIV/0! | M5: =AVERAGE('400K_SR40'!AC28:AC32) -> #DIV/0! | N5: =Graphs!$B$1*80.9*0.248*SQRT(L5)/1000000 -> #DIV/0! | O5: =Graphs!$B$2*80.9*0.248*SQRT(M5)/1000000 -> #DIV/0! | P5: =SQRT(N5^2+O5^2) -> #DIV/0! | Q5: =K5*0.4707 -> #DIV/0! | R5: =Q5/P5 -> #DIV/0! | S5: =L5/M5 -> #DIV/0!
A6: 0.00498831 | B6: 181789000 | D6: 0.00497604 | E6: 152235000 | G6: 0.00495574 | H6: 137014000
A7: 0.00597565 | B7: 179478000 | D7: 0.00601587 | E7: 144367000 | G7: 0.00603446 | H7: 134997000
A8: 0.00709854 | B8: 182370000 | D8: 0.00699331 | E8: 150875000 | G8: 0.00695306 | H8: 135127000
A9: 0.00793644 | B9: 184268000 | D9: 0.00792334 | E9: 160983000 | G9: 0.00806867 | H9: 122028000
A10: 0.00903514 | B10: 189406000 | D10: 0.00881076 | E10: 152994000 | G10: 0.00896638 | H10: 123633000
A11: 0.00989916 | B11: 213005000 | D11: 0.00995094 | E11: 143607000 | G11: 0.00999492 | H11: 124037000 | J11: 1-1.5%
A12: 0.011033 | B12: 222248000 | D12: 0.0109953 | E12: 150443000 | G12: 0.0109973 | H12: 127387000 | J12: C1 | K12: =AVERAGE(B12:B16)/1000000 -> 205.5338 | L12: =AVERAGE('400K_SR40'!L12:L16) -> 74905020000000 | M12: =AVERAGE('400K_SR40'!C12:C16) -> 434244000000000 | N12: =Graphs!$B$1*80.9*0.248*SQRT(L12)/1000000 -> 56.433765 | O12: =Graphs!$B$2*80.9*0.248*SQRT(M12)/1000000 -> 20.904372 | P12: =SQRT(N12^2+O12^2) -> 60.181082 | Q12: =K12*0.4707 -> 96.74476 | R12: =Q12/P12 -> 1.607561 | S12: =L12/M12 -> 0.17249523
A13: 0.0120692 | B13: 212890000 | D13: 0.0119229 | E13: 152218000 | G13: 0.0118829 | H13: 124035000 | J13: C2 | K13: =AVERAGE(E12:E16)/1000000 -> 150.2312 | L13: =AVERAGE('400K_SR40'!Y12:Y16) -> 55463900000000 | M13: =AVERAGE('400K_SR40'!P12:P16) -> 429487800000000 | N13: =Graphs!$B$1*80.9*0.248*SQRT(L13)/1000000 -> 48.561128 | O13: =Graphs!$B$2*80.9*0.248*SQRT(M13)/1000000 -> 20.789576 | P13: =SQRT(N13^2+O13^2) -> 52.824138 | Q13: =K13*0.4707 -> 70.713826 | R13: =Q13/P13 -> 1.338665 | S13: =L13/M13 -> 0.12913964
A14: 0.0129993 | B14: 193745000 | D14: 0.0130019 | E14: 158608000 | J14: C3 | K14: =AVERAGE(H12:H16)/1000000 -> 125.711 | L14: =AVERAGE('400K_SR40'!AL12:AL16) -> 47698250000000 | M14: =AVERAGE('400K_SR40'!AC12:AC16) -> 428208000000000 | N14: =Graphs!$B$1*80.9*0.248*SQRT(L14)/1000000 -> 45.033405 | O14: =Graphs!$B$2*80.9*0.248*SQRT(M14)/1000000 -> 20.758578 | P14: =SQRT(N14^2+O14^2) -> 49.58756 | Q14: =K14*0.4707 -> 59.172168 | R14: =Q14/P14 -> 1.1932865 | S14: =L14/M14 -> 0.11139038
A15: 0.0139792 | B15: 203418000 | D15: 0.0139389 | E15: 154115000
A16: 0.0149929 | B16: 195368000 | D16: 0.0149368 | E16: 135772000
A17: 0.016016 | B17: 204682000 | D17: 0.0159799 | E17: 131273000
A18: 0.0169786 | B18: 199871000 | D18: 0.0168151 | E18: 133922000
A19: 0.0179804 | B19: 181629000 | D19: 0.0180751 | E19: 127716000
A20: 0.0189697 | B20: 179109000 | D20: 0.0189972 | E20: 124653000
A21: 0.0199925 | B21: 171997000 | D21: 0.0200119 | E21: 128234000
A22: 0.0210047 | B22: 176103000 | D22: 0.0210762 | E22: 117611000
A23: 0.0219883 | B23: 168376000 | D23: 0.0220045 | E23: 127784000
A24: 0.022975 | B24: 166977000 | D24: 0.0230589 | E24: 118395000
A25: 0.0240369 | B25: 169288000 | D25: 0.023955 | E25: 118086000
A26: 0.0249957 | B26: 173641000
A27: 0.0260109 | B27: 174550000
A28: 0.0270271 | B28: 174051000
A29: 0.0280122 | B29: 181680000
A30: 0.0289998 | B30: 189277000
A31: 0.0300117 | B31: 191968000
A32: 0.0309902 | B32: 180057000
A33: 0.0319913 | B33: 183432000
A34: 0.0330492 | B34: 198092000
A35: 0.0341097 | B35: 203168000

Sheet 400K_SR100_Stress
A1: Config | B1: 1 | D1: Config 2 | G1: Config3 | J1: AverageValue of Last 0.5%
A2: 0.00100305 | B2: 133135000 | D2: 0.00096455 | E2: 141072000 | G2: 0.00100922 | H2: 145095000 | K2: TotalStress | L2: RhoI | M2: Rho | N2: TauF1 | O2: TauF2 | P2: TauF | Q2: Tau | R2: Tau/TauF | S2: RhoI/Rho
A3: 0.00195105 | B3: 151436000 | D3: 0.00198499 | E3: 159861000 | G3: 0.00200223 | H3: 157343000 | J3: C1 | K3: =AVERAGE(B27:B31)/1000000 -> 134.5096 | L3: =AVERAGE('400K_SR100'!L28:L32) -> 20713220000000 | M3: =AVERAGE('400K_SR100'!C28:C32) -> 128675600000000 | N3: =Graphs!$B$1*80.9*0.248*SQRT(L3)/1000000 -> 29.676137 | O3: =Graphs!$B$2*80.9*0.248*SQRT(M3)/1000000 -> 11.379372 | P3: =SQRT(N3^2+O3^2) -> 31.783065 | Q3: =K3*0.4707 -> 63.313669 | R3: =Q3/P3 -> 1.9920567 | S3: =L3/M3 -> 0.1609724
A4: 0.00300435 | B4: 147107000 | D4: 0.00298361 | E4: 177334000 | G4: 0.00299889 | H4: 179079000 | J4: C2 | K4: =AVERAGE(E26:E31)/1000000 -> 111.4318 | L4: =AVERAGE('400K_SR100'!Y26:Y31) -> 6.1122033e+13 | M4: =AVERAGE('400K_SR100'!P21:P26) -> 158345500000000 | N4: =Graphs!$B$1*80.9*0.248*SQRT(L4)/1000000 -> 50.977961 | O4: =Graphs!$B$2*80.9*0.248*SQRT(M4)/1000000 -> 12.623305 | P4: =SQRT(N4^2+O4^2) -> 52.517619 | Q4: =K4*0.4707 -> 52.450948 | R4: =Q4/P4 -> 0.9987305 | S4: =L4/M4 -> 0.38600423
A5: 0.00406285 | B5: 152224000 | D5: 0.00405299 | E5: 189427000 | G5: 0.00401574 | H5: 173672000 | J5: C3 | K5: =AVERAGE(H27:H31)/1000000 -> 146.9014 | L5: =AVERAGE('400K_SR100'!AL28:AL32) -> 39632140000000 | M5: =AVERAGE('400K_SR100'!AC28:AC32) -> 172208400000000 | N5: =Graphs!$B$1*80.9*0.248*SQRT(L5)/1000000 -> 41.049448 | O5: =Graphs!$B$2*80.9*0.248*SQRT(M5)/1000000 -> 13.164288 | P5: =SQRT(N5^2+O5^2) -> 43.10865 | Q5: =K5*0.4707 -> 69.146489 | R5: =Q5/P5 -> 1.604005 | S5: =L5/M5 -> 0.23014057
A6: 0.00491866 | B6: 150657000 | D6: 0.00499286 | E6: 191513000 | G6: 0.00498702 | H6: 179048000
A7: 0.00588823 | B7: 152861000 | D7: 0.00596458 | E7: 188496000 | G7: 0.00606104 | H7: 166694000
A8: 0.00700253 | B8: 148531000 | D8: 0.00703084 | E8: 182395000 | G8: 0.00705237 | H8: 171296000
A9: 0.00808125 | B9: 157635000 | D9: 0.00797811 | E9: 177427000 | G9: 0.00808073 | H9: 171607000
A10: 0.00900344 | B10: 157475000 | D10: 0.00899288 | E10: 184501000 | G10: 0.00908066 | H10: 163539000
A11: 0.00983994 | B11: 159633000 | D11: 0.0099876 | E11: 183676000 | G11: 0.0100073 | H11: 165636000
A12: 0.0109546 | B12: 158334000 | D12: 0.0109844 | E12: 183431000 | G12: 0.0110286 | H12: 164523000
A13: 0.0120175 | B13: 148019000 | D13: 0.0119833 | E13: 177833000 | G13: 0.0120155 | H13: 163538000
A14: 0.0130162 | B14: 138985000 | D14: 0.0130141 | E14: 175879000 | G14: 0.0129099 | H14: 170562000
A15: 0.014014 | B15: 143794000 | D15: 0.0139991 | E15: 172847000 | G15: 0.0139741 | H15: 168225000 | J15: 1-1.5%
A16: 0.015016 | B16: 150247000 | D16: 0.0149295 | E16: 193458000 | G16: 0.0150037 | H16: 152920000 | J16: C1 | K16: =AVERAGE(B12:B16)/1000000 -> 147.8758 | L16: =AVERAGE('400K_SR100'!L12:L16) -> 18017560000000 | M16: =AVERAGE('400K_SR100'!C12:C16) -> 128001000000000 | N16: =Graphs!$B$1*80.9*0.248*SQRT(L16)/1000000 -> 27.677799 | O16: =Graphs!$B$2*80.9*0.248*SQRT(M16)/1000000 -> 11.349504 | P16: =SQRT(N16^2+O16^2) -> 29.914408 | Q16: =K16*0.4707 -> 69.605139 | R16: =Q16/P16 -> 2.3268098 | S16: =L16/M16 -> 0.14076109
A17: 0.0160033 | B17: 146068000 | D17: 0.0160176 | E17: 183819000 | G17: 0.0160084 | H17: 168054000 | J17: C2 | K17: =AVERAGE(E12:E16)/1000000 -> 180.6896 | L17: =AVERAGE('400K_SR100'!Y12:Y16) -> 27495040000000 | M17: =AVERAGE('400K_SR100'!P12:P16) -> 134356400000000 | N17: =Graphs!$B$1*80.9*0.248*SQRT(L17)/1000000 -> 34.190916 | O17: =Graphs!$B$2*80.9*0.248*SQRT(M17)/1000000 -> 11.627849 | P17: =SQRT(N17^2+O17^2) -> 36.114064 | Q17: =K17*0.4707 -> 85.050595 | R17: =Q17/P17 -> 2.3550546 | S17: =L17/M17 -> 0.20464258
A18: 0.0169705 | B18: 141798000 | D18: 0.0169467 | E18: 206434000 | G18: 0.0169991 | H18: 165813000 | J18: C3 | K18: =AVERAGE(H12:H16)/1000000 -> 163.9536 | L18: =AVERAGE('400K_SR100'!AL12:AL16) -> 18663160000000 | M18: =AVERAGE('400K_SR100'!AC12:AC16) -> 130183200000000 | N18: =Graphs!$B$1*80.9*0.248*SQRT(L18)/1000000 -> 28.169306 | O18: =Graphs!$B$2*80.9*0.248*SQRT(M18)/1000000 -> 11.44584 | P18: =SQRT(N18^2+O18^2) -> 30.405872 | Q18: =K18*0.4707 -> 77.17296 | R18: =Q18/P18 -> 2.5380939 | S18: =L18/M18 -> 0.14336074
A19: 0.017963 | B19: 140701000 | D19: 0.0179997 | E19: 201263000 | G19: 0.017996 | H19: 177351000
A20: 0.0190256 | B20: 139286000 | D20: 0.0190322 | E20: 178870000 | G20: 0.0189916 | H20: 173024000
A21: 0.0199899 | B21: 144587000 | D21: 0.0199931 | E21: 178253000 | G21: 0.0199893 | H21: 177340000
A22: 0.0210189 | B22: 136511000 | D22: 0.0209919 | E22: 179369000 | G22: 0.0210129 | H22: 177153000
A23: 0.0220262 | B23: 141857000 | D23: 0.0220331 | E23: 168658000 | G23: 0.0220072 | H23: 179877000
A24: 0.0230102 | B24: 141320000 | D24: 0.0229667 | E24: 159993000 | G24: 0.0229843 | H24: 180974000
A25: 0.0239974 | B25: 145505000 | D25: 0.0239774 | E25: 155129000 | G25: 0.0240046 | H25: 177700000
A26: 0.0248874 | B26: 143613000 | D26: 0.0250117 | E26: 138106000 | G26: 0.0250748 | H26: 162146000
A27: 0.0259781 | B27: 139523000 | D27: 0.0259907 | E27: 125283000 | G27: 0.0259812 | H27: 159914000
A28: 0.0270155 | B28: 131931000 | D28: 0.0269809 | E28: 115659000 | G28: 0.0269566 | H28: 161260000
A29: 0.0279952 | B29: 133028000 | D29: 0.0281636 | E29: 103274000 | G29: 0.0279655 | H29: 147524000
A30: 0.0290926 | B30: 135754000 | D30: 0.0289706 | E30: 96426500 | G30: 0.0289957 | H30: 140054000
... A47: 0.0460726 | B47: 87985000 | D47: 0.0458763 | E47: 46581200 | G47: 0.0459514 | H47: 48987100
A48: 0.0469727 | B48: 82759600 | G48: 0.0470057 | H48: 49622700
A49: 0.0479596 | B49: 81393400 | G49: 0.0480148 | H49: 46195800
A50: 0.0489212 | B50: 82852400 | G50: 0.0489706 | H50: 47272000
A51: 0.0499793 | B51: 82325900 | G51: 0.0499974 | H51: 46928000
A52: 0.0510426 | B52: 84656400
A53: 0.0520212 | B53: 86988100
A54: 0.0529936 | B54: 87179600
A55: 0.0540112 | B55: 85878100
A56: 0.0549946 | B56: 85071300

Sheet 400K_SR100
A1: Config1 | N1: Config2 | AA1: Config3 | AN1: Pstrain | AO1: Total | AP1: Totalmin | AQ1: Totalmax | AR1: Junction | AS1: Junctionmin | AT1: Junctionmax
A2: 0.00100305 | B2: 0.00163748 | C2: 127629000000000 | D2: 8499870000 | E2: 0 | F2: 0 | G2: 2 | H2: 30492100000000 | I2: 30102000000000 | J2: 29643300000000 | K2: 29842100000000 | L2: 7549640000000 | N2: 0.00096455 | O2: 0.0016368 | P2: 127824000000000 | Q2: 22194400000 | R2: 0 | S2: 0 | T2: 2 | U2: 29941100000000 | V2: 29694800000000 | W2: 29994600000000 | X2: 29531300000000 | Y2: 8662350000000 | AA2: 0.00100922 | AB2: 0.00170064 | AC2: 128466000000000 | AD2: 8021510000 | AE2: 0 | AF2: 0 | AG2: 2 | AH2: 30153800000000 | AI2: 30085700000000 | AJ2: 30148700000000 | AK2: 29875900000000 | AL2: 8201610000000 | AN2: =A2 -> 0.00100305 | AO2: =(C2+P2+AC2)/3 -> 127973000000000 | AP2: =MIN(C2,P2,AC2) -> 127629000000000 | AQ2: =MAX(C2,P2,AC2) -> 128466000000000 | AR2: =(L2+Y2+AL2)/3 -> 8.1378667e+12 | AS2: =MIN(L2,Y2,AL2) -> 7549640000000 | AT2: =MAX(L2,Y2,AL2) -> 8662350000000
A3: 0.00195105 | B3: 0.00267269 | C3: 128639000000000 | D3: 44111500000 | E3: 0 | F3: 0 | G3: 2 | H3: 29661300000000 | I3: 29281200000000 | J3: 29318300000000 | K3: 28976300000000 | L3: 11402100000000 | N3: 0.00198499 | O3: 0.00274677 | P3: 129130000000000 | Q3: 17786500000 | R3: 0 | S3: 0 | T3: 2 | U3: 27945600000000 | V3: 28637500000000 | W3: 27757000000000 | X3: 28040000000000 | Y3: 16749800000000 | AA3: 0.00200223 | AB3: 0.00275202 | AC3: 128441000000000 | AD3: 23279500000 | AE3: 0 | AF3: 0 | AG3: 2 | AH3: 28142900000000 | AI3: 28072200000000 | AJ3: 28585900000000 | AK3: 28289600000000 | AL3: 15350800000000 | AN3: =A3 -> 0.00195105 | AO3: =(C3+P3+AC3)/3 -> 128736666666667 | AP3: =MIN(C3,P3,AC3) -> 128441000000000 | AQ3: =MAX(C3,P3,AC3) -> 129130000000000 | AR3: =(L3+Y3+AL3)/3 -> 14500900000000 | AS3: =MIN(L3,Y3,AL3) -> 11402100000000 | AT3: =MAX(L3,Y3,AL3) -> 16749800000000
A4: 0.00300435 | B4: 0.00370536 | C4: 128629000000000 | D4: 7714150000 | E4: 0 | F4: 0 | G4: 2 | H4: 29047700000000 | I4: 28483900000000 | J4: 29001800000000 | K4: 28465900000000 | L4: 13627600000000 | N4: 0.00298361 | O4: 0.00382865 | P4: 129674000000000 | Q4: 12891600000 | R4: 0 | S4: 0 | T4: 2 | U4: 26564200000000 | V4: 27431800000000 | W4: 27337400000000 | X4: 26905400000000 | Y4: 21418300000000 | AA4: 0.00299889 | AB4: 0.00385225 | AC4: 129393000000000 | AD4: 63186600000 | AE4: 0 | AF4: 0 | AG4: 2 | AH4: 27686900000000 | AI4: 27293800000000 | AJ4: 27483300000000 | AK4: 27910400000000 | AL4: 18986000000000 | AN4: =A4 -> 0.00300435 | AO4: =(C4+P4+AC4)/3 -> 129232000000000 | AP4: =MIN(C4,P4,AC4) -> 128629000000000 | AQ4: =MAX(C4,P4,AC4) -> 129674000000000 | AR4: =(L4+Y4+AL4)/3 -> 1.8010633e+13 | AS4: =MIN(L4,Y4,AL4) -> 13627600000000 | AT4: =MAX(L4,Y4,AL4) -> 21418300000000
A5: 0.00406285 | B5: 0.00478823 | C5: 128166000000000 | D5: 8892800000 | E5: 0 | F5: 0 | G5: 2 | H5: 28634400000000 | I5: 27704600000000 | J5: 28504900000000 | K5: 27771900000000 | L5: 15549400000000 | N5: 0.00405299 | O5: 0.00495565 | P5: 129396000000000 | Q5: 6767290000 | R5: 0 | S5: 0 | T5: 2 | U5: 25569800000000 | V5: 25660400000000 | W5: 26315900000000 | X5: 26651200000000 | Y5: 25195200000000 | AA5: 0.00401574 | AB5: 0.00484333 | AC5: 129350000000000 | AD5: 28444600000 | AE5: 0 | AF5: 0 | AG5: 2 | AH5: 27113400000000 | AI5: 26680100000000 | AJ5: 26700800000000 | AK5: 28131300000000 | AL5: 20724900000000 | AN5: =A5 -> 0.00406285 | AO5: =(C5+P5+AC5)/3 -> 128970666666667 | AP5: =MIN(C5,P5,AC5) -> 128166000000000 | AQ5: =MAX(C5,P5,AC5) -> 129396000000000 | AR5: =(L5+Y5+AL5)/3 -> 2.0489833e+13 | AS5: =MIN(L5,Y5,AL5) -> 15549400000000 | AT5: =MAX(L5,Y5,AL5) -> 25195200000000
A6: 0.00491866 | B6: 0.00563657 | C6: 128204000000000 | D6: 32050000000 | E6: 0 | F6: 0 | G6: 2 | H6: 28456700000000 | I6: 27165200000000 | J6: 28315400000000 | K6: 27082100000000 | L6: 17184900000000 | N6: 0.00499286 | O6: 0.00590546 | P6: 131741000000000 | Q6: 13853100000 | R6: 0 | S6: 0 | T6: 2 | U6: 26305100000000 | V6: 25824200000000 | W6: 27228700000000 | X6: 26680000000000 | Y6: 25701700000000 | AA6: 0.00498702 | AB6: 0.00584023 | AC6: 129659000000000 | AD6: 9406510000 | AE6: 0 | AF6: 0 | AG6: 2 | AH6: 27893100000000 | AI6: 26846300000000 | AJ6: 26763100000000 | AK6: 27875100000000 | AL6: 20278600000000 | AN6: =A6 -> 0.00491866 | AO6: =(C6+P6+AC6)/3 -> 129868000000000 | AP6: =MIN(C6,P6,AC6) -> 128204000000000 | AQ6: =MAX(C6,P6,AC6) -> 131741000000000 | AR6: =(L6+Y6+AL6)/3 -> 2.1055067e+13 | AS6: =MIN(L6,Y6,AL6) -> 17184900000000 | AT6: =MAX(L6,Y6,AL6) -> 25701700000000
A7: 0.00588823 | B7: 0.00661664 | C7: 128443000000000 | D7: 13647700000 | E7: 0 | F7: 0 | G7: 2 | H7: 28131300000000 | I7: 27272400000000 | J7: 27409500000000 | K7: 26986200000000 | L7: 18643400000000 | N7: 0.00596458 | O7: 0.00686281 | P7: 132850000000000 | Q7: 8569800000 | R7: 0 | S7: 0 | T7: 2 | U7: 26566000000000 | V7: 25774000000000 | W7: 26656300000000 | X7: 27550600000000 | Y7: 26302500000000 | AA7: 0.00606104 | AB7: 0.00685537 | AC7: 130213000000000 | AD7: 14406400000 | AE7: 0 | AF7: 0 | AG7: 2 | AH7: 27883100000000 | AI7: 27641000000000 | AJ7: 26810000000000 | AK7: 27761100000000 | AL7: 20115700000000 | AN7: =A7 -> 0.00588823 | AO7: =(C7+P7+AC7)/3 -> 130502000000000 | AP7: =MIN(C7,P7,AC7) -> 128443000000000 | AQ7: =MAX(C7,P7,AC7) -> 132850000000000 | AR7: =(L7+Y7+AL7)/3 -> 21687200000000 | AS7: =MIN(L7,Y7,AL7) -> 18643400000000 | AT7: =MAX(L7,Y7,AL7) -> 26302500000000
A8: 0.00700253 | B8: 0.00771032 | C8: 128655000000000 | D8: 37009300000 | E8: 0 | F8: 0 | G8: 2 | H8: 28075100000000 | I8: 26810900000000 | J8: 28166900000000 | K8: 27034800000000 | L8: 18567100000000 | N8: 0.00703084 | O8: 0.00789999 | P8: 131671000000000 | Q8: 199981000000 | R8: 0 | S8: 0 | T8: 2 | U8: 26467300000000 | V8: 24994900000000 | W8: 26125000000000 | X8: 26526300000000 | Y8: 27520500000000 | AA8: 0.00705237 | AB8: 0.00786864 | AC8: 130737000000000 | AD8: 9163660000 | AE8: 0 | AF8: 0 | AG8: 2 | AH8: 28016400000000 | AI8: 27814700000000 | AJ8: 27365200000000 | AK8: 27728100000000 | AL8: 19812200000000 | AN8: =A8 -> 0.00700253 | AO8: =(C8+P8+AC8)/3 -> 130354333333333 | AP8: =MIN(C8,P8,AC8) -> 128655000000000 | AQ8: =MAX(C8,P8,AC8) -> 131671000000000 | AR8: =(L8+Y8+AL8)/3 -> 21966600000000 | AS8: =MIN(L8,Y8,AL8) -> 18567100000000 | AT8: =MAX(L8,Y8,AL8) -> 27520500000000
A9: 0.00808125 | B9: 0.00883247 | C9: 128312000000000 | D9: 10869300000 | E9: 0 | F9: 0 | G9: 2 | H9: 28512500000000 | I9: 27226600000000 | J9: 28201100000000 | K9: 27486900000000 | L9: 16884800000000 | N9: 0.00797811 | O9: 0.00882359 | P9: 130929000000000 | Q9: 20329300000 | R9: 0 | S9: 0 | T9: 2 | U9: 26462100000000 | V9: 25520700000000 | W9: 26889800000000 | X9: 26876800000000 | Y9: 25164300000000 | AA9: 0.00808073 | AB9: 0.00889849 | AC9: 130386000000000 | AD9: 13772400000 | AE9: 0 | AF9: 0 | AG9: 2 | AH9: 28244800000000 | AI9: 27676000000000 | AJ9: 27600000000000 | AK9: 28314700000000 | AL9: 18549100000000 | AN9: =A9 -> 0.00808125 | AO9: =(C9+P9+AC9)/3 -> 129875666666667 | AP9: =MIN(C9,P9,AC9) -> 128312000000000 | AQ9: =MAX(C9,P9,AC9) -> 130929000000000 | AR9: =(L9+Y9+AL9)/3 -> 20199400000000 | AS9: =MIN(L9,Y9,AL9) -> 16884800000000 | AT9: =MAX(L9,Y9,AL9) -> 25164300000000
A10: 0.00900344 | B10: 0.00975394 | C10: 127876000000000 | D10: 15473000000 | E10: 0 | F10: 0 | G10: 2 | H10: 28569100000000 | I10: 27555100000000 | J10: 28091500000000 | K10: 26807900000000 | L10: 16852400000000 | N10: 0.00899288 | O10: 0.00987207 | P10: 130240000000000 | Q10: 10189600000 | R10: 0 | S10: 0 | T10: 2 | U10: 25245300000000 | V10: 25034200000000 | W10: 26509100000000 | X10: 27130100000000 | Y10: 26321500000000 | AA10: 0.00908066 | AB10: 0.00985999 | AC10: 130294000000000 | AD10: 52548600000 | AE10: 0 | AF10: 0 | AG10: 2 | AH10: 28597600000000 | AI10: 27353200000000 | AJ10: 27579100000000 | AK10: 27934500000000 | AL10: 18828400000000 | AN10: =A10 -> 0.00900344 | AO10: =(C10+P10+AC10)/3 -> 129470000000000 | AP10: =MIN(C10,P10,AC10) -> 127876000000000 | AQ10: =MAX(C10,P10,AC10) -> 130294000000000 | AR10: =(L10+Y10+AL10)/3 -> 2.0667433e+13 | AS10: =MIN(L10,Y10,AL10) -> 16852400000000 | AT10: =MAX(L10,Y10,AL10) -> 26321500000000
A11: 0.00983994 | B11: 0.0106007 | C11: 127798000000000 | D11: 20887900000 | E11: 0 | F11: 0 | G11: 2 | H11: 28182300000000 | I11: 27005400000000 | J11: 27648200000000 | K11: 26171300000000 | L11: 18790200000000 | N11: 0.0099876 | O11: 0.0108629 | P11: 131620000000000 | Q11: 12422100000 | R11: 0 | S11: 0 | T11: 2 | U11: 25548800000000 | V11: 26161700000000 | W11: 26832700000000 | X11: 27507400000000 | Y11: 25566000000000 | AA11: 0.0100073 | AB11: 0.0107966 | AC11: 130647000000000 | AD11: 8177290000 | AE11: 0 | AF11: 0 | AG11: 2 | AH11: 28612300000000 | AI11: 28061200000000 | AJ11: 27725400000000 | AK11: 28548600000000 | AL11: 17689500000000 | AN11: =A11 -> 0.00983994 | AO11: =(C11+P11+AC11)/3 -> 130021666666667 | AP11: =MIN(C11,P11,AC11) -> 127798000000000 | AQ11: =MAX(C11,P11,AC11) -> 131620000000000 | AR11: =(L11+Y11+AL11)/3 -> 20681900000000 | AS11: =MIN(L11,Y11,AL11) -> 17689500000000 | AT11: =MAX(L11,Y11,AL11) -> 25566000000000
A12: 0.0109546 | B12: 0.0117092 | C12: 128406000000000 | D12: 14925200000 | E12: 0 | F12: 0 | G12: 2 | H12: 28958300000000 | I12: 27138600000000 | J12: 27857300000000 | K12: 26885000000000 | L12: 17566800000000 | N12: 0.0109844 | O12: 0.0118584 | P12: 133996000000000 | Q12: 15732300000 | R12: 0 | S12: 0 | T12: 2 | U12: 26013800000000 | V12: 28426200000000 | W12: 27617900000000 | X12: 28835200000000 | Y12: 23100800000000 | AA12: 0.0110286 | AB12: 0.0118127 | AC12: 130392000000000 | AD12: 10851000000 | AE12: 0 | AF12: 0 | AG12: 2 | AH12: 28177100000000 | AI12: 28240600000000 | AJ12: 27534300000000 | AK12: 28972200000000 | AL12: 17465600000000 | AN12: =A12 -> 0.0109546 | AO12: =(C12+P12+AC12)/3 -> 130931333333333 | AP12: =MIN(C12,P12,AC12) -> 128406000000000 | AQ12: =MAX(C12,P12,AC12) -> 133996000000000 | AR12: =(L12+Y12+AL12)/3 -> 1.9377733e+13 | AS12: =MIN(L12,Y12,AL12) -> 17465600000000 | AT12: =MAX(L12,Y12,AL12) -> 23100800000000
A13: 0.0120175 | B13: 0.0127229 | C13: 128001000000000 | D13: 18592800000 | E13: 0 | F13: 0 | G13: 2 | H13: 28655200000000 | I13: 27224100000000 | J13: 27798700000000 | K13: 27387000000000 | L13: 16934600000000 | N13: 0.0119833 | O13: 0.0128307 | P13: 135111000000000 | Q13: 13181200000 | R13: 0 | S13: 0 | T13: 2 | U13: 26784800000000 | V13: 26818000000000 | W13: 27824800000000 | X13: 27954300000000 | Y13: 25728400000000 | AA13: 0.0120155 | AB13: 0.0127948 | AC13: 130519000000000 | AD13: 3482290000 | AE13: 0 | AF13: 0 | AG13: 2 | AH13: 28566600000000 | AI13: 27712300000000 | AJ13: 27841700000000 | AK13: 28372900000000 | AL13: 18019200000000 | AN13: =A13 -> 0.0120175 | AO13: =(C13+P13+AC13)/3 -> 131210333333333 | AP13: =MIN(C13,P13,AC13) -> 128001000000000 | AQ13: =MAX(C13,P13,AC13) -> 135111000000000 | AR13: =(L13+Y13+AL13)/3 -> 20227400000000 | AS13: =MIN(L13,Y13,AL13) -> 16934600000000 | AT13: =MAX(L13,Y13,AL13) -> 25728400000000
